Workbook

Sheet Veiledning
A1: Starte egen elektrobedrift — startbudsjett, kapitalbehov og likviditet
A2: LØM · Økonomistyring, tema under kapittel 1 · Fagskolen Oslo, Elkraft · Øvingsark
A4: Dette regnearket følger Nordlys Elektro AS gjennom oppstartsåret 2019, da Kari Nordlund og Tom Berg startet for seg selv. Tallene er de samme som i kapittel 6 om kapitalbehov og finansiering, med et startbudsjett og en likviditetsplan lagt oppå.
A6: Slik bruker du arket
A7: Gule celler med blå skrift er inndata. Alt annet regnes ut. Endre ett tall om gangen og se hva som skjer med bunnlinja og med kontoen.
A8: Arkene bygger på hverandre: Kapitalbehov sier hvor mye penger som må inn før første faktura. Startbudsjett sier om driften bærer seg i løpet av året. Likviditet sier om pengene holder måned for måned — det er det siste som avgjør om bedriften overlever år 1.
A9: Arket «Din egen bedrift» er tomt. Fyll inn for en bedrift du selv kunne tenke deg å starte.
A11: Spørsmål arket kan svare på
A12: Hvor mye må Kari og Tom skyte inn selv, og hvor mye må banken låne dem?
A13: Går Nordlys med overskudd i oppstartsåret? Hvor mye må de selge for å gå i null?
A14: Hvorfor kan kontoen være full av penger samtidig som resultatet er negativt — og hva skjer året etter?
A15: Hva skjer med kontoen i januar hvis de ikke har kassekreditt?
... A21: Kilde: Hjertnes og Skorpen, Økonomistyring for LØM-emnet, kapittel 1 (selskapsform), kapittel 6 (kapitalbehov og finansiering) og kapittel 9 (budsjett). Gebyrer og terskler: brreg.no og skatteetaten.no, oktober 2026.

Sheet Kapitalbehov og finansiering
A1: Kapitalbehov og finansiering — Nordlys Elektro AS, før første driftsdag i 2019
A2: Hvor mye penger må inn før første faktura? Samme oppstilling som kapittel 6. Gule celler er inndata.
A4: 1 · Anleggsmidler (det som skal vare i flere år)
A5: Verktøy og utstyr | B5: 850000 | D5: Måleinstrumenter, stiger, lift, verktøykasser til to montører.
A6: Servicebil | B6: 480000 | D6: Brukt varebil med innredning. Alternativ: leasing, se prøv-raden nederst.
A7: Sum anleggsmidler | B7: =B5+B6
A9: 2 · Omløpsmidler (det som bindes i driften)
A10: Budsjettert salg år 1, ekskl. mva | B10: 7200000 | D10: 9 000 000 inkl. mva. Grunnlaget for alt nedenfor.
A11: Bruttofortjeneste, andel av salg | B11: 0.45 | D11: Salg minus materiell og innleie. 45 % i oppstartsåret; 62,5 % i 2026.
A12: Varekostnad år 1, ekskl. mva | B12: =B10*(1-B11)
A13: Varekjøp år 1, inkl. mva | B13: =B12*1.25 | D13: Det er dette beløpet som skal betales til grossisten.
A14: Lagringstid for materiell, dager | B14: 20 | D14: Hvor lenge materiellet ligger på lageret før det monteres.
A15: Varelager | B15: =ROUND(B12/360*B14,0) | D15: Varekostnad per dag × lagringstid. Kapittel 6 bruker 360 dager.
A16: Andel av salget på kreditt | B16: 0.25 | D16: Resten betales kontant eller med kort på stedet.
A17: Kredittid til kundene, dager | B17: 20
A18: Kundefordringer | B18: =ROUND(B10*1.25*B16/360*B17,0) | D18: Kredittsalg inkl. mva per dag × kredittid — det er fakturabeløpet kunden skylder.
A19: Reserve (kasse og bank) | B19: 200000 | D19: Buffer til uforutsett. Mange starter uten — og angrer.
A20: Sum omløpsmidler | B20: =B15+B18+B19
A22: 3 · Kapitalbehov
A23: Kapitalbehov = anleggsmidler + omløpsmidler | B23: =B7+B20 | D23: Så mye må finansieres før Nordlys kan sende første faktura.
A25: 4 · Finansiering
A26: Egenkapital, andel av kapitalbehovet | B26: 0.3 | D26: Banken krevde minst 30 %. Aksjekapitalen på 300 000 er en del av dette.
A27: Egenkapital | B27: =ROUND(B23*B26,0)
A28: Leverandørgjeld | B28: =ROUND(B13/360*15,0) | D28: Grossisten gir 15 dagers kreditt: varekjøp inkl. mva per dag × 15.
A29: Kassekreditt og offentlige avgifter | B29: =B23-B27-B28-B30 | D29: Det som er igjen når egenkapital, leverandørgjeld og langsiktig lån er dekket.
A30: Langsiktig lån | B30: 877500 | D30: Banklån over 5 år, med personlig kausjon fra Kari og Tom.
A31: Sum finansiering | B31: =B27+B28+B29+B30
A33: Kontroll | B33: =IF(B31=B23,"OK — finansieringen dekker kapitalbehovet","AVVIK: finansiering og kapitalbehov stemmer ikke")
A35: Prøv dette:
A36: Sett servicebilen (B6) til 0 og tenk deg at den leases for 9 000 kr per måned i stedet. Kapitalbehovet faller med 480 000, men driftskostnadene i startbudsjettet øker med 108 000 i året.
A37: Sett lagringstiden (B14) til 34 dager. Hva skjer med kapitalbehovet og egenkapitalandelen hvis egenkapitalen holdes på 562 500?
A39: Kilde: Hjertnes og Skorpen, Økonomistyring for LØM-emnet, kapittel 6. Tallene er Nordlys Elektro AS' egne fra oppstarten i 2019.

Sheet Startbudsjett år 1
A1: Startbudsjett år 1 — Nordlys Elektro AS, 2019 (ekskl. mva)
A2: Bærer driften seg i oppstartsåret? Gule celler er inndata. Nullpunktet nederst viser hvor mye salg som trengs for å gå i null.
A4: 1 · Salg og varekostnad
A5: Salgsinntekt år 1 | B5: ='Kapitalbehov og finansiering'!B10 | D5: Hentes fra arket Kapitalbehov og finansiering.
A6: Bruttofortjeneste, andel | B6: ='Kapitalbehov og finansiering'!B11
A7: Varekostnad (materiell og innleie) | B7: =B5*(1-B6)
A8: Bruttofortjeneste | B8: =B5-B7
A10: 2 · Lønn
A11: Kari (daglig leder og installatør) | B11: 560000
A12: Tom (montør og prosjektleder) | B12: 500000
A13: Én montør | B13: 460000
A14: Én lærling | B14: 190000
A15: Sum lønn | B15: =SUM(B11:B14)
A16: Sosiale kostnader, andel av lønn | B16: 0.468 | D16: Feriepenger, arbeidsgiveravgift, pensjon, forsikring, sykefravær. Lærebokas tabell 2.4.
A17: Sosiale kostnader | B17: =ROUND(B15*B16,0)
A18: Sum lønnskostnad | B18: =B15+B17
A20: 3 · Andre driftskostnader
A21: Husleie verksted og lager | B21: 180000
A22: Forsikringer (ansvar, bil, yrkesskade) | B22: 55000
A23: Regnskapsfører og revisor | B23: 60000
A24: Telefon, IT og programvare | B24: 45000
A25: Markedsføring og nettside | B25: 30000
A26: Småverktøy og forbruksmateriell | B26: 50000
A27: Kurs og sertifisering | B27: 25000
A28: Drivstoff og bildrift | B28: 70000
A29: Sum andre driftskostnader | B29: =SUM(B21:B28)
A31: 4 · Avskrivninger
A32: Verktøy og utstyr | B32: ='Kapitalbehov og finansiering'!B5
A33: Levetid verktøy og utstyr, år | B33: 5
A34: Servicebil | B34: ='Kapitalbehov og finansiering'!B6
A35: Levetid servicebil, år | B35: 5
A36: Sum avskrivninger | B36: =B32/B33+B34/B35 | D36: Lineær avskrivning: anskaffelseskost delt på levetid.
A38: 5 · Resultat
A39: Driftsresultat | B39: =B8-B18-B29-B36 | D39: Bruttofortjeneste minus lønn, andre driftskostnader og avskrivninger.
A40: Rente langsiktig lån, sats | B40: 0.05
A41: Rente kassekreditt, sats | B41: 0.08 | D41: Regnes av gjennomsnittlig trekk, her satt lik kassekreditt og offentlige avgifter fra arket Kapitalbehov.
A42: Rentekostnad | B42: =ROUND('Kapitalbehov og finansiering'!B30*B40+'Kapitalbehov og finansiering'!B29*B41,0)
A43: Resultat før skatt | B43: =B39-B42 | D43: Negativt i oppstartsåret. Det er ikke uvanlig — men det må være planlagt, og det må finnes penger til å bære det.
A45: 6 · Nullpunkt
A46: Faste kostnader (lønn, andre driftskostnader, avskrivninger, renter) | B46: =B18+B29+B36+B42 | D46: I oppstartsåret regnes all lønn som fast: montørene er ansatt uansett.
...

Sheet Likviditet 12 mnd
A1: Likviditetsbudsjett 2019 — Nordlys Elektro AS, måned for måned (inkl. mva)
A2: Holder pengene? Resultatet kan være negativt mens kontoen er full — og omvendt. Gule celler er inndata.
A4: 1 · Forutsetninger
A5: Andel av salget på kreditt | B5: ='Kapitalbehov og finansiering'!B16
A6: Andel av kredittsalget betalt samme måned | B6: 0.33333333 | D6: 20 dagers kreditt: en tredel kommer inn samme måned, to tredeler måneden etter.
A7: Varekjøp, andel av salget (ekskl. mva) | B7: 0.55 | D7: Her lik varekostnaden. Over 55 % bygger lager, under tærer på det.
A8: Andel av varekjøpet betalt samme måned | B8: 0.5 | D8: 15 dagers kreditt hos grossisten: halvparten samme måned, halvparten neste.
A9: Arbeidsgiveravgift | B9: 0.141 | D9: Betales annenhver måned (15. mars, 15. mai …).
A10: Pensjon (OTP) og personalforsikring, andel av lønn | B10: 0.05 | D10: Betales månedlig. Feriepengene (12 %) opptjenes i 2019 og utbetales i juni 2020 — de er en kostnad i år, men ikke en utbetaling.
A11: Merverdiavgift | B11: 0.25 | D11: Terminer på to måneder, betales 10. i måneden etter terminen (her: måneden etter).
A12: Kassekredittramme | B12: 300000 | D12: Avtalt med banken. Kontoen kan gå så langt i minus.
A13: Avdrag på lån per kvartal (fra 2. kvartal) | B13: ='Kapitalbehov og finansiering'!B30/20 | D13: 5 år = 20 kvartaler.
A14: Rente på lån per kvartal | B14: ='Kapitalbehov og finansiering'!B30*'Startbudsjett år 1'!B40/4 | D14: Betales etterskuddsvis i mars, juni, september og desember.
A16: Måned | B16: Jan | C16: Feb | D16: Mar | E16: Apr | F16: Mai | G16: Jun | H16: Jul | I16: Aug | J16: Sep | K16: Okt | L16: Nov | M16: Des | N16: Sum år | P16: Forklaring
A17: 2 · Salg
A18: Salg ekskl. mva (budsjett) | B18: 450000 | C18: 550000 | D18: 650000 | E18: 650000 | F18: 650000 | G18: 650000 | H18: 350000 | I18: 600000 | J18: 700000 | K18: 700000 | L18: 750000 | M18: 500000 | N18: =SUM(B18:M18) | P18: Fordelingen over året: rolig januar, stille juli, travel høst. Summen skal stemme med startbudsjettet.
A19: Salg inkl. mva | B19: =B18*(1+$B$11) | C19: =C18*(1+$B$11) | D19: =D18*(1+$B$11) | E19: =E18*(1+$B$11) | F19: =F18*(1+$B$11) | G19: =G18*(1+$B$11) | H19: =H18*(1+$B$11) | I19: =I18*(1+$B$11) | ... M19: =M18*(1+$B$11) | N19: =SUM(B19:M19)
A20: Kontroll | B20: =IF(N18='Startbudsjett år 1'!B5,"OK — salget stemmer med startbudsjettet","AVVIK: månedene summerer ikke til årssalget")
A22: 3 · Innbetalinger
A23: Kontantsalg (kort og Vipps) | B23: =B19*(1-$B$5) | C23: =C19*(1-$B$5) | D23: =D19*(1-$B$5) | E23: =E19*(1-$B$5) | F23: =F19*(1-$B$5) | G23: =G19*(1-$B$5) | H23: =H19*(1-$B$5) | I23: =I19*(1-$B$5) | ... M23: =M19*(1-$B$5) | N23: =SUM(B23:M23)
A24: Innbetaling fra kredittkunder | B24: =B19*$B$5*$B$6 | C24: =C19*$B$5*$B$6+B19*$B$5*(1-$B$6) | D24: =D19*$B$5*$B$6+C19*$B$5*(1-$B$6) | E24: =E19*$B$5*$B$6+D19*$B$5*(1-$B$6) | F24: =F19*$B$5*$B$6+E19*$B$5*(1-$B$6) | G24: =G19*$B$5*$B$6+F19*$B$5*(1-$B$6) | H24: =H19*$B$5*$B$6+G19*$B$5*(1-$B$6) | I24: =I19*$B$5*$B$6+H19*$B$5*(1-$B$6) | J24: =J19*$B$5*$B$6+I19*$B$5*(1-$B$6) | ... M24: =M19*$B$5*$B$6+L19*$B$5*(1-$B$6) | N24: =SUM(B24:M24) | P24: Kundene som får faktura. Det siste av desembersalget kommer inn i januar 2020.
A25: Egenkapital innbetalt | B25: ='Kapitalbehov og finansiering'!B27 | C25: 0 | D25: 0 | E25: 0 | F25: 0 | G25: 0 | H25: 0 | I25: 0 | J25: 0 | K25: 0 | L25: 0 | M25: 0 | N25: =SUM(B25:M25) | P25: Aksjekapital og annen egenkapital, inn i januar.
A26: Langsiktig lån utbetalt | B26: ='Kapitalbehov og finansiering'!B30 | C26: 0 | D26: 0 | E26: 0 | F26: 0 | G26: 0 | H26: 0 | I26: 0 | J26: 0 | K26: 0 | L26: 0 | M26: 0 | N26: =SUM(B26:M26)
A27: Mva til gode (refusjon) | B27: =MAX(0,-B52) | C27: =MAX(0,-C52) | D27: =MAX(0,-D52) | E27: =MAX(0,-E52) | F27: =MAX(0,-F52) | G27: =MAX(0,-G52) | H27: =MAX(0,-H52) | I27: =MAX(0,-I52) | ... M27: =MAX(0,-M52) | N27: =SUM(B27:M27) | P27: Når inngående mva er større enn utgående, får bedriften penger tilbake. Skjer i mars etter utstyrskjøpet i januar.
A28: Sum innbetalinger | B28: =SUM(B23:B27) | C28: =SUM(C23:C27) | D28: =SUM(D23:D27) | E28: =SUM(E23:E27) | F28: =SUM(F23:F27) | G28: =SUM(G23:G27) | H28: =SUM(H23:H27) | I28: =SUM(I23:I27) | ... M28: =SUM(M23:M27) | N28: =SUM(B28:M28)
A30: 4 · Utbetalinger
A31: Investering i verktøy, utstyr og bil (inkl. mva) | B31: ='Kapitalbehov og finansiering'!B7*(1+$B$11) | C31: 0 | D31: 0 | E31: 0 | F31: 0 | G31: 0 | H31: 0 | I31: 0 | J31: 0 | K31: 0 | L31: 0 | M31: 0 | N31: =SUM(B31:M31) | P31: Betales i januar, inkl. mva. Mva-delen kommer tilbake i mars.
A32: Varekjøp inkl. mva | B32: =B18*$B$7*(1+$B$11) | C32: =C18*$B$7*(1+$B$11) | D32: =D18*$B$7*(1+$B$11) | E32: =E18*$B$7*(1+$B$11) | F32: =F18*$B$7*(1+$B$11) | G32: =G18*$B$7*(1+$B$11) | H32: =H18*$B$7*(1+$B$11) | I32: =I18*$B$7*(1+$B$11) | ... M32: =M18*$B$7*(1+$B$11) | N32: =SUM(B32:M32)
A33: Betalt til grossist | B33: =B32*$B$8 | C33: =C32*$B$8+B32*(1-$B$8) | D33: =D32*$B$8+C32*(1-$B$8) | E33: =E32*$B$8+D32*(1-$B$8) | F33: =F32*$B$8+E32*(1-$B$8) | G33: =G32*$B$8+F32*(1-$B$8) | H33: =H32*$B$8+G32*(1-$B$8) | I33: =I32*$B$8+H32*(1-$B$8) | J33: =J32*$B$8+I32*(1-$B$8) | ... M33: =M32*$B$8+L32*(1-$B$8) | N33: =SUM(B33:M33) | P33: Halvparten samme måned, resten neste måned. Desemberkjøpet betales ferdig i januar 2020.
A34: Lønn utbetalt | B34: ='Startbudsjett år 1'!$B$15/12 | C34: ='Startbudsjett år 1'!$B$15/12 | D34: ='Startbudsjett år 1'!$B$15/12 | E34: ='Startbudsjett år 1'!$B$15/12 | F34: ='Startbudsjett år 1'!$B$15/12 | G34: ='Startbudsjett år 1'!$B$15/12 | H34: ='Startbudsjett år 1'!$B$15/12 | I34: ='Startbudsjett år 1'!$B$15/12 | ... M34: ='Startbudsjett år 1'!$B$15/12 | N34: =SUM(B34:M34) | P34: Lik lønn hver måned. Feriepengene utbetales først i 2020.
A35: Arbeidsgiveravgift | B35: 0 | C35: =(C34+B34)*$B$9 | D35: 0 | E35: =(E34+D34)*$B$9 | F35: 0 | G35: =(G34+F34)*$B$9 | H35: 0 | I35: =(I34+H34)*$B$9 | J35: 0 | K35: =(K34+J34)*$B$9 | L35: 0 | M35: =(M34+L34)*$B$9 | N35: =SUM(B35:M35) | P35: To måneders lønn × 14,1 %, betalt annenhver måned.
A36: Pensjon og personalforsikring | B36: =B34*$B$10 | C36: =C34*$B$10 | D36: =D34*$B$10 | E36: =E34*$B$10 | F36: =F34*$B$10 | G36: =G34*$B$10 | H36: =H34*$B$10 | I36: =I34*$B$10 | ... M36: =M34*$B$10 | N36: =SUM(B36:M36)
A37: Andre driftskostnader inkl. mva | B37: ='Startbudsjett år 1'!$B$29/12*(1+$B$11) | C37: ='Startbudsjett år 1'!$B$29/12*(1+$B$11) | D37: ='Startbudsjett år 1'!$B$29/12*(1+$B$11) | E37: ='Startbudsjett år 1'!$B$29/12*(1+$B$11) | F37: ='Startbudsjett år 1'!$B$29/12*(1+$B$11) | G37: ='Startbudsjett år 1'!$B$29/12*(1+$B$11) | H37: ='Startbudsjett år 1'!$B$29/12*(1+$B$11) | I37: ='Startbudsjett år 1'!$B$29/12*(1+$B$11) | ... M37: ='Startbudsjett år 1'!$B$29/12*(1+$B$11) | N37: =SUM(B37:M37) | P37: Husleie, forsikring, regnskap, telefon, bil — fordelt likt.
A38: Avdrag på lån | B38: 0 | C38: 0 | D38: 0 | E38: =$B$13 | F38: 0 | G38: 0 | H38: =$B$13 | I38: 0 | J38: 0 | K38: =$B$13 | L38: 0 | M38: 0 | N38: =SUM(B38:M38) | P38: Første avdrag i april. I desember er neste avdrag like rundt hjørnet.
A39: Renter på lån | B39: 0 | C39: 0 | D39: =$B$14 | E39: 0 | F39: 0 | G39: =$B$14 | H39: 0 | I39: 0 | J39: =$B$14 | K39: 0 | L39: 0 | M39: =$B$14 | N39: =SUM(B39:M39)
A40: Mva innbetalt | B40: =MAX(0,B52) | C40: =MAX(0,C52) | D40: =MAX(0,D52) | E40: =MAX(0,E52) | F40: =MAX(0,F52) | G40: =MAX(0,G52) | H40: =MAX(0,H52) | I40: =MAX(0,I52) | ... M40: =MAX(0,M52) | N40: =SUM(B40:M40) | P40: Terminen januar–februar betales i mars, mars–april i mai, og så videre.
A41: Sum utbetalinger | B41: =SUM(B31:B40)-B32 | C41: =SUM(C31:C40)-C32 | D41: =SUM(D31:D40)-D32 | E41: =SUM(E31:E40)-E32 | F41: =SUM(F31:F40)-F32 | G41: =SUM(G31:G40)-G32 | H41: =SUM(H31:H40)-H32 | I41: =SUM(I31:I40)-I32 | ... M41: =SUM(M31:M40)-M32 | N41: =SUM(B41:M41) | P41: Varekjøp inkl. mva er et hjelpetall og telles ikke med — det er «Betalt til grossist» som går ut av kontoen.
A43: 5 · Kontoen
A44: Beholdning ved månedens start | B44: 0 | C44: =B46 | D44: =C46 | E44: =D46 | F44: =E46 | G44: =F46 | H44: =G46 | I44: =H46 | J44: =I46 | ... M44: =L46
A45: Inn − ut i måneden | B45: =B28-B41 | C45: =C28-C41 | D45: =D28-D41 | E45: =E28-E41 | F45: =F28-F41 | G45: =G28-G41 | H45: =H28-H41 | I45: =I28-I41 | ... M45: =M28-M41 | N45: =SUM(B45:M45)
...

Sheet Din egen bedrift
A1: Din egen bedrift — kapitalbehov og startbudsjett
A2: Fyll inn de gule cellene for en bedrift du kunne tenke deg å starte. Bruk Nordlys-arkene som fasit for hvordan det henger sammen.
A4: 1 · Kapitalbehov
A5: Verktøy og utstyr | B5: 0
A6: Bil | B6: 0
A7: Annet (innredning, IT, lokaler) | B7: 0
A8: Sum anleggsmidler | B8: =SUM(B5:B7)
A9: Budsjettert salg år 1, ekskl. mva | B9: 0
A10: Bruttofortjeneste, andel | B10: 0.45
A11: Lagringstid, dager | B11: 20
A12: Varelager | B12: =ROUND(B9*(1-B10)/360*B11,0)
A13: Andel kredittsalg | B13: 0.25
A14: Kredittid, dager | B14: 20
A15: Kundefordringer | B15: =ROUND(B9*B13/360*B14,0)
A16: Reserve | B16: 0
A17: Kapitalbehov | B17: =B8+B12+B15+B16
A18: Egenkapital du kan skyte inn | B18: 0 | D18: Minst 30 000 i aksjekapital for et AS. Banken vil vanligvis se 25–35 % egenkapital.
A19: Egenkapitalandel | B19: =IF(B17=0,0,B18/B17)
A20: Må lånes eller finansieres på annen måte | B20: =B17-B18
A22: 2 · Startbudsjett år 1
A23: Salgsinntekt | B23: =B9
A24: Varekostnad | B24: =B23*(1-B10)
A25: Bruttofortjeneste | B25: =B23-B24
A26: Lønn (alle ansatte, inkl. deg selv) | B26: 0
A27: Sosiale kostnader, andel | B27: 0.468
A28: Lønnskostnad | B28: =B26*(1+B27)
A29: Andre driftskostnader (husleie, forsikring, regnskap, bil, telefon …) | B29: 0
A30: Levetid anleggsmidler, år | B30: 5
A31: Avskrivninger | B31: =IF(B30=0,0,B8/B30)
A32: Driftsresultat | B32: =B25-B28-B29-B31
A33: Rentesats på lån | B33: 0.06
A34: Rentekostnad | B34: =B20*B33
A35: Resultat før skatt | B35: =B32-B34
A36: Nullpunktomsetning | B36: =IF(B10=0,0,ROUND((B28+B29+B31+B34)/B10,0)) | D36: Så mye må du selge for å gå i null.
A37: Sikkerhetsmargin | B37: =IF(B23=0,0,(B23-B36)/B23)
A39: Prøv dette:
A40: Hva er den minste omsetningen du kan leve med? Hva skjer med nullpunktet hvis du dropper bilen og leier ved behov? Ta med arket til en regnskapsfører eller banken — det er dette de vil se.
