Workbook

Sheet Enkelt
A1: Hvem betaler gjelden? Den enkle versjonen
A2: Fyll inn de fire gule cellene. Svaret står i den grønne. Alt annet regner seg selv. Vil du gå dypere, ligger hele modellen i arkene bak.
A4: Det du vet
A5: Hvor mye gjeld mangler det når konkursboet er gjort opp? | B5: 2400000 | C5: Det som står igjen når alt boet eier, er solgt og fordelt.
A6: Hvor stor del av selskapet eier du? | B6: 0.5 | C6: Brukes bare i DA. Der svarer hver eier for sin andel.
A7: Hvor mye har eierne kausjonert for personlig? | B7: 800000 | C7: Et løfte til banken om å betale selv. Sett 0 hvis ingen har kausjonert.
A8: Hvor mye aksjekapital skjøt eierne inn? | B8: 300000 | C8: Minst 30 000 kroner i et AS. Den er tapt ved konkurs.
A10: Regnestykket
A11: Eieren skylder i enkeltpersonforetak | B11: =B5 -> 2400000 | C11: Ingen vegg mellom eier og firma. Hele beløpet er eierens.
A12: Kan kreves av én eier i ANS | B12: =B5 -> 2400000 | C12: En for alle og alle for en. Kreditor velger hvem han går etter.
A13: Hver eier skylder i DA | B13: =B5*B6 -> 1200000 | C13: Hver svarer for sin andel av gjelden.
A14: Eierne skylder i AS uten kausjon | B14: =0*B5 -> 0 | C14: Aksjekapitalen er tapt. Der stopper det.
A16: DET EIERNE KAN TAPE PRIVAT I AS MED KAUSJON | B16: =B7+B8 -> 1100000 | C16: Kausjonen pluss aksjekapitalen. Kausjonen gjelder uansett selskapsform.
A17: Spart i forhold til enkeltpersonforetak | B17: =B11-B16 -> 1300000 | C17: Det aksjeselskapet er verdt for eierne i dette tilfellet.
A19: Hva svaret betyr
A20: ="I et enkeltpersonforetak skylder eieren "&TEXT(ROUND(B11,0),"#,##0")&" kroner. I et AS med kausjon kan eierne tape "&TEXT(ROUND(B16,0),"#,##0")&" kroner privat." -> I et enkeltpersonforetak skylder eieren 2,400,000 kroner. I et AS med kausjon kan eierne tape 1,100,000 kroner privat.
A22: Prøv selv
A23: 1. Sett kausjonen (B7) til 0. Hva kan eierne nå tape i AS?
A24: 2. Sett eierandelen (B6) til 40 %. Hva skylder du i DA?
A25: 3. Sett kausjonen (B7) lik gjelden i B5. Hva er AS-et nå verdt for eierne?
A27: Tallene er fra eksempelet i kapitlet og Nordlys Elektro AS sin aksjekapital (faktaarket). Kilde: Økonomistyring for LØM-emnet, kap. 1.3 og 1.4. Nordlys Elektro AS er en konstruert casebedrift.

Sheet Veiledning
A1: Selskapsform og skatt
A2: LØM Økonomistyring kap. 1 · arbeidsregneark · Fagskolen Oslo, Avdeling Elkraft
A3: Emne: Teknisk kommunikasjon og ledelse for 1ET-klassene · LØM for 2ET, 2EK, 3EK og 4EK
A4: Fargekode
A5: Gul celle med blå skrift | B5: Inndata — dette er tallene du endrer.
A6: Grå eller lyseblå celle, svart skrift | B6: Formel — regner seg selv. Ikke skriv over den.
A7: Mørkeblå rad med hvit skrift | B7: Kolonneoverskrift.
A9: Ark i arbeidsboka
A10: Enkelt | B10: Start her. Fire gule celler, ett svar. Hvem som betaler gjelden etter en konkurs, i hver selskapsform.
A11: Skatt | B11: Hva et gitt overskudd koster deg i skatt i enkeltpersonforetak og i aksjeselskap, og hva som blir igjen — både i selskapet og privat. Her ligger den ene cellen du styrer alt fra: B5.
A12: Ansvar | B12: Hva du personlig skylder etter en konkurs, i de fire formene, og hva en personlig kausjon gjør med svaret.
A13: Grenser | B13: Revisjonsplikt, regnskapsplikt og bokføringsplikt: fyll inn dine tall og se hvilke plikter som inntrer.
A14: Scenario | B14: Tre spørsmål: hva skjer når overskuddet endrer seg, hva ansvarsbegrensningen er verdt den dagen det går galt, og hva montøren i oppgave 5 bør velge.
A16: Tallene som ligger inne er Nordlys Elektro AS sine egne tall for 2026.
A17: Arket er laget for å brukes på jobben etterpå: bytt ut de gule cellene med dine egne tall.
A18: Merk: sammenlikningen i Skatt-arket gjelder overskudd som blir stående i selskapet.
A19: Penger du tar ut av et aksjeselskap beskattes en gang til, som lønn eller som utbytte.
A21: Tallene som ligger inne er et eksempel fra en elektrobedrift. Bytt dem ut med dine egne — alle formler følger med.
A22: Arbeidsregneark til LØM · Fagskolen Oslo, Avdeling Elkraft. Regnearket er øvingsstøtte, ikke et regnskapssystem.
A24: Den ene knappen
A25: Skatt!B5 | B25: Overskudd før eierlønn og skatt | C25: Endrer du denne cellen, følger hele tabellen i Skatt-arket og midtkolonnen i scenario A med.
A27: Hvilken oppgave bruker hvilket ark
A28: Oppgave i øvingsheftet | B28: Ark | C28: Celler du endrer og leser av
A29: A1 · Fire bedrifter — hvilken form? | B29: Ansvar | C29: Endre B5 og B6. Les av radene 11 til 15.
A30: A2 · Konkursen: hvem sitter igjen med regningen? | B30: Ansvar | C30: Endre B5, B6 og B7. Les av radene 11 til 15 og B18.
A31: A3 · Klasseoppgave: kunne Tom startet alene? | B31: Grenser | C31: Legg anslåtte tall for første driftsår i B5, B6 og B7, og les av D16 og D17. Merk at arket bare svarer på det andre spørsmålet i oppgaven — det første, om foretaket kan tilby tjenesten, avgjøres av FEK § 7 og ikke av tall.
A32: 1 · Fra idé til organisasjonsnummer | B32: Ansvar | C32: Endre B5 og B6. Les av radene 11 til 15, og B19 og B20 for hva ansvarsbegrensningen er verdt.
A33: 2 · Hva koster formen deg i kroner? | B33: Skatt | C33: Endre B5, B6, B7 og B8. Les av rad 14 for penger som blir stående og rad 20 for penger du tar ut. Tabellen i rad 26 til 28 gir deloppgave e).
A34: 3 · Revisjon, regnskap og bokføring | B34: Grenser | C34: Endre B5, B6 og B7. Les av kolonne D i radene 10 til 12, og konklusjonene i D16, D17 og D18.
A35: 4 · Fem veier ut — og hva du sitter igjen med | B35: Ansvar | C35: Endre B5, B6 og B7. Les av radene 11 til 15. Sett B7 til null og se hva som skjer med rad 15.
A36: 5 · Eksamensnær: installatøren som vil starte for seg selv | B36: Scenario | C36: Scenario A: endre B8 og D8. Scenario B: endre B29. Scenario C: endre B39, B42, B43 og B57, og les av B44, B50, B51, B53, B54 og B58.
A38: Kontrollradene
A39: Hvert regneark har en kontrollblokk. Står det OK, henger tallene sammen. Står det AVVIK, farges cellen rød, og teksten sier hva som ikke går opp.
A40: Ett unntak: kontrollen i scenario C skal vise AVVIK med tallene som ligger inne. Der er avviket selve svaret — skattefordelen ved aksjeselskap er negativ når hele overskuddet tas ut, og det er nettopp poenget i oppgave 5.
A41: Kontroller i arbeidsboka: Skatt B32, Skatt B33, Skatt B34, Ansvar B23, Ansvar B24, Ansvar B25, Grenser B26, Grenser B27, Scenario B17, Scenario B33, Scenario B61, Scenario B63, Scenario B64
A43: Slik henger kapitlet sammen med resten
A44: Aksjekapitalen Kari og Tom skjøt inn i 2019, står fortsatt i balansen i kapittel 3 og er en del av egenkapitalandelen du regner ut i kapittel 4. Kapitalbehovet ved oppstart tas opp igjen i kapittel 6.
A46: Kilder
A47: Hjertnes, J. og Skorpen, K.: Økonomistyring for LØM-emnet (ISBN 978-82-450-5544-3), kapittel 1 «Etablering og oppstart av egen bedrift», avsnitt 1.1 til 1.7 og Tabell 1.1.
A48: Aksjeloven § 3-1 og § 7-6, regnskapsloven § 1-2 og bokføringsloven § 2 (Lovdata). Skattesatser: Skatteetaten, satser for inntektsåret 2024. Registrering: Brønnøysundregistrene og altinn.no (hentet 08.09.2026).
...

Sheet Skatt
A1: Hva koster selskapsformen deg?
A2: Endre de gule cellene. Alt annet regner seg selv.
A4: 1 · Forutsetninger
A5: OVERSKUDD FØR EIERLØNN OG SKATT — den ene knappen | B5: 900000 | D5: Dette er cellen du endrer. Tabellen nedenfor og scenario C i arket Scenario henter overskuddet herfra.
A6: Effektiv personbeskatning i enkeltpersonforetak | B6: 0.34 | D6: Forenklet samlet sats. Se bort fra trinnskattens detaljer.
A7: Selskapsskatt i aksjeselskap | B7: 0.22 | D7: Skatteetatens sats. Læreboka bruker den samme i avsnitt 1.4.
A8: Oppjusteringsfaktor for utbytte | B8: 1.72
A9: = Effektiv utbytteskatt | B9: =B7*B8 -> 0.3784 | D9: Selskapsskatt ganger oppjusteringsfaktor. Beskatning nummer to, på eierens hånd.
B11: Enkeltpersonforetak | C11: Aksjeselskap | D11: Hva forskjellen betyr
A12: Overskudd før skatt | B12: =$B$5 -> 900000 | C12: =$B$5 -> 900000 | D12: Samme utgangspunkt i begge former.
A13: Skatt | B13: =B12*$B$6 -> 306000 | C13: =C12*$B$7 -> 198000 | D13: Her ser du hele skattefordelen ved aksjeselskap.
A14: = Igjen etter skatt | B14: =B12-B13 -> 594000 | C14: =C12-C13 -> 702000 | D14: Men pengene ligger to helt ulike steder.
A15: Hvem disponerer pengene? | B15: Eieren, fritt | C15: Selskapet | D15: Dette er kjernen: i et aksjeselskap er ikke pengene dine ennå.
A16: Fordel ved AS for penger som BLIR STÅENDE | C16: =C14-B14 -> 108000 | D16: Positivt tall: aksjeselskapet kommer best ut her.
A18: 2 · Hvis du tar ALT ut av selskapet
A19: Utbytteskatt ved fullt uttak | B19: — | C19: =C14*$B$9 -> 265636.8 | D19: Det samme overskuddet beskattes en gang til.
A20: = Igjen hos deg privat | B20: =B14 -> 594000 | C20: =C14-C19 -> 436363.2 | D20: Sammenlikn DENNE raden hvis du trenger pengene til å leve av.
A21: Samlet skattesats | B21: =1-B20/$B$5 -> 0.34 | C21: =1-C20/$B$5 -> 0.515152 | D21: Aksjeselskapets sats er summen av de to trinnene.
A22: Fordel ved AS for penger du TAR UT | C22: =C20-B20 -> -157636.8 | D22: Negativt tall: her kommer aksjeselskapet dårligst ut.
A24: 3 · Samme regning ved tre overskuddsnivåer
A25: Overskudd før eierlønn | B25: Igjen i EPF | C25: Igjen i AS-selskapet | D25: Igjen privat via AS | E25: Fordel i selskapet | F25: Fordel privat
A26: 300000 | B26: =A26*(1-$B$6) -> 198000 | C26: =A26*(1-$B$7) -> 234000 | D26: =C26*(1-$B$9) -> 145454.4 | E26: =C26-B26 -> 36000 | F26: =D26-B26 -> -52545.6
A27: 900000 | B27: =A27*(1-$B$6) -> 594000 | C27: =A27*(1-$B$7) -> 702000 | D27: =C27*(1-$B$9) -> 436363.2 | E27: =C27-B27 -> 108000 | F27: =D27-B27 -> -157636.8
A28: 1800000 | B28: =A28*(1-$B$6) -> 1188000 | C28: =A28*(1-$B$7) -> 1404000 | D28: =C28*(1-$B$9) -> 872726.4 | E28: =C28-B28 -> 216000 | F28: =D28-B28 -> -315273.6
A29: Legg merke til at forholdstallet er det samme på alle tre radene. Alle tre satsene er flate prosenter — derfor skalerer skatten, og derfor blir den aldri det avgjørende argumentet.
A31: Kontroll
A32: Er aksjeselskapet best for penger som blir stående? | B32: =IF(C16>0,"OK — aksjeselskapet beholder mer av overskuddet så lenge pengene blir stående i selskapet","AVVIK: med disse satsene er det ingen skattefordel ved aksjeselskap i det hele tatt") -> OK — aksjeselskapet beholder mer av overskuddet så lenge pengene blir stående i selskapet
A33: Er aksjeselskapet dårligst når alt tas ut? | B33: =IF(C22<0,"OK — tar du alt ut, betaler du mer i aksjeselskap enn i enkeltpersonforetak. Det er kapitlets viktigste skattepoeng","AVVIK: sjekk satsene i B6, B7 og B8 — poenget i oppgave 2 forutsetter at fullt uttak er dyrere i aksjeselskap") -> OK — tar du alt ut, betaler du mer i aksjeselskap enn i enkeltpersonforetak. Det er kapitlets viktigste skattepoeng
A34: Går skatt og rest opp mot overskuddet? | B34: =IF(AND(ABS(B13+B14-B12)<1,ABS(C13+C14-C12)<1),"OK — skatt pluss rest er lik overskuddet i begge former","AVVIK: regnestykket går ikke opp") -> OK — skatt pluss rest er lik overskuddet i begge former
A36: Konklusjonen å ta med seg
A37: Sammenlikn rad 14 hvis overskuddet blir stående i selskapet, for eksempel for å bygge egenkapital eller finansiere neste investering.
A38: Sammenlikn rad 20 hvis du trenger pengene privat. Da går forskjellen den andre veien.
A39: Og husk: for de fleste er ikke skatten hovedgrunnen til å velge aksjeselskap. Ansvaret er — se arket Ansvar.
A40: Kilde: Økonomistyring for LØM-emnet kap. 1.4. Aksjeloven § 3-1 og § 7-6, regnskapsloven § 1-2 og bokføringsloven § 2 (Lovdata). Skattesatser: Skatteetaten, satser for inntektsåret 2024. Registrering: Brønnøysundregistrene og altinn.no (hentet 08.09.2026)

Sheet Ansvar
A1: Hva skylder du etter en konkurs?
A2: Oppgave A2 og oppgave 4 i øvingsheftet. Endre de gule cellene.
A4: 1 · Forutsetninger
A5: Udekket gjeld etter avsluttet bo | B5: 2400000 | C5: Det som står igjen når alt boet eier, er solgt og fordelt.
A6: Din eierandel | B6: 0.5 | C6: Brukes bare i DA — der hefter hver for sin forholdsmessige andel.
A7: Personlig kausjon du har stilt | B7: 800000 | C7: Sett til 0 hvis du ikke har kausjonert, og se hva som skjer med rad 15.
A8: Aksjekapital du har skutt inn | B8: 300000 | C8: Den er tapt uansett — men den er også taket i et aksjeselskap.
A10: Selskapsform | B10: Du skylder dagen etter | C10: Hvorfor
A11: Enkeltpersonforetak | B11: =$B$5 -> 2400000 | C11: Ingen skille mellom deg og foretaket. Hele beløpet er ditt.
A12: Ansvarlig selskap (ANS) | B12: =$B$5 -> 2400000 | C12: Solidarisk ansvar. Kreditor kan kreve hele beløpet av deg alene, og du må selv kreve medeieren din etterpå.
A13: Ansvarlig selskap (DA) | B13: =$B$5*$B$6 -> 1200000 | C13: Delt ansvar. Du hefter bare for din forholdsmessige andel.
A14: Aksjeselskap | B14: =0 -> 0 | C14: Begrenset ansvar. Du har tapt aksjekapitalen, og der stopper det.
A15: Aksjeselskap MED personlig kausjon | B15: =$B$7 -> 800000 | C15: Kausjonen er en selvstendig forpliktelse du har påtatt deg privat. Den overlever konkursen, og selskapsformen beskytter deg ikke mot den.
A17: 2 · Hvor mye av ansvarsbegrensningen står igjen?
A18: Kausjonen i prosent av den udekkede gjelden | B18: =IF($B$5=0,0,$B$7/$B$5) -> 0.33333333 | C18: Så stor del av ansvaret har du i praksis beholdt, selv i et aksjeselskap.
A19: Samlet tap i aksjeselskap: kausjon og aksjekapital | B19: =B15+B8 -> 1100000 | C19: Dette er det aksjeselskapet faktisk koster deg i dette tilfellet.
A20: Spart i forhold til enkeltpersonforetak | B20: =B11-B19 -> 1300000 | C20: Verdien av ansvarsbegrensningen, i kroner.
A22: Kontroll
A23: Går ansvarsstigen oppover? | B23: =IF(AND(B14<=B15,B15<=B13,B13<=B12),"OK — ansvaret øker fra aksjeselskap via kausjon og DA til ANS og enkeltpersonforetak","AVVIK: sjekk eierandelen i B6 og kausjonen i B7 — stigen går ikke oppover") -> OK — ansvaret øker fra aksjeselskap via kausjon og DA til ANS og enkeltpersonforetak
A24: Er kausjonen mindre enn den udekkede gjelden? | B24: =IF(B7<=B5,"OK — kausjonen dekker en del av gjelden, ikke hele","AVVIK: en kausjon større enn den udekkede gjelden gir ikke mening her") -> OK — kausjonen dekker en del av gjelden, ikke hele
A25: Lønner ansvarsbegrensningen seg i dette tilfellet? | B25: =IF(B20>0,"OK — aksjeselskapet sparer deg for det beløpet som står i B20","AVVIK: med denne kausjonen er det ingenting igjen av ansvarsbegrensningen") -> OK — aksjeselskapet sparer deg for det beløpet som står i B20
A27: Prøv dette: sett kausjonen i B7 til hele beløpet i B5. Da er ansvarsbegrensningen borte, og aksjeselskapet gir deg ingenting igjen for papirarbeidet. Det er nettopp den situasjonen mange nystartede havner i.
A28: Kilde: Økonomistyring for LØM-emnet kap. 1.3 og avsnittet om konkurs. Aksjeloven § 3-1 og § 7-6, regnskapsloven § 1-2 og bokføringsloven § 2 (Lovdata). Skattesatser: Skatteetaten, satser for inntektsåret 2024. Registrering: Brønnøysundregistrene og altinn.no (hentet 08.09.2026)

Sheet Grenser
A1: Er du over grensene?
A2: Fyll inn tallene for din egen bedrift i de gule cellene.
A4: 1 · Din bedrift
A5: Driftsinntekter | B5: 22400000 | E5: Tallet for Nordlys Elektro AS 2026 ligger inne som eksempel.
A6: Sum eiendeler i balansen | B6: 10182650 | E6: Sum av anleggsmidler og omløpsmidler. Se kapittel 3.
A7: Gjennomsnittlig antall årsverk | B7: 18
A9: Grense | B9: Din verdi | C9: Grensen | D9: Over? | E9: Hva grensen måler
A10: Revisjonsplikt — driftsinntekter | B10: =$B$5 -> 22400000 | C10: 7000000 | D10: =IF(B10>C10,"JA — over grensen","Nei") -> JA — over grensen | E10: Hvor stor omsetning bedriften har.
A11: Revisjonsplikt — eiendeler | B11: =$B$6 -> 10182650 | C11: 27000000 | D11: =IF(B11>C11,"JA — over grensen","Nei") -> Nei | E11: Hvor mye kapital som er bundet. En installatør ligger lavt her.
A12: Revisjonsplikt — årsverk | B12: =$B$7 -> 18 | C12: 10 | D12: =IF(B12>C12,"JA — over grensen","Nei") -> JA — over grensen | E12: Hvor mange folk bedriften har ansvar for.
A13: Antall grenser som er passert | B13: =COUNTIF(D10:D12,"JA*") -> 2
A15: 2 · Konklusjon
A16: Aksjeselskap | D16: =IF(B13=0,"Kan velge bort revisor","Revisjonsplikt — minst én grense er passert") -> Revisjonsplikt — minst én grense er passert | E16: Et AS slipper revisor bare når ALLE tre ligger under.
A17: Enkeltpersonforetak og ANS/DA | D17: =IF(B13=0,"Fritatt for revisjon","Revisjonsplikt") -> Revisjonsplikt | E17: Plikten inntrer så snart MINST ÉN grense passeres.
A18: Bokføringsplikt | D18: JA — alltid | E18: Alle som driver næring og er registrert i Enhetsregisteret. Uansett størrelse og form.
A20: 3 · Aksjekapitalen
A21: Lovens minstekrav | B21: 30000
A22: Det du skyter inn | B22: 300000
A23: Ganger minstekravet | B23: =B22/B21 -> 10 | E23: Kari og Tom skjøt inn ti ganger minstekravet i 2019 — like mye et signal til bank og grossist som det er penger.
A25: Kontroll
A26: Er bedriften over minst én grense? | B26: =IF(B13>0,"OK — bedriften har revisjonsplikt. Med Nordlys-tallene er den over på to av tre grenser: omsetning og årsverk","OK — bedriften er under alle tre grensene og kan velge bort revisor") -> OK — bedriften har revisjonsplikt. Med Nordlys-tallene er den over på to av tre grenser: omsetning og årsverk
A27: Er aksjekapitalen minst lovens minstekrav? | B27: =IF(B22>=B21,"OK — aksjekapitalen er minst lovens minstekrav","AVVIK: aksjekapitalen er lavere enn minstekravet — et slikt aksjeselskap kan ikke registreres") -> OK — aksjekapitalen er minst lovens minstekrav
A29: Merk forskjellen mellom de tre pliktene: bokføringsplikten sier at du må registrere hver transaksjon. Regnskapsplikten sier at du i tillegg må sette opp og sende inn et årsregnskap. Revisjonsplikten sier at en uavhengig tredjepart må gå god for tallene.
A30: Kilde: Økonomistyring for LØM-emnet kap. 1.2. Aksjeloven § 3-1 og § 7-6, regnskapsloven § 1-2 og bokføringsloven § 2 (Lovdata). Skattesatser: Skatteetaten, satser for inntektsåret 2024. Registrering: Brønnøysundregistrene og altinn.no (hentet 08.09.2026)

Sheet Scenario
A1: Tre scenarioer
A2: Endre de gule cellene og se hva som skjer. Alle tall hentes fra de andre arkene.
A4: Scenario A · overskuddet endrer seg
A5: Satsene er de samme. Det eneste som endrer seg, er hvor stort overskuddet er.
B7: Lavt overskudd | C7: Overskuddet du regner med | D7: Høyt overskudd | E7: Hva raden betyr
A8: Overskudd før eierlønn | B8: 300000 | C8: =Skatt!B5 -> 900000 | D8: 1800000 | E8: Midtkolonnen henter fra Skatt!B5. De to gule kan du endre fritt.
A9: Igjen i enkeltpersonforetak | B9: =B8*(1-Skatt!$B$6) -> 198000 | C9: =C8*(1-Skatt!$B$6) -> 594000 | D9: =D8*(1-Skatt!$B$6) -> 1188000 | E9: Ett skattetrinn. Pengene er eierens.
A10: Igjen i aksjeselskapet | B10: =B8*(1-Skatt!$B$7) -> 234000 | C10: =C8*(1-Skatt!$B$7) -> 702000 | D10: =D8*(1-Skatt!$B$7) -> 1404000 | E10: Ett skattetrinn, men pengene ligger i selskapet.
A11: Igjen privat via aksjeselskap og utbytte | B11: =B10*(1-Skatt!$B$9) -> 145454.4 | C11: =C10*(1-Skatt!$B$9) -> 436363.2 | D11: =D10*(1-Skatt!$B$9) -> 872726.4 | E11: To skattetrinn. Dette er tallet å sammenlikne med rad 9.
A12: = Fordel ved AS for penger som blir stående | B12: =B10-B9 -> 36000 | C12: =C10-C9 -> 108000 | D12: =D10-D9 -> 216000 | E12: Positivt på alle tre nivåene.
A13: = Fordel ved AS for penger du tar ut | B13: =B11-B9 -> -52545.6 | C13: =C11-C9 -> -157636.8 | D13: =D11-D9 -> -315273.6 | E13: Negativt på alle tre nivåene. Det er hele poenget.
A14: Fordelen i selskapet, i prosent av overskuddet | B14: =B12/B8 -> 0.12 | C14: =C12/C8 -> 0.12 | D14: =D12/D8 -> 0.12 | E14: Legg merke til at prosenten er den samme i alle tre kolonnene.
A16: Kontroll
A17: Er forholdstallet det samme uansett overskuddsnivå? | B17: =IF(AND(ABS(B14-C14)<0.0001,ABS(C14-D14)<0.0001),"OK — samme prosent på alle tre nivåene. Skatten skalerer, og derfor blir den aldri det avgjørende argumentet","AVVIK: satsene er ikke flate — sjekk Skatt!B6, B7 og B8") -> OK — samme prosent på alle tre nivåene. Skatten skalerer, og derfor blir den aldri det avgjørende argumentet
A20: Scenario B · det går galt
A21: Samme konkurs som i arket Ansvar, men her måles den mot det bedriften tjener på et år.
A23: Udekket gjeld etter avsluttet bo | B23: =Ansvar!B5 -> 2400000
A24: Du skylder som enkeltpersonforetak | B24: =Ansvar!B11 -> 2400000
A25: Ditt samlede tap som aksjeselskap: kausjon og aksjekapital | B25: =Ansvar!B15+Ansvar!B8 -> 1100000
A26: = Verdien av ansvarsbegrensningen | B26: =B24-B25 -> 1300000 | E26: Dette er hva aksjeselskapet er verdt den dagen det går galt.
A27: Igjen etter skatt på ett år (fra Skatt!B20) | B27: =Skatt!B20 -> 594000
A28: Ansvarsbegrensningen målt i år | B28: =B26/B27 -> 2.1885522 | E28: Så mange års inntekt etter skatt sparer ansvarsbegrensningen deg for.
A29: Merkostnad ved aksjeselskap per år | B29: 25000
A30: År med merkostnad før den er like dyr som konkursen | B30: =IF(B29=0,0,B26/B29) -> 52 | E30: Så mange år må du betale for aksjeselskapet før det koster like mye som én konkurs uten ansvarsbegrensning.
A32: Kontroll
A33: Er ansvarsbegrensningen verdt mer enn merkostnaden? | B33: =IF(B30>10,"OK — det tar mer enn ti år med merkostnad før aksjeselskapet er like dyrt som én konkurs. Det er derfor ansvaret veier tyngre enn skatten","AVVIK: her er merkostnaden så høy at regnestykket bør gjøres på nytt") -> OK — det tar mer enn ti år med merkostnad før aksjeselskapet er like dyrt som én konkurs. Det er derfor ansvaret veier tyngre enn skatten
A36: Scenario C · installatøren som vil starte for seg selv
A37: Oppgave 5 i øvingsheftet. Regn først, drøft etterpå.
A38: Forutsetning: han fyller selv FEK § 7 — fagskole, tre års praksis etter endt utdanning og installatørprøven — og kan stå som faglig ansvarlig. Uten det er selskapsform ikke hans første spørsmål.
A39: Fakturerte montørtimer i året | B39: 1102 | E39: Alene rekker han færre timer enn en montør i en bemannet bedrift.
A40: Timepris uten mva. | B40: 890
A41: = Timeinntekt | B41: =B39*B40 -> 980780
A42: Bruttofortjeneste på materiell | B42: 133111.11 | E42: Påslaget på materiellet han kjøper inn og fakturerer videre.
A43: − egne faste kostnader | B43: 260000 | E43: Bil, verktøy, forsikring, regnskapsfører, telefon og kurs.
A44: = Overskudd før eierlønn | B44: =B41+B42-B43 -> 853891.11
A46: Skatteregningen for dette overskuddet
A47: Igjen som enkeltpersonforetak | B47: =B44*(1-Skatt!$B$6) -> 563568.13
A48: Igjen i aksjeselskapet, penger som blir stående | B48: =B44*(1-Skatt!$B$7) -> 666035.07
A49: Igjen privat via aksjeselskap og utbytte | B49: =B48*(1-Skatt!$B$9) -> 414007.4
A50: = Skattefordel ved AS for penger som blir stående | B50: =B48-B47 -> 102466.93
...
