Workbook

Sheet Enkelt
A1: Hva gir ett oppdrag per montørtime? Den enkle versjonen
A2: Fyll inn de seks gule cellene. Svaret står i den grønne. Alt annet regner seg selv. Vil du gå dypere, ligger hele modellen i arkene bak.
A4: Det du vet
A5: Hva betaler kunden for oppdraget, uten mva.? | B5: 6820 | C5: Tallet som ligger inne, er et typisk boligoppdrag.
A6: Hva koster materiellet? | B6: 4000 | C6: Innkjøpsprisen for materiellet på jobben.
A7: Hvor mange montørtimer tar jobben? | B7: 3 | C7: Timene montøren står på jobben.
A8: Hva koster en montørtime bedriften? | B8: 640 | C8: Lønn med feriepenger, arbeidsgiveravgift og pensjon. Ikke timeprisen til kunden.
A9: Hva er dekningsbidraget for hele bedriften i året? | B9: 5184000 | C9: Brukes bare til å finne snittet per time.
A10: Hvor mange montørtimer fakturerer bedriften i året? | B10: 14400 | C10: Den knappe faktoren.
A12: Regnestykket
A13: Det montørtimene koster | B13: =B7*B8 -> 1920 | C13: Timer ganger det en time koster bedriften.
A14: Materiell og timer til sammen | B14: =B6+B13 -> 5920 | C14: Det jobben selv koster. Kalles merkost.
A15: Dekningsbidrag på oppdraget | B15: =B5-B14 -> 900 | C15: Det som er igjen av prisen.
A17: DEKNINGSBIDRAG PER MONTØRTIME | B17: =B15/B7 -> 300 | C17: Kroner per time av det bedriften har minst av.
A18: Snittet for hele bedriften per montørtime | B18: =B9/B10 -> 360 | C18: Ligger oppdraget under dette, bæres det av de andre tjenestene.
A20: Hva svaret betyr
A21: ="Hver montørtime på dette oppdraget gir "&TEXT(ROUND(B17,2),"#,##0.00")&" kroner i dekningsbidrag. Snittet for hele bedriften er "&TEXT(ROUND(B18,2),"#,##0.00")&" kroner. Ligger oppdraget under snittet, bæres det av de andre tjenestene." -> Hver montørtime på dette oppdraget gir 300.00 kroner i dekningsbidrag. Snittet for hele bedriften er 360.00 kroner. Ligger oppdraget under snittet, bæres det av de andre tjenestene.
A23: Prøv selv
A24: 1. Regn serviceoppdraget på et næringsbygg: sett B5 til 18 500, B6 til 7 360 og B7 til 6.
A25: 2. Regn antenneoppdraget: sett B5 til 4 800, B6 til 1 500 og B7 til 4. Over eller under snittet?
A26: 3. Tilbake til boligoppdraget. En konkurrent er 10 % billigere. Sett B5 til 6 138. Hva er igjen per time?
A28: Tallene er Nordlys Elektro AS sine for 2026 (regnearket «Produktbidrag og sortiment» og presentasjonen til kap. 6). Kilde: Markedsføring, organisasjon og ledelse for LØM-emnet, kap. 6, og Økonomistyring for LØM-emnet, kap. 7. Nordlys Elektro AS er en konstruert casebedrift.

Sheet Veiledning
A1: Produktbidrag og sortiment
A2: LØM Markedsføring kap. 6 · arbeidsregneark · Fagskolen Oslo, Avdeling Elkraft
A3: Emne: Teknisk kommunikasjon og ledelse for 1ET-klassene · LØM for 2ET, 2EK, 3EK og 4EK
A4: Fargekode
A5: Gul celle med blå skrift | B5: Inndata — dette er tallene du endrer.
A6: Grå eller lyseblå celle, svart skrift | B6: Formel — regner seg selv. Ikke skriv over den.
A7: Mørkeblå rad med hvit skrift | B7: Kolonneoverskrift.
A9: Ark i arbeidsboka
A10: Enkelt | B10: Start her. Seks gule celler, ett svar. Hva ett oppdrag gir per montørtime, regnet på den enkleste måten.
A11: Sortimentet | B11: Bredden, dybden og hvordan omsetningen fordeler seg på de seks tjenestegruppene. Her ser du hvor kronene ligger.
A12: Produktbidrag | B12: DET VIKTIGSTE ARKET. Dekningsbidrag per montørtime for ett typeoppdrag fra hver tjeneste, målt mot bedriftens eget snitt. Her ser du hvem som bærer hvem.
A13: Scenario | B13: Tre spørsmål: skal antenneanlegg saneres, skal en billigere konkurrent møtes med pris eller med produkt, og hva koster det å satse på en ny tjeneste.
A14: Din egen meny | B14: Samme oppsett, tomt. Legg inn tjenestene til din egen bedrift.
A16: Tallene som ligger inne er Nordlys Elektro AS sine egne for 2026.
A17: Omsetningen, dekningsbidraget og de fakturerte montørtimene er de samme som i Økonomistyring kapittel 2, 3 og 5.
A19: Tallene som ligger inne er et eksempel fra en elektrobedrift. Bytt dem ut med dine egne — alle formler følger med.
A20: Arbeidsregneark til LØM · Fagskolen Oslo, Avdeling Elkraft. Regnearket er øvingsstøtte, ikke et regnskapssystem.
A22: Den ene innsikten
A23: Produktbidrag!B8 | B23: Dekningsbidrag per fakturert montørtime | C23: Bedriftens eget snitt. En tjeneste som gir mindre enn dette per montørtime, blir båret av de andre. Sortimentet forteller hvor omsetningen ligger; denne cellen forteller hvor lønnsomheten ligger.
A24: De to er ikke det samme, og det er hele grunnen til at arket finnes: den største tjenestegruppen i omsetning er den svakeste per montørtime.
A26: Hvilken oppgave bruker hvilket ark
A27: Oppgave i øvingsheftet | B27: Ark | C27: Celler du endrer og leser av
A28: A2 · Klasseoppgave: plasser tjenestene i kurven | B28: Sortimentet | C28: Les kolonne E. Prøv å endre andelene i kolonne B og se hva som skjer med omsetningen i kolonne C.
A29: 3 · Bredde, dybde og konsistens | B29: Sortimentet | C29: Endre B8 til B13 og D8 til D13. Les av B17, B18 og B19.
A30: 4 · Plasser tjenestene i livssyklusen | B30: Sortimentet og Scenario | C30: Sortimentet kolonne E. Saneringsspørsmålet regnes i scenario A: B7 til B15.
A31: 5 · Eksamensnær: konkurrenten er billigere | B31: Scenario | C31: Scenario B: endre B30 og C30, og les av B33, C33, B35, C35 og dommen i E39.
A32: Alle oppgaver | B32: Produktbidrag | C32: Endre C12 til E19. Les av kolonne G, I og J, og oppsummeringen i B23 til B29.
A34: Kontrollradene
A35: Hvert ark har en kontrollblokk nederst. Står det OK, henger tallene sammen. Står det AVVIK, farges cellen rød, og teksten sier hva som ikke går opp.
A36: Ett unntak: kontrollen i arket «Din egen meny» står på AVVIK til du har fylt inn dine egne tall. Arket er tomt når du får det.
A37: Kontroller i arbeidsboka: Sortimentet C24, Sortimentet C25, Sortimentet C26, Sortimentet C27, Produktbidrag C32, Produktbidrag C33, Produktbidrag C34, Produktbidrag C35, Scenario C18, Scenario C42, Scenario C43, Scenario C59, Scenario C60, Din egen meny C22, Din egen meny C23
A39: Kilder
A40: Hjertnes, Frode: Markedsføring, organisasjon og ledelse for LØM-emnet, 4. utgave, kapittel 6 «Produkt som konkurransevirkemiddel», avsnitt 6.1 til 6.9.
A41: Dekningsbidrag, montørtimer og kostsats: Bok 1 kapittel 2 og 5. Bransjetall: NHO Elektro, Lønnsomhetsrapport 2025, gjengitt i Elektro 24-7 19.08.2026 (hentet 10.09.2026). De 809 er bedriftene i datagrunnlaget, ikke bransjen. NHO Elektro oppgir ikke svarprosent.
A42: Nordlys Elektro AS er en konstruert casebedrift. Tallene henger sammen på tvers av begge bøkene.

Sheet Sortimentet
A1: Sortimentet: bredde, dybde og omsetning
A2: Seks tjenestegrupper. Endre de gule cellene — alt annet regner seg selv.
A4: Salgsinntekt 2026 (Bok 1 kap. 3) | B4: 22400000 | F4: Nordlys Elektro AS sin egen omsetning. Gruppene deler denne summen.
A6: 1 · Bredden og dybden
A7: Tjenestegruppe | B7: Andel av omsetningen | C7: Omsetning 2026 | D7: Varianter (dybde) | E7: Fase i livssyklusen | F7: Kjernebehovet gruppen dekker
A8: Boliginstallasjon og rehabilitering | B8: 0.22 | C8: =B8*$B$4 -> 4928000 | D8: 5 | E8: Modning | F8: Trygghet for at det ikke begynner å brenne, og strøm nok til det familien faktisk bruker.
A9: Prosjekt og nybygg | B9: 0.3810875 | C9: =B9*$B$4 -> 8536360 | D9: 3 | E9: Modning | F9: At byggeprosjektet blir ferdig til avtalt dato uten avvik ved overtakelsen.
A10: Service og feilsøking | B10: 0.17 | C10: =B10*$B$4 -> 3808000 | D10: 3 | E10: Modning | F10: At bygget er i drift igjen i dag, ikke på fredag.
A11: El-kontroll og dokumentasjon | B11: 0.06 | C11: =B11*$B$4 -> 1344000 | D11: 3 | E11: Modning | F11: Et papir som holder overfor forsikringsselskapet og tilsynsmyndigheten.
A12: Solcelle og lading | B12: 0.1489125 | C12: =B12*$B$4 -> 3335640 | D12: 4 | E12: Vekst | F12: Lavere strømregning, og en bil som er ladet når den skal brukes.
A13: Antenne- og koaksanlegg | B13: 0.02 | C13: =B13*$B$4 -> 448000 | D13: 2 | E13: Tilbakegang | F13: Et bilde på skjermen — et behov fiberen nå dekker bedre.
A14: = Sum | B14: =SUM(B8:B13) -> 1 | C14: =SUM(C8:C13) -> 22400000 | D14: =SUM(D8:D13) -> 20
A16: 2 · Bredde, dybde og konsistens i tall
A17: Bredde — antall tjenestegrupper | B17: =COUNTA(A8:A13) -> 6 | F17: Antall forskjellige behov bedriften dekker.
A18: Dybde — antall varianter til sammen | B18: =D14 -> 20 | F18: Antall varianter innenfor gruppene til sammen.
A19: Gjennomsnittlig dybde per gruppe | B19: =B18/B17 -> 3.3333333 | F19: Allmennpraktikeren har stor bredde og liten dybde. Øyelegen har det motsatte. Hvor ligger din bedrift?
A20: Største gruppe, andel av omsetningen | B20: =MAX(B8:B13) -> 0.3810875
A21: Minste gruppe, andel av omsetningen | B21: =MIN(B8:B13) -> 0.02 | F21: Den minste gruppen er den som er i tilbakegang. Se arket Produktbidrag før du bestemmer deg for hva du gjør med den.
A23: Kontroll
A24: Summerer andelene seg til hundre prosent? | C24: =IF(ABS(B14-1)<0.0001,"OK — gruppene deler hele omsetningen mellom seg","AVVIK: andelene summerer seg ikke til 100 prosent") -> OK — gruppene deler hele omsetningen mellom seg
A25: Stemmer summen med salgsinntekten? | C25: =IF(ABS(C14-B4)<1,"OK — gruppenes omsetning summerer seg til salgsinntekten","AVVIK: gruppenes omsetning summerer seg ikke til salgsinntekten") -> OK — gruppenes omsetning summerer seg til salgsinntekten
A26: Er tjenesten i tilbakegang den minste? | C26: =IF(B13=MIN(B8:B13),"OK — gruppen i tilbakegang er den minste i omsetning","AVVIK: en gruppe i tilbakegang som ikke er den minste, er en gruppe som er på vei ned og fortsatt betyr mye") -> OK — gruppen i tilbakegang er den minste i omsetning
A27: Har alle gruppene noe dybde? | C27: =IF(MIN(D8:D13)>=2,"OK — alle gruppene har minst to varianter","AVVIK: en gruppe med bare én variant har ingen dybde") -> OK — alle gruppene har minst to varianter
A29: Prøv dette: sett andelen til antenne- og koaksanlegg til null og fordel de to prosentene på solcelle og lading. Det er saneringsvedtaket, uttrykt i tall.
A30: Kilde: Hjertnes, Markedsføring, organisasjon og ledelse for LØM-emnet, 4. utg., kap. 6.5 om sortimentets bredde, dybde og konsistens. Omsetningen er Nordlys Elektro AS sin egen for 2026.

Sheet Produktbidrag
A1: Hvilke tjenester bærer bedriften?
A2: Dekningsbidrag per montørtime. Montørtimene er det knappe, ikke kronene.
A4: 1 · Forutsetninger
A5: Kostsats per montørtime | B5: 640 | J5: Lønn med feriepenger, arbeidsgiveravgift og pensjon. Ikke timeprisen til kunden.
A6: Dekningsbidrag 2026, hele bedriften (Bok 1 kap. 2) | B6: 5184000
A7: Fakturerte montørtimer 2026 | B7: 14400
A8: = Dekningsbidrag per fakturert montørtime | B8: =B6/B7 -> 360 | J8: Målestokken. Alt som ligger under denne, tapper bedriften for bidrag hver time montøren bruker på det.
A10: 2 · Ett typeoppdrag fra hver tjeneste
A11: Typeoppdrag | B11: Fase | C11: Pris uten mva. | D11: Materiell | E11: Montørtimer | F11: Merkost (VEK) | G11: Dekningsbidrag | H11: Dekningsgrad | I11: DB per montørtime | J11: Mot snittet
A12: Boliginstallasjon, typisk oppdrag | B12: Modning | C12: 6820 | D12: 4000 | E12: 3 | F12: =D12+E12*$B$5 -> 5920 | G12: =C12-F12 -> 900 | H12: =G12/C12 -> 0.13196481 | I12: =G12/E12 -> 300 | J12: =IF(I12>=$B$8,"Over snittet — bærer bedriften","Under snittet — bæres av de andre") -> Under snittet — bæres av de andre
A13: Nybygg, én boenhet i et felt | B13: Modning | C13: 29860 | D13: 22000 | E13: 9 | F13: =D13+E13*$B$5 -> 27760 | G13: =C13-F13 -> 2100 | H13: =G13/C13 -> 0.070328198 | I13: =G13/E13 -> 233.33333 | J13: =IF(I13>=$B$8,"Over snittet — bærer bedriften","Under snittet — bæres av de andre") -> Under snittet — bæres av de andre
A14: Serviceoppdrag på næringsbygg | B14: Modning | C14: 18500 | D14: 7360 | E14: 6 | F14: =D14+E14*$B$5 -> 11200 | G14: =C14-F14 -> 7300 | H14: =G14/C14 -> 0.39459459 | I14: =G14/E14 -> 1216.6667 | J14: =IF(I14>=$B$8,"Over snittet — bærer bedriften","Under snittet — bæres av de andre") -> Over snittet — bærer bedriften
A15: El-kontroll av bolig | B15: Modning | C15: 3200 | D15: 300 | E15: 2 | F15: =D15+E15*$B$5 -> 1580 | G15: =C15-F15 -> 1620 | H15: =G15/C15 -> 0.50625 | I15: =G15/E15 -> 810 | J15: =IF(I15>=$B$8,"Over snittet — bærer bedriften","Under snittet — bæres av de andre") -> Over snittet — bærer bedriften
A16: Solcelleanlegg på enebolig | B16: Vekst | C16: 51360 | D16: 38000 | E16: 14 | F16: =D16+E16*$B$5 -> 46960 | G16: =C16-F16 -> 4400 | H16: =G16/C16 -> 0.085669782 | I16: =G16/E16 -> 314.28571 | J16: =IF(I16>=$B$8,"Over snittet — bærer bedriften","Under snittet — bæres av de andre") -> Under snittet — bæres av de andre
A17: Ladepunkt i garasje | B17: Vekst | C17: 8830 | D17: 6500 | E17: 2 | F17: =D17+E17*$B$5 -> 7780 | G17: =C17-F17 -> 1050 | H17: =G17/C17 -> 0.1189128 | I17: =G17/E17 -> 525 | J17: =IF(I17>=$B$8,"Over snittet — bærer bedriften","Under snittet — bæres av de andre") -> Over snittet — bærer bedriften
A18: Antenne- og koaksanlegg | B18: Tilbakegang | C18: 4800 | D18: 1500 | E18: 4 | F18: =D18+E18*$B$5 -> 4060 | G18: =C18-F18 -> 740 | H18: =G18/C18 -> 0.15416667 | I18: =G18/E18 -> 185 | J18: =IF(I18>=$B$8,"Over snittet — bærer bedriften","Under snittet — bæres av de andre") -> Under snittet — bæres av de andre
A19: Batterilagring og energistyring (ikke levert ennå) | B19: Introduksjon | C19: 84000 | D19: 62000 | E19: 24 | F19: =D19+E19*$B$5 -> 77360 | G19: =C19-F19 -> 6640 | H19: =G19/C19 -> 0.079047619 | I19: =G19/E19 -> 276.66667 | J19: =IF(I19>=$B$8,"Over snittet allerede første året","Under snittet — som en ny tjeneste pleier å være") -> Under snittet — som en ny tjeneste pleier å være
J20: Anslag. Timetallet er høyt fordi den første jobben av et slag alltid går langsomt.
A22: 3 · Hva tabellen sier
A23: Beste dekningsbidrag per montørtime | B23: =MAX(I12:I18) -> 1216.6667
A24: Svakeste dekningsbidrag per montørtime | B24: =MIN(I12:I18) -> 185
A25: Forskjell mellom beste og svakeste | B25: =B23-B24 -> 1031.6667 | J25: Så mye betyr det hvilken jobb montøren står på — per time, hele året.
A26: Typeoppdrag over snittet | B26: =COUNTIF(I12:I18,">="&$B$8) -> 3
A27: Typeoppdrag under snittet | B27: =COUNTIF(I12:I18,"<"&$B$8) -> 4
A28: Hva ett år med bare den beste tjenesten ville gitt | B28: =B23*B7 -> 17520000 | J28: Et umulig tall — markedet er ikke så stort. Men det viser hvor mye sammensetningen av oppdragene betyr.
A29: Hva ett år med bare den svakeste ville gitt | B29: =B24*B7 -> 2664000
A31: Kontroll
A32: Har alle tjenestene positivt dekningsbidrag? | C32: =IF(MIN(G12:G19)>0,"OK — alle tjenestene dekker sin egen merkost","AVVIK: en tjeneste med negativt dekningsbidrag taper penger på hvert eneste oppdrag") -> OK — alle tjenestene dekker sin egen merkost
A33: Stemmer snittet med regnskapet for 2026? | C33: =IF(ABS(B8*B7-B6)<1,"OK — snittet er dekningsbidraget delt på de fakturerte timene","AVVIK: snittet henger ikke sammen med dekningsbidraget i B6") -> OK — snittet er dekningsbidraget delt på de fakturerte timene
A34: Ligger noen over og noen under snittet? | C34: =IF(AND(B26>0,B27>0),"OK — noen tjenester bærer bedriften og noen blir båret. Det er hele poenget med tabellen","AVVIK: ligger alle på samme side av snittet, er det ingenting å prioritere mellom") -> OK — noen tjenester bærer bedriften og noen blir båret. Det er hele poenget med tabellen
A35: Gir tjenesten i tilbakegang det svakeste bidraget? | C35: =IF(I18=MIN(I12:I18),"OK — tjenesten i tilbakegang gir svakest bidrag per montørtime","AVVIK: en tjeneste i tilbakegang som gir godt bidrag, skal ikke saneres uten videre") -> OK — tjenesten i tilbakegang gir svakest bidrag per montørtime
A37: Prøv dette: sett montørtimene på nybygg i E13 ned med to. Se hva som skjer med DB per montørtime — og hvor lite som skal til før den svakeste tjenesten er en av de beste.
A38: Kilde: Hjertnes kap. 6 om produktnivåer, kvalitet og sortiment. Dekningsbidrag og montørtimer: Bok 1 kap. 2 og 5. Prisene på typeoppdragene er Nordlys Elektro AS sine egne.

Sheet Scenario
A1: Tre scenarioer
A2: Endre de gule cellene og se hva som skjer. Alle tall hentes fra de andre arkene.
A4: Scenario A · saneres antenne- og koaksanlegg?
A5: Tjenesten er i tilbakegang og gir det svakeste bidraget per montørtime. Hva er den verdt, og hva ville timene gitt et annet sted?
A7: Antenneoppdrag i 2026 | B7: 22 | E7: Var 96 i 2022. Fiberen har overtatt behovet.
A8: Montørtimer per oppdrag | B8: =Produktbidrag!E18 -> 4
A9: Dekningsbidrag per oppdrag | B9: =Produktbidrag!G18 -> 740
A10: = Montørtimer tjenesten binder i året | B10: =B7*B8 -> 88
A11: Andel av de fakturerte montørtimene | B11: =B10/Produktbidrag!B7 -> 0.0061111111 | E11: Legg merke til hvor lite det er. Sanering handler om oppmerksomhet og kompetanse, ikke om kapasitet.
A12: = Dekningsbidrag tjenesten gir i året | B12: =B7*B9 -> 16280
A13: Dekningsbidrag per montørtime, beste tjeneste | B13: =Produktbidrag!B23 -> 1216.6667
A14: Hva de samme timene ville gitt der | B14: =B10*B13 -> 107066.67
A15: = Gevinst ved å flytte timene | B15: =B14-B12 -> 90786.667 | E15: Forutsetter at det finnes oppdrag å flytte timene til. Gjør det ikke det, er gevinsten null og oppdraget verdt å ta.
A17: Kontroll
A18: Lønner det seg å flytte timene? | C18: =IF(B15>0,"OK — timene gir mer et annet sted, forutsatt at det finnes oppdrag å flytte dem til","AVVIK: tjenesten gir mer per time enn alternativet — da skal den ikke saneres") -> OK — timene gir mer et annet sted, forutsatt at det finnes oppdrag å flytte dem til
A21: Scenario B · konkurrenten er billigere. Pris eller produkt?
A22: Den eksamensnære oppgaven i kapitlet. To svar på det samme presset, regnet mot hverandre.
A24: Oppdraget vi regner på: boliginstallasjon | B24: =Produktbidrag!C12 -> 6820 | E24: Pris uten mva., hentet fra arket Produktbidrag.
A25: Merkost på oppdraget | B25: =Produktbidrag!F12 -> 5920
A26: Dekningsbidrag i dag | B26: =B24-B25 -> 900
A27: Montørtimer på oppdraget | B27: =Produktbidrag!E12 -> 3
B29: Svar med prisen | C29: Svar med produktet | E29: Hva raden betyr
A30: Konkurrentens priskutt / produktløftets kostnad | B30: 0.1 | C30: 250 | E30: De to gule cellene er tiltaket. Til venstre en prosent av prisen, til høyre kroner per oppdrag.
A31: Pris til kunden etter tiltaket | B31: =$B$24*(1-B30) -> 6138 | C31: =$B$24 -> 6820 | E31: Produktløftet endrer ikke prisen. Det er hele forskjellen.
A32: Merkost etter tiltaket | B32: =$B$25 -> 5920 | C32: =$B$25+C30 -> 6170
A33: = Dekningsbidrag etter tiltaket | B33: =B31-B32 -> 218 | C33: =C31-C32 -> 650
A34: Endring i dekningsbidrag | B34: =B33/$B$26-1 -> -0.75777778 | C34: =C33/$B$26-1 -> -0.27777778
A35: = Nødvendig volumfaktor for å komme ut likt | B35: =IF(B33<=0,"umulig",$B$26/B33) -> 4.1284404 | C35: =IF(C33<=0,"umulig",$B$26/C33) -> 1.3846154 | E35: Gammelt dekningsbidrag delt på nytt. Så mange ganger så mange oppdrag må til.
A36: Nødvendig volumøkning | B36: =IF(B33<=0,"umulig",B35-1) -> 3.1284404 | C36: =IF(C33<=0,"umulig",C35-1) -> 0.38461538
A37: Dekningsbidrag per montørtime etter tiltaket | B37: =B33/$B$27 -> 72.666667 | C37: =C33/$B$27 -> 216.66667
A38: Mot snittet i bedriften | B38: =IF(B37>=Produktbidrag!$B$8,"over","under") -> under | C38: =IF(C37>=Produktbidrag!$B$8,"over","under") -> under
A39: Dom | E39: =IF(C35<B35,"Produktløftet krever minst volumøkning. Svar med produktet, ikke med prisen","Prisavslaget krever minst volumøkning. Sjekk om produktløftet er priset for dyrt") -> Produktløftet krever minst volumøkning. Svar med produktet, ikke med prisen
A41: Kontroll
A42: Er det fortsatt dekningsbidrag igjen etter prisavslaget? | C42: =IF(B33>0,"OK — avslaget spiser ikke hele bidraget","AVVIK: prisavslaget gir null eller negativt dekningsbidrag — da finnes det ingen volumøkning som redder jobben") -> OK — avslaget spiser ikke hele bidraget
A43: Koster produktløftet mindre enn bidraget? | C43: =IF(C30<B26,"OK — produktløftet koster mindre enn dekningsbidraget på oppdraget","AVVIK: et produktløft som koster mer enn bidraget, er en prisreduksjon i forkledning") -> OK — produktløftet koster mindre enn dekningsbidraget på oppdraget
A46: Scenario C · den nye tjenesten i introduksjonsfasen
A47: Batterilagring er ikke levert ennå. Prisen er et anslag, og den første jobben går langsomt.
A49: Mål for 2027, antall anlegg | B49: 6
A50: Dekningsbidrag per anlegg | B50: =Produktbidrag!G19 -> 6640
A51: Montørtimer per anlegg | B51: =Produktbidrag!E19 -> 24
...

Sheet Din egen meny
A1: Din egen bedrift
A2: Samme oppsett, tomt. Fyll inn dine egne tjenester.
A4: Kostsats per montørtime | B4: 0
A5: Dekningsbidrag i fjor, hele bedriften | B5: 0
A6: Fakturerte montørtimer i fjor | B6: 0
A7: = Dekningsbidrag per fakturert montørtime | B7: =IF(B6=0,"",B5/B6) | J7: Målestokken din. Alt under denne bæres av noe annet.
A9: Typeoppdrag | B9: Fase | C9: Pris uten mva. | D9: Materiell | E9: Montørtimer | F9: Merkost (VEK) | G9: Dekningsbidrag | H9: Dekningsgrad | I9: DB per montørtime | J9: Mot snittet
C10: 0 | D10: 0 | E10: 0 | F10: =D10+E10*$B$4 -> 0 | G10: =IF(C10=0,"",C10-F10) | H10: =IF(C10=0,"",G10/C10) | I10: =IF(E10=0,"",G10/E10) | J10: =IF(OR(E10=0,$B$7=""),"",IF(I10>=$B$7,"Over snittet","Under snittet"))
C11: 0 | D11: 0 | E11: 0 | F11: =D11+E11*$B$4 -> 0 | G11: =IF(C11=0,"",C11-F11) | H11: =IF(C11=0,"",G11/C11) | I11: =IF(E11=0,"",G11/E11) | J11: =IF(OR(E11=0,$B$7=""),"",IF(I11>=$B$7,"Over snittet","Under snittet"))
C12: 0 | D12: 0 | E12: 0 | F12: =D12+E12*$B$4 -> 0 | G12: =IF(C12=0,"",C12-F12) | H12: =IF(C12=0,"",G12/C12) | I12: =IF(E12=0,"",G12/E12) | J12: =IF(OR(E12=0,$B$7=""),"",IF(I12>=$B$7,"Over snittet","Under snittet"))
C13: 0 | D13: 0 | E13: 0 | F13: =D13+E13*$B$4 -> 0 | G13: =IF(C13=0,"",C13-F13) | H13: =IF(C13=0,"",G13/C13) | I13: =IF(E13=0,"",G13/E13) | J13: =IF(OR(E13=0,$B$7=""),"",IF(I13>=$B$7,"Over snittet","Under snittet"))
C14: 0 | D14: 0 | E14: 0 | F14: =D14+E14*$B$4 -> 0 | G14: =IF(C14=0,"",C14-F14) | H14: =IF(C14=0,"",G14/C14) | I14: =IF(E14=0,"",G14/E14) | J14: =IF(OR(E14=0,$B$7=""),"",IF(I14>=$B$7,"Over snittet","Under snittet"))
C15: 0 | D15: 0 | E15: 0 | F15: =D15+E15*$B$4 -> 0 | G15: =IF(C15=0,"",C15-F15) | H15: =IF(C15=0,"",G15/C15) | I15: =IF(E15=0,"",G15/E15) | J15: =IF(OR(E15=0,$B$7=""),"",IF(I15>=$B$7,"Over snittet","Under snittet"))
C16: 0 | D16: 0 | E16: 0 | F16: =D16+E16*$B$4 -> 0 | G16: =IF(C16=0,"",C16-F16) | H16: =IF(C16=0,"",G16/C16) | I16: =IF(E16=0,"",G16/E16) | J16: =IF(OR(E16=0,$B$7=""),"",IF(I16>=$B$7,"Over snittet","Under snittet"))
C17: 0 | D17: 0 | E17: 0 | F17: =D17+E17*$B$4 -> 0 | G17: =IF(C17=0,"",C17-F17) | H17: =IF(C17=0,"",G17/C17) | I17: =IF(E17=0,"",G17/E17) | J17: =IF(OR(E17=0,$B$7=""),"",IF(I17>=$B$7,"Over snittet","Under snittet"))
C18: 0 | D18: 0 | E18: 0 | F18: =D18+E18*$B$4 -> 0 | G18: =IF(C18=0,"",C18-F18) | H18: =IF(C18=0,"",G18/C18) | I18: =IF(E18=0,"",G18/E18) | J18: =IF(OR(E18=0,$B$7=""),"",IF(I18>=$B$7,"Over snittet","Under snittet"))
C19: 0 | D19: 0 | E19: 0 | F19: =D19+E19*$B$4 -> 0 | G19: =IF(C19=0,"",C19-F19) | H19: =IF(C19=0,"",G19/C19) | I19: =IF(E19=0,"",G19/E19) | J19: =IF(OR(E19=0,$B$7=""),"",IF(I19>=$B$7,"Over snittet","Under snittet"))
A21: Kontroll
A22: Er målestokken fylt ut? | C22: =IF(B6>0,"OK — målestokken er på plass, og kolonne J kan svare","AVVIK: fyll inn dekningsbidrag og fakturerte timer i B5 og B6 først — uten en målestokk er tabellen bare tall") -> AVVIK: fyll inn dekningsbidrag og fakturerte timer i B5 og B6 først — uten en målestokk er tabellen bare tall
A23: Har alle tjenestene du har lagt inn positivt bidrag? | C23: =IF(COUNTIF(G10:G19,"<0")=0,"OK — ingen av tjenestene taper penger på hvert oppdrag","AVVIK: minst én tjeneste har negativt dekningsbidrag. Den skal du enten prise om eller slutte med") -> OK — ingen av tjenestene taper penger på hvert oppdrag
A25: Ta med tre til fem av tjenestene dine, ikke alle. Det er rekkefølgen som er poenget, ikke fullstendigheten.
