Workbook

Sheet Enkelt
A1: Lønner utstyret seg? Den enkle versjonen
A2: Fyll inn de fire gule cellene. Svaret står i den grønne. Arket regner med fire års levetid og ingen restverdi. Vil du gå dypere, ligger hele modellen i arkene bak.
A4: Det du vet
A5: Hva koster utstyret i dag? | B5: 480000 | C5: Kjøpesummen uten mva. Den betales i år 0 og skal ikke diskonteres.
A6: Hvor mye mer kommer inn hvert år med utstyret? | B6: 260000 | C6: Ekstra penger inn hvert år fordi dere har eget utstyr.
A7: Hvor mye mer går ut hvert år til drift av utstyret? | B7: 90000 | C7: Ikke avskrivninger. Bare penger som faktisk går ut.
A8: Hvor mye vil bedriften minst tjene på pengene? | B8: 0.1 | C8: Avkastningskravet. Det er ikke lånerenta, men det du kunne fått uten risiko pluss et påslag for risikoen.
A10: Regnestykket
A11: Netto inn hvert år | B11: =B6-B7 -> 170000 | C11: Innbetalingsoverskuddet. Det er dette tallet som står i kontantstrømmen.
A12: År 1 verdt i dag | B12: =B11/(1+B8) -> 154545.45 | C12: Delt på 1 pluss kravet.
A13: År 2 verdt i dag | B13: =B11/(1+B8)^2 -> 140495.87 | C13: Delt på 1 pluss kravet, opphøyd i andre.
A14: År 3 verdt i dag | B14: =B11/(1+B8)^3 -> 127723.52 | C14: Opphøyd i tredje.
A15: År 4 verdt i dag | B15: =B11/(1+B8)^4 -> 116112.29 | C15: Opphøyd i fjerde. Jo lenger fram, jo mindre verdt.
A16: Alle fire årene verdt i dag | B16: =B12+B13+B14+B15 -> 538877.13 | C16: Det investeringen gir, regnet om til kjøpsdagen.
A18: NÅVERDI | B18: =B16-B5 -> 58877.126 | C18: Positiv betyr lønnsom. Negativ betyr at investeringen gir mindre enn kravet.
A19: Tilbakebetalingstid, år | B19: =B5/B11 -> 2.8235294 | C19: Hvor fort pengene er tilbake. Sier ikke om investeringen lønner seg.
A20: Pluss på papiret, uten å regne om | B20: =4*B11-B5 -> 200000 | C20: Kroner fra ulike år lagt sammen. Ser bra ut, men betyr ingenting.
A22: Hva svaret betyr
A23: ="Nåverdien er "&TEXT(ROUND(B18,0),"#,##0")&" kroner. Positiv nåverdi betyr at utstyret lønner seg ved dette kravet. Negativ betyr at det ikke gjør det." -> Nåverdien er 58,877 kroner. Positiv nåverdi betyr at utstyret lønner seg ved dette kravet. Negativ betyr at det ikke gjør det.
A25: Prøv selv
A26: 1. Sett avkastningskravet (B8) til 16 prosent. Hva skjer med nåverdien?
A27: 2. Hvor høyt kan kravet (B8) bli før nåverdien blir negativ?
A28: 3. Hvorfor er tallet i B20 så mye større enn nåverdien?
A30: Tallene er termograferingsutstyret Nordlys Elektro AS vurderer i 2027 (sammendraget og faktaarket). Kilde: Økonomistyring for LØM-emnet, kap. 10.1 og 10.2. Nordlys Elektro AS er en konstruert casebedrift.

Sheet Veiledning
A1: Investeringsanalyse
A2: LØM Økonomistyring kap. 10 · arbeidsregneark · Fagskolen Oslo, Avdeling Elkraft
A3: Emne: Teknisk kommunikasjon og ledelse for 1ET-klassene · LØM for 2ET, 2EK, 3EK og 4EK
A4: Fargekode
A5: Gul celle med blå skrift | B5: Inndata — dette er tallene du endrer.
A6: Grå eller lyseblå celle, svart skrift | B6: Formel — regner seg selv. Ikke skriv over den.
A7: Mørkeblå rad med hvit skrift | B7: Kolonneoverskrift.
A9: Ark i arbeidsboka
A10: Enkelt | B10: Start her. Fire gule celler, ett svar. Nåverdien regnet år for år på den enkleste måten.
A11: Investering | B11: Kalkulatoren. Kontantstrøm år for år, diskontering år for år, og de tre svarene: tilbakebetalingstid, nåverdi og internrente.
A12: Nåverdiprofil | B12: Nåverdien ved avkastningskrav fra 6 til 20 prosent. Der tabellen krysser null, ligger internrenten.
A13: To alternativer | B13: To investeringer til samme pris, med ulik tilbakebetalingstid og motsatt rangering etter nåverdi.
A14: Kabling | B14: Klasseoppgaven: et kabelanlegg med 35 års levetid, målt mot et krav om tilbakebetaling på fire år.
A15: Din investering | B15: Samme kalkulator, tomt. Legg inn dine egne tall.
A17: Tallene som ligger inne er investeringen Nordlys Elektro AS vurderer i 2027 — den samme som betales i mars i likviditetsbudsjettet i kapittel 9.
A18: Kontantstrøm er ikke resultat. Avskrivninger hører ikke hjemme i en investeringsanalyse: pengene gikk ut den dagen utstyret ble betalt, og de står i år 0.
A19: Investeringsutgiften i år 0 skal ALDRI diskonteres. Den er allerede i dagens kroner.
A21: Tallene som ligger inne er et eksempel fra en elektrobedrift. Bytt dem ut med dine egne — alle formler følger med.
A22: Arbeidsregneark til LØM · Fagskolen Oslo, Avdeling Elkraft. Regnearket er øvingsstøtte, ikke et regnskapssystem.
A24: Den ene knappen
A25: Investering!B12 | B25: Avkastningskravet | C25: Endrer konklusjonen uten at ett eneste tall om utstyret er rørt. Prøv 10 % og 16 %.
A26: Investering!B11 | B26: Kapitalbindingen | C26: Står på null i utgangspunktet. Sett den til 30 000 i oppgave 3 og se både nåverdien og tilbakebetalingstiden stramme seg.
A28: Hvilken oppgave bruker hvilket ark
A29: Oppgave i øvingsheftet | B29: Ark | C29: Celler du endrer og leser av
A30: A1 · Lønner utstyret seg? | B30: Investering | C30: Les av B28, B29 og B32. Sett B12 til 16 % og se dommen i N33 snu.
A31: A2 · Klasseoppgave: linja som skal i kabel | B31: Kabling | C31: Les av B11, B17, B19, B20 og B21. Rad 25 og 26 viser hva kravet ikke ser.
A32: 1 · Kontantstrømmen og tilbakebetalingstiden | B32: Investering | C32: Endre B5, B6, B7 og B9. Les av kontantstrømmen i rad 21, den kumulerte i rad 22 og tilbakebetalingstiden i B31.
A33: 2 · Nåverdi ved to ulike avkastningskrav | B33: Investering | C33: Sett B12 til 10 % og deretter 16 %. Les av diskonteringsfaktorene i rad 23, nåverdien per år i rad 24 og summen i B29. Internrenten står i B32, og hele bildet i arket Nåverdiprofil.
A34: 3 · Kapitalbindingen ingen husker | B34: Investering | C34: Sett kapitalbindingen i B11. Les av kontantstrømmen i rad 21 på nytt, nåverdien i B29 og tilbakebetalingstiden i B31.
A35: 4 · Kablingen der metodene gir motsatt svar | B35: Kabling | C35: Endre B7 til B14. Les av B17, B18, B19, B20, B21, B22, B25 og B26.
A36: 5 · Eksamensnær: to investeringer til samme pris | B36: To alternativer | C36: Endre B6 til C8 og kravet i B10. Les av rad 15 til 19, sammenlikningen i rad 22 til 26 og gjentakelsesregningen i rad 30 til 33.
A38: Kontrollradene
A39: Hvert regneark har en kontrollblokk. Står det OK, henger tallene sammen. Står det AVVIK, farges cellen rød, og teksten sier hva som ikke går opp.
A40: Ett unntak: arket «Din investering» står på AVVIK til du har fylt inn dine egne tall.
A41: Kontroller i arbeidsboka: Investering B38, Investering B39, Investering B40, Investering B41, Nåverdiprofil B31, Nåverdiprofil B32, Nåverdiprofil B33, To alternativer B36, To alternativer B37, To alternativer B38, To alternativer B39, Kabling B29, Kabling B30, Kabling B31, Din investering B29, Din investering B31
A43: Slik henger kapitlene sammen
A44: Investeringen her er den samme som betales i mars i likviditetsbudsjettet i kapittel 9 — og som klasseoppgaven der foreslår å utsette til september. Kapitalbindingen er den samme typen kapitalbinding som i kapittel 6. Avkastningskravet er det samme kravet eierne stiller til egenkapitalen sin, og som du regner egenkapitalrentabiliteten av i kapittel 4. Og innbetalingsoverskuddet er dekningsbidrag, slik det defineres i kapittel 2.
A46: Kilder
A47: Hjertnes, J. og Skorpen, K.: Økonomistyring for LØM-emnet (ISBN 978-82-450-5544-3), kapittel 10 «Investeringsanalyse», avsnitt 10.1 til 10.3. Formler for nåverdi, tilbakebetalingstid og internrente: formelsamlingen til LØM-emnet.
A48: Bransjetall: NHO Elektro, Lønnsomhetsrapport 2025, gjengitt i Elektro 24-7 19.08.2026 (hentet 10.09.2026). De 809 er bedriftene i datagrunnlaget, ikke bransjen. NHO Elektro oppgir ikke svarprosent.
...

Sheet Investering
A1: Lønner investeringen seg?
A2: Endre de gule cellene. Kontantstrømmen settes opp år for år, og diskonteres år for år.
A4: 1 · Investeringen
A5: Kjøpesum, betalt i dag | B5: 480000 | N5: Hele beløpet står i år 0 og skal IKKE diskonteres.
A6: Årlige innbetalinger | B6: 260000
A7: Årlige utbetalinger | B7: 90000
A8: = Årlig innbetalingsoverskudd | B8: =B6-B7 -> 170000 | N8: Kontantstrøm, ikke resultat. Avskrivninger hører ikke hjemme her.
A9: Levetid, år | B9: 4 | N9: Høyst 10 år i dette arket.
A10: Utrangeringsverdi i siste år | B10: 0
A11: Kapitalbinding i omløpsmidler | B11: 0 | N11: Ut i år 0, inn igjen i siste år. Sett den til 30 000 i oppgave 3.
A12: Avkastningskrav | B12: 0.1 | N12: DETTE er cellen. Endre den til 16 % og se konklusjonen snu.
A13: Krav til tilbakebetalingstid, år | B13: 3
A15: 2 · Kontantstrømmen år for år
A16: Post | C16: År 0 | D16: År 1 | E16: År 2 | F16: År 3 | G16: År 4 | H16: År 5 | I16: År 6 | J16: År 7 | K16: År 8 | L16: År 9 | M16: År 10 | N16: Kommentar
A17: Årstall | C17: =0 -> 0 | D17: =1 -> 1 | E17: =2 -> 2 | F17: =3 -> 3 | G17: =4 -> 4 | H17: =5 -> 5 | I17: =6 -> 6 | J17: =7 -> 7 | K17: =8 -> 8 | L17: =9 -> 9 | M17: =10 -> 10
A18: Investering og kapitalbinding | C18: =-($B$5+$B$11) -> -480000 | D18: =0 -> 0 | E18: =0 -> 0 | F18: =0 -> 0 | G18: =0 -> 0 | H18: =0 -> 0 | I18: =0 -> 0 | J18: =0 -> 0 | K18: =0 -> 0 | ... M18: =0 -> 0
A19: Innbetalingsoverskudd | C19: =0 -> 0 | D19: =IF(D17<=$B$9,$B$8,0) -> 170000 | E19: =IF(E17<=$B$9,$B$8,0) -> 170000 | F19: =IF(F17<=$B$9,$B$8,0) -> 170000 | G19: =IF(G17<=$B$9,$B$8,0) -> 170000 | H19: =IF(H17<=$B$9,$B$8,0) -> 0 | I19: =IF(I17<=$B$9,$B$8,0) -> 0 | J19: =IF(J17<=$B$9,$B$8,0) -> 0 | K19: =IF(K17<=$B$9,$B$8,0) -> 0 | ... M19: =IF(M17<=$B$9,$B$8,0) -> 0
A20: Utrangeringsverdi og frigjort kapitalbinding | C20: =0 -> 0 | D20: =IF(D17=$B$9,$B$10+$B$11,0) -> 0 | E20: =IF(E17=$B$9,$B$10+$B$11,0) -> 0 | F20: =IF(F17=$B$9,$B$10+$B$11,0) -> 0 | G20: =IF(G17=$B$9,$B$10+$B$11,0) -> 0 | H20: =IF(H17=$B$9,$B$10+$B$11,0) -> 0 | I20: =IF(I17=$B$9,$B$10+$B$11,0) -> 0 | J20: =IF(J17=$B$9,$B$10+$B$11,0) -> 0 | K20: =IF(K17=$B$9,$B$10+$B$11,0) -> 0 | ... M20: =IF(M17=$B$9,$B$10+$B$11,0) -> 0
A21: = Kontantstrøm | C21: =SUM(C18:C20) -> -480000 | D21: =SUM(D18:D20) -> 170000 | E21: =SUM(E18:E20) -> 170000 | F21: =SUM(F18:F20) -> 170000 | G21: =SUM(G18:G20) -> 170000 | H21: =SUM(H18:H20) -> 0 | I21: =SUM(I18:I20) -> 0 | J21: =SUM(J18:J20) -> 0 | ... M21: =SUM(M18:M20) -> 0
A22: Kumulert kontantstrøm | C22: =C21 -> -480000 | D22: =C22+D21 -> -310000 | E22: =D22+E21 -> -140000 | F22: =E22+F21 -> 30000 | G22: =F22+G21 -> 200000 | H22: =G22+H21 -> 200000 | I22: =H22+I21 -> 200000 | J22: =I22+J21 -> 200000 | K22: =J22+K21 -> 200000 | ... M22: =L22+M21 -> 200000 | N22: Året denne snur fra minus til pluss, er året investeringen er tilbakebetalt.
A23: Diskonteringsfaktor | C23: =1/(1+$B$12)^C17 -> 1 | D23: =1/(1+$B$12)^D17 -> 0.90909091 | E23: =1/(1+$B$12)^E17 -> 0.82644628 | F23: =1/(1+$B$12)^F17 -> 0.7513148 | G23: =1/(1+$B$12)^G17 -> 0.68301346 | H23: =1/(1+$B$12)^H17 -> 0.62092132 | I23: =1/(1+$B$12)^I17 -> 0.56447393 | J23: =1/(1+$B$12)^J17 -> 0.51315812 | ... M23: =1/(1+$B$12)^M17 -> 0.38554329 | N23: Hvor mye én krone i det året er verdt i dag.
A24: Nåverdi av årets kontantstrøm | C24: =C21*C23 -> -480000 | D24: =D21*D23 -> 154545.45 | E24: =E21*E23 -> 140495.87 | F24: =F21*F23 -> 127723.52 | G24: =G21*G23 -> 116112.29 | H24: =H21*H23 -> 0 | I24: =I21*I23 -> 0 | J24: =J21*J23 -> 0 | ... M24: =M21*M23 -> 0
A25: Kumulert nåverdi | C25: =C24 -> -480000 | D25: =C25+D24 -> -325454.55 | E25: =D25+E24 -> -184958.68 | F25: =E25+F24 -> -57235.162 | G25: =F25+G24 -> 58877.126 | H25: =G25+H24 -> 58877.126 | I25: =H25+I24 -> 58877.126 | J25: =I25+J24 -> 58877.126 | K25: =J25+K24 -> 58877.126 | ... M25: =L25+M24 -> 58877.126
A27: 3 · De tre svarene
A28: Sum kontantstrøm, udiskontert | B28: =SUM(C21:M21) -> 200000 | N28: Dette tallet ser bra ut og betyr ingenting: det legger sammen kroner fra ulike år som om de var like mye verdt.
A29: = NÅVERDI | B29: =SUM(C24:M24) -> 58877.126
A30: Nåverdi kontrollregnet med NPV-funksjonen | B30: =C21+NPV(B12,D21:M21) -> 58877.126 | N30: Merk at NPV-funksjonen diskonterer FRA år 1. År 0 legges til utenfor.
A31: = Tilbakebetalingstid, år | B31: =(B5+B11)/B8 -> 2.8235294
A32: = Internrente | B32: =IRR(C21:M21) -> 0.15549578 | N32: Den renten som gjør nåverdien null. Investeringen gjennomføres hvis den er høyere enn kravet.
A33: Dom etter nåverdimetoden | N33: =IF(B29>0,"Lønnsom — nåverdien er positiv, altså gir investeringen mer enn kravet","Ulønnsom — nåverdien er negativ, altså gir investeringen mindre enn kravet") -> Lønnsom — nåverdien er positiv, altså gir investeringen mer enn kravet
A34: Dom etter tilbakebetalingsmetoden | N34: =IF(B31<=B13,"Passerer kravet","Stryker på kravet") -> Passerer kravet
A35: Er de to metodene enige? | N35: =IF((B29>0)=(B31<=B13),"Ja — begge metodene peker samme vei","Nei — metodene gir motsatt svar. Da må du velge, og begrunne valget") -> Ja — begge metodene peker samme vei
A37: Kontroll
A38: Gir de to nåverdiregningene samme svar? | B38: =IF(ABS(B29-B30)<1,"OK — den håndregnede nåverdien stemmer med NPV-funksjonen","AVVIK: de to måtene å regne nåverdi på gir ulikt svar") -> OK — den håndregnede nåverdien stemmer med NPV-funksjonen
A39: Henger internrenten sammen med nåverdien? | B39: =IF(OR(AND(B32>B12,B29>0),AND(B32<B12,B29<0),ABS(B29)<1),"OK — positiv nåverdi og internrente over kravet hører sammen","AVVIK: internrenten og nåverdien peker hver sin vei — det er umulig") -> OK — positiv nåverdi og internrente over kravet hører sammen
A40: Er levetiden innenfor arket? | B40: =IF(AND($B$9>=1,$B$9<=10),"OK — levetiden får plass i tabellen","AVVIK: arket har plass til høyst 10 år. Lengre levetid regner du med annuitetsformelen, slik arket Kabling gjør") -> OK — levetiden får plass i tabellen
A41: Er kapitalbindingen behandlet med begge fortegn? | B41: =IF(OR($B$11=0,ABS(SUMIF($C$17:$M$17,$B$9,$C$20:$M$20)-($B$10+$B$11))<1),"OK — kapitalbindingen står med minus i år 0 og pluss i siste år","AVVIK: kapitalbindingen kommer ikke tilbake i siste år") -> OK — kapitalbindingen står med minus i år 0 og pluss i siste år
A43: 4 · Hva de tre metodene svarer på
A44: Tilbakebetalingsmetoden | B44: Hvor lenge er pengene bundet? | N44: Ser ingenting av det som skjer etter tilbakebetalingsdagen, og tar ikke hensyn til pengenes tidsverdi.
A45: Nåverdimetoden | B45: Hvor mye er investeringen verdt i dag? | N45: Svarer i kroner. Krever at du har et avkastningskrav.
...

Sheet Nåverdiprofil
A1: Nåverdien ved ulike avkastningskrav
A2: Samme investering, samme kontantstrøm. Bare kravet endrer seg.
A4: Hentes fra arket Investering
A5: Kravet du bruker nå | B5: =Investering!B12 -> 0.1
A6: Internrente | B6: =Investering!B32 -> 0.15549578 | E6: Der linja under krysser null.
A8: Avkastningskrav | B8: Nåverdi | C8: Endring fra raden over | D8: Dom | E8: Hva raden betyr
A9: 0.06 | B9: =Investering!$C$21+NPV(A9,Investering!$D$21:$M$21) -> 109067.95 | D9: =IF(B9>0,"Lønnsom","Ulønnsom") -> Lønnsom | E9: Lavt krav — for eksempel et tiltak banken finansierer billig.
A10: 0.07 | B10: =Investering!$C$21+NPV(A10,Investering!$D$21:$M$21) -> 95825.914 | C10: =B10-B9 -> -13242.041 | D10: =IF(B10>0,"Lønnsom","Ulønnsom") -> Lønnsom
A11: 0.08 | B11: =Investering!$C$21+NPV(A11,Investering!$D$21:$M$21) -> 83061.563 | C11: =B11-B10 -> -12764.351 | D11: =IF(B11>0,"Lønnsom","Ulønnsom") -> Lønnsom
A12: 0.09 | B12: =Investering!$C$21+NPV(A12,Investering!$D$21:$M$21) -> 70752.379 | C12: =B12-B11 -> -12309.184 | D12: =IF(B12>0,"Lønnsom","Ulønnsom") -> Lønnsom
A13: 0.1 | B13: =Investering!$C$21+NPV(A13,Investering!$D$21:$M$21) -> 58877.126 | C13: =B13-B12 -> -11875.253 | D13: =IF(B13>0,"Lønnsom","Ulønnsom") -> Lønnsom | E13: Nordlys' vanlige krav.
A14: 0.11 | B14: =Investering!$C$21+NPV(A14,Investering!$D$21:$M$21) -> 47415.767 | C14: =B14-B13 -> -11461.359 | D14: =IF(B14>0,"Lønnsom","Ulønnsom") -> Lønnsom
A15: 0.12 | B15: =Investering!$C$21+NPV(A15,Investering!$D$21:$M$21) -> 36349.389 | C15: =B15-B14 -> -11066.378 | D15: =IF(B15>0,"Lønnsom","Ulønnsom") -> Lønnsom
A16: 0.13 | B16: =Investering!$C$21+NPV(A16,Investering!$D$21:$M$21) -> 25660.125 | C16: =B16-B15 -> -10689.264 | D16: =IF(B16>0,"Lønnsom","Ulønnsom") -> Lønnsom
A17: 0.14 | B17: =Investering!$C$21+NPV(A17,Investering!$D$21:$M$21) -> 15331.092 | C17: =B17-B16 -> -10329.034 | D17: =IF(B17>0,"Lønnsom","Ulønnsom") -> Lønnsom
A18: 0.15 | B18: =Investering!$C$21+NPV(A18,Investering!$D$21:$M$21) -> 5346.3217 | C18: =B18-B17 -> -9984.7701 | D18: =IF(B18>0,"Lønnsom","Ulønnsom") -> Lønnsom | E18: Her er marginen nesten borte.
A19: 0.16 | B19: =Investering!$C$21+NPV(A19,Investering!$D$21:$M$21) -> -4309.2915 | C19: =B19-B18 -> -9655.6132 | D19: =IF(B19>0,"Lønnsom","Ulønnsom") -> Ulønnsom | E19: Eierens krav. Nå er nåverdien negativ.
A20: 0.17 | B20: =Investering!$C$21+NPV(A20,Investering!$D$21:$M$21) -> -13650.048 | C20: =B20-B19 -> -9340.7567 | D20: =IF(B20>0,"Lønnsom","Ulønnsom") -> Ulønnsom
A21: 0.18 | B21: =Investering!$C$21+NPV(A21,Investering!$D$21:$M$21) -> -22689.493 | C21: =B21-B20 -> -9039.445 | D21: =IF(B21>0,"Lønnsom","Ulønnsom") -> Ulønnsom
A22: 0.19 | B22: =Investering!$C$21+NPV(A22,Investering!$D$21:$M$21) -> -31440.462 | C22: =B22-B21 -> -8750.9686 | D22: =IF(B22>0,"Lønnsom","Ulønnsom") -> Ulønnsom
A23: 0.2 | B23: =Investering!$C$21+NPV(A23,Investering!$D$21:$M$21) -> -39915.123 | C23: =B23-B22 -> -8474.6617 | D23: =IF(B23>0,"Lønnsom","Ulønnsom") -> Ulønnsom | E23: Krav som stilles til risikable prosjekter.
A25: Les tabellen slik
A26: Nåverdien faller hele veien nedover, og den faller fordi hver framtidig krone blir mindre verdt når du krever mer avkastning.
A27: Der kolonne D skifter fra «Lønnsom» til «Ulønnsom», ligger internrenten. Det er ikke en tilfeldighet — det er definisjonen.
A28: Legg merke til kolonne C: fallet blir mindre for hvert prosentpoeng. Diskontering er ikke lineær.
A30: Kontroll
A31: Faller nåverdien når kravet stiger? | B31: =IF(AND(B9>B10,B22>B23),"OK — høyere krav gir lavere nåverdi, hele tabellen igjennom","AVVIK: tabellen skal falle nedover") -> OK — høyere krav gir lavere nåverdi, hele tabellen igjennom
A32: Krysser tabellen null ved internrenten? | B32: =IF(AND(MIN(B9:B23)<0,MAX(B9:B23)>0),"OK — nåverdien skifter fortegn inne i tabellen, og der ligger internrenten","AVVIK: internrenten ligger utenfor tabellen — utvid kravene i kolonne A") -> OK — nåverdien skifter fortegn inne i tabellen, og der ligger internrenten
A33: Stemmer raden for dagens krav med kalkulatoren? | B33: =IF(ABS(INDEX($B$9:$B$23,MATCH($B$5,$A$9:$A$23,0))-Investering!B29)<1,"OK — raden for kravet du bruker, gir samme nåverdi som arket Investering","AVVIK: kravet i Investering!B12 finnes ikke i tabellen, eller tallene stemmer ikke") -> OK — raden for kravet du bruker, gir samme nåverdi som arket Investering
A35: Kilde: Økonomistyring for LØM-emnet kap. 10.2 og 10.3.

Sheet To alternativer
A1: To investeringer til samme pris
A2: Oppgave 5 i øvingsheftet. Ulik tilbakebetalingstid, motsatt rangering.
A4: 1 · De to alternativene
B5: A · Kabelmaskin med grøftefres | C5: B · Solcelleanlegg på verksted og lager | J5: Hva raden betyr
A6: Kjøpesum | B6: 480000 | C6: 480000 | J6: Like dyre. Det er bare profilen som skiller dem.
A7: Årlig innbetalingsoverskudd | B7: 200000 | C7: 140000
A8: Levetid, år | B8: 3 | C8: 6
A9: Avkastningskrav | B9: =Investering!$B$12 -> 0.1 | C9: =Investering!$B$12 -> 0.1 | J9: Hentes fra arket Investering. Endre det der.
A10: Krav til tilbakebetalingstid, år | B10: 3 | C10: =B10 -> 3
A12: 2 · Svarene
A13: Sum innbetalt, udiskontert | B13: =B7*B8 -> 600000 | C13: =C7*C8 -> 840000
A14: Netto udiskontert | B14: =B13-B6 -> 120000 | C14: =C13-C6 -> 360000
A15: = Tilbakebetalingstid, år | B15: =B6/B7 -> 2.4 | C15: =C6/C7 -> 3.4285714
A16: Dom etter tilbakebetalingsmetoden | B16: =IF(B15<=B10,"Passerer","Stryker") -> Passerer | C16: =IF(C15<=C10,"Passerer","Stryker") -> Stryker | J16: Her stryker det ene alternativet — og det er det som er verdt mest.
A17: = Nåverdi | B17: =-B6+B7*(1-(1+B9)^-B8)/B9 -> 17370.398 | C17: =-C6+C7*(1-(1+C9)^-C8)/C9 -> 129736.5 | J17: Annuitetsformelen: like store beløp hvert år kan diskonteres i én operasjon.
A18: Dom etter nåverdimetoden | B18: =IF(B17>0,"Lønnsom","Ulønnsom") -> Lønnsom | C18: =IF(C17>0,"Lønnsom","Ulønnsom") -> Lønnsom
A19: = Internrente | B19: =RATE(B8,B7,-B6) -> 0.12044398 | C19: =RATE(C8,C7,-C6) -> 0.18782481
A21: 3 · Sammenlikningen
A22: B er verdt mer enn A med | B22: =C17-B17 -> 112366.1
A23: så mange ganger så høy nåverdi | B23: =C17/B17 -> 7.4688269
A24: Tilbakebetalingskravet måtte vært minst | B24: =C15 -> 3.4285714 | J24: for at B skulle passere. Kravet i B10 er strengere enn det.
A25: A slutter å være lønnsom ved et krav på | B25: =B19 -> 0.12044398
A26: B slutter å være lønnsom ved et krav på | B26: =C19 -> 0.18782481 | J26: B tåler et langt høyere krav før den blir ulønnsom. Det er robusthet.
A28: 4 · Er sammenlikningen rettferdig?
A29: A har kortere levetid. Kjøpes den på nytt når den er utslitt, blir horisonten den samme.
A30: Antall ganger A kjøpes i løpet av B sin levetid | B30: =INT(C8/B8) -> 2
A31: Nåverdi av A kjøpt om igjen, over hele horisonten | B31: =B17+B17/(1+B9)^B8*(B30-1) -> 30421.035 | J31: Hver ny runde er den samme nåverdien, diskontert til det året den starter.
A32: B er fortsatt bedre med | B32: =C17-B31 -> 99315.462
A33: Dom | J33: =IF(C17>B31,"B er best også når A kjøpes om igjen over samme horisont","A blir best når den kjøpes om igjen — da snur konklusjonen") -> B er best også når A kjøpes om igjen over samme horisont
A35: Kontroll
A36: Koster de to alternativene det samme? | B36: =IF(B6=C6,"OK — samme pris, så bare profilen skiller dem","AVVIK: ulik pris gjør sammenlikningen vanskeligere — da må du også se på nåverdi per investert krone") -> OK — samme pris, så bare profilen skiller dem
A37: Gir de to metodene motsatt svar? | B37: =IF(AND(B15<C15,C17>B17),"OK — A har kortest tilbakebetalingstid, og B har høyest nåverdi. Metodene rangerer motsatt, og det er hele oppgaven","AVVIK: her er metodene enige — da finnes det ingen sak å drøfte") -> OK — A har kortest tilbakebetalingstid, og B har høyest nåverdi. Metodene rangerer motsatt, og det er hele oppgaven
A38: Er begge alternativene lønnsomme i det hele tatt? | B38: =IF(AND(B17>0,C17>0),"OK — begge gir positiv nåverdi. Valget står mellom to gode alternativer","AVVIK: et alternativ med negativ nåverdi skal ikke rangeres, det skal droppes") -> OK — begge gir positiv nåverdi. Valget står mellom to gode alternativer
A39: Stemmer internrenten med nåverdien? | B39: =IF(AND(B19>B9,C19>C9),"OK — begge internrentene ligger over kravet, som de skal når nåverdien er positiv","AVVIK: internrente og nåverdi peker hver sin vei") -> OK — begge internrentene ligger over kravet, som de skal når nåverdien er positiv
A41: Prøv dette: skru avkastningskravet i Investering!B12 oppover. Ved hvilket krav slutter A å være lønnsom, og ved hvilket krav slutter B? Forskjellen mellom de to tallene er hvor mye mer B tåler før den ryker.
A42: Kilde: Økonomistyring for LØM-emnet kap. 10.1 til 10.3, og avsnittet om hva tilbakebetalingsmetoden ikke ser. Prisen er den samme som utstyret i kapitlets hovedeksempel.

Sheet Kabling
A1: Linja som skal i kabel
A2: Klasseoppgaven. Et anlegg som skal stå i en generasjon, målt med en metode som ser fire år.
A4: 1 · Tiltaket
A5: Selskap | B5: Fjellkraft Nett AS
A6: Lengde luftlinje, km | B6: 3.5
A7: Investering | B7: 3450000
A8: Spart vedlikehold per år | B8: 260000
A9: Spart KILE-kostnad per år | B9: 340000 | E9: KILE: kvalitetsjusterte inntektsrammer ved ikke levert energi. Nettselskapet betaler for avbrudd hos kundene.
A10: Spart nettap per år | B10: 90000
A11: = Årlig innbetalingsoverskudd | B11: =SUM(B8:B10) -> 690000
A12: Levetid, år | B12: 35
A13: Avkastningskrav | B13: 0.06
A14: Krav til tilbakebetalingstid, år | B14: 4
A16: 2 · De to metodene gir motsatt svar
A17: Tilbakebetalingstid, år | B17: =B7/B11 -> 5 | C17: =IF(B17<=B14,"Passerer","Stryker") -> Stryker
A18: Årlig overskudd som måtte til for å passere | B18: =B7/B14 -> 862500 | E18: Så mye måtte spares hvert år for at tiltaket skulle klare kravet.
A19: Nåverdi over hele levetiden | B19: =-B7+B11*(1-(1+B13)^-B12)/B13 -> 6553790 | C19: =IF(B19>0,"Lønnsom","Ulønnsom") -> Lønnsom
A20: Nåverdi regnet over bare kravets fire år | B20: =-B7+B11*(1-(1+B13)^-B14)/B13 -> -1059077.1 | C20: =IF(B20>0,"Lønnsom","Ulønnsom") -> Ulønnsom | E20: Dette er alt tilbakebetalingsmetoden ser. Resten av levetiden er usynlig for den.
A21: Internrente | B21: =RATE(B12,B11,-B7) -> 0.19965801
A22: Hvor mange års levetid som skal til for nåverdi lik null | B22: =-LN(1-B7*B13/B11)/LN(1+B13) -> 6.121188 | E22: Under dette antallet år er tiltaket ulønnsomt. Sammenlikn med levetiden i B12.
A24: 3 · Hva et krav på fire år gjør
A25: Andel av levetiden kravet ser | B25: =B14/B12 -> 0.11428571 | E25: Et tilbakebetalingskrav på fire år er et rimelig krav på et instrument som blir utdatert, og et urimelig krav på en kabel i bakken.
A26: Verdi som ligger etter kravets fjerde år | B26: =B19-B20 -> 7612867.1 | E26: Alt dette er verdi metoden kaster.
A28: Kontroll
A29: Gir de to metodene motsatt svar? | B29: =IF(AND(B17>B14,B19>0),"OK — tiltaket stryker på tilbakebetalingstid og består på nåverdi. Det er hele poenget i oppgaven","AVVIK: her er metodene enige — da er saken enkel, og oppgaven mister sin spenning") -> OK — tiltaket stryker på tilbakebetalingstid og består på nåverdi. Det er hele poenget i oppgaven
A30: Er nåverdien over fire år negativ? | B30: =IF(B20<0,"OK — regnet bare over kravets år er tiltaket ulønnsomt. Metoden er ikke gal, den ser bare for kort","AVVIK: da passerer tiltaket begge metodene") -> OK — regnet bare over kravets år er tiltaket ulønnsomt. Metoden er ikke gal, den ser bare for kort
A31: Er levetiden lengre enn nullpunktet i år? | B31: =IF(B12>B22,"OK — anlegget lever lenger enn det må for å forsvare seg","AVVIK: levetiden er for kort til at tiltaket bærer seg") -> OK — anlegget lever lenger enn det må for å forsvare seg
A33: Kilde: Økonomistyring for LØM-emnet kap. 10.1 og 10.2. Fjellkraft Nett AS er nettselskapet Nordlys Elektro AS har rammeavtale med. Tallene er didaktiske forutsetninger, oppgitt i oppgaven slik eksamensoppgaver gjør det.

Sheet Din investering
A1: Din egen investering
A2: Samme kalkulator, ingen tall. Ta den med på jobb.
A4: 1 · Investeringen
A5: Kjøpesum, betalt i dag | B5: 0 | N5: Alt som må ut før anlegget virker.
A6: Årlige innbetalinger | B6: 0 | N6: Økt inntekt, eller spart utbetaling.
A7: Årlige utbetalinger | B7: 0 | N7: Drift, vedlikehold, forsikring.
A8: = Årlig innbetalingsoverskudd | B8: =B6-B7 -> 0
A9: Levetid, år | B9: 0 | N9: Høyst 10 år i dette arket.
A10: Utrangeringsverdi i siste år | B10: 0 | N10: Det du får for utstyret når du er ferdig.
A11: Kapitalbinding i omløpsmidler | B11: 0 | N11: Reservedeler og lager. Ut i år 0, inn igjen til slutt.
A12: Avkastningskrav | B12: 0.1
A13: Krav til tilbakebetalingstid, år | B13: 3
A15: 2 · Kontantstrømmen
A16: Post | C16: År 0 | D16: År 1 | E16: År 2 | F16: År 3 | G16: År 4 | H16: År 5 | I16: År 6 | J16: År 7 | K16: År 8 | L16: År 9 | M16: År 10 | N16: Kommentar
A17: Årstall | C17: =0 -> 0 | D17: =1 -> 1 | E17: =2 -> 2 | F17: =3 -> 3 | G17: =4 -> 4 | H17: =5 -> 5 | I17: =6 -> 6 | J17: =7 -> 7 | K17: =8 -> 8 | L17: =9 -> 9 | M17: =10 -> 10
A18: = Kontantstrøm | C18: =-($B$5+$B$11) -> 0 | D18: =IF(D17<=$B$9,$B$8,0)+IF(D17=$B$9,$B$10+$B$11,0) -> 0 | E18: =IF(E17<=$B$9,$B$8,0)+IF(E17=$B$9,$B$10+$B$11,0) -> 0 | F18: =IF(F17<=$B$9,$B$8,0)+IF(F17=$B$9,$B$10+$B$11,0) -> 0 | G18: =IF(G17<=$B$9,$B$8,0)+IF(G17=$B$9,$B$10+$B$11,0) -> 0 | H18: =IF(H17<=$B$9,$B$8,0)+IF(H17=$B$9,$B$10+$B$11,0) -> 0 | I18: =IF(I17<=$B$9,$B$8,0)+IF(I17=$B$9,$B$10+$B$11,0) -> 0 | J18: =IF(J17<=$B$9,$B$8,0)+IF(J17=$B$9,$B$10+$B$11,0) -> 0 | K18: =IF(K17<=$B$9,$B$8,0)+IF(K17=$B$9,$B$10+$B$11,0) -> 0 | ... M18: =IF(M17<=$B$9,$B$8,0)+IF(M17=$B$9,$B$10+$B$11,0) -> 0
A19: Kumulert | C19: =C18 -> 0 | D19: =C19+D18 -> 0 | E19: =D19+E18 -> 0 | F19: =E19+F18 -> 0 | G19: =F19+G18 -> 0 | H19: =G19+H18 -> 0 | I19: =H19+I18 -> 0 | J19: =I19+J18 -> 0 | K19: =J19+K18 -> 0 | ... M19: =L19+M18 -> 0
A20: Nåverdi av årets kontantstrøm | C20: =C18/(1+$B$12)^C17 -> 0 | D20: =D18/(1+$B$12)^D17 -> 0 | E20: =E18/(1+$B$12)^E17 -> 0 | F20: =F18/(1+$B$12)^F17 -> 0 | G20: =G18/(1+$B$12)^G17 -> 0 | H20: =H18/(1+$B$12)^H17 -> 0 | I20: =I18/(1+$B$12)^I17 -> 0 | J20: =J18/(1+$B$12)^J17 -> 0 | ... M20: =M18/(1+$B$12)^M17 -> 0
A22: 3 · Svarene
A23: = Nåverdi | B23: =SUM(C20:M20) -> 0
A24: = Tilbakebetalingstid, år | B24: =IF(B8<=0,"",(B5+B11)/B8)
A25: = Internrente | B25: =IF(B8<=0,"",IRR(C18:M18))
A26: Dom | N26: =IF(B5=0,"Fyll inn kjøpesummen i B5",IF(B23>0,"Lønnsom ved kravet i B12","Ulønnsom ved kravet i B12")) -> Fyll inn kjøpesummen i B5
A28: Kontroll
A29: Er arket fylt ut? | B29: =IF(B5=0,"AVVIK: fyll inn kjøpesummen i B5 og levetiden i B9",IF(B9<1,"AVVIK: levetiden må være minst ett år","OK — arket regner på din egen investering")) -> AVVIK: fyll inn kjøpesummen i B5 og levetiden i B9
A30: Dette arket starter tomt, så kontrollen står på AVVIK til du har fylt inn tallene.
A31: Er levetiden innenfor arket? | B31: =IF(B9<=10,"OK — levetiden får plass i tabellen","AVVIK: arket har plass til høyst 10 år") -> OK — levetiden får plass i tabellen
A33: Tre spørsmål å ta med: hva er avkastningskravet vårt, hvor lenge lever anlegget, og hva er alternativet til å bruke pengene her?
