Workbook

Sheet Enkelt
A1: Hva koster en overtidstime? Den enkle versjonen
A2: Fyll inn de seks gule cellene. Svaret står i den grønne. Alt annet regner seg selv. Vil du gå dypere, ligger hele modellen i arkene bak.
A4: Det du vet
A5: Hva tjener montøren i måneden, før skatt? | B5: 40000 | C5: 40 000 kroner er beløpet i oppgave 6, kapittel 2 i Økonomistyring for LØM-emnet. Satsene står i tabell 2.4.
A6: Hvor mange timer i uka er avtalt? | B6: 37.5 | C6: Nordlys har avtalt 37,5 timer. Loven setter taket på 40 (arbeidsmiljøloven § 10-4).
A7: Hvor mye kommer på toppen av lønna for en vanlig time? | B7: 0.468 | C7: Feriepenger, arbeidsgiveravgift, pensjon, helligdager, yrkesskade og sykepenger. Til sammen 46,8 prosent.
A8: Hvor stort er overtidstillegget? | B8: 0.4 | C8: Loven sier minst 40 prosent (arbeidsmiljøloven § 10-6).
A9: Hvor mye kommer på toppen for en overtidstime? | B9: 0.369 | C9: Bare feriepenger, arbeidsgiveravgift og pensjon løper på overtid. Til sammen 36,9 prosent.
A10: Hva betaler kunden for en time? | B10: 890 | C10: Timeprisen uten mva. Den er den samme om timen er overtid eller ikke.
A12: Regnestykket
A13: Timelønn | B13: =B5*12/(B6*52) -> 246.15385 | C13: Årslønn delt på timene i året: 480 000 delt på 1 950.
A14: Hva en vanlig time koster bedriften | B14: =B13*(1+B7) -> 361.35385 | C14: Timelønn pluss alt som kommer på toppen.
A15: Overtidslønn, før det som kommer på toppen | B15: =B13*(1+B8) -> 344.61538 | C15: Timelønn pluss overtidstillegget.
A16: Igjen av kundens pris, vanlig time | B16: =B10-B14 -> 528.64615 | C16: Dette kalles dekningsbidrag: det timen gir igjen til resten av bedriften.
A18: HVA EN OVERTIDSTIME KOSTER BEDRIFTEN | B18: =B15*(1+B9) -> 471.77846 | C18: Overtidslønn pluss det som løper på overtid.
A19: Så mye dyrere er overtidstimen | B19: =B18/B14-1 -> 0.30558583 | C19: Rundt 31 prosent, ikke 40, fordi noen av påslagene ikke løper på overtid.
A20: Igjen av kundens pris, overtidstime | B20: =B10-B18 -> 418.22154 | C20: Kunden betaler det samme. Det som blir igjen, faller.
A22: Hva svaret betyr
A23: ="En overtidstime koster bedriften "&TEXT(ROUND(B18,2),"#,##0.00")&" kroner, mot "&TEXT(ROUND(B14,2),"#,##0.00")&" for en vanlig time. Kunden betaler "&TEXT(ROUND(B10,0),"#,##0")&" kroner for begge, så det som blir igjen, faller fra "&TEXT(ROUND(B16,2),"#,##0.00")&" til "&TEXT(ROUND(B20,2),"#,##0.00")&" kroner." -> En overtidstime koster bedriften 471.78 kroner, mot 361.35 for en vanlig time. Kunden betaler 890 kroner for begge, så det som blir igjen, faller fra 528.65 til 418.22 kroner.
A25: Prøv selv
A26: 1. Sett overtidstillegget (B8) til 50 %. Hva koster overtidstimen nå?
A27: 2. Tillegget er 40 %, men overtidstimen blir bare rundt 31 % dyrere. Sammenlikn B7 og B9. Hvorfor?
A28: 3. Hva må timeprisen (B10) være for at en overtidstime skal gi like mye igjen som en vanlig time gjør i dag?
A30: Månedslønnen er fra oppgave 6 og påslagene fra tabell 2.4, begge i kapittel 2 i Økonomistyring for LØM-emnet. Timeprisen 890 kroner er Nordlys Elektro AS sin (faktaarket). Overtidstillegget: arbeidsmiljøloven § 10-6. Nordlys Elektro AS er en konstruert casebedrift.

Sheet Veiledning
A1: Arbeidstid, overtid og feriepenger
A2: LØM Organisasjon og ledelse kap. 20 · arbeidsregneark · Fagskolen Oslo, Elkraft
A3: Emne: Teknisk kommunikasjon og ledelse for 1ET-klassene · LØM for 2ET, 2EK, 3EK og 4EK
A4: Fargekode
A5: Gul celle med blå skrift | B5: Inndata — dette er tallene du endrer.
A6: Grå eller lyseblå celle, svart skrift | B6: Formel — regner seg selv. Ikke skriv over den.
A7: Mørkeblå rad med hvit skrift | B7: Kolonneoverskrift.
A9: Ark i arbeidsboka
A10: Enkelt | B10: Start her. Seks gule celler, ett svar. Hva en overtidstime koster bedriften, regnet på den enkleste måten.
A11: Uka og grensene | B11: Legg inn timene for én uke. Arket sier hva som er overtid og hvilke grenser som brytes.
A12: Hva overtidstimen koster | B12: DET VIKTIGSTE ARKET. Hva en overtidstime koster bedriften, og hva den gjør med dekningsbidraget.
A13: Overtid eller én montør til | B13: Regnestykket ingen gjør: er det billigere å ansette enn å kjøre overtid året rundt?
A14: Feriepenger | B14: Satsene i ferieloven og med avtalefestet femte ferieuke, med arbeidsgiveravgift og månedlig avsetning.
A15: Scenario | B15: Tre spørsmål: hva skjer når uka blir lengre, når overtidstillegget er høyere enn lovens minstekrav, og når overtidstimene fordeles på flere montører.
A16: Din egen uke | B16: Samme oppsett som ark 1, tomt. Legg inn timene fra din egen arbeidsplass.
A18: Gule celler er inndata. Alt annet regner seg selv.
A20: Oppgave A2 og oppgave 3 i øvingsheftet til kapittel 20 bruker dette arket.
A22: HVORFOR DETTE REGNEARKET FINNES:
A23: Arbeidstid og overtid er IKKE behandlet i lærebokas kapittel 20. Reglene står i
A24: arbeidsmiljøloven kapittel 10 og i ferieloven, og de er navngitt på hvert ark.
A25: Kapitlet dekker markedsføringsloven, håndverkertjenesteloven og de delene av
A26: arbeidsmiljøloven som gjelder arbeidsmiljø, ansettelse og opphør.
A28: DE TRE TALLENE Å HUSKE:
A29: 1) Alminnelig arbeidstid: 9 timer i løpet av 24 timer og 40 timer i løpet av sju dager (§ 10-4).
A30: 2) Overtid uten avtale: 10 timer per sju dager, 25 timer per fire uker, 200 timer per 52 uker (§ 10-6).
A31: 3) Overtidstillegget skal være på minst 40 prosent (§ 10-6).
A33: DEN ENE ERKJENNELSEN:
... A46: Hvilken oppgave bruker hvilket ark
A47: Oppgave i øvingsheftet | B47: Ark | C47: Celler du endrer og leser av
A48: A2 · Bemanningen er for lav | B48: Overtid eller ny montør | C48: Endre B5 og B12. Les av B11, B23, B27, B28 og teksten i D30.
A49: 1 · Prisoverslaget som sprakk | B49: — | C49: Ingen regning i arket.
A50: 2 · Arbeidsavtalen til den nye lærlingen | B50: — | C50: Ingen regning i arket.
A51: 3 · Uka, overtiden og hva den koster | B51: Uka og grensene, Hva overtidstimen koster, Overtid eller ny montør, Scenario | C51: Punkt a) og b): legg timene inn i kolonne B på ark 1 og les av blokka «Uka målt mot loven». Punkt c): ark 2, les av kostnad ordinær time, kostnad overtidstime og dekningsbidragene. Punkt d): ark 3, og scenario C.
A52: 4 · Angreretten og de grønne påstandene | B52: — | C52: Ingen regning i arket.
A53: 5 · Eksamensnær: kunden som ikke vil betale | B53: — | C53: Ingen regning i arket.
A54: Din egen arbeidsplass | B54: Din egen uke og Feriepenger | C54: Legg inn dine egne timer i kolonne B, og din egen årslønn i Feriepenger B5.
A56: Kontrollradene
A57: Hvert regneark har en kontrollblokk nederst. Står det OK, henger tallene sammen. Står det AVVIK, farges cellen rød, og teksten sier hva som ikke går opp.
A58: Ett unntak: arket «Din egen uke» er tomt, og statusraden der sier at uka er innenfor grensene helt til du har lagt inn timer. Det er riktig — en uke uten timer bryter ingen grense.
A59: Kontroller i arbeidsboka: Uka og grensene F34, Uka og grensene F35, Uka og grensene F36, Hva overtidstimen koster D46, Hva overtidstimen koster D47, Hva overtidstimen koster D48, Overtid eller ny montør D36, Overtid eller ny montør D37, Overtid eller ny montør D38, Feriepenger D33, Feriepenger D34, Feriepenger D35, Scenario F39, Scenario F40, Scenario F41, Scenario F42
...

Sheet Uka og grensene
A1: Én uke hos Nordlys — hva er overtid, og hvilke grenser brytes?
A2: Endre de gule cellene i kolonne B. Alt annet regner seg selv.
A4: Avtalt og lovbestemt arbeidstid
A5: Avtalt arbeidstid per uke (timer) | B5: 37.5 | F5: Nordlys' egen avtale. Loven setter taket, avtalen setter normalen.
A6: Avtalt arbeidstid per dag, mandag til fredag | B6: =B5/5 -> 7.5
A7: Alminnelig arbeidstid per døgn, lovens grense | B7: 9 | F7: Arbeidsmiljøloven § 10-4. Timer ut over dette er overtid.
A8: Alminnelig arbeidstid per sju dager, lovens grense | B8: 40 | F8: Arbeidsmiljøloven § 10-4.
A9: Samlet arbeidstid per døgn, lovens grense | B9: 13 | F9: Arbeidsmiljøloven § 10-6. Alminnelig arbeidstid pluss overtid.
A10: Samlet arbeidstid per sju dager, lovens grense | B10: 48 | F10: Arbeidsmiljøloven § 10-6.
A11: Arbeidsfri per døgn, lovens minstekrav | B11: 11 | F11: Arbeidsmiljøloven § 10-8. Sammenhengende arbeidsfri i løpet av 24 timer.
A12: Overtid per sju dager, grensen uten avtale | B12: 10 | F12: Arbeidsmiljøloven § 10-6.
A14: Uka til Ronnys lag
A15: Dag | B15: Timer arbeidet | C15: Ut over avtalt dag | D15: Overtid etter loven | E15: Arbeidsfri i døgnet | F15: Merknad
A16: Mandag | B16: 7.5 | C16: =MAX(0,B16-$B$6) -> 0 | D16: =MAX(0,B16-$B$7) -> 0 | E16: =24-B16 -> 16.5 | F16: =IF(B16>$B$9,"BRUDD: over samlet arbeidstid på "&$B$9&" timer i døgnet (§ 10-6).",IF(E16<$B$11,"BRUDD: mindre enn "&$B$11&" timer arbeidsfri (§ 10-8).",IF(D16>0,"Overtid denne dagen. Krever særlig og tidsavgrenset behov (§ 10-6).",IF(C16>0,"Ut over avtalt arbeidstid, men innenfor lovens grense for alminnelig arbeidstid.","Innenfor avtalt arbeidstid.")))) -> Innenfor avtalt arbeidstid.
A17: Tirsdag | B17: 9 | C17: =MAX(0,B17-$B$6) -> 1.5 | D17: =MAX(0,B17-$B$7) -> 0 | E17: =24-B17 -> 15 | F17: =IF(B17>$B$9,"BRUDD: over samlet arbeidstid på "&$B$9&" timer i døgnet (§ 10-6).",IF(E17<$B$11,"BRUDD: mindre enn "&$B$11&" timer arbeidsfri (§ 10-8).",IF(D17>0,"Overtid denne dagen. Krever særlig og tidsavgrenset behov (§ 10-6).",IF(C17>0,"Ut over avtalt arbeidstid, men innenfor lovens grense for alminnelig arbeidstid.","Innenfor avtalt arbeidstid.")))) -> Ut over avtalt arbeidstid, men innenfor lovens grense for alminnelig arbeidstid.
A18: Onsdag | B18: 11.5 | C18: =MAX(0,B18-$B$6) -> 4 | D18: =MAX(0,B18-$B$7) -> 2.5 | E18: =24-B18 -> 12.5 | F18: =IF(B18>$B$9,"BRUDD: over samlet arbeidstid på "&$B$9&" timer i døgnet (§ 10-6).",IF(E18<$B$11,"BRUDD: mindre enn "&$B$11&" timer arbeidsfri (§ 10-8).",IF(D18>0,"Overtid denne dagen. Krever særlig og tidsavgrenset behov (§ 10-6).",IF(C18>0,"Ut over avtalt arbeidstid, men innenfor lovens grense for alminnelig arbeidstid.","Innenfor avtalt arbeidstid.")))) -> Overtid denne dagen. Krever særlig og tidsavgrenset behov (§ 10-6).
A19: Torsdag | B19: 8 | C19: =MAX(0,B19-$B$6) -> 0.5 | D19: =MAX(0,B19-$B$7) -> 0 | E19: =24-B19 -> 16 | F19: =IF(B19>$B$9,"BRUDD: over samlet arbeidstid på "&$B$9&" timer i døgnet (§ 10-6).",IF(E19<$B$11,"BRUDD: mindre enn "&$B$11&" timer arbeidsfri (§ 10-8).",IF(D19>0,"Overtid denne dagen. Krever særlig og tidsavgrenset behov (§ 10-6).",IF(C19>0,"Ut over avtalt arbeidstid, men innenfor lovens grense for alminnelig arbeidstid.","Innenfor avtalt arbeidstid.")))) -> Ut over avtalt arbeidstid, men innenfor lovens grense for alminnelig arbeidstid.
A20: Fredag | B20: 10 | C20: =MAX(0,B20-$B$6) -> 2.5 | D20: =MAX(0,B20-$B$7) -> 1 | E20: =24-B20 -> 14 | F20: =IF(B20>$B$9,"BRUDD: over samlet arbeidstid på "&$B$9&" timer i døgnet (§ 10-6).",IF(E20<$B$11,"BRUDD: mindre enn "&$B$11&" timer arbeidsfri (§ 10-8).",IF(D20>0,"Overtid denne dagen. Krever særlig og tidsavgrenset behov (§ 10-6).",IF(C20>0,"Ut over avtalt arbeidstid, men innenfor lovens grense for alminnelig arbeidstid.","Innenfor avtalt arbeidstid.")))) -> Overtid denne dagen. Krever særlig og tidsavgrenset behov (§ 10-6).
A21: Lørdag | B21: 6 | C21: =MAX(0,B21-$B$6) -> 0 | D21: =MAX(0,B21-$B$7) -> 0 | E21: =24-B21 -> 18 | F21: =IF(B21>$B$9,"BRUDD: over samlet arbeidstid på "&$B$9&" timer i døgnet (§ 10-6).",IF(E21<$B$11,"BRUDD: mindre enn "&$B$11&" timer arbeidsfri (§ 10-8).",IF(D21>0,"Overtid denne dagen. Krever særlig og tidsavgrenset behov (§ 10-6).",IF(C21>0,"Ut over avtalt arbeidstid, men innenfor lovens grense for alminnelig arbeidstid.","Innenfor avtalt arbeidstid.")))) -> Innenfor avtalt arbeidstid.
A22: Søndag | B22: 0 | C22: =MAX(0,B22-$B$6) -> 0 | D22: =MAX(0,B22-$B$7) -> 0 | E22: =24-B22 -> 24 | F22: =IF(B22>$B$9,"BRUDD: over samlet arbeidstid på "&$B$9&" timer i døgnet (§ 10-6).",IF(E22<$B$11,"BRUDD: mindre enn "&$B$11&" timer arbeidsfri (§ 10-8).",IF(D22>0,"Overtid denne dagen. Krever særlig og tidsavgrenset behov (§ 10-6).",IF(C22>0,"Ut over avtalt arbeidstid, men innenfor lovens grense for alminnelig arbeidstid.","Innenfor avtalt arbeidstid.")))) -> Innenfor avtalt arbeidstid.
A23: = Sum uke | B23: =SUM(B16:B22) -> 52 | C23: =SUM(C16:C22) -> 8.5 | D23: =SUM(D16:D22) -> 3.5
A25: Uka målt mot loven
A26: = Overtid etter dagsgrensen | B26: =D23 -> 3.5 | F26: Sum av timene ut over 9 timer i løpet av 24 timer.
A27: = Overtid etter ukegrensen | B27: =MAX(0,B23-$B$8) -> 12 | F27: Timene ut over 40 i løpet av sju dager.
A28: = Overtid i uka (den største av de to) | B28: =MAX(B26,B27) -> 12 | F28: De to grensene teller ikke dobbelt. Den strengeste gjelder.
A29: = Merarbeid ut over avtalt, som ikke er overtid | B29: =MAX(0,B23-$B$5-B28) -> 2.5 | F29: Timene mellom avtalt ukentlig arbeidstid og lovens grense. Betales, men er ikke overtid etter loven.
A30: = Lengste dag i uka | B30: =MAX(B16:B22) -> 11.5
A31: = Status for uka | F31: =IF(B30>$B$9,"BRUDD på samlet arbeidstid i døgnet (§ 10-6).",IF(B23>$B$10,"Over 48 timer denne uka. Lovlig bare hvis snittet over åtte uker er høyst 48 (§ 10-6 åttende ledd).",IF(B28>$B$12,"BRUDD på overtidsgrensen for sju dager (§ 10-6). Grensen er "&$B$12&" timer uten avtale.","Uka er innenfor grensene i arbeidsmiljøloven kapittel 10."))) -> Over 48 timer denne uka. Lovlig bare hvis snittet over åtte uker er høyst 48 (§ 10-6 åttende ledd).
A33: Kontroll
A34: Er overtiden den strengeste av dags- og ukegrensen? | F34: =IF(B28=MAX(B26,B27),"OK — den strengeste av de to grensene gjelder, og timene telles ikke dobbelt","AVVIK: overtiden skal være den STØRSTE av dagsovertid og ukeovertid, ikke summen") -> OK — den strengeste av de to grensene gjelder, og timene telles ikke dobbelt
A35: Går timene i uka opp? | F35: =IF(ABS(B23-($B$5+B28+B29))<0.01,"OK — avtalt arbeidstid pluss overtid pluss merarbeid er lik sum uke","AVVIK: summen av avtalt tid, overtid og merarbeid stemmer ikke med sum uke") -> OK — avtalt arbeidstid pluss overtid pluss merarbeid er lik sum uke
A36: Er merarbeidet et positivt tall? | F36: =IF(B29>=0,"OK","AVVIK: negativt merarbeid betyr at uka er kortere enn avtalt arbeidstid. Sjekk timene i kolonne B") -> OK
A38: Overtid krever et særlig og tidsavgrenset behov, og skal drøftes med de tillitsvalgte. Fast overtid året rundt er ikke et særlig og tidsavgrenset behov — det er underbemanning.
A39: Kilde: arbeidsmiljøloven §§ 10-4, 10-6 og 10-8. Timetallene i uka er konstruert for undervisningen.

Sheet Hva overtidstimen koster
A1: Hva koster én overtidstime — og hva gjør den med dekningsbidraget?
A2: Endre de gule cellene. Alt annet regner seg selv.
A4: Lønnsgrunnlaget
A5: Brutto månedslønn | B5: 40000 | D5: Beløpet i oppgave 6, kapittel 2 i Økonomistyring for LØM-emnet. Satsene står i tabell 2.4.
A6: Avtalt arbeidstid per uke (timer) | B6: 37.5
A7: Uker i året | B7: 52
A8: = Årslønn | B8: =B5*12 -> 480000
A9: = Årstimer etter avtalt arbeidstid | B9: =B6*B7 -> 1950
A10: = Timelønn | B10: =B8/B9 -> 246.15385 | D10: Årslønn delt på årstimer. Ikke skrevet inn — regnet ut.
A12: Sosiale kostnader — påslag på lønnen
A13: Post | B13: Sats | C13: Løper på overtid? | D13: Merknad
A14: Feriepenger, inkludert arbeidsgiveravgift | B14: 0.137 | C14: 1 | D14: Ja — løper også på overtidsgodtgjørelsen.
A15: Arbeidsgiveravgift på lønn | B15: 0.141 | C15: 1 | D15: Ja — løper også på overtidsgodtgjørelsen.
A16: Pensjonspremie | B16: 0.08 | C16: 1 | D16: Ja — løper også på overtidsgodtgjørelsen.
A17: Arbeidsgiveravgift på pensjon | B17: 0.011 | C17: 1 | D17: Ja — løper også på overtidsgodtgjørelsen.
A18: Lønn for bevegelige helligdager, høytidsdager m.m. | B18: 0.045 | C18: 0 | D18: Nei — beregnes av den ordinære lønnen, ikke av overtiden.
A19: Premie til yrkesskadetrygd | B19: 0.004 | C19: 0 | D19: Nei — beregnes av den ordinære lønnen, ikke av overtiden.
A20: Sykepenger i arbeidsgiverperioden | B20: 0.05 | C20: 0 | D20: Nei — beregnes av den ordinære lønnen, ikke av overtiden.
A21: = Fullt påslag, ordinær time | B21: =SUM(B14:B20) -> 0.468
A22: = Påslag som løper på en overtidstime | B22: =SUMPRODUCT(B14:B20,C14:C20) -> 0.369 | D22: Sett 1 i kolonne C for de postene som skal telle med. Lønn for bevegelige helligdager løper ikke på en overtidstime.
A24: Timen, ordinær og på overtid
A25: Overtidstillegg (lovens minstekrav er 40 %) | B25: 0.4 | D25: Arbeidsmiljøloven § 10-6. Mange tariffavtaler i bransjen har høyere satser — prøv med dem.
A26: = Kostnad, ordinær time | B26: =B10*(1+B21) -> 361.35385
A27: = Overtidslønn før sosiale kostnader | B27: =B10*(1+B25) -> 344.61538
A28: = Kostnad, overtidstime | B28: =B27*(1+B22) -> 471.77846
A29: = Merkostnad per overtidstime | B29: =B28-B26 -> 110.42462
A30: = Merkostnad i prosent | B30: =IF(B26=0,0,B28/B26-1) -> 0.30558583
A32: Hva timen gjør med dekningsbidraget
A33: Timepris til kunden, eksklusive merverdiavgift | B33: 890 | D33: Nordlys' egen timepris. Den er den samme uansett når timen jobbes.
A34: = Dekningsbidrag, ordinær time | B34: =B33-B26 -> 528.64615
A35: = Dekningsbidrag, overtidstime | B35: =B33-B28 -> 418.22154
A36: = Fall i dekningsbidrag per time | B36: =B34-B35 -> 110.42462
A37: = Fall i prosent | B37: =IF(B34=0,0,B36/B34) -> 0.2088819 | D37: =IF(B35<0,"Overtidstimen går med tap. Sjekk timeprisen.",IF(B37>0.3,"Marginen faller kraftig. Regn på alternativet i neste ark.","Timen lønner seg fortsatt, men marginen er lavere.")) -> Timen lønner seg fortsatt, men marginen er lavere.
A39: Over ett år
A40: Overtidstimer siste tolv måneder, én montør | B40: 212
A41: = Merkostnad for bedriften, ett år | B41: =B40*B29 -> 23410.018
A42: = Tapt dekningsbidrag mot ordinære timer | B42: =B40*B36 -> 23410.018
A43: = Innenfor lovens grense uten avtale? | D43: =IF(B40>300,"OVER 300 timer. Ingen avtale kan hjemle dette (§ 10-6).",IF(B40>200,"Over 200 timer. Krever skriftlig avtale med de tillitsvalgte i tariffbundet virksomhet (§ 10-6).","Innenfor 200 timer (§ 10-6).")) -> Over 200 timer. Krever skriftlig avtale med de tillitsvalgte i tariffbundet virksomhet (§ 10-6).
A45: Kontroll
A46: Er påslaget på overtid lavere enn det fulle påslaget? | D46: =IF(B22<B21,"OK — noen av postene løper ikke på en overtidstime","AVVIK: alle postene er merket som om de løper på overtid. Sett 0 i kolonne C for dem som ikke gjør det") -> OK — noen av postene løper ikke på en overtidstime
...

Sheet Overtid eller ny montør
A1: Overtid året rundt, eller én montør til?
A2: Regnestykket ingen gjør før de sier ja til neste oppdrag.
A4: Behovet
A5: Timer som må dekkes ut over ordinær kapasitet, per år | B5: 1200 | D5: Sett inn deres eget tall. 1 200 timer er det Nordlys regner som ett montørårsverk i fakturerbare timer.
A7: Alternativ A — overtid
A8: Kostnad per overtidstime | B8: ='Hva overtidstimen koster'!$B$28 -> 471.77846
A9: = Lønnskostnad, ett år | B9: =B5*B8 -> 566134.15
A10: = Fakturert, ett år | B10: =B5*'Hva overtidstimen koster'!$B$33 -> 1068000
A11: = Dekningsbidrag, ett år | B11: =B10-B9 -> 501865.85
A12: = Overtidstimer per montør hvis fordelt på antall montører | B12: 12 | C12: =IF(B12=0,0,B5/B12) -> 100 | D12: =IF(C12>300,"Ikke lovlig. Over 300 timer per montør (§ 10-6).",IF(C12>200,"Krever skriftlig avtale med de tillitsvalgte (§ 10-6).","Innenfor 200 timer per montør (§ 10-6).")) -> Innenfor 200 timer per montør (§ 10-6).
A14: Alternativ B — ansette én montør til
A15: Brutto månedslønn | B15: ='Hva overtidstimen koster'!$B$5 -> 40000
A16: = Årslønn | B16: =B15*12 -> 480000
A17: Fullt påslag for sosiale kostnader | B17: ='Hva overtidstimen koster'!$B$21 -> 0.468
A18: = Lønnskostnad inklusive sosiale kostnader | B18: =B16*(1+B17) -> 704640
A19: Andre kostnader per montør: bil, verktøy, telefon, arbeidstøy, kurs | B19: 145000 | D19: Sett inn deres eget tall. Dette er ofte det som glemmes i sammenlikningen.
A20: = Årskostnad, ny montør | B20: =B18+B19 -> 849640
A21: Fakturerbare timer per montør, per år | B21: 1200 | D21: Nordlys' eget tall. Resten av tida går til kjøring, dokumentasjon, møter, kurs og fravær.
A22: = Fakturert, ett år | B22: =B21*'Hva overtidstimen koster'!$B$33 -> 1068000
A23: = Dekningsbidrag, ett år | B23: =B22-B20 -> 218360
A24: = Kostnad per fakturert time | B24: =IF(B21=0,0,B20/B21) -> 708.03333
A26: Sammenlikningen
A27: = Kostnad per fakturert time, overtid | B27: =B8 -> 471.77846
A28: = Kostnad per fakturert time, ny montør | B28: =B24 -> 708.03333
A29: = Forskjell per time | B29: =B27-B28 -> -236.25487
A30: = Hva sier tallene? | D30: =IF(B29>0,"Overtidstimen er dyrest per fakturert time. Ansettelse lønner seg — HVIS behovet er varig og timene faktisk blir fakturert.","Overtidstimen er billigst per fakturert time. Det forutsetter at grensene i § 10-6 holdes.") -> Overtidstimen er billigst per fakturert time. Det forutsetter at grensene i § 10-6 holdes.
A32: Regnestykket avgjør ikke saken alene. En ansettelse binder bedriften i årevis og forutsetter at oppdragsmengden holder seg. Overtid er fleksibelt, men kan ikke være en varig ordning — loven krever et særlig og tidsavgrenset behov.
A35: Kontroll
A36: Er timebehovet fordelt på minst én montør? | D36: =IF(B12>0,"OK","AVVIK: sett antall montører i B12 før du leser av timene per montør") -> OK
A37: Gir en ny montør positivt dekningsbidrag? | D37: =IF(B23>0,"OK — montøren bærer sine egne kostnader og bidrar","AVVIK: en ny montør går med tap ved disse forutsetningene. Sjekk fakturerbare timer i B21 og andre kostnader i B19") -> OK — montøren bærer sine egne kostnader og bidrar
A38: Går sammenlikningen opp? | D38: =IF(ABS(B29-(B27-B28))<0.01,"OK — forskjellen er differansen mellom de to kostnadene per fakturert time","AVVIK: sammenlikningen nederst stemmer ikke med tallene over") -> OK — forskjellen er differansen mellom de to kostnadene per fakturert time
A40: Kilde: arbeidsmiljøloven § 10-6. Bemanning og fakturerbare timer er Nordlys Elektro AS' egne tall.

Sheet Feriepenger
A1: Feriepenger — satsene, avgiften og avsetningen
A2: Endre de gule cellene. Alt annet regner seg selv.
A4: Feriepengegrunnlaget
A5: Arbeidsvederlag utbetalt i opptjeningsåret | B5: 480000 | D5: Ferieloven § 10. Grunnlaget er det som faktisk er utbetalt i opptjeningsåret — også overtidsgodtgjørelse.
A6: Overtidsgodtgjørelse utbetalt i opptjeningsåret | B6: ='Hva overtidstimen koster'!$B$27*'Hva overtidstimen koster'!$B$40 -> 73058.462 | D6: Overtidsbetalingen inngår i grunnlaget. Feriepenger av feriepenger gjør det ikke.
A7: = Samlet feriepengegrunnlag | B7: =B5+B6 -> 553058.46
A9: Satsene
A10: Sats | B10: Prosent | C10: Feriepenger | D10: Hjemmel
A11: Ferieloven, under 60 år | B11: 0.102 | C11: =$B$7*B11 -> 56411.963 | D11: Ferieloven § 10 andre ledd. Svarer til 25 virkedager ferie etter § 5.
A12: Ferieloven, fylt 60 år | B12: 0.125 | C12: =$B$7*B12 -> 69132.308 | D12: Satsen er 2,3 prosentpoeng høyere.
A13: Avtalefestet fem ukers ferie, under 60 år | B13: 0.12 | C13: =$B$7*B13 -> 66367.015 | D13: Nordlys' egen avtale. Loven er et minstekrav — bedre vilkår kan avtales.
A14: Avtalefestet fem ukers ferie, fylt 60 år | B14: 0.143 | C14: =$B$7*B14 -> 79087.36 | D14: Samme tillegg på 2,3 prosentpoeng.
A16: Det Nordlys faktisk avsetter
A17: Satsen som brukes | B17: =B13 -> 0.12
A18: = Feriepenger | B18: =$B$7*B17 -> 66367.015
A19: Arbeidsgiveravgift | B19: 0.141
A20: = Arbeidsgiveravgift på feriepengene | B20: =B18*B19 -> 9357.7492
A21: = Samlet avsetning | B21: =B18+B20 -> 75724.765
A22: = Avsetning per måned | B22: =B21/12 -> 6310.397 | D22: Feriepengene er ikke en kostnad som kommer i juni. De opptjenes hver måned og skal avsettes hver måned.
A23: = Feriepenger med arbeidsgiveravgift, i prosent av grunnlaget | B23: =IF(B7=0,0,B21/B7) -> 0.13692 | D23: Sammenlikn med posten «Feriepenger, inkludert arbeidsgiveravgift» i lønnspåslaget. Den skal stemme.
A25: Feriefritiden
A26: Feriedager etter ferieloven (virkedager) | B26: 25 | D26: Ferieloven § 5. Lørdag regnes som virkedag, så 25 virkedager er fire uker og én dag.
A27: = Tilsvarer, i uker med seks virkedager | B27: =B26/6 -> 4.1666667
A29: Loven gir fire uker og én dag. Den femte uka er avtalt, og den er grunnen til at satsen er 12 prosent og ikke 10,2.
A32: Kontroll
A33: Er 60-årssatsen høyere enn hovedsatsen? | D33: =IF(AND(B12>B11,B14>B13),"OK — satsen for dem som har fylt 60 år er høyere i begge kolonnene","AVVIK: 60-årssatsene skal ligge over de ordinære satsene") -> OK — satsen for dem som har fylt 60 år er høyere i begge kolonnene
A34: Er den avtalte satsen minst like høy som lovens? | D34: =IF(B13>=B11,"OK — loven er et minstekrav, og avtalen ligger over","AVVIK: en avtale kan ikke gi svakere vilkår enn ferieloven") -> OK — loven er et minstekrav, og avtalen ligger over
A35: Stemmer avsetningen med lønnspåslaget? | D35: =IF(ABS(B23-0.137)<0.01,"OK — feriepenger med arbeidsgiveravgift er lik posten i lønnspåslaget","AVVIK: avsetningen avviker fra posten «Feriepenger, inkludert arbeidsgiveravgift» i lønnspåslaget") -> OK — feriepenger med arbeidsgiveravgift er lik posten i lønnspåslaget
A37: Kilde: ferieloven §§ 5 og 10. Arbeidsgiveravgiften er den samme satsen som i budsjettet til Nordlys.

Sheet Scenario
A1: Tre scenarioer
A2: Endre de gule cellene og se hva som skjer. Alle tall hentes fra de andre arkene.
A4: Scenario A · hva skjer når uka blir lengre?
A5: Samme lag, samme timepris. Det eneste som endrer seg, er hvor mange timer uka inneholder.
A6: Uker i året med denne belastningen | B6: 45 | F6: Årsverket delt på avtalt ukentlig arbeidstid. Endre det gjerne.
A7: Timer i uka | B7: Overtid etter loven | C7: Merkostnad i uka | D7: Merkostnad på et år | E7: Innenfor § 10-6? | F7: Hva raden betyr
A8: 37.5 | B8: =MAX(0,A8-'Uka og grensene'!$B$8) -> 0 | C8: =B8*('Hva overtidstimen koster'!$B$28-'Hva overtidstimen koster'!$B$26) -> 0 | D8: =C8*$B$6 -> 0 | E8: =IF(A8>'Uka og grensene'!$B$10,"BRUDD § 10-6",IF(B8>'Uka og grensene'!$B$12,"Krever avtale","Innenfor")) -> Innenfor | F8: Avtalt arbeidstid. Ingen overtid, ingen merkostnad.
A9: 40 | B9: =MAX(0,A9-'Uka og grensene'!$B$8) -> 0 | C9: =B9*('Hva overtidstimen koster'!$B$28-'Hva overtidstimen koster'!$B$26) -> 0 | D9: =C9*$B$6 -> 0 | E9: =IF(A9>'Uka og grensene'!$B$10,"BRUDD § 10-6",IF(B9>'Uka og grensene'!$B$12,"Krever avtale","Innenfor")) -> Innenfor | F9: Lovens grense for alminnelig arbeidstid. Fortsatt ingen overtid.
A10: 45 | B10: =MAX(0,A10-'Uka og grensene'!$B$8) -> 5 | C10: =B10*('Hva overtidstimen koster'!$B$28-'Hva overtidstimen koster'!$B$26) -> 552.12308 | D10: =C10*$B$6 -> 24845.538 | E10: =IF(A10>'Uka og grensene'!$B$10,"BRUDD § 10-6",IF(B10>'Uka og grensene'!$B$12,"Krever avtale","Innenfor")) -> Innenfor | F10: Fem timer overtid. Vanlig i en travel periode.
A11: 48 | B11: =MAX(0,A11-'Uka og grensene'!$B$8) -> 8 | C11: =B11*('Hva overtidstimen koster'!$B$28-'Hva overtidstimen koster'!$B$26) -> 883.39692 | D11: =C11*$B$6 -> 39752.862 | E11: =IF(A11>'Uka og grensene'!$B$10,"BRUDD § 10-6",IF(B11>'Uka og grensene'!$B$12,"Krever avtale","Innenfor")) -> Innenfor | F11: Taket for samlet arbeidstid i løpet av sju dager. Grensen kan gjennomsnittsberegnes over åtte uker (§ 10-6 åttende ledd).
A12: 52 | B12: =MAX(0,A12-'Uka og grensene'!$B$8) -> 12 | C12: =B12*('Hva overtidstimen koster'!$B$28-'Hva overtidstimen koster'!$B$26) -> 1325.0954 | D12: =C12*$B$6 -> 59629.292 | E12: =IF(A12>'Uka og grensene'!$B$10,"BRUDD § 10-6",IF(B12>'Uka og grensene'!$B$12,"Krever avtale","Innenfor")) -> BRUDD § 10-6 | F12: Uka til Ronnys lag. Over taket, og over overtidsgrensen.
A15: Scenario B · hva hvis tillegget er høyere enn lovens minstekrav?
A16: Mange tariffavtaler i bransjen har høyere satser enn de 40 prosentene loven krever. Prøv med deres egne.
A17: Overtidstillegg | B17: Overtidslønn | C17: Kostnad per time | D17: Dekningsbidrag | E17: Fall mot ordinær time | F17: Hva raden betyr
A18: 0.4 | B18: ='Hva overtidstimen koster'!$B$10*(1+A18) -> 344.61538 | C18: =B18*(1+'Hva overtidstimen koster'!$B$22) -> 471.77846 | D18: ='Hva overtidstimen koster'!$B$33-C18 -> 418.22154 | E18: =IF('Hva overtidstimen koster'!$B$26=0,0,C18/'Hva overtidstimen koster'!$B$26-1) -> 0.30558583 | F18: Lovens minstekrav, jf. § 10-6.
A19: 0.5 | B19: ='Hva overtidstimen koster'!$B$10*(1+A19) -> 369.23077 | C19: =B19*(1+'Hva overtidstimen koster'!$B$22) -> 505.47692 | D19: ='Hva overtidstimen koster'!$B$33-C19 -> 384.52308 | E19: =IF('Hva overtidstimen koster'!$B$26=0,0,C19/'Hva overtidstimen koster'!$B$26-1) -> 0.39884196 | F19: Vanlig sats for de første timene i mange tariffavtaler.
A20: 0.75 | B20: ='Hva overtidstimen koster'!$B$10*(1+A20) -> 430.76923 | C20: =B20*(1+'Hva overtidstimen koster'!$B$22) -> 589.72308 | D20: ='Hva overtidstimen koster'!$B$33-C20 -> 300.27692 | E20: =IF('Hva overtidstimen koster'!$B$26=0,0,C20/'Hva overtidstimen koster'!$B$26-1) -> 0.63198229 | F20: Kveld og natt i mange avtaler.
A21: 1 | B21: ='Hva overtidstimen koster'!$B$10*(1+A21) -> 492.30769 | C21: =B21*(1+'Hva overtidstimen koster'!$B$22) -> 673.96923 | D21: ='Hva overtidstimen koster'!$B$33-C21 -> 216.03077 | E21: =IF('Hva overtidstimen koster'!$B$26=0,0,C21/'Hva overtidstimen koster'!$B$26-1) -> 0.86512262 | F21: Søndag og helligdag i mange avtaler.
A24: Scenario C · hva hvis overtiden fordeles på flere?
A25: Samme timetall, fordelt på ulikt antall montører. Grensene i § 10-6 gjelder PER ARBEIDSTAKER.
A26: Montører å fordele på | B26: Timer per montør | C26: Merkostnad i året | E26: Innenfor § 10-6? | F26: Hva raden betyr
A27: Overtidstimer å fordele, ett år | B27: 212 | F27: Sett inn deres eget tall. Nordlys' egen montør hadde 212 timer.
A28: 1 | B28: =IF(A28=0,0,$B$27/A28) -> 212 | C28: =$B$27*('Hva overtidstimen koster'!$B$28-'Hva overtidstimen koster'!$B$26) -> 23410.018 | E28: =IF(B28>300,"BRUDD § 10-6",IF(B28>200,"Krever skriftlig avtale","Innenfor 200 timer")) -> Krever skriftlig avtale | F28: Én montør tar alt.
A29: 2 | B29: =IF(A29=0,0,$B$27/A29) -> 106 | C29: =$B$27*('Hva overtidstimen koster'!$B$28-'Hva overtidstimen koster'!$B$26) -> 23410.018 | E29: =IF(B29>300,"BRUDD § 10-6",IF(B29>200,"Krever skriftlig avtale","Innenfor 200 timer")) -> Innenfor 200 timer | F29: Fordelt på 2 montører.
A30: 3 | B30: =IF(A30=0,0,$B$27/A30) -> 70.666667 | C30: =$B$27*('Hva overtidstimen koster'!$B$28-'Hva overtidstimen koster'!$B$26) -> 23410.018 | E30: =IF(B30>300,"BRUDD § 10-6",IF(B30>200,"Krever skriftlig avtale","Innenfor 200 timer")) -> Innenfor 200 timer | F30: Fordelt på 3 montører.
A31: 12 | B31: =IF(A31=0,0,$B$27/A31) -> 17.666667 | C31: =$B$27*('Hva overtidstimen koster'!$B$28-'Hva overtidstimen koster'!$B$26) -> 23410.018 | E31: =IF(B31>300,"BRUDD § 10-6",IF(B31>200,"Krever skriftlig avtale","Innenfor 200 timer")) -> Innenfor 200 timer | F31: Fordelt på alle 12 montørene.
A33: Les tabellene slik
A34: Scenario A: merkostnaden i uka ser liten ut. Kolonnen ved siden av ganger den med et helt år, og da slutter den å se liten ut.
A35: Scenario B: overtidstillegget er det eneste tallet i arket bedriften ikke kan forhandle ned — loven setter et minstekrav på 40 prosent, og tariffavtalen kan sette det høyere.
A36: Scenario C: merkostnaden i kroner er den samme uansett hvor mange som deler timene. Det som endrer seg, er om det er lovlig — og det er nettopp derfor fordeling er det første grepet, ikke det siste.
A38: Kontroll
A39: Stiger overtiden når uka blir lengre? | F39: =IF(B12>B8,"OK — lengre uke gir mer overtid","AVVIK: tabellen i scenario A skal stige nedover") -> OK — lengre uke gir mer overtid
A40: Faller dekningsbidraget når tillegget øker? | F40: =IF(D21<D18,"OK — høyere overtidstillegg gir lavere dekningsbidrag","AVVIK: tabellen i scenario B skal falle nedover") -> OK — høyere overtidstillegg gir lavere dekningsbidrag
A41: Stemmer 40-prosentraden med arket «Hva overtidstimen koster»? | F41: =IF(ABS(C18-'Hva overtidstimen koster'!$B$28)<0.01,"OK — raden gir samme kostnad som kalkylen","AVVIK: raden stemmer ikke med arket «Hva overtidstimen koster»") -> OK — raden gir samme kostnad som kalkylen
A42: Blir timene per montør færre når flere deler? | F42: =IF(B31<B28,"OK — flere montører gir færre timer hver","AVVIK: tabellen i scenario C skal falle nedover") -> OK — flere montører gir færre timer hver
A44: Kilde: arbeidsmiljøloven §§ 10-4, 10-6 og 10-8. Timepris og bemanning er Nordlys Elektro AS' egne tall.

Sheet Din egen uke
A1: Din egen uke — samme oppsett, tomt
A2: Legg inn timene fra din egen arbeidsplass. Formlene følger med.
A4: Avtalt og lovbestemt arbeidstid
A5: Avtalt arbeidstid per uke (timer) | B5: 37.5
A6: Avtalt arbeidstid per dag, mandag til fredag | B6: =B5/5 -> 7.5
A7: Alminnelig arbeidstid per døgn, lovens grense | B7: 9
A8: Alminnelig arbeidstid per sju dager, lovens grense | B8: 40
A9: Samlet arbeidstid per døgn, lovens grense | B9: 13
A10: Samlet arbeidstid per sju dager, lovens grense | B10: 48
A11: Arbeidsfri per døgn, lovens minstekrav | B11: 11
A12: Overtid per sju dager, grensen uten avtale | B12: 10
A14: Din uke
A15: Dag | B15: Timer arbeidet | C15: Ut over avtalt dag | D15: Overtid etter loven | E15: Arbeidsfri i døgnet | F15: Merknad
A16: Mandag | B16: 0 | C16: =MAX(0,B16-$B$6) -> 0 | D16: =MAX(0,B16-$B$7) -> 0 | E16: =24-B16 -> 24 | F16: =IF(B16>$B$9,"BRUDD: over samlet arbeidstid på "&$B$9&" timer i døgnet (§ 10-6).",IF(E16<$B$11,"BRUDD: mindre enn "&$B$11&" timer arbeidsfri (§ 10-8).",IF(D16>0,"Overtid denne dagen.",IF(C16>0,"Ut over avtalt arbeidstid, men innenfor lovens grense.","Innenfor avtalt arbeidstid.")))) -> Innenfor avtalt arbeidstid.
A17: Tirsdag | B17: 0 | C17: =MAX(0,B17-$B$6) -> 0 | D17: =MAX(0,B17-$B$7) -> 0 | E17: =24-B17 -> 24 | F17: =IF(B17>$B$9,"BRUDD: over samlet arbeidstid på "&$B$9&" timer i døgnet (§ 10-6).",IF(E17<$B$11,"BRUDD: mindre enn "&$B$11&" timer arbeidsfri (§ 10-8).",IF(D17>0,"Overtid denne dagen.",IF(C17>0,"Ut over avtalt arbeidstid, men innenfor lovens grense.","Innenfor avtalt arbeidstid.")))) -> Innenfor avtalt arbeidstid.
A18: Onsdag | B18: 0 | C18: =MAX(0,B18-$B$6) -> 0 | D18: =MAX(0,B18-$B$7) -> 0 | E18: =24-B18 -> 24 | F18: =IF(B18>$B$9,"BRUDD: over samlet arbeidstid på "&$B$9&" timer i døgnet (§ 10-6).",IF(E18<$B$11,"BRUDD: mindre enn "&$B$11&" timer arbeidsfri (§ 10-8).",IF(D18>0,"Overtid denne dagen.",IF(C18>0,"Ut over avtalt arbeidstid, men innenfor lovens grense.","Innenfor avtalt arbeidstid.")))) -> Innenfor avtalt arbeidstid.
A19: Torsdag | B19: 0 | C19: =MAX(0,B19-$B$6) -> 0 | D19: =MAX(0,B19-$B$7) -> 0 | E19: =24-B19 -> 24 | F19: =IF(B19>$B$9,"BRUDD: over samlet arbeidstid på "&$B$9&" timer i døgnet (§ 10-6).",IF(E19<$B$11,"BRUDD: mindre enn "&$B$11&" timer arbeidsfri (§ 10-8).",IF(D19>0,"Overtid denne dagen.",IF(C19>0,"Ut over avtalt arbeidstid, men innenfor lovens grense.","Innenfor avtalt arbeidstid.")))) -> Innenfor avtalt arbeidstid.
A20: Fredag | B20: 0 | C20: =MAX(0,B20-$B$6) -> 0 | D20: =MAX(0,B20-$B$7) -> 0 | E20: =24-B20 -> 24 | F20: =IF(B20>$B$9,"BRUDD: over samlet arbeidstid på "&$B$9&" timer i døgnet (§ 10-6).",IF(E20<$B$11,"BRUDD: mindre enn "&$B$11&" timer arbeidsfri (§ 10-8).",IF(D20>0,"Overtid denne dagen.",IF(C20>0,"Ut over avtalt arbeidstid, men innenfor lovens grense.","Innenfor avtalt arbeidstid.")))) -> Innenfor avtalt arbeidstid.
A21: Lørdag | B21: 0 | C21: =MAX(0,B21-$B$6) -> 0 | D21: =MAX(0,B21-$B$7) -> 0 | E21: =24-B21 -> 24 | F21: =IF(B21>$B$9,"BRUDD: over samlet arbeidstid på "&$B$9&" timer i døgnet (§ 10-6).",IF(E21<$B$11,"BRUDD: mindre enn "&$B$11&" timer arbeidsfri (§ 10-8).",IF(D21>0,"Overtid denne dagen.",IF(C21>0,"Ut over avtalt arbeidstid, men innenfor lovens grense.","Innenfor avtalt arbeidstid.")))) -> Innenfor avtalt arbeidstid.
A22: Søndag | B22: 0 | C22: =MAX(0,B22-$B$6) -> 0 | D22: =MAX(0,B22-$B$7) -> 0 | E22: =24-B22 -> 24 | F22: =IF(B22>$B$9,"BRUDD: over samlet arbeidstid på "&$B$9&" timer i døgnet (§ 10-6).",IF(E22<$B$11,"BRUDD: mindre enn "&$B$11&" timer arbeidsfri (§ 10-8).",IF(D22>0,"Overtid denne dagen.",IF(C22>0,"Ut over avtalt arbeidstid, men innenfor lovens grense.","Innenfor avtalt arbeidstid.")))) -> Innenfor avtalt arbeidstid.
A23: = Sum uke | B23: =SUM(B16:B22) -> 0 | C23: =SUM(C16:C22) -> 0 | D23: =SUM(D16:D22) -> 0
A25: = Overtid i uka (den strengeste av dags- og ukegrensen) | B25: =MAX(D23,MAX(0,B23-$B$8)) -> 0
A26: = Status for uka | F26: =IF(MAX(B16:B22)>$B$9,"BRUDD på samlet arbeidstid i døgnet (§ 10-6).",IF(B23>$B$10,"Over 48 timer denne uka. Lovlig bare hvis snittet over åtte uker er høyst 48 (§ 10-6 åttende ledd).",IF(B25>$B$12,"BRUDD på overtidsgrensen for sju dager (§ 10-6).","Uka er innenfor grensene i arbeidsmiljøloven kapittel 10."))) -> Uka er innenfor grensene i arbeidsmiljøloven kapittel 10.
A28: Kilde: arbeidsmiljøloven §§ 10-4, 10-6 og 10-8.
