Workbook

Sheet Enkelt
A1: Hva gir én kundegruppe per montørtime? Den enkle versjonen
A2: Fyll inn de seks gule cellene. Svaret står i den grønne. Alt annet regner seg selv. Vil du gå dypere, ligger hele modellen i arkene bak.
A4: Det du vet
A5: Hvor mye selger bedriften for i året, uten mva.? | B5: 22400000 | C5: Hele salgsinntekten, alle kundegruppene til sammen.
A6: Hvor stor del av salget kommer fra denne kundegruppen? | B6: 0.2 | C6: Tallet som ligger inne, er næringsbygg.
A7: Hvor mye av hver krone er igjen når materiellet er betalt? | B7: 0.65 | C7: Det er dekningsgraden for kundegruppen.
A8: Hvor mange montørtimer fakturerer bedriften i året? | B8: 14400 | C8: Den knappe faktoren. Det er disse timene alt skal måles mot.
A9: Hvor stor del av montørtimene går til denne kundegruppen? | B9: 0.13 | C9: Ofte en annen andel enn salget. Det er hele poenget.
A10: Hva gir den svakeste kundegruppen per montørtime? | B10: 819 | C10: Entreprenørene, i kroner per montørtime. Brukes bare til å sammenlikne.
A12: Regnestykket
A13: Salg fra kundegruppen | B13: =B5*B6 -> 4480000 | C13: Andelen ganger hele salget.
A14: Dekningsbidrag fra kundegruppen | B14: =B13*B7 -> 2912000 | C14: Det som er igjen når materiellet er betalt.
A15: Montørtimer kundegruppen bruker | B15: =B8*B9 -> 1872 | C15: Andelen ganger alle de fakturerte timene.
A17: DEKNINGSBIDRAG PER MONTØRTIME | B17: =B14/B15 -> 1555.5556 | C17: Kroner per time av det bedriften har minst av.
A18: Så mange ganger mer enn den svakeste kundegruppen | B18: =B17/B10 -> 1.8993352 | C18: Over 1 betyr at timen gir mer her enn hos de svakeste.
A20: Hva svaret betyr
A21: ="Hver montørtime hos denne kundegruppen gir "&TEXT(ROUND(B17,0),"#,##0")&" kroner i dekningsbidrag. Det er "&TEXT(ROUND(B18,2),"#,##0.00")&" ganger så mye som hos den svakeste." -> Hver montørtime hos denne kundegruppen gir 1,556 kroner i dekningsbidrag. Det er 1.90 ganger så mye som hos den svakeste.
A23: Prøv selv
A24: 1. Regn huseierne: sett B6 til 20 %, B7 til 75 % og B9 til 25 %. Hva gir timen nå?
A25: 2. Regn borettslagene: sett B6 til 14 %, B7 til 65 % og B9 til 15 %.
A26: 3. Huseierne har høyest dekningsgrad. Hvem gir mest per montørtime av huseierne og borettslagene?
A28: Tallene er Nordlys Elektro AS sine for 2026 (sammendraget til kap. 5 og regnearket). Kilde: Markedsføring, organisasjon og ledelse for LØM-emnet, kap. 5.7, og Økonomistyring for LØM-emnet, kap. 7. Nordlys Elektro AS er en konstruert casebedrift.

Sheet Veiledning
A1: Kundelønnsomhet per segment
A2: LØM Markedsføring kap. 5 · arbeidsregneark · Fagskolen Oslo, Avdeling Elkraft
A3: Emne: Teknisk kommunikasjon og ledelse for 1ET-klassene · LØM for 2ET, 2EK, 3EK og 4EK
A4: Fargekode
A5: Gul celle med blå skrift | B5: Inndata — dette er tallene du endrer.
A6: Grå eller lyseblå celle, svart skrift | B6: Formel — regner seg selv. Ikke skriv over den.
A7: Mørkeblå rad med hvit skrift | B7: Kolonneoverskrift.
A9: Ark i arbeidsboka
A10: Enkelt | B10: Start her. Seks gule celler, ett svar. Hva én kundegruppe gir per montørtime, regnet på den enkleste måten.
A11: Segmenter | B11: De fem kundetypene, med omsetning, montørtimer, dekningsgrad og dekningsbidrag per montørtime. Her ligger knappene B19 til D23.
A12: Kundelønnsomhet | B12: Hva som er igjen når kalkulatørtimene og kredittiden er trukket fra — og hvordan rangeringen endrer seg. Knappene er B6 til F10.
A13: Scenario | B13: Tre spørsmål: hva det er verdt å flytte timer, hva kredittiden er verdt, og hva det koster å si nei til et helt segment.
A14: Din egen bedrift | B14: Samme regnestykke, tomt. Legg inn dine egne segmenter.
A16: Tallene som ligger inne er Nordlys Elektro AS sine egne for 2026.
A17: Arket svarer på ett spørsmål: hvilket segment gir mest igjen per montørtime — og holder svaret når salgsarbeidet og kredittiden regnes med?
A18: Merk: montørlønna er IKKE trukket fra dekningsbidraget her. Den er fast på kort sikt og følger montøren, ikke kunden. Det er derfor tallene er høyere enn dekningsbidraget per oppdragstype i Økonomistyring for LØM-emnet kap. 7.
A20: Tallene som ligger inne er et eksempel fra en elektrobedrift. Bytt dem ut med dine egne — alle formler følger med.
A21: Arbeidsregneark til LØM · Fagskolen Oslo, Avdeling Elkraft. Regnearket er øvingsstøtte, ikke et regnskapssystem.
A23: Knappene
A24: Segmenter!B19:B23 | B24: Andel av omsetningen | C24: Hvor stor del av salgsinntekten hvert segment står for. Må summere seg til 100 %.
A25: Segmenter!C19:C23 | B25: Andel av montørtimene | C25: Hvor stor del av timene hvert segment legger beslag på. Må summere seg til 100 %.
A26: Segmenter!D19:D23 | B26: Dekningsgrad | C26: Hva som er igjen av hver omsatt krone etter materiell og innleide montører.
A27: Kundelønnsomhet!B6:C10 | B27: Tilbud og timer per tilbud | C27: Hva det koster i kalkulatørtid å holde segmentet.
A28: Kundelønnsomhet!F6:F10 | B28: Kredittdager | C28: Hvor lenge kunden bruker på å betale. Bind kapital koster renter.
A30: Hvilken oppgave bruker hvilket ark
A31: Oppgave i øvingsheftet | B31: Ark | C31: Celler du endrer og leser av
A32: A1 · Hvilket segment ville du valgt bort først? | B32: Scenario | C32: Scenario C: skriv segmentet du sier nei til i B42, og les av hva det koster i B45 og hva som må til for å fylle timene i B53 og B55.
A33: A2 · Klasseoppgave: velg to målgrupper for Nordlys | B33: Segmenter og Scenario | C33: Rangeringen står ferdig i kolonne H i arket «Segmenter». Scenario C regner ut hva det koster å si nei.
A34: 1 · Fem kundetyper, rangert etter kroner per montørtime | B34: Segmenter | C34: Legg inn andeler og dekningsgrad i B19 til D23. Les av omsetning, timer og dekningsbidrag i E, F og G, og kroner per montørtime i H.
A35: 2 · Hva salgsarbeidet og kreditten koster | B35: Kundelønnsomhet | C35: Legg inn tilbud, timer per tilbud og kredittdager i B6 til F10. Les av kundelønnsomheten i E16 til F20, og hvem som bytter plass i kolonne H og I.
A36: 3 · Hva det er verdt å flytte en time | B36: Scenario | C36: Scenario A: sett antall timer i B7 og les av B11, B12 og B14.
A37: 4 · Holder «alle som har elbil i Oslo» som målgruppe? | B37: Scenario | C37: Scenario C: skriv segmentet du sier nei til i B42 og segmentet timene flyttes til i B43. Les av B49, B53 og B55, og dommen i E56.
A38: 5 · Eksamensnær: satse på ett segment | B38: Scenario | C38: Alle tre scenarioene. Scenario B gir deg argumentet om kredittid som ikke koster pris. Bruk «Din egen bedrift» hvis du vil regne på din egen bedrift.
A40: Kontrollradene
A41: Hvert regneark har en kontrollblokk. Står det OK, henger tallene sammen. Står det AVVIK, farges cellen rød, og teksten sier hva som ikke går opp.
A42: Tre av kontrollene er faglige og ikke tekniske: at segmentet med høyest dekningsgrad IKKE er det som gir mest per time, at det største segmentet ikke er det beste, og at minst ett segment bytter plass når salgsarbeidet regnes med. Slår en av dem ut i AVVIK, er det ikke en regnefeil — det er kapitlets poeng som har falt bort.
A43: Kontroller i arbeidsboka: Segmenter E34, Segmenter E35, Segmenter E36, Segmenter E37, Kundelønnsomhet E30, Kundelønnsomhet E31, Kundelønnsomhet E32, Kundelønnsomhet E33, Kundelønnsomhet E34, Scenario B17, Scenario B18, Scenario B35, Scenario B36, Scenario B59, Scenario B60, Scenario B61, Din egen bedrift E22, Din egen bedrift E23
A45: Kilder
A46: Hjertnes, F.: Markedsføring, organisasjon og ledelse for LØM-emnet, 4. utg., kap. 5.1 til 5.8. Knapp faktor og dekningsbidrag: Økonomistyring for LØM-emnet, kap. 2, 7 og 8. Kundefordringer og kapitalbinding: Økonomistyring for LØM-emnet kap. 3 og 4.
A47: Salgskostnad og kredittid per segment er ikke lærebokas begreper. De er en utvidelse av lærebokas krav om at et segment skal vurderes på lønnsomhet, og de er merket som det. Læreboka gjelder foran arket.
...

Sheet Segmenter
A1: Fem kundetyper, én bedrift
A2: Endre de gule cellene. Alt annet regner seg selv.
A4: 1 · Bedriftens egne tall for året
A5: Salgsinntekt, uten mva. | B5: 22400000 | J5: Hele bedriften, alle tre avdelingene.
A6: − varekostnad materiell | B6: 7990000
A7: − varekostnad innleide montører | B7: 400000
A8: = Dekningsbidrag totalt | B8: =B5-B6-B7 -> 14010000 | J8: Her er montørlønna IKKE trukket fra. Den er en fast kostnad på kort sikt, og den følger montøren, ikke kunden.
A9: Dekningsgrad totalt | B9: =B8/B5 -> 0.62544643
A10: Fakturerbare montørtimer | B10: 14400 | J10: Den knappe faktoren. Det er denne alt skal måles mot.
A11: Faste kostnader | B11: 12666000
A12: = Driftsresultat | B12: =B8-B11 -> 1344000
A13: Merverdiavgift | B13: 0.25
A14: Kostsats, administrasjonstime | B14: 327.43363 | J14: Det en time hos kalkulatøren koster bedriften.
A15: Lånerente | B15: 0.028555888 | J15: Bedriftens egen gjennomsnittsrente. Brukes på kapitalen som ligger i ubetalte fakturaer.
A17: 2 · De fem segmentene
A18: Segment | B18: Andel av omsetningen | C18: Andel av montørtimene | D18: Deknings- grad | E18: Omsetning | F18: Montør- timer | G18: Deknings- bidrag | H18: DB per montørtime | I18: Omsetning per time | J18: Hva kunden er
A19: Huseiere og boligeiere | B19: 0.2 | C19: 0.25 | D19: 0.75 | E19: =B19*$B$5 -> 4480000 | F19: =C19*$B$10 -> 3600 | G19: =E19*D19 -> 3360000 | H19: =IF(F19=0,0,G19/F19) -> 933.33333 | I19: =IF(F19=0,0,E19/F19) -> 1244.4444 | J19: Nytt sikringsskap, varmekabler på bad, ett ladepunkt i garasjen.
A20: Borettslag og sameier | B20: 0.14 | C20: 0.15 | D20: 0.65 | E20: =B20*$B$5 -> 3136000 | F20: =C20*$B$10 -> 2160 | G20: =E20*D20 -> 2038400 | H20: =IF(F20=0,0,G20/F20) -> 943.7037 | I20: =IF(F20=0,0,E20/F20) -> 1451.8519 | J20: Felles ladeanlegg med lastbalansering, oppgradering av stigeledninger, fellesarealbelysning.
A21: Entreprenører og byggmestere | B21: 0.34 | C21: 0.36 | D21: 0.55778361 | E21: =B21*$B$5 -> 7616000 | F21: =C21*$B$10 -> 5184 | G21: =E21*D21 -> 4248080 | H21: =IF(F21=0,0,G21/F21) -> 819.45988 | I21: =IF(F21=0,0,E21/F21) -> 1469.1358 | J21: Elektroarbeid i et rekkehusfelt eller et mindre næringsbygg, som underleverandør.
A22: Næringsbygg og eiendomsdrift | B22: 0.2 | C22: 0.13 | D22: 0.65 | E22: =B22*$B$5 -> 4480000 | F22: =C22*$B$10 -> 1872 | G22: =E22*D22 -> 2912000 | H22: =IF(F22=0,0,G22/F22) -> 1555.5556 | I22: =IF(F22=0,0,E22/F22) -> 2393.1624 | J22: Feilsøking, service, el-kontroll og småendringer i bygg Nordlys kjenner fra før.
A23: Offentlige rammeavtaler | B23: 0.12 | C23: 0.11 | D23: 0.54 | E23: =B23*$B$5 -> 2688000 | F23: =C23*$B$10 -> 1584 | G23: =E23*D23 -> 1451520 | H23: =IF(F23=0,0,G23/F23) -> 916.36364 | I23: =IF(F23=0,0,E23/F23) -> 1696.9697 | J23: Lysarmaturer og småoppdrag på skoler og sykehjem, avropt på rammeavtale.
A24: SUM | B24: =SUM(B19:B23) -> 1 | C24: =SUM(C19:C23) -> 1 | D24: =G24/E24 -> 0.62544643 | E24: =SUM(E19:E23) -> 22400000 | F24: =SUM(F19:F23) -> 14400 | G24: =SUM(G19:G23) -> 14010000 | H24: =G24/F24 -> 972.91667 | I24: =E24/F24 -> 1555.5556
A26: 3 · Det som er verdt å legge merke til
A27: Høyeste dekningsgrad | B27: =INDEX($A$19:$A$23,MATCH(MAX($D$19:$D$23),$D$19:$D$23,0)) -> Huseiere og boligeiere | D27: =MAX($D$19:$D$23) -> 0.75 | J27: Prosenten som ser best ut på papiret.
A28: Mest igjen per montørtime | B28: =INDEX($A$19:$A$23,MATCH(MAX($H$19:$H$23),$H$19:$H$23,0)) -> Næringsbygg og eiendomsdrift | H28: =MAX($H$19:$H$23) -> 1555.5556 | J28: Kroner per time av det bedriften har minst av.
A29: Størst i omsetning | B29: =INDEX($A$19:$A$23,MATCH(MAX($E$19:$E$23),$E$19:$E$23,0)) -> Entreprenører og byggmestere | E29: =MAX($E$19:$E$23) -> 7616000 | J29: Det segmentet ordreboka gjør mest av seg.
A30: Minst igjen per montørtime | B30: =INDEX($A$19:$A$23,MATCH(MIN($H$19:$H$23),$H$19:$H$23,0)) -> Entreprenører og byggmestere | H30: =MIN($H$19:$H$23) -> 819.45988
A31: Spredning, beste mot svakeste | H31: =MAX($H$19:$H$23)/MIN($H$19:$H$23) -> 1.8982693 | J31: Så mange ganger mer gir den beste montørtimen enn den svakeste.
A33: Kontroll
A34: Summerer andelene seg til hundre prosent? | E34: =IF(AND(ABS(B24-1)<0.0001,ABS(C24-1)<0.0001),"OK — både omsetning og timer er fullt fordelt på de fem segmentene","AVVIK: andelene summerer seg ikke til hundre prosent. Da er det enten omsetning eller montørtimer som ikke er fordelt") -> OK — både omsetning og timer er fullt fordelt på de fem segmentene
A35: Stemmer segmentenes dekningsbidrag med bedriftens? | E35: =IF(ABS(G24-B8)<1,"OK — segmentene deler bedriftens eget dekningsbidrag, verken mer eller mindre","AVVIK: summen av segmentenes dekningsbidrag er ikke lik bedriftens. Juster dekningsgraden i ett av segmentene") -> OK — segmentene deler bedriftens eget dekningsbidrag, verken mer eller mindre
A36: Er det høyeste dekningsgrad og mest per time i to ULIKE segmenter? | E36: =IF(B27<>B28,"OK — segmentet med høyest dekningsgrad er ikke det som gir mest per montørtime. Det er hele kapitlets poeng","AVVIK: samme segment vinner på begge mål. Da forsvinner poenget om at prosent rangerer feil når timen er knapp") -> OK — segmentet med høyest dekningsgrad er ikke det som gir mest per montørtime. Det er hele kapitlets poeng
A37: Er det største segmentet noe annet enn det beste? | E37: =IF(B29<>B28,"OK — det mest omsetningstunge segmentet er ikke det mest lønnsomme per time","AVVIK: det største segmentet er også det beste. Da er det ingenting ubehagelig å ta stilling til") -> OK — det mest omsetningstunge segmentet er ikke det mest lønnsomme per time
A39: Prøv dette: sett dekningsgraden for huseiere ned til nivået i de andre segmentene, og se om rekkefølgen i kolonne H endrer seg. Det gjør den ikke — og det er poenget: prosenten avgjør ikke.
A40: Kilde: Hjertnes, F.: Markedsføring, organisasjon og ledelse for LØM-emnet, 4. utg., kap. 5.1 til 5.3 og 5.7 om lønnsomhetspotensial. Knapp faktor: Økonomistyring for LØM-emnet, kap. 7. Tallene er Nordlys Elektro AS sine egne for 2026.

Sheet Kundelønnsomhet
A1: Hva er igjen når salgsarbeidet og kreditten er betalt?
A2: Dekningsbidraget stopper ved materiellet. Et segment koster mer enn det.
A4: 1 · Salgsarbeidet og kredittiden
A5: Segment | B5: Tilbud i året | C5: Kalkulatørtimer per tilbud | D5: Salgs- timer | E5: Salgs- kostnad | F5: Kreditt- dager | G5: Kapital- binding | H5: Rente- kostnad | I5: Hvorfor det koster det det gjør
A6: =Segmenter!A19 -> Huseiere og boligeiere | B6: 240 | C6: 1.5 | D6: =B6*C6 -> 360 | E6: =D6*Segmenter!$B$14 -> 117876.11 | F6: 14 | G6: =Segmenter!E19*(1+Segmenter!$B$13)*F6/365 -> 214794.52 | H6: =G6*Segmenter!$B$15 -> 6133.6483 | I6: Sammenlikner to–tre tilbud og spør alltid om prisen inkluderer alt.
A7: =Segmenter!A20 -> Borettslag og sameier | B7: 14 | C7: 26 | D7: =B7*C7 -> 364 | E7: =D7*Segmenter!$B$14 -> 119185.84 | F7: 45 | G7: =Segmenter!E20*(1+Segmenter!$B$13)*F7/365 -> 483287.67 | H7: =G7*Segmenter!$B$15 -> 13800.709 | I7: Prisfølsom på papiret, men velger oftest den som forklarer best.
A8: =Segmenter!A21 -> Entreprenører og byggmestere | B8: 36 | C8: 22 | D8: =B8*C8 -> 792 | E8: =D8*Segmenter!$B$14 -> 259327.43 | F8: 85 | G8: =Segmenter!E21*(1+Segmenter!$B$13)*F8/365 -> 2216986.3 | H8: =G8*Segmenter!$B$15 -> 63308.012 | I8: Kjøper på pris. Nordlys er én av fire på lista.
A9: =Segmenter!A22 -> Næringsbygg og eiendomsdrift | B9: 22 | C9: 6 | D9: =B9*C9 -> 132 | E9: =D9*Segmenter!$B$14 -> 43221.239 | F9: 30 | G9: =Segmenter!E22*(1+Segmenter!$B$13)*F9/365 -> 460273.97 | H9: =G9*Segmenter!$B$15 -> 13143.532 | I9: Spør sjelden om timeprisen. Spør om responstiden.
A10: =Segmenter!A23 -> Offentlige rammeavtaler | B10: 4 | C10: 30 | D10: =B10*C10 -> 120 | E10: =D10*Segmenter!$B$14 -> 39292.035 | F10: 90 | G10: =Segmenter!E23*(1+Segmenter!$B$13)*F10/365 -> 828493.15 | H10: =G10*Segmenter!$B$15 -> 23658.358 | I10: Prisen er bundet i avtalen i fire år. Ingen forhandling underveis.
A11: SUM | B11: =SUM(B6:B10) -> 316 | D11: =SUM(D6:D10) -> 1768 | E11: =SUM(E6:E10) -> 578902.65 | G11: =SUM(G6:G10) -> 4203835.6 | H11: =SUM(H6:H10) -> 120044.26
A12: Salgstimene i årsverk | D12: =D11/1695 -> 1.0430678 | I12: Så stor del av et årsverk går til å skrive tilbud.
A14: 2 · Kundelønnsomheten
A15: Segment | B15: Deknings- bidrag | C15: − salgs- kostnad | D15: − rente- kostnad | E15: Kunde- lønnsomhet | F15: Per montør- time | G15: Andel av dekningsbidraget | H15: Plass før og etter | I15: Hva som skjedde
A16: =Segmenter!A19 -> Huseiere og boligeiere | B16: =Segmenter!G19 -> 3360000 | C16: =-E6 -> -117876.11 | D16: =-H6 -> -6133.6483 | E16: =B16+C16+D16 -> 3235990.2 | F16: =IF(Segmenter!F19=0,0,E16/Segmenter!F19) -> 898.88618 | G16: =IF(B16=0,0,E16/B16) -> 0.96309233 | H16: =RANK(Segmenter!H19,Segmenter!$H$19:$H$23,0)&" → "&RANK(F16,$F$16:$F$20,0) -> 3 → 2 | I16: =IF(RANK(Segmenter!H19,Segmenter!$H$19:$H$23,0)=RANK(F16,$F$16:$F$20,0),"Samme plass",IF(RANK(F16,$F$16:$F$20,0)<RANK(Segmenter!H19,Segmenter!$H$19:$H$23,0),"Opp — segmentet er billigere å selge til enn tabellen over viser","Ned — salgsarbeidet eller kredittiden spiser mer enn i de andre")) -> Opp — segmentet er billigere å selge til enn tabellen over viser
A17: =Segmenter!A20 -> Borettslag og sameier | B17: =Segmenter!G20 -> 2038400 | C17: =-E7 -> -119185.84 | D17: =-H7 -> -13800.709 | E17: =B17+C17+D17 -> 1905413.5 | F17: =IF(Segmenter!F20=0,0,E17/Segmenter!F20) -> 882.13586 | G17: =IF(B17=0,0,E17/B17) -> 0.93475935 | H17: =RANK(Segmenter!H20,Segmenter!$H$19:$H$23,0)&" → "&RANK(F17,$F$16:$F$20,0) -> 2 → 3 | I17: =IF(RANK(Segmenter!H20,Segmenter!$H$19:$H$23,0)=RANK(F17,$F$16:$F$20,0),"Samme plass",IF(RANK(F17,$F$16:$F$20,0)<RANK(Segmenter!H20,Segmenter!$H$19:$H$23,0),"Opp — segmentet er billigere å selge til enn tabellen over viser","Ned — salgsarbeidet eller kredittiden spiser mer enn i de andre")) -> Ned — salgsarbeidet eller kredittiden spiser mer enn i de andre
A18: =Segmenter!A21 -> Entreprenører og byggmestere | B18: =Segmenter!G21 -> 4248080 | C18: =-E8 -> -259327.43 | D18: =-H8 -> -63308.012 | E18: =B18+C18+D18 -> 3925444.6 | F18: =IF(Segmenter!F21=0,0,E18/Segmenter!F21) -> 757.2231 | G18: =IF(B18=0,0,E18/B18) -> 0.92405147 | H18: =RANK(Segmenter!H21,Segmenter!$H$19:$H$23,0)&" → "&RANK(F18,$F$16:$F$20,0) -> 5 → 5 | I18: =IF(RANK(Segmenter!H21,Segmenter!$H$19:$H$23,0)=RANK(F18,$F$16:$F$20,0),"Samme plass",IF(RANK(F18,$F$16:$F$20,0)<RANK(Segmenter!H21,Segmenter!$H$19:$H$23,0),"Opp — segmentet er billigere å selge til enn tabellen over viser","Ned — salgsarbeidet eller kredittiden spiser mer enn i de andre")) -> Samme plass
A19: =Segmenter!A22 -> Næringsbygg og eiendomsdrift | B19: =Segmenter!G22 -> 2912000 | C19: =-E9 -> -43221.239 | D19: =-H9 -> -13143.532 | E19: =B19+C19+D19 -> 2855635.2 | F19: =IF(Segmenter!F22=0,0,E19/Segmenter!F22) -> 1525.4462 | G19: =IF(B19=0,0,E19/B19) -> 0.98064397 | H19: =RANK(Segmenter!H22,Segmenter!$H$19:$H$23,0)&" → "&RANK(F19,$F$16:$F$20,0) -> 1 → 1 | I19: =IF(RANK(Segmenter!H22,Segmenter!$H$19:$H$23,0)=RANK(F19,$F$16:$F$20,0),"Samme plass",IF(RANK(F19,$F$16:$F$20,0)<RANK(Segmenter!H22,Segmenter!$H$19:$H$23,0),"Opp — segmentet er billigere å selge til enn tabellen over viser","Ned — salgsarbeidet eller kredittiden spiser mer enn i de andre")) -> Samme plass
A20: =Segmenter!A23 -> Offentlige rammeavtaler | B20: =Segmenter!G23 -> 1451520 | C20: =-E10 -> -39292.035 | D20: =-H10 -> -23658.358 | E20: =B20+C20+D20 -> 1388569.6 | F20: =IF(Segmenter!F23=0,0,E20/Segmenter!F23) -> 876.62223 | G20: =IF(B20=0,0,E20/B20) -> 0.9566314 | H20: =RANK(Segmenter!H23,Segmenter!$H$19:$H$23,0)&" → "&RANK(F20,$F$16:$F$20,0) -> 4 → 4 | I20: =IF(RANK(Segmenter!H23,Segmenter!$H$19:$H$23,0)=RANK(F20,$F$16:$F$20,0),"Samme plass",IF(RANK(F20,$F$16:$F$20,0)<RANK(Segmenter!H23,Segmenter!$H$19:$H$23,0),"Opp — segmentet er billigere å selge til enn tabellen over viser","Ned — salgsarbeidet eller kredittiden spiser mer enn i de andre")) -> Samme plass
A21: SUM | B21: =SUM(B16:B20) -> 14010000 | C21: =SUM(C16:C20) -> -578902.65 | D21: =SUM(D16:D20) -> -120044.26 | E21: =SUM(E16:E20) -> 13311053 | F21: =E21/Segmenter!F24 -> 924.37869 | G21: =E21/B21 -> 0.95011086
A23: 3 · Rangeringen, før og etter
A24: Best per montørtime etter salgskostnad og rente | B24: =INDEX($A$16:$A$20,MATCH(MAX($F$16:$F$20),$F$16:$F$20,0)) -> Næringsbygg og eiendomsdrift | F24: =MAX($F$16:$F$20) -> 1525.4462
A25: Svakest per montørtime etter salgskostnad og rente | B25: =INDEX($A$16:$A$20,MATCH(MIN($F$16:$F$20),$F$16:$F$20,0)) -> Entreprenører og byggmestere | F25: =MIN($F$16:$F$20) -> 757.2231
A26: Spredning, beste mot svakeste | F26: =MAX($F$16:$F$20)/MIN($F$16:$F$20) -> 2.0145267 | I26: Sammenlikn med spredningen i arket Segmenter. Den er større her.
A27: Antall segmenter som bytter plass | F27: =SUMPRODUCT(--(I16:I20<>"Samme plass")) -> 2
A29: Kontroll
A30: Går regnestykket opp mot dekningsbidraget? | E30: =IF(ABS(B21+C21+D21-E21)<1,"OK — dekningsbidrag minus salgskostnad og rente er lik kundelønnsomheten","AVVIK: linjene summerer seg ikke til kundelønnsomheten") -> OK — dekningsbidrag minus salgskostnad og rente er lik kundelønnsomheten
A31: Stemmer kapitalbindingen med kundefordringene i balansen? | E31: =IF(ABS(G11-4200000)/4200000<0.05,"OK — den kapitalen segmentene binder, stemmer med kundefordringene i balansen til Nordlys","AVVIK: kredittdagene stemmer ikke med balansen. Enten er betalingstiden feil, eller så mangler et segment") -> OK — den kapitalen segmentene binder, stemmer med kundefordringene i balansen til Nordlys
A32: Beholder alle segmentene noe av dekningsbidraget? | E32: =IF(MIN($G$16:$G$20)>0,"OK — alle fem segmentene gir positivt bidrag etter salgsarbeid og kreditt","AVVIK: minst ett segment går i minus. Da er det ikke lenger et segment å diskutere, men et som skal avvikles") -> OK — alle fem segmentene gir positivt bidrag etter salgsarbeid og kreditt
A33: Bytter noen segmenter plass? | E33: =IF(F27>0,"OK — rangeringen endrer seg når salgsarbeidet og kreditten regnes med. Det er hele grunnen til at dette arket finnes","AVVIK: ingen segmenter bytter plass. Da holder det med tabellen i arket Segmenter") -> OK — rangeringen endrer seg når salgsarbeidet og kreditten regnes med. Det er hele grunnen til at dette arket finnes
A34: Er tilbudsarbeidet mulig for én kalkulatør? | E34: =IF(D12<1.3,"OK — tilbudsarbeidet får plass innenfor drøyt ett årsverk","AVVIK: tilbudsarbeidet krever mer enn ett og et kvart årsverk. Da må noen ansettes, eller så må bedriften gi færre tilbud") -> OK — tilbudsarbeidet får plass innenfor drøyt ett årsverk
A36: Prøv dette: sett kredittdagene for entreprenørene ned til tretti, og se hvor mye kundelønnsomheten stiger. Det er en forhandling, ikke en prisøkning.
A37: Kilde: Hjertnes kap. 5.7 om lønnsomhetspotensial. Salgskostnaden og kredittiden er ikke lærebokas begreper, men en utvidelse: læreboka sier at segmentet må vurderes på lønnsomhet, og dette er hvordan man gjør det i en installasjonsbedrift. Kapitalbindingen henger sammen med kundefordringene i Økonomistyring for LØM-emnet, kap. 3 og 4.

Sheet Scenario
A1: Tre scenarioer
A2: Endre de gule cellene og se hva som skjer. Alle tall hentes fra de andre arkene.
A4: Scenario A · flytt timer fra det svakeste til det beste segmentet
A5: Montørtimen er den knappe faktoren. Å flytte den er den eneste beslutningen som ikke koster penger.
A7: Timer som flyttes | B7: 500 | E7: Endre denne. Fem hundre timer er omtrent en tredel av et montørår.
A8: Svakeste segment | B8: =Kundelønnsomhet!B25 -> Entreprenører og byggmestere | C8: =Kundelønnsomhet!F25 -> 757.2231
A9: Beste segment | B9: =Kundelønnsomhet!B24 -> Næringsbygg og eiendomsdrift | C9: =Kundelønnsomhet!F24 -> 1525.4462
A10: Forskjell per montørtime | C10: =C9-C8 -> 768.22307
A11: = Hva flyttingen er verdt på ett år | B11: =B7*C10 -> 384111.53 | E11: Ingen prisøkning, ingen ansettelse. Bare andre kunder.
A12: I prosent av driftsresultatet | B12: =B11/Segmenter!$B$12 -> 0.28579727
A13: Timer i det svakeste segmentet i dag | B13: =INDEX(Segmenter!$F$19:$F$23,MATCH(B8,Segmenter!$A$19:$A$23,0)) -> 5184
A14: Andel av det svakeste segmentet som må bort | B14: =B7/B13 -> 0.096450617 | E14: Så stor del av segmentet må sies nei til. Er tallet lite, er beslutningen lett. Er det stort, er det en omlegging.
A16: Kontroll
A17: Er flyttingen mulig? | B17: =IF(B7<=B13,"OK — det er nok timer i det svakeste segmentet til å flytte så mange","AVVIK: du flytter flere timer enn det finnes i segmentet. Da må du ta timer fra et annet segment også") -> OK — det er nok timer i det svakeste segmentet til å flytte så mange
A18: Gir flyttingen gevinst? | B18: =IF(B11>0,"OK — det beste segmentet gir mer per time enn det svakeste","AVVIK: flyttingen gir ingen gevinst. Sjekk rangeringen i arket Kundelønnsomhet") -> OK — det beste segmentet gir mer per time enn det svakeste
A21: Scenario B · kredittiden er en forhandling, ikke en prisøkning
A22: Å få en kunde ned fra åtti til tretti dagers kreditt koster ingenting i pris. Se hva det er verdt.
B24: I dag | C24: Forhandlet | D24: Endring | E24: Hva raden betyr
A25: Segment | B25: Entreprenører og byggmestere | E25: Skriv navnet på segmentet nøyaktig slik det står i arket Segmenter.
A26: Kredittdager | B26: =INDEX(Kundelønnsomhet!$F$6:$F$10,MATCH(B25,Kundelønnsomhet!$A$6:$A$10,0)) -> 85 | C26: 30 | D26: =C26-B26 -> -55
A27: Omsetning i segmentet | B27: =INDEX(Segmenter!$E$19:$E$23,MATCH(B25,Segmenter!$A$19:$A$23,0)) -> 7616000 | C27: =B27 -> 7616000 | E27: Uendret. Forhandlingen gjelder betalingstiden, ikke prisen.
A28: Kapitalbinding | B28: =B27*(1+Segmenter!$B$13)*B26/365 -> 2216986.3 | C28: =C27*(1+Segmenter!$B$13)*C26/365 -> 782465.75 | D28: =C28-B28 -> -1434520.5
A29: Rentekostnad | B29: =B28*Segmenter!$B$15 -> 63308.012 | C29: =C28*Segmenter!$B$15 -> 22344.004 | D29: =C29-B29 -> -40964.008
A30: = Spart i året | B30: =B29-C29 -> 40964.008 | E30: Lite i kroner, men det er penger bedriften ikke måtte selge for å få.
A31: Frigjort kapital | B31: =B28-C28 -> 1434520.5 | E31: Dette er det store tallet: kapital som slutter å ligge i kundefordringer, og som kan brukes til å forskuttere materiell.
A32: Frigjort kapital i prosent av bankinnskuddet | B32: =B31/1000000 -> 1.4345205
A34: Kontroll
A35: Finnes segmentet? | B35: =IF(ISNUMBER(MATCH(B25,Segmenter!$A$19:$A$23,0)),"OK — segmentet finnes i arket Segmenter","AVVIK: fant ikke segmentet. Skriv navnet nøyaktig slik det står i kolonne A i arket Segmenter") -> OK — segmentet finnes i arket Segmenter
A36: Frigjør kortere kredittid kapital? | B36: =IF(C26<B26,IF(B31>0,"OK — kortere kredittid frigjør kapital","AVVIK: kortere kredittid skal frigjøre kapital"),"OK — du har satt kredittiden opp, ikke ned. Da binder du mer kapital, og tallene er negative") -> OK — kortere kredittid frigjør kapital
A39: Scenario C · si nei til ett segment
A40: Å si nei koster timer du må fylle med noe annet. Her ser du hva det koster, og hva som må til for å fylle timene.
A42: Segmentet du sier nei til | B42: Entreprenører og byggmestere
A43: Segmentet timene skal flyttes til | B43: Næringsbygg og eiendomsdrift | E43: Begge navnene må stå nøyaktig slik de står i arket Segmenter.
A44: Omsetning som forsvinner | B44: =INDEX(Segmenter!$E$19:$E$23,MATCH(B42,Segmenter!$A$19:$A$23,0)) -> 7616000
A45: Kundelønnsomhet som forsvinner | B45: =INDEX(Kundelønnsomhet!$E$16:$E$20,MATCH(B42,Kundelønnsomhet!$A$16:$A$20,0)) -> 3925444.6
A46: Montørtimer som blir ledige | B46: =INDEX(Segmenter!$F$19:$F$23,MATCH(B42,Segmenter!$A$19:$A$23,0)) -> 5184
A47: Kundelønnsomhet per time i segmentet timene flyttes til | B47: =INDEX(Kundelønnsomhet!$F$16:$F$20,MATCH(B43,Kundelønnsomhet!$A$16:$A$20,0)) -> 1525.4462
A48: = Kundelønnsomhet hvis timene fylles der | B48: =B46*B47 -> 7907912.9
A49: = Gevinst ved byttet | B49: =B48-B45 -> 3982468.4 | E49: Positivt tall betyr at byttet lønner seg — HVIS timene lar seg fylle.
A51: Men lar timene seg fylle?
...

Sheet Din egen bedrift
A1: Din egen bedrift
A2: Samme regnestykke, tomt. Fem segmenter er nok for de aller fleste.
A4: 1 · Bedriftens tall
A5: Salgsinntekt, uten mva. | B5: 0 | I5: Hele bedriften, eller den avdelingen du ser på.
A6: Dekningsbidrag totalt | B6: 0 | I6: Omsetning minus materiell og innleide montører.
A7: Fakturerbare montørtimer | B7: 0 | I7: Timene kunden faktisk betaler for.
A8: Kostsats, administrasjonstime | B8: 0 | I8: Hva en time hos den som skriver tilbud, koster.
A9: Lånerente | B9: 0 | I9: Rentekostnader delt på gjennomsnittlig gjeld.
A10: Merverdiavgift | B10: 0.25
A12: 2 · Segmentene dine
A13: Segment | B13: Andel av omsetningen | C13: Andel av montørtimene | D13: Deknings- grad | E13: Tilbud i året | F13: Kalkulatørtimer per tilbud | G13: Kreditt- dager | H13: DB per montørtime | I13: Kundelønnsomhet per montørtime
B14: 0 | C14: 0 | D14: 0 | E14: 0 | F14: 0 | G14: 0 | H14: =IF(C14=0,0,(B14*$B$5*D14)/(C14*$B$7)) -> 0 | I14: =IF(C14=0,0,(B14*$B$5*D14-E14*F14*$B$8-B14*$B$5*(1+$B$10)*G14/365*$B$9)/(C14*$B$7)) -> 0
B15: 0 | C15: 0 | D15: 0 | E15: 0 | F15: 0 | G15: 0 | H15: =IF(C15=0,0,(B15*$B$5*D15)/(C15*$B$7)) -> 0 | I15: =IF(C15=0,0,(B15*$B$5*D15-E15*F15*$B$8-B15*$B$5*(1+$B$10)*G15/365*$B$9)/(C15*$B$7)) -> 0
B16: 0 | C16: 0 | D16: 0 | E16: 0 | F16: 0 | G16: 0 | H16: =IF(C16=0,0,(B16*$B$5*D16)/(C16*$B$7)) -> 0 | I16: =IF(C16=0,0,(B16*$B$5*D16-E16*F16*$B$8-B16*$B$5*(1+$B$10)*G16/365*$B$9)/(C16*$B$7)) -> 0
B17: 0 | C17: 0 | D17: 0 | E17: 0 | F17: 0 | G17: 0 | H17: =IF(C17=0,0,(B17*$B$5*D17)/(C17*$B$7)) -> 0 | I17: =IF(C17=0,0,(B17*$B$5*D17-E17*F17*$B$8-B17*$B$5*(1+$B$10)*G17/365*$B$9)/(C17*$B$7)) -> 0
B18: 0 | C18: 0 | D18: 0 | E18: 0 | F18: 0 | G18: 0 | H18: =IF(C18=0,0,(B18*$B$5*D18)/(C18*$B$7)) -> 0 | I18: =IF(C18=0,0,(B18*$B$5*D18-E18*F18*$B$8-B18*$B$5*(1+$B$10)*G18/365*$B$9)/(C18*$B$7)) -> 0
A19: SUM | B19: =SUM(B14:B18) -> 0 | C19: =SUM(C14:C18) -> 0
A21: Kontroll
A22: Summerer andelene seg til hundre prosent? | E22: =IF($B$5=0,"Fyll inn tallene over.",IF(AND(ABS(B19-1)<0.0001,ABS(C19-1)<0.0001),"OK — omsetning og timer er fullt fordelt","AVVIK: andelene summerer seg ikke til hundre prosent")) -> Fyll inn tallene over.
A23: Stemmer segmentenes dekningsbidrag med bedriftens? | E23: =IF($B$5=0,"Fyll inn tallene over.",IF(ABS(SUMPRODUCT(B14:B18,D14:D18)*$B$5-$B$6)/MAX(1,$B$6)<0.02,"OK — segmentene deler bedriftens eget dekningsbidrag","AVVIK: summen av segmentenes dekningsbidrag stemmer ikke med bedriftens. Juster dekningsgraden i ett av segmentene")) -> Fyll inn tallene over.
A25: Og det arket ikke kan svare på: om kundene i det svakeste segmentet bærer noe som ikke synes i tallene — jevnt belegg gjennom vinteren, en referanse, eller anbefalinger videre. Det må du vite selv.
