Workbook

Sheet Enkelt
A1: Hva må timen koste? Den enkle versjonen
A2: Fyll inn de seks gule cellene. Svaret står i den grønne. Alt annet regner seg selv. Vil du gå dypere, ligger hele modellen i arkene bak.
A4: Det du vet
A5: Hvor mange montører har dere? | B5: 12 | C5: Bare de som kan faktureres. Lærlinger teller som en halv.
A6: Hvor mange timer er én montør på jobb i året? | B6: 1695 | C6: Etter ferie, helligdager og kurs. 1 695 er vanlig i bransjen.
A7: Hvor mange av de timene får kunden regning for? | B7: 1200 | C7: Resten går til kjøring, henting, rydding og venting. De fleste gjetter for høyt.
A8: Hva bruker bedriften på alt i løpet av et år? | B8: 21056000 | C8: Lønn, materiell, biler, husleie, alt. Står i regnskapet som sum driftskostnader.
A9: Hvor mye av det betaler kunden for direkte, som materiell? | B9: 9584000 | C9: Materiell som faktureres videre med påslag. Det skal ikke dekkes av timene.
A10: Hvor mye vil dere sitte igjen med i overskudd? | B10: 1344000 | C10: Det eierne og banken skal ha. Sett det du trenger, ikke det du håper på.
A12: Regnestykket
A13: Timer kunden betaler for, hele bedriften | B13: =B5*B7 -> 14400 | C13: Montører ganger fakturerte timer. Det er dette tallet du deler på.
A14: Faktureringsgrad | B14: =B7/B6 -> 0.7079646 | C14: Fakturerte timer delt på timer på jobb. Rundt 70 prosent er vanlig.
A15: Det timene må dekke | B15: =B8-B9 -> 11472000 | C15: Alt bedriften bruker, minus det kunden betaler for direkte.
A16: Selvkost per time | B16: =B15/B13 -> 796.66667 | C16: Her går bedriften i null.
A17: Fortjeneste per time | B17: =B10/B13 -> 93.333333 | C17: Ønsket overskudd delt på de samme timene.
A19: TIMEPRIS UTEN MVA. | B19: =B16+B17 -> 890 | C19: Dette er prisen på tilbudet til en bedriftskunde.
A20: Timepris med mva. | B20: =B19*1.25 -> 1112.5 | C20: Det privatkunden ser på regningen.
A22: Hva svaret betyr
A23: ="Hver time kunden betaler for må koste "&TEXT(ROUND(B19,0),"#,##0")&" kroner uten mva. for at bedriften skal dekke kostnadene og få overskuddet." -> Hver time kunden betaler for må koste 890 kroner uten mva. for at bedriften skal dekke kostnadene og få overskuddet.
A25: Prøv selv
A26: 1. Sett fakturerte timer (B7) til 1 100. Hva skjer med prisen?
A27: 2. Ansett to montører til (B5 = 14), men husk at lønna deres også kommer inn i B8. Hva skjer?
A28: 3. Hva må B7 være for at prisen skal komme under 800 kroner uten at overskuddet endres?
A30: Tallene er Nordlys Elektro AS sine for 2026 (faktaarket). Kilde: Økonomistyring for LØM-emnet, kap. 5.2. Nordlys Elektro AS er en konstruert casebedrift.

Sheet Veiledning
A1: Timepris og kalkyle
A2: LØM Økonomistyring kap. 5 · arbeidsregneark · Fagskolen Oslo, Avdeling Elkraft
A3: Emne: Teknisk kommunikasjon og ledelse for 1ET-klassene · LØM for 2ET, 2EK, 3EK og 4EK
A4: Fargekode
A5: Gul celle med blå skrift | B5: Inndata — dette er tallene du endrer.
A6: Grå eller lyseblå celle, svart skrift | B6: Formel — regner seg selv. Ikke skriv over den.
A7: Mørkeblå rad med hvit skrift | B7: Kolonneoverskrift.
A9: Ark i arbeidsboka
A10: Enkelt | B10: Start her. Seks gule celler, ett svar. Timeprisen regnet på den enkleste måten.
A11: Timepris | B11: Timepriskalkulatoren. Montører, timer, faktureringsgrad, kostnader og ønsket resultat inn — timeprisen ut. Her ligger den ene cellen du styrer alt fra: B37.
A12: Handelskalkyle | B12: Varen som kjøpes inn og selges videre: inntakskost, selvkost, pris, avanse og bruttofortjeneste.
A13: Oppdrag | B13: Ett oppdrag fra direkte kostnader via selvkost til kundens pris med mva. Med bidragskalkyle og etterkalkyle.
A14: Faktureringsgrad | B14: Hva timeprisen må være ved ulik faktureringsgrad. Kapitlets viktigste tabell.
A15: Scenario | B15: Tre spørsmål: hva skjer når faktureringsgraden faller, når en jobb prises under selvkost, og når en konkurrent tar en lavere timepris.
A17: Tallene som ligger inne er Nordlys Elektro AS sine egne tall for 2026.
A18: Arket er laget for å brukes på jobben etterpå: bytt ut de gule cellene med din egen bedrifts tall.
A19: Merk: timeprisen skal dekke alt bedriften ikke får igjen gjennom materiellet som faktureres videre med påslag.
A21: Tallene som ligger inne er et eksempel fra en elektrobedrift. Bytt dem ut med dine egne — alle formler følger med.
A22: Arbeidsregneark til LØM · Fagskolen Oslo, Avdeling Elkraft. Regnearket er øvingsstøtte, ikke et regnskapssystem.
A24: Den ene knappen
A25: Timepris!B37 | B25: Timepris uten mva. som brukes overalt | C25: Endrer du denne cellen, følger arkene Oppdrag, Faktureringsgrad og Scenario med. Cellen over, B32, viser hva kalkylen din sier prisen burde være.
A27: Hvilken oppgave bruker hvilket ark
A28: Oppgave i øvingsheftet | B28: Ark | C28: Celler du endrer og leser av
A29: A1 · Hvilket timetall skal Ida dele på? | B29: Timepris | C29: Faktureringsgraden står i B9, og prisen ved alternativ A i B47.
A30: A2 · Hvor mange timer tåler en fastpris? | B30: Oppdrag | C30: Timetallet står ferdig regnet i B44.
A31: A3 · Klasseoppgave: sett timeprisen for 2027 | B31: Timepris | C31: Sett antall montører i B5 og lønnskostnaden i B14, prøv ulike verdier i B7, og les av timeprisen i B32.
A32: 1 · Timeprisen til Nordlys | B32: Timepris | C32: Endre B5, B6 og B7. Les av B9, B25, B30, B32 og B34. Deloppgave d) leser du i B47 og B48, og e) i arket Faktureringsgrad.
A33: 2 · Handelskalkylen og de to prosentene | B33: Handelskalkyle | C33: Endre B5, B6, B8, B11 og B17. Les av B13, B16, B18, B21, B22, B23 og B29.
A34: 3 · Sikringsskapet: selvkost og bidrag | B34: Oppdrag | C34: Endre B6, C6, D7, D8 og D10. Les av D11, D13 og D15. Deloppgave b) og c) regner du i bidragsblokka: skriv kundens pris i D27 og les av D29 og D30.
A35: 4 · Etterkalkylen | B35: Oppdrag | C35: Sett timene i C36 til de faktiske. Les av C41, C42 og avvikene i kolonne D. Timegrensen står i B44, den nye prisen i B45.
A36: 5 · Eksamensnær: vi taper anbud på pris | B36: Scenario | C36: Scenario A: endre C8 og D8. Scenario B: endre B24. Scenario C: endre B45 og les av B48, B49, B50, B56 og B59.
A38: Kontrollradene
A39: Hvert regneark har en kontrollblokk nederst. Står det OK, henger tallene sammen. Står det AVVIK, farges cellen rød, og teksten sier hva som ikke går opp.
A40: Ett unntak: kontrollen i scenario B skal vise AVVIK med tallene som ligger inne. Der er avviket selve svaret — prisen er så lav at året ikke har timer nok til å dekke de faste kostnadene.
A41: Kontroller i arbeidsboka: Timepris B42, Timepris B43, Timepris B44, Handelskalkyle B33, Handelskalkyle B34, Handelskalkyle B35, Oppdrag D48, Oppdrag D49, Oppdrag D50, Faktureringsgrad D29, Faktureringsgrad D30, Scenario B18, Scenario B39, Scenario B62, Scenario B63
A43: Kilder
A44: Hjertnes, J. og Skorpen, K.: Økonomistyring for LØM-emnet (ISBN 978-82-450-5544-3), kapittel 5 «Kalkulasjon og kalkyleprinsipper», avsnitt 5.1, 5.1.2, 5.2 og 5.2.1. Formler for faktureringsgrad, timelønn og dekningsbidrag: formelsamlingen til LØM-emnet. Merverdiavgiftssatser: merverdiavgiftsloven kapittel 5 (Lovdata).
A45: Bransjetall: NHO Elektro, Lønnsomhetsrapport 2025, gjengitt i Elektro 24-7 19.08.2026 (hentet 10.09.2026). De 809 er bedriftene i datagrunnlaget, ikke bransjen. NHO Elektro oppgir ikke svarprosent.
A46: Nordlys Elektro AS er en konstruert casebedrift. Tallene henger sammen på tvers av alle ti kapitlene i Økonomistyring for LØM-emnet.

Sheet Timepris
A1: Hva må timen koste?
A2: Endre de gule cellene. Alt annet regner seg selv.
A4: 1 · Kapasiteten
A5: Antall montører (fakturerbare) | B5: 12 | D5: Lærlinger som ikke faktureres fullt, telles som en brøkdel.
A6: Tilgjengelige timer per montør per år | B6: 1695 | D6: Årsverket etter ferie, helligdager, kurs og annet fravær.
A7: Fakturerte timer per montør per år | B7: 1200 | D7: Timene som faktisk står på en faktura. Hent tallet fra timeregistreringen.
A9: Faktureringsgrad | B9: =B7/B6 -> 0.7079646 | D9: Kapitlets viktigste tall. De fleste anslår for høyt.
A10: Tilgjengelige timer totalt | B10: =B5*B6 -> 20340
A11: Fakturerte timer totalt | B11: =B5*B7 -> 14400 | D11: Det er DETTE tallet timeprisen skal regnes på.
A13: 2 · Kostnadene for et år
A14: Lønnskostnad, montører og lærlinger | B14: 8440000 | D14: Lønn med feriepenger, arbeidsgiveravgift og pensjon.
A15: Lønnskostnad, administrasjon | B15: 2220000 | D15: Daglig leder, kalkulatør, driftsleder og kontor.
A16: Varekostnad materiell | B16: 7990000
A17: Varekostnad innleide montører | B17: 400000
A18: Avskrivninger | B18: 620000
A19: Andre variable kostnader | B19: 386000 | D19: Drivstoff og forbruksmateriell knyttet til oppdragene.
A20: Andre faste kostnader | B20: 1000000 | D20: Husleie, forsikring, IT, telefon, regnskap og kurs.
A21: = Sum driftskostnader | B21: =SUM(B14:B20) -> 21056000
A23: 3 · Hva timene må hente inn
A24: − materiell fakturert videre | B24: 9584000 | D24: Salgsinntekten som IKKE kommer fra timer. Resten må timene bære.
A25: = Kostnader timeprisen må dekke | B25: =B21-B24 -> 11472000
A26: Ønsket driftsresultat for året | B26: 1344000 | D26: Det du vil sitte igjen med. Sett det du trenger, ikke det du håper.
A27: = Sum som skal hentes inn på timene | B27: =B25+B26 -> 12816000
A29: 4 · Timeprisen kalkylen gir
A30: Selvkost per fakturert time | B30: =B25/B11 -> 796.66667 | D30: Her går bedriften nøyaktig i null.
A31: Fortjeneste per fakturert time | B31: =B26/B11 -> 93.333333 | C31: =B31/B30 -> 0.11715481 | D31: Kolonne C: fortjenesten i prosent av selvkost.
A32: = Timepris uten mva. | B32: =B30+B31 -> 890
A33: Merverdiavgift | B33: 0.25
A34: = Timepris med mva. | B34: =B32*(1+B33) -> 1112.5 | D34: Prisen privatkunden ser.
A36: 5 · Timeprisen du faktisk bruker — den ene knappen
A37: TIMEPRIS UTEN MVA. SOM BRUKES I ALLE ARK | B37: 890 | D37: Dette er cellen du endrer. Arkene Oppdrag, Faktureringsgrad og Scenario henter timeprisen herfra.
A38: Timepris med mva. | B38: =B37*(1+B33) -> 1112.5
A39: Avvik fra timeprisen kalkylen gir | B39: =B37-B32 -> 0 | D39: Står det noe annet enn null her, tar du en annen pris enn din egen kalkyle tilsier.
A41: Kontroll
A42: Henter timeprisen inn det den skal? | B42: =IF(ABS(B32*B11-B27)<1,"OK — timeprisen henter inn nøyaktig det den skal","AVVIK: timepris ganger fakturerte timer er ikke lik summen i B27") -> OK — timeprisen henter inn nøyaktig det den skal
A43: Dekker prisen du bruker selvkost per time? | B43: =IF(B37>=B30,"OK — prisen du bruker dekker selvkost per time. Under den grensen taper bedriften penger på hver eneste time","AVVIK: prisen du bruker ligger UNDER selvkost per time — da taper bedriften penger på hver eneste time") -> OK — prisen du bruker dekker selvkost per time. Under den grensen taper bedriften penger på hver eneste time
A44: Er faktureringsgraden mulig? | B44: =IF(AND(B9>0,B9<1),"OK — faktureringsgraden ligger mellom null og hundre prosent","AVVIK: fakturerte timer kan ikke overstige tilgjengelige timer") -> OK — faktureringsgraden ligger mellom null og hundre prosent
A46: 6 · Feilen som koster mest
A47: Timepris hvis du deler på ALLE tilgjengelige timer | B47: =B27/B10 -> 630.0885 | D47: Den vanligste feilen i faget. Se hvor mye lavere prisen blir.
A48: Det den feilen koster deg på et år | B48: =B27-B47*B11 -> 3742725.7 | D48: Manglende dekning når du priser på tilgjengelige, men fakturerer færre timer.
...

Sheet Handelskalkyle
A1: Fra innkjøpspris til det kunden betaler
A2: Handelskalkylen. Arket står med Nordlys' eget materiellpåslag — bytt prosentene når du regner lærebokas eksempel.
A4: 1 · Kalkylen
A5: Innkjøpspris fra leverandøren | B5: 68000 | D5: Fakturaen fra grossisten, uten mva.
A6: + innkjøpskostnader (frakt og forsikring) | B6: 3200
A7: = Inntakskost (= varekostnad) | B7: =B5+B6 -> 71200 | D7: Det varen kostet å få inn i bedriften. Alle prosentpåslag regnes videre herfra.
A8: Påslag for indirekte kostnader | B8: 0 | D8: Nordlys bruker ett samlet påslag på materiell og setter denne til null. Læreboka deler påslaget i to — sett lærebokas prosent inn her.
A9: + indirekte kostnader i kroner | B9: =B7*B8 -> 0
A10: = Selvkost | B10: =B7+B9 -> 71200
A11: Fortjeneste i prosent av selvkost | B11: 0.2 | D11: Nordlys' påslag på materiell som faktureres videre.
A12: + fortjeneste i kroner | B12: =B10*B11 -> 14240
A13: = Pris uten mva. | B13: =B10+B12 -> 85440
A14: Merverdiavgift | B14: 0.25
A15: + merverdiavgift i kroner | B15: =B13*B14 -> 21360
A16: = Pris med mva. | B16: =B13+B15 -> 106800
A17: Antall enheter i partiet | B17: 1
A18: Pris per enhet med mva. | B18: =B16/B17 -> 106800 | D18: Sett antallet i B17 når oppgaven spør om prisen per enhet.
A20: 2 · Avanse og bruttofortjeneste — samme kroner, to prosenter
A21: Avanse i kroner | B21: =B13-B7 -> 14240 | D21: Pris uten mva. minus inntakskost.
A22: Avanse i prosent av inntakskost | B22: =B21/B7 -> 0.2
A23: Bruttofortjeneste i prosent av pris uten mva. | B23: =B21/B13 -> 0.16666667 | D23: Samme kroner, mindre prosent. Nevneren er ulik.
A24: Kalkylefaktor | B24: =(1+B8)*(1+B11) -> 1.2 | D24: Inntakskost ganger denne faktoren gir prisen uten mva. direkte.
A26: 3 · Feilen: å legge de to påslagene sammen
A27: Samlet påslag hvis du legger dem sammen | B27: =B8+B11 -> 0.2
A28: Pris uten mva. med den feilen | B28: =B7*(1+B27) -> 85440
A29: Hvor mye for lavt tilbudet ligger | B29: =B13-B28 -> 0
A30: Andel av fortjenesten som forsvinner | B30: =IF(B12=0,"",B29/B12) -> 0 | D30: Prosentpåslag oppå prosentpåslag virker multiplikativt, ikke additivt.
A32: Kontroll
A33: Gir kalkylefaktoren samme pris som kalkylen? | B33: =IF(ABS(B7*B24-B13)<0.01,"OK — faktor og kalkyle gir samme pris","AVVIK: kalkylefaktoren stemmer ikke med kalkylen") -> OK — faktor og kalkyle gir samme pris
A34: Er bruttofortjenesten lavere enn avansen? | B34: =IF(B21=0,"OK — ingen avanse å sammenlikne",IF(B23<B22,"OK — bruttofortjenesten er lavere enn avansen, som den skal","AVVIK: bruttofortjenesten kan ikke være større enn avansen")) -> OK — bruttofortjenesten er lavere enn avansen, som den skal
A35: Gir feilmetoden en for lav pris? | B35: =IF(B8*B11=0,"OK — bare ett påslag, da er metodene like",IF(B29>0,"OK — å legge påslagene sammen gir for lav pris","AVVIK: feilmetoden skal gi lavere pris enn kalkylen")) -> OK — bare ett påslag, da er metodene like
A37: Prøv dette: sett B8 til lærebokas påslag for indirekte kostnader og B11 til fortjenesteprosenten, og les av B22, B23 og B29. Det er oppgave 2.
A38: Kilde: Økonomistyring for LØM-emnet, avsnitt 5.1 og 5.1.2. Materiellpåslaget er Nordlys Elektro AS' eget.

Sheet Oppdrag
A1: Ett oppdrag: fra kostnad til kundens pris
A2: Sikringsskapbytte hos privatkunde. Endre de gule cellene.
A4: 1 · Forkalkylen — det du gir kunden
A5: Post | B5: Antall | C5: Sats | D5: Kroner | E5: Forklaring
A6: Direkte arbeid | B6: 14 | C6: 640 | D6: =B6*C6 -> 8960 | E6: Antall timer × kostsats per time. Kostsatsen er ikke timeprisen til kunden.
A7: Direkte materiell (inntakskost) | D7: 9800 | E7: Innkjøpspris pluss frakt — det materiellet kostet å få inn.
A8: Andre direkte kostnader | D8: 800 | E8: Kjøring og forbruksmateriell.
A9: = Sum direkte kostnader | D9: =SUM(D6:D8) -> 19560 | E9: Direkte kostnader er alltid variable. Dette er også merkosten.
A10: + indirekte kostnader | D10: 4200 | E10: Oppdragets andel av kontor, husleie, biler og avskrivninger.
A11: = Selvkost | D11: =D9+D10 -> 23760 | E11: Her går jobben i null.
A12: + fortjeneste | C12: 0.12 | D12: =D11*C12 -> 2851.2 | E12: Prosent AV SELVKOST — ikke av de direkte kostnadene.
A13: = Pris uten mva. | D13: =D11+D12 -> 26611.2 | E13: Tilbudet til en næringskunde.
A14: + merverdiavgift | C14: 0.25 | D14: =D13*C14 -> 6652.8
A15: = Pris med mva. | D15: =D13+D14 -> 33264 | E15: Det privatkunden betaler.
A17: 2 · Samme jobb priset etter prislista
A18: Timepris i bruk, uten mva. | B18: =Timepris!B37 -> 890 | E18: Hentet fra Timepris!B37. Endrer du den cellen, endrer denne seg med.
A19: Timer × timepris | D19: =B6*B18 -> 12460
A20: Materiell med påslag | C20: 0.2 | D20: =D7*(1+C20) -> 11760
A21: Andre direkte kostnader viderefakturert | D21: =D8 -> 800
A22: = Pris uten mva. etter prislista | D22: =D19+D20+D21 -> 25020
A23: Forskjell fra selvkostkalkylen | D23: =D22-D13 -> -1591.2 | E23: Prislista og kalkylen gir sjelden nøyaktig samme svar. Er forskjellen stor, er enten timeprisen eller de indirekte kostnadene i kalkylen feil.
A25: 3 · Bidragskalkyle — når prisen er gitt
A26: Merkost (minimumskost) | D26: =D9 -> 19560 | E26: Bare kostnadene som kommer av å ta jobben. De indirekte regnes som faste.
A27: Pris kunden tilbyr, uten mva. | D27: 0 | E27: Skriv inn kundens pris. Står den på 0, brukes prisen fra forkalkylen.
A28: Pris brukt i bidragskalkylen | D28: =IF(D27>0,D27,D13) -> 26611.2
A29: = Dekningsbidrag | D29: =D28-D26 -> 7051.2
A30: Dekningsgrad | D30: =D29/D28 -> 0.26497114
A31: Konklusjon | E31: =IF(D29>0,"Positivt dekningsbidrag — ta jobben HVIS det er ledig kapasitet","Negativt dekningsbidrag — si nei uansett") -> Positivt dekningsbidrag — ta jobben HVIS det er ledig kapasitet
A32: Regelen for pristilbud: bidragsmetoden gjelder ved ledig kapasitet, i lavsesong og for å holde volumet oppe i krisetid. Ikke ellers.
A34: 4 · Etterkalkylen — hva jobben faktisk kostet
A35: Post | B35: Forkalkyle | C35: Etterkalkyle | D35: Avvik i kr | E35: Avvik i prosent
A36: Timer brukt | B36: =B6 -> 14 | C36: 14 | D36: =(C36-B36)*$C$6 -> 0 | E36: =IF(B36=0,"",(C36-B36)/B36) -> 0
A37: Direkte arbeid | B37: =D6 -> 8960 | C37: =C36*$C$6 -> 8960 | D37: =C37-B37 -> 0 | E37: =IF(B37=0,"",(C37-B37)/B37) -> 0
A38: Direkte materiell | B38: =D7 -> 9800 | C38: 9800 | D38: =C38-B38 -> 0 | E38: =IF(B38=0,"",(C38-B38)/B38) -> 0
A39: Andre direkte kostnader | B39: =D8 -> 800 | C39: 800 | D39: =C39-B39 -> 0 | E39: =IF(B39=0,"",(C39-B39)/B39) -> 0
A40: Indirekte kostnader | B40: =D10 -> 4200 | C40: 4200 | D40: =C40-B40 -> 0 | E40: =IF(B40=0,"",(C40-B40)/B40) -> 0
A41: = Selvkost | B41: =D11 -> 23760 | C41: =C37+C38+C39+C40 -> 23760 | D41: =C41-B41 -> 0 | E41: =IF(B41=0,"",(C41-B41)/B41) -> 0
A42: Fortjeneste ved avtalt fastpris | B42: =D12 -> 2851.2 | C42: =$D$13-C41 -> 2851.2 | D42: =C42-B42 -> 0 | E42: Fastpris betyr at timene er din risiko, ikke kundens.
A44: Hvor mange timer tåler jobben? | B44: =(D13-C38-C39-C40)/C6 -> 18.455 | E44: Over dette timetallet er hele fortjenesten borte ved avtalt fastpris.
A45: Ny pris med mva. hvis vi kalkulerer med de faktiske timene | B45: =C41*(1+C12)*(1+C14) -> 33264 | E45: Neste forkalkyle. Sammenlikn med D15.
...

Sheet Faktureringsgrad
A1: Hva faktureringsgraden gjør med timeprisen
A2: Samme kostnader, samme ønskede resultat — bare færre timer å dele på.
A4: Hentes fra arket Timepris
A5: Sum som skal hentes inn på timene | B5: =Timepris!B27 -> 12816000
A6: Antall montører | B6: =Timepris!B5 -> 12
A7: Tilgjengelige timer per montør | B7: =Timepris!B6 -> 1695
A8: Dagens faktureringsgrad | B8: =Timepris!B9 -> 0.7079646
A9: Timeprisen du bruker i dag, uten mva. | B9: =Timepris!B37 -> 890
A11: Faktureringsgrad | B11: Timer per montør | C11: Fakturerte timer | D11: Timepris uten mva. | E11: Endring fra i dag | F11: Hva det betyr
A12: 0.9 | B12: =A12*$B$7 -> 1525.5 | C12: =B12*$B$6 -> 18306 | D12: =$B$5/C12 -> 700.09833 | E12: =D12/$B$9-1 -> -0.21337266 | F12: Urealistisk høyt. Ingen montør kjører aldri og venter aldri.
A13: 0.85 | B13: =A13*$B$7 -> 1440.75 | C13: =B13*$B$6 -> 17289 | D13: =$B$5/C13 -> 741.28058 | E13: =D13/$B$9-1 -> -0.16710047 | F13: Svært godt drevet. Krever ferdig plukket materiell og god planlegging.
A14: 0.8 | B14: =A14*$B$7 -> 1356 | C14: =B14*$B$6 -> 16272 | D14: =$B$5/C14 -> 787.61062 | E14: =D14/$B$9-1 -> -0.11504425 | F14: Godt. Her ligger de beste i bransjen.
A15: 0.75 | B15: =A15*$B$7 -> 1271.25 | C15: =B15*$B$6 -> 15255 | D15: =$B$5/C15 -> 840.11799 | E15: =D15/$B$9-1 -> -0.056047198 | F15: Bra. Et realistisk mål for de fleste.
A16: =$B$8 -> 0.7079646 | B16: =A16*$B$7 -> 1200 | C16: =B16*$B$6 -> 14400 | D16: =$B$5/C16 -> 890 | E16: =D16/$B$9-1 -> 0 | F16: Nordlys i dag.
A17: 0.7 | B17: =A17*$B$7 -> 1186.5 | C17: =B17*$B$6 -> 14238 | D17: =$B$5/C17 -> 900.12642 | E17: =D17/$B$9-1 -> 0.011378003 | F17: Vanlig nivå i en installasjonsbedrift. Scenario A i arket Scenario.
A18: =$B$8-0.05 -> 0.6579646 | B18: =A18*$B$7 -> 1115.25 | C18: =B18*$B$6 -> 13383 | D18: =$B$5/C18 -> 957.63282 | E18: =D18/$B$9-1 -> 0.07599193 | F18: Fem prosentpoeng ned fra Nordlys.
A19: 0.65 | B19: =A19*$B$7 -> 1101.75 | C19: =B19*$B$6 -> 13221 | D19: =$B$5/C19 -> 969.36692 | E19: =D19/$B$9-1 -> 0.08917631 | F19: Fem prosentpoeng under 70. Se hva prisen må gjøre.
A20: 0.6 | B20: =A20*$B$7 -> 1017 | C20: =B20*$B$6 -> 12204 | D20: =$B$5/C20 -> 1050.1475 | E20: =D20/$B$9-1 -> 0.179941 | F20: Her begynner det å svi. Prisen må opp, eller resultatet ryker.
A21: 0.55 | B21: =A21*$B$7 -> 932.25 | C21: =B21*$B$6 -> 11187 | D21: =$B$5/C21 -> 1145.6154 | E21: =D21/$B$9-1 -> 0.28720837 | F21: Nesten halvparten av timene er ubetalt. Ingen pris redder dette.
A23: Les tabellen slik
A24: Kostnadene endrer seg ikke én krone nedover i tabellen. Det eneste som endrer seg, er hvor mange timer regningen kan fordeles på.
A25: Derfor er faktureringsgraden den enkleste knappen å skru på: hever du den, kan du beholde prisen og likevel tjene mer.
A26: Og motsatt: setter du prisen etter et for optimistisk timetall, taper du penger på hver eneste jobb uten å oppdage det før året er omme.
A28: Kontroll
A29: Stemmer raden «Nordlys i dag» med kalkylen? | D29: =IF(ABS(D16-Timepris!B32)<0.01,"OK — raden gir samme timepris som kalkylen i arket Timepris","AVVIK: raden stemmer ikke med kalkylen i arket Timepris") -> OK — raden gir samme timepris som kalkylen i arket Timepris
A30: Stiger prisen når faktureringsgraden faller? | D30: =IF(D12<D21,"OK — lavere faktureringsgrad krever høyere timepris","AVVIK: tabellen skal stige nedover") -> OK — lavere faktureringsgrad krever høyere timepris
A32: Kilde: Økonomistyring for LØM-emnet, kap. 5.2 og formelsamlingen. Tallene er Nordlys Elektro AS sine egne.

Sheet Scenario
A1: Tre scenarioer
A2: Endre de gule cellene og se hva som skjer. Alle tall hentes fra de andre arkene.
A4: Scenario A · faktureringsgraden faller
A5: Kostnadene er de samme. Det eneste som endrer seg, er hvor mange timer regningen kan fordeles på.
B7: Nordlys i dag | C7: Scenario A | D7: Scenario B | E7: Hva raden betyr
A8: Faktureringsgrad | B8: =Timepris!B9 -> 0.7079646 | C8: 0.7 | D8: 0.65 | E8: De gule cellene er scenarioene. Endre dem fritt.
A9: Fakturerte timer i året | B9: =B8*Timepris!$B$10 -> 14400 | C9: =C8*Timepris!$B$10 -> 14238 | D9: =D8*Timepris!$B$10 -> 13221 | E9: Faktureringsgrad × tilgjengelige timer.
A10: Sum som skal hentes inn på timene | B10: =Timepris!$B$27 -> 12816000 | C10: =Timepris!$B$27 -> 12816000 | D10: =Timepris!$B$27 -> 12816000 | E10: Uendret. Verken kostnadene eller kravet til resultat blir mindre.
A11: = Timepris som må til, uten mva. | B11: =B10/B9 -> 890 | C11: =C10/C9 -> 900.12642 | D11: =D10/D9 -> 969.36692 | E11: Dette er svaret: prisen må opp når timene blir færre.
A12: Endring fra timeprisen du bruker | B12: =B11-Timepris!$B$37 -> 0 | C12: =C11-Timepris!$B$37 -> 10.126422 | D12: =D11-Timepris!$B$37 -> 79.366916
A13: Endring i prosent | B13: =B11/Timepris!$B$37-1 -> 0 | C13: =C11/Timepris!$B$37-1 -> 0.011378003 | D13: =D11/Timepris!$B$37-1 -> 0.08917631
A14: Driftsresultat hvis timeprisen står stille | B14: =Timepris!$B$37*B9-Timepris!$B$25 -> 1344000 | C14: =Timepris!$B$37*C9-Timepris!$B$25 -> 1199820 | D14: =Timepris!$B$37*D9-Timepris!$B$25 -> 294690 | E14: Holder du prisen når faktureringsgraden faller, er det resultatet som tar støyten.
A15: Endring i driftsresultat fra i dag | B15: =B14-$B$14 -> 0 | C15: =C14-$B$14 -> -144180 | D15: =D14-$B$14 -> -1049310
A17: Kontroll
A18: Krever lavere faktureringsgrad høyere pris? | B18: =IF(AND(D8<C8,D11>C11),"OK — færre timer krever høyere timepris","AVVIK: sjekk at scenario B har lavere faktureringsgrad enn scenario A") -> OK — færre timer krever høyere timepris
A21: Scenario B · en jobb prises under selvkost
A22: Oppdraget er sikringsskapbyttet fra arket Oppdrag. Kunden får en pris som dekker de direkte kostnadene og halvparten av de indirekte.
A24: Pris kunden får, uten mva. | B24: 21660 | E24: Endre denne og se når dekningsbidraget snur.
A25: Merkost — sum direkte kostnader (arket Oppdrag) | B25: =Oppdrag!D9 -> 19560
A26: Selvkost (arket Oppdrag) | B26: =Oppdrag!D11 -> 23760
A27: = Dekningsbidrag | B27: =B24-B25 -> 2100 | E27: Fortsatt positivt: jobben bidrar til å dekke de faste kostnadene.
A28: Dekningsgrad | B28: =B27/B24 -> 0.096952909
A29: = Resultat på jobben | B29: =B24-B26 -> -2100 | E29: Negativt: jobben dekker ikke sin egen andel av kontor, husleie og biler.
A30: Andel av oppdragets indirekte kostnader som dekkes | B30: =B27/Oppdrag!D10 -> 0.5
A31: Dom | E31: =IF(B27<0,"Negativt dekningsbidrag — si nei uansett",IF(B29<0,"Positivt dekningsbidrag, men under selvkost — forsvarlig BARE ved ledig kapasitet, aldri som normalpris","Dekker selvkost og gir fortjeneste")) -> Positivt dekningsbidrag, men under selvkost — forsvarlig BARE ved ledig kapasitet, aldri som normalpris
A33: Hva om alle jobber prises slik?
A34: Faste kostnader i året (kap. 2) | B34: 3840000 | E34: Administrasjonslønn, avskrivninger og andre faste kostnader.
A35: Slike oppdrag for å dekke de faste kostnadene | B35: =B34/B27 -> 1828.5714
A36: Til normalprisen fra forkalkylen | B36: =B34/(Oppdrag!D13-Oppdrag!D9) -> 544.58816
A37: Kapasitet: oppdrag av denne størrelsen i året | B37: =Timepris!B11/Oppdrag!B6 -> 1028.5714 | E37: Fakturerte timer delt på timene ett slikt oppdrag tar.
A38: Kontroll
A39: Kan underprisen dekke de faste kostnadene? | B39: =IF(B35>B37,"AVVIK: året har ikke nok timer — underprisen kan aldri dekke de faste kostnadene","OK — underprisen kan dekkes innenfor kapasiteten") -> AVVIK: året har ikke nok timer — underprisen kan aldri dekke de faste kostnadene
A40: Her SKAL det stå AVVIK med tallene som ligger inne. Det er hele poenget: prisen er ikke bare lav, den er umulig.
A42: Scenario C · konkurrenten tar en lavere timepris
A43: Oppgave 5 i øvingsheftet. Regn først, drøft etterpå.
A45: Konkurrentens timepris uten mva. | B45: 801
A46: Din timepris i bruk, uten mva. | B46: =Timepris!B37 -> 890
A47: Forskjell per time | B47: =B46-B45 -> 89
A48: Hva det koster å matche prisen, ett år | B48: =B47*Timepris!B11 -> 1281600 | E48: Forskjellen per time ganger alle timene du fakturerer.
A49: Driftsresultat etter at prisen er matchet | B49: =Timepris!B26-B48 -> 62400 | E49: Sammenlikn med ønsket driftsresultat i Timepris!B26.
...
