Workbook

Sheet Enkelt
A1: Fra salg til resultat. Den enkle versjonen
A2: Fyll inn de fire gule cellene. Svaret står i den grønne. Alt annet regner seg selv. Vil du gå dypere, ligger hele modellen i arkene bak.
A4: Det du vet
A5: Hvor mye fakturerte bedriften i året? | B5: 22400000 | C5: Salgsinntekten. Pris ganger antall, for alle jobbene til sammen.
A6: Hvor mye kostet det som følger jobbene? | B6: 17216000 | C6: Variable kostnader. De forsvinner hvis dere sier nei til jobbene.
A7: Hvor mye kostet det som kommer uansett? | B7: 3840000 | C7: Faste kostnader: husleie, forsikring, administrasjon, avskrivninger.
A8: Hvor mange timer fikk kundene regning for? | B8: 14400 | C8: Fakturerte montørtimer for hele bedriften.
A10: Regnestykket
A11: Sum kostnader | B11: =B6+B7 -> 21056000 | C11: Faste pluss variable.
A12: Faste kostnader av alle kostnadene | B12: =B7/B11 -> 0.18237082 | C12: Lavt hos en installatør. Mesteparten følger jobbene.
A13: Dekningsbidrag: salg minus variable | B13: =B5-B6 -> 5184000 | C13: Det jobbene gir til å dekke de faste kostnadene.
A14: Dekningsbidrag i prosent av salget | B14: =B13/B5 -> 0.23142857 | C14: Hvor mye av hver krone som går til de faste og til overskudd.
A15: Faste kostnader per fakturert time | B15: =B7/B8 -> 266.66667 | C15: Dette tallet endrer seg når timene endrer seg.
A17: DRIFTSRESULTAT | B17: =B13-B7 -> 1344000 | C17: Dekningsbidrag minus faste kostnader. Det samme tallet som i regnskapet.
A19: Hva svaret betyr
A20: ="Jobbene gir "&TEXT(ROUND(B13,0),"#,##0")&" kroner til å dekke de faste kostnadene. Når de faste er betalt, er "&TEXT(ROUND(B17,0),"#,##0")&" kroner igjen." -> Jobbene gir 5,184,000 kroner til å dekke de faste kostnadene. Når de faste er betalt, er 1,344,000 kroner igjen.
A22: Prøv selv
A23: 1. Sett fakturerte timer (B8) til 10 000. Hva skjer med de faste kostnadene per time?
A24: 2. Sett de faste kostnadene (B7) 10 prosent høyere. Hvor mye faller driftsresultatet?
A25: 3. Flytt 400 000 kroner fra variable (B6) til faste (B7). Hva skjer med dekningsbidraget og med driftsresultatet?
A27: Tallene er Nordlys Elektro AS sine for 2026 (faktaarket). Kilde: Økonomistyring for LØM-emnet, kap. 2.2.2. Nordlys Elektro AS er en konstruert casebedrift.

Sheet Veiledning
A1: Kostnadsbegreper
A2: LØM Økonomistyring kap. 2 · arbeidsregneark · Fagskolen Oslo, Avdeling Elkraft
A3: Emne: Teknisk kommunikasjon og ledelse for 1ET-klassene · LØM for 2ET, 2EK, 3EK og 4EK
A4: Fargekode
A5: Gul celle med blå skrift | B5: Inndata — dette er tallene du endrer.
A6: Grå eller lyseblå celle, svart skrift | B6: Formel — regner seg selv. Ikke skriv over den.
A7: Mørkeblå rad med hvit skrift | B7: Kolonneoverskrift.
A9: Ark i arbeidsboka
A10: Enkelt | B10: Start her. Fire gule celler, ett svar. Fra salgsinntekt via dekningsbidrag til driftsresultat.
A11: Utgift og kostnad | B11: De tre tallene for det samme materiellet: hva du kjøpte, hva du betalte, hva du brukte opp.
A12: Fast eller variabel | B12: Sorteringen. De sju Nordlys-postene ligger inne, og under dem er det plass til dine egne.
A13: Per enhet | B13: Hovedarket: hva som skjer med faste og variable per enhet når aktiviteten endres. Her ligger den ene cellen du styrer alt fra: B5.
A14: Avskrivning | B14: Lineær metode mot saldometoden på den samme servicebilen.
A15: Lønnspåslag | B15: Hva en ansatt faktisk koster, ikke hva som står på lønnsslippen.
A16: Scenario | B16: Tre spørsmål: hva skjer når aktiviteten faller, hva en kampanjepris gjør med dekningsbidraget, og hvorfor en bedrift med full ordrebok kan gå med underskudd.
A18: Tallene som ligger inne er Nordlys Elektro AS sine egne tall for 2026.
A19: Arket er laget for å brukes på jobben etterpå: bytt ut de gule cellene med dine egne tall.
A20: Merk: arket «Per enhet» forutsetter at de variable kostnadene er proporsjonale med
A21: aktiviteten. Det holder så lenge jobbmiksen er den samme.
A23: Tallene som ligger inne er et eksempel fra en elektrobedrift. Bytt dem ut med dine egne — alle formler følger med.
A24: Arbeidsregneark til LØM · Fagskolen Oslo, Avdeling Elkraft. Regnearket er øvingsstøtte, ikke et regnskapssystem.
A26: Den ene knappen
A27: «Per enhet»!B5 | B27: Fakturerte montørtimer i året | C27: Endrer du denne cellen, følger hele blokken i rad 10 til 16 og midtkolonnen i scenario A med.
A29: Hvilken oppgave bruker hvilket ark
A30: Oppgave i øvingsheftet | B30: Ark | C30: Celler du endrer og leser av
A31: A1 · Ida bestiller kabel | B31: Utgift og kostnad | C31: Les av radene 10 til 12 og summene i rad 13.
A32: A2 · Sorter de tolv kostnadene | B32: Fast eller variabel | C32: Skriv F eller V i kolonne C og se hva som skjer med summene nederst.
A33: A3 · Klasseoppgave: din egen avdeling | B33: Fast eller variabel | C33: Legg dine egne kostnader i de tomme radene 14 til 19, med beløp i kolonne B og F eller V i kolonne C.
A34: 1 · Utgift, utbetaling og kostnad | B34: Utgift og kostnad | C34: Endre B5, B6 og B7, og varekjøp og lager i kolonne B og C. Les av kolonne D, E og F og summene i rad 13. Sett B7 til 0 for deloppgave e).
A35: 2 · Fast eller variabel — og hva det betyr per time | B35: Fast eller variabel, Per enhet | C35: Sorter i «Fast eller variabel». Regn per time i «Per enhet»: endre B5, og les av B10 til B16 og tabellen i rad 20 til 24.
A36: 3 · Direkte, indirekte og proporsjonalitet | B36: Lønnspåslag | C36: Legg brutto månedslønn i B5 og les av samlet lønnskostnad nederst.
A37: 4 · Priselastisitet — og fellen i resonnementet | B37: Scenario | C37: Scenario B: endre B26 til B32, og les av elastisiteten i B37, salgsinntekten i B40, dekningsbidraget i B43 og hva kampanjen måtte solgt i B44 og B45.
A38: 5 · Eksamensnær: full ordrebok, og likevel underskudd | B38: Scenario | C38: Scenario C: endre B56 til B61, og les av B63, B65, B67, B68, B70, B71, B72, B73 og B75. Scenario A viser hva faste kostnader per time gjør når aktiviteten endres.
A40: Kontrollradene
A41: Hvert regneark har en kontrollblokk. Står det OK, henger tallene sammen. Står det AVVIK, farges cellen rød, og teksten sier hva som ikke går opp.
A42: To unntak: kontrollen i scenario B og den første i scenario C skal vise AVVIK med tallene som ligger inne. Der er avviket selve svaret — salgsinntekten stiger mens dekningsbidraget faller, og bedriften ligger under nullpunktet med full ordrebok.
A43: Ett tredje unntak: legger du inn dine egne kostnader i arket «Fast eller variabel», slår kontrollen mot resultatregnskapet ut. Det er meningen — den gjelder Nordlys-tallene slik de står.
A44: Kontroller i arbeidsboka: Utgift og kostnad B16, Utgift og kostnad B17, Fast eller variabel B33, Fast eller variabel B35, Per enhet B29, Per enhet B30, Per enhet B31, Avskrivning B26, Avskrivning B27, Avskrivning B28, Lønnspåslag B21, Lønnspåslag B22, Scenario B20, Scenario B49, Scenario B50, Scenario B78, Scenario B80, Scenario B81
A46: Slik henger kapitlet sammen med resten
A47: Delingen i faste og variable kostnader er den samme delingen timeprisen i kapittel 5 bygger på, og nullpunktet i B15 i arket «Per enhet» er det samme nullpunktet kapittel 8 regner for serviceavdelingen. Skillet mellom kostnad og utbetaling er grunnen til at kapittel 9 har både resultatbudsjett og likviditetsbudsjett.
...

Sheet Utgift og kostnad
A1: Utgift, utbetaling og kostnad
A2: Endre de gule cellene. Alt annet regner seg selv.
A4: 1 · Forutsetninger
A5: Varelager 1. mars (IB) | B5: 1250000 | G5: Verdien av materiellet på hylla ved periodens begynnelse.
A6: Varekjøp i februar | B6: 760000 | G6: Betales i mars, siden kreditten er 30 dager.
A7: Kredittid fra grossisten, dager | B7: 30 | G7: Sett den til 0 og se hva som skjer med kolonne E.
A9: Måned | B9: Varekjøp | C9: Lager UB | D9: Utgift | E9: Utbetaling | F9: Varekostnad | G9: Slik regnes det
A10: Mars | B10: 890000 | C10: 1460000 | D10: =B10 -> 890000 | E10: =IF($B$7=0,B10,$B$6) -> 760000 | F10: =$B$5+B10-C10 -> 680000 | G10: Varekostnad = lager IB + varekjøp − lager UB
A11: April | B11: 640000 | C11: 1380000 | D11: =B11 -> 640000 | E11: =IF($B$7=0,B11,B10) -> 890000 | F11: =C10+B11-C11 -> 720000 | G11: Varekostnad = lager IB + varekjøp − lager UB
A12: Mai | B12: 520000 | C12: 1100000 | D12: =B12 -> 520000 | E12: =IF($B$7=0,B12,B11) -> 640000 | F12: =C11+B12-C12 -> 800000 | G12: Varekostnad = lager IB + varekjøp − lager UB
A13: Sum kvartalet | D13: =SUM(D10:D12) -> 2050000 | E13: =SUM(E10:E12) -> 2290000 | F13: =SUM(F10:F12) -> 2200000 | G13: Tre helt ulike tall for det samme materiellet.
A15: Kontroll
A16: Går varekostnaden opp over hele kvartalet? | B16: =IF(ABS($B$5+D13-C12-F13)<1,"OK — lager IB pluss alle kjøp minus lager UB er lik summen av varekostnadene","AVVIK: sjekk lagertallene i kolonne C") -> OK — lager IB pluss alle kjøp minus lager UB er lik summen av varekostnadene
A17: Er de tre summene tre ulike tall? | B17: =IF(AND(D13<>E13,E13<>F13,D13<>F13),"OK — utgift, utbetaling og varekostnad er tre ulike tall. Det er hele poenget i kapitlet","AVVIK: to av summene er like — da forsvinner poenget") -> OK — utgift, utbetaling og varekostnad er tre ulike tall. Det er hele poenget i kapitlet
A19: Dette er hele poenget i kapittel 2
A20: Utgiften forteller hva du har forpliktet deg til. Den oppstår når du bestiller.
A21: Utbetalingen forteller hva som har forlatt kontoen. Den avgjør om det er penger til lønn den 15.
A22: Kostnaden forteller hva du har brukt opp. Den avgjør om måneden gikk med overskudd.
A23: Prøv dette: sett kredittiden i B7 til 0. Da — og bare da — er utgift og utbetaling det samme. Legg merke til at varekostnaden ikke rører seg.
A24: Kilde: Økonomistyring for LØM-emnet kap. 2.2.1. Tallene er Nordlys Elektro AS, mars til mai 2026, med Polarlys Elektro Grossist AS som leverandør.

Sheet Fast eller variabel
A1: Fast eller variabel?
A2: Skriv F eller V i kolonne C. Legg inn dine egne kostnader nederst.
A4: Testen: forsvinner kostnaden hvis dere sier nei til jobben? Gjør den det, er den variabel (V). Løper den videre uansett, er den fast (F).
A6: Kostnad | B6: Beløp per år | C6: F/V | D6: Hvorfor
A7: Varekostnad materiell | B7: 7990000 | C7: V | D7: Kabel, skap og kursutstyr som går rett inn i den enkelte jobben.
A8: Varekostnad innleide montører | B8: 400000 | C8: V | D8: Innleide montører i topper, bestilt per prosjekt.
A9: Produksjonslønn (montører og lærlinger) | B9: 8440000 | C9: V | D9: Timen som går til en konkret jobb. Læreboka skiller den fra administrasjonslønn.
A10: Drivstoff og forbruksmateriell på oppdrag | B10: 386000 | C10: V | D10: Følger kjøringen til og fra oppdragene.
A11: Administrasjonslønn | B11: 2220000 | C11: F | D11: Daglig leder, kalkulatør, driftsleder og kontor. Løper i juli også.
A12: Avskrivninger | B12: 620000 | C12: F | D12: Følger avskrivningsplanen og tida, ikke kilometerne.
A13: Husleie, forsikring, IT, telefon, regnskap og kurs | B13: 1000000 | C13: F | D13: Kapasitetskostnader — de følger av hvor stor bedrift dere har valgt å være.
B14: 0 | D14: Seks tomme rader: skriv inn kostnader fra din egen arbeidsplass, beløpet per år, og F eller V.
B15: 0
B16: 0
B17: 0
B18: 0
B19: 0
A21: Sum faste kostnader (FTK) | B21: =SUMIF($C$7:$C$19,"F",$B$7:$B$19) -> 3840000 | D21: Dette beløpet må dekkes før én krone blir til overskudd.
A22: Sum variable kostnader (VTK) | B22: =SUMIF($C$7:$C$19,"V",$B$7:$B$19) -> 17216000 | D22: Dette forsvinner hvis dere ikke tar jobbene.
A23: Sum kostnader (TK = FTK + VTK) | B23: =B21+B22 -> 21056000
A24: Faste kostnader i prosent av totalen | B24: =IF(B23=0,0,B21/B23) -> 0.18237082 | D24: En installatør ligger typisk lavt her — mesteparten av kostnadene følger jobbene.
A26: Salgsinntekt for året | B26: 22400000
A27: = Dekningsbidrag | B27: =B26-B22 -> 5184000 | D27: Salgsinntekt minus variable kostnader.
A28: Dekningsgrad | B28: =IF(B26=0,0,B27/B26) -> 0.23142857
A29: = Driftsresultat | B29: =B27-B21 -> 1344000 | D29: Dekningsbidrag minus faste kostnader.
A31: Kontroll
A32: Sum driftskostnader i resultatregnskapet 2026 | B32: 21056000
A33: Går delingen opp mot resultatregnskapet? | B33: =IF(ABS(B23-B32)<1,"OK — faste pluss variable er lik sum driftskostnader i resultatregnskapet","AVVIK: delingen går ikke opp mot resultatregnskapet — det er riktig så snart du har lagt inn dine egne kostnader") -> OK — faste pluss variable er lik sum driftskostnader i resultatregnskapet
A34: Legger du inn dine egne kostnader i de tomme radene, vil denne slå ut. Det er meningen: kontrollen gjelder Nordlys-tallene slik de står.
A35: Går dekningsbidraget minus faste kostnader opp mot driftsresultatet? | B35: =IF(ABS(B27-B21-B29)<1,"OK — dekningsbidrag minus faste kostnader er driftsresultatet. Det er sammenhengen kapittel 8 bygger videre på","AVVIK: regnestykket henger ikke sammen") -> OK — dekningsbidrag minus faste kostnader er driftsresultatet. Det er sammenhengen kapittel 8 bygger videre på
A37: Prøv dette: sett F på en av de variable postene og se hva som skjer med prosenten — og med driftsresultatet. Sorteringen er ikke en formalitet; den avgjør hele kalkylen i kapittel 5.
A38: Kilde: Økonomistyring for LØM-emnet kap. 2.2.2. Tallene er Nordlys Elektro AS 2026.

Sheet Per enhet
A1: Hva skjer per enhet når aktiviteten endres?
A2: Hovedarket i kapittel 2. Endre de gule cellene og se på kolonne D og E.
A4: 1 · Årets tall
A5: FAKTURERTE MONTØRTIMER — den ene knappen | B5: 14400 | D5: Dette er cellen du endrer. Aktivitetsmålet i en elektrobedrift.
A6: Salgsinntekt | B6: 22400000
A7: Variable totale kostnader (VTK) | B7: 17216000
A8: Faste totale kostnader (FTK) | B8: 3840000
A10: Inntekt per fakturert time | B10: =B6/B5 -> 1555.5556
A11: Variable kostnader per time (VEK) | B11: =B7/B5 -> 1195.5556
A12: = Dekningsbidrag per time (DB) | B12: =B10-B11 -> 360 | D12: Dette tallet står stille når aktiviteten endres. Det er derfor det er nyttig.
A13: Faste kostnader per time | B13: =B8/B5 -> 266.66667 | D13: Dette tallet endrer seg hele tiden. Det er derfor det er farlig å styre etter.
A14: = Igjen per time | B14: =B12-B13 -> 93.333333
A15: Nullpunkt i fakturerte timer | B15: =B8/B12 -> 10666.667 | D15: Faste kostnader delt på dekningsbidrag per time. Under dette taper bedriften penger.
A16: Margin: timer over nullpunktet | B16: =B5-B15 -> 3733.3333
A18: 2 · Samme kostnader, ulikt aktivitetsnivå
A19: Fakturerte timer | B19: Faste totalt | C19: Faste per enhet | D19: Variable per enhet | E19: Kostnad per enhet | F19: Salgsinntekt | G19: Sum kostnader | H19: Driftsresultat
A20: 10000 | B20: =$B$8 -> 3840000 | C20: =$B$8/A20 -> 384 | D20: =$B$11 -> 1195.5556 | E20: =C20+D20 -> 1579.5556 | F20: =$B$10*A20 -> 15555556 | G20: =$B$8+$B$11*A20 -> 15795556 | H20: =F20-G20 -> -240000
A21: 12000 | B21: =$B$8 -> 3840000 | C21: =$B$8/A21 -> 320 | D21: =$B$11 -> 1195.5556 | E21: =C21+D21 -> 1515.5556 | F21: =$B$10*A21 -> 18666667 | G21: =$B$8+$B$11*A21 -> 18186667 | H21: =F21-G21 -> 480000
A22: 14400 | B22: =$B$8 -> 3840000 | C22: =$B$8/A22 -> 266.66667 | D22: =$B$11 -> 1195.5556 | E22: =C22+D22 -> 1462.2222 | F22: =$B$10*A22 -> 22400000 | G22: =$B$8+$B$11*A22 -> 21056000 | H22: =F22-G22 -> 1344000
A23: 16000 | B23: =$B$8 -> 3840000 | C23: =$B$8/A23 -> 240 | D23: =$B$11 -> 1195.5556 | E23: =C23+D23 -> 1435.5556 | F23: =$B$10*A23 -> 24888889 | G23: =$B$8+$B$11*A23 -> 22968889 | H23: =F23-G23 -> 1920000
A24: 18000 | B24: =$B$8 -> 3840000 | C24: =$B$8/A24 -> 213.33333 | D24: =$B$11 -> 1195.5556 | E24: =C24+D24 -> 1408.8889 | F24: =$B$10*A24 -> 28000000 | G24: =$B$8+$B$11*A24 -> 25360000 | H24: =F24-G24 -> 2640000
A26: Legg merke til to ting: kolonne C faller når timene stiger, mens kolonne D står bom stille. De faste kostnadene har ikke endret seg med en eneste krone — det er bare antallet timer de fordeles på som er ulikt.
A28: Kontroll
A29: Faller faste kostnader per enhet når aktiviteten stiger? | B29: =IF(C20>C24,"OK — faste per enhet faller når aktiviteten stiger. Det er hele figuren i læreboka","AVVIK: sjekk at timene i kolonne A stiger nedover") -> OK — faste per enhet faller når aktiviteten stiger. Det er hele figuren i læreboka
A30: Står variable kostnader per enhet stille? | B30: =IF(ABS(D20-D24)<0.01,"OK — variable per enhet er den samme på alle nivåene. Arket forutsetter proporsjonale variable kostnader","AVVIK: de variable per enhet endrer seg — da er de ikke proporsjonale") -> OK — variable per enhet er den samme på alle nivåene. Arket forutsetter proporsjonale variable kostnader
A31: Stemmer nullpunktet med tabellen? | B31: =IF(AND(H20<0,H24>0),"OK — det laveste nivået gir underskudd og det høyeste overskudd. Nullpunktet ligger mellom dem","AVVIK: nullpunktet ligger utenfor tabellen — legg inn et lavere eller høyere aktivitetsnivå i kolonne A") -> OK — det laveste nivået gir underskudd og det høyeste overskudd. Nullpunktet ligger mellom dem
A33: Prøv dette: sett fakturerte timer i B5 ned til nullpunktet i B15. Da skal «igjen per time» i B14 bli null.
A34: Merk: arket forutsetter at de variable kostnadene er proporsjonale med aktiviteten. Det holder så lenge jobbmiksen er den samme. Følger materiellet jobben og ikke timen, blir det en forenkling — en ærlig en, men en forenkling.
A35: Kilde: Økonomistyring for LØM-emnet kap. 2.2.2 og figurene 2.2 til 2.5. Tallene er Nordlys Elektro AS 2026.

Sheet Avskrivning
A1: Avskrivning: lineær metode mot saldometoden
A2: Samme servicebil, to metoder. Endre de gule cellene.
A4: 1 · Bilen
A5: Anskaffelseskost | B5: 450000
A6: Økonomisk levetid, år | B6: 5
A7: Antatt restverdi etter levetiden | B7: 100000 | F7: Salgssummen du regner med å få når bilen er utrangert.
A8: Saldosats, varebil | B8: 0.24 | F8: Skattemessig sats. Kilde: skatteetaten.no, saldogruppe for varebiler.
A10: 2 · Lineær metode
A11: Årlig avskrivning uten restverdi | B11: =B5/B6 -> 90000 | F11: Samme beløp hvert år. Bokført verdi blir null når levetiden er ute.
A12: Årlig avskrivning med restverdi | B12: =(B5-B7)/B6 -> 70000 | F12: Restverdi gir lavere årlig avskrivning — du avskriver bare det du faktisk bruker opp.
A13: Avskrivningssats, lineært | B13: =1/B6 -> 0.2
A15: 3 · Avskrivningsplan
A16: År | B16: Lineært, avskrivning | C16: Lineært, bokført verdi | D16: Saldo, avskrivning | E16: Saldo, bokført verdi
A17: År 1 | B17: =IF(1<=$B$6,$B$11,0) -> 90000 | C17: =MAX($B$5-$B$11*MIN(1,$B$6),0) -> 360000 | D17: =$B$5*$B$8 -> 108000 | E17: =$B$5-D17 -> 342000
A18: År 2 | B18: =IF(2<=$B$6,$B$11,0) -> 90000 | C18: =MAX($B$5-$B$11*MIN(2,$B$6),0) -> 270000 | D18: =E17*$B$8 -> 82080 | E18: =E17-D18 -> 259920
A19: År 3 | B19: =IF(3<=$B$6,$B$11,0) -> 90000 | C19: =MAX($B$5-$B$11*MIN(3,$B$6),0) -> 180000 | D19: =E18*$B$8 -> 62380.8 | E19: =E18-D19 -> 197539.2
A20: År 4 | B20: =IF(4<=$B$6,$B$11,0) -> 90000 | C20: =MAX($B$5-$B$11*MIN(4,$B$6),0) -> 90000 | D20: =E19*$B$8 -> 47409.408 | E20: =E19-D20 -> 150129.79
A21: År 5 | B21: =IF(5<=$B$6,$B$11,0) -> 90000 | C21: =MAX($B$5-$B$11*MIN(5,$B$6),0) -> 0 | D21: =E20*$B$8 -> 36031.15 | E21: =E20-D21 -> 114098.64
A22: År 6 | B22: =IF(6<=$B$6,$B$11,0) -> 0 | C22: =MAX($B$5-$B$11*MIN(6,$B$6),0) -> 0 | D22: =E21*$B$8 -> 27383.674 | E22: =E21-D22 -> 86714.968
A23: År 7 | B23: =IF(7<=$B$6,$B$11,0) -> 0 | C23: =MAX($B$5-$B$11*MIN(7,$B$6),0) -> 0 | D23: =E22*$B$8 -> 20811.592 | E23: =E22-D23 -> 65903.376
A25: Kontroll
A26: Gir saldometoden høyere avskrivning det første året? | B26: =IF(D17>B17,"OK — saldometoden avskriver mest i starten og minst mot slutten. Det er den store forskjellen mellom metodene","AVVIK: sjekk saldosatsen i B8 mot levetiden i B6") -> OK — saldometoden avskriver mest i starten og minst mot slutten. Det er den store forskjellen mellom metodene
A27: Kommer saldometoden noen gang ned i null? | B27: =IF(E23>0,"OK — saldometoden bringer aldri bokført verdi helt ned i null. Den avskriver en prosent av restverdien hvert år","AVVIK: saldosatsen kan ikke være 100 prosent eller mer") -> OK — saldometoden bringer aldri bokført verdi helt ned i null. Den avskriver en prosent av restverdien hvert år
A28: Gir restverdi lavere årlig lineær avskrivning? | B28: =IF(B12<=B11,"OK — restverdi gir lavere årlig avskrivning","AVVIK: restverdien i B7 kan ikke være negativ") -> OK — restverdi gir lavere årlig avskrivning
A30: Merk: avskrivning er ikke en utbetaling. Pengene forsvant da bilen ble kjøpt — kolonnene fordeler bare kostnaden over årene bilen brukes. Derfor er avskrivningen en fast kostnad: den følger tida, ikke kilometerne.
A31: Kilde: Økonomistyring for LØM-emnet kap. 2.4.3. Saldosats: skatteetaten.no. Bilen er servicebilen Nordlys kjøpte i 2026.

Sheet Lønnspåslag
A1: Hva koster en ansatt?
A2: Ikke det som står på lønnsslippen. Endre brutto månedslønn i den gule cellen.
A4: 1 · Utgangspunktet
A5: Brutto månedslønn | B5: 40000 | D5: Det som står på lønnsslippen, før skatt.
A7: 2 · Sosiale kostnader (Tabell 2.4)
A8: Post | B8: Prosent av brutto lønn | C8: Kroner
A9: Feriepenger, inkludert arbeidsgiveravgift | B9: 0.137 | C9: =$B$5*B9 -> 5480
A10: Arbeidsgiveravgift på lønn | B10: 0.141 | C10: =$B$5*B10 -> 5640
A11: Pensjonspremie | B11: 0.08 | C11: =$B$5*B11 -> 3200
A12: Arbeidsgiveravgift på pensjon | B12: 0.011 | C12: =$B$5*B12 -> 440
A13: Lønn for bevegelige helligdager, høytidsdager m.m. | B13: 0.045 | C13: =$B$5*B13 -> 1800
A14: Premie til yrkesskadetrygd | B14: 0.004 | C14: =$B$5*B14 -> 160
A15: Sykepenger i arbeidsgiverperioden | B15: 0.05 | C15: =$B$5*B15 -> 2000
A16: = Sum sosiale kostnader | B16: =SUM(B9:B15) -> 0.468 | C16: =SUM(C9:C15) -> 18720
A17: = Samlet lønnskostnad per måned | B17: =1+B16 -> 1.468 | C17: =B5+C16 -> 58720 | D17: Dette er tallet som skal inn i kalkylen — ikke månedslønna.
A18: Samlet lønnskostnad per år | C18: =C17*12 -> 704640
A20: Kontroll
A21: Stemmer summen med Tabell 2.4? | B21: =IF(ABS(B16-0.468)<0.0001,"OK — de sju postene summerer til 46,8 prosent, som i Tabell 2.4","AVVIK: summen avviker fra Tabell 2.4. Det er riktig hvis du har lagt inn dine egne satser") -> OK — de sju postene summerer til 46,8 prosent, som i Tabell 2.4
A22: Er samlet lønnskostnad høyere enn brutto lønn? | B22: =IF(C17>B5,"OK — en ansatt koster mer enn månedslønna. Det er derfor timeprisen aldri kan settes lik timelønna","AVVIK: påslagene kan ikke være negative") -> OK — en ansatt koster mer enn månedslønna. Det er derfor timeprisen aldri kan settes lik timelønna
A24: Tallene i Tabell 2.4 varierer mellom bedrifter og bransjer og tjener som illustrasjon, men størrelsesordenen er reell. Legg inn din egen bedrifts satser i kolonne B, så følger kronene med.
A25: Kilde: Tabell 2.4, Hjertnes/Skorpen, Økonomistyring for LØM-emnet, kap. 2.

Sheet Scenario
A1: Tre scenarioer
A2: Endre de gule cellene og se hva som skjer. Alle tall hentes fra de andre arkene.
A4: Scenario A · aktivitetsnivået endrer seg
A5: Kostnadene er de samme. Det eneste som endrer seg, er hvor mange timer som faktureres.
B7: Lavt nivå | C7: Dagens nivå | D7: Høyt nivå | E7: Hva raden betyr
A8: Fakturerte montørtimer | B8: 10000 | C8: ='Per enhet'!B5 -> 14400 | D8: 16000 | E8: Midtkolonnen henter fra «Per enhet»!B5. De to gule kan du endre fritt.
A9: Faste totale kostnader | B9: ='Per enhet'!$B$8 -> 3840000 | C9: ='Per enhet'!$B$8 -> 3840000 | D9: ='Per enhet'!$B$8 -> 3840000 | E9: Uendret på alle tre nivåene. Det er nettopp derfor de heter faste.
A10: Faste kostnader per time | B10: =B9/B8 -> 384 | C10: =C9/C8 -> 266.66667 | D10: =D9/D8 -> 240 | E10: Her skjer det som er hele poenget: tallet faller når timene stiger.
A11: Variable kostnader per time | B11: ='Per enhet'!$B$11 -> 1195.5556 | C11: ='Per enhet'!$B$11 -> 1195.5556 | D11: ='Per enhet'!$B$11 -> 1195.5556 | E11: Står bom stille.
A12: Inntekt per time | B12: ='Per enhet'!$B$10 -> 1555.5556 | C12: ='Per enhet'!$B$10 -> 1555.5556 | D12: ='Per enhet'!$B$10 -> 1555.5556
A13: = Dekningsbidrag per time | B13: =B12-B11 -> 360 | C13: =C12-C11 -> 360 | D13: =D12-D11 -> 360
A14: Salgsinntekt | B14: =B12*B8 -> 15555556 | C14: =C12*C8 -> 22400000 | D14: =D12*D8 -> 24888889
A15: Sum kostnader | B15: =B9+B11*B8 -> 15795556 | C15: =C9+C11*C8 -> 21056000 | D15: =D9+D11*D8 -> 22968889
A16: = Driftsresultat | B16: =B14-B15 -> -240000 | C16: =C14-C15 -> 1344000 | D16: =D14-D15 -> 1920000 | E16: Legg merke til hvor fort resultatet snur når timene faller.
A17: Nullpunkt i timer | B17: =B9/B13 -> 10666.667 | C17: =C9/C13 -> 10666.667 | D17: =D9/D13 -> 10666.667 | E17: Det samme tallet i alle tre kolonnene — nullpunktet flytter seg ikke når aktiviteten endres.
A19: Kontroll
A20: Faller faste per time når timene stiger? | B20: =IF(AND(B10>C10,C10>D10),"OK — faste kostnader per time faller når aktiviteten stiger, mens dekningsbidraget per time står stille","AVVIK: sjekk at B8 er lavere enn C8 og C8 lavere enn D8") -> OK — faste kostnader per time faller når aktiviteten stiger, mens dekningsbidraget per time står stille
A23: Scenario B · prisen settes ned på et elastisk produkt
A24: Kampanjen på ladepunkter, oppgave 4 i øvingsheftet. Regn først, drøft etterpå.
A26: Pris før, uten mva. | B26: 8830
A27: Antall solgt før | B27: 180
A28: Kampanjepris, uten mva. | B28: 8400
A29: Antall solgt etter, anslag | B29: 215
A30: Materiell per enhet | B30: 6500
A31: Montørtimer per enhet | B31: 2
A32: Lønnskostnad per montørtime | B32: 640
A33: = Variable kostnader per enhet | B33: =B30+B31*B32 -> 7780
A35: Endring i mengde | B35: =(B29-B27)/B27 -> 0.19444444
A36: Endring i pris | B36: =(B28-B26)/B26 -> -0.048697622
A37: = Elastisitetskoeffisient (Ep) | B37: =B35/B36 -> -3.9928941 | E37: Tallverdien over 1: elastisk. Under 1: uelastisk. Fortegnet er alltid negativt.
A38: Salgsinntekt før | B38: =B26*B27 -> 1589400
A39: Salgsinntekt etter | B39: =B28*B29 -> 1806000
A40: = Endring i salgsinntekt | B40: =B39-B38 -> 216600 | E40: Positivt: kampanjen gir mer omsetning, akkurat som teorien sier.
A41: Dekningsbidrag før | B41: =(B26-B33)*B27 -> 189000
A42: Dekningsbidrag etter | B42: =(B28-B33)*B29 -> 133300
A43: = Endring i dekningsbidrag | B43: =B42-B41 -> -55700 | E43: Negativt: kampanjen gir mindre til å dekke de faste kostnadene. Det er hele fellen.
A44: Antall som måtte selges for å holde dekningsbidraget | B44: =B41/(B28-B33) -> 304.83871
A45: Nødvendig økning i prosent | B45: =B44/B27-1 -> 0.69354839
A46: Ekstra montørtimer kampanjen krever | B46: =(B29-B27)*B31 -> 70 | E46: Timer som da ikke kan brukes på andre oppdrag.
A48: Kontroll
...
