Workbook

Sheet Veiledning
A1: Markedsplanen i tall
A2: LØM Markedsføring kap. 10 · arbeidsregneark · Fagskolen Oslo, Avdeling Elkraft
A3: Emne: Teknisk kommunikasjon og ledelse for 1ET-klassene · LØM for 2ET, 2EK, 3EK og 4EK
A4: Fargekode
A5: Gul celle med blå skrift | B5: Inndata — dette er tallene du endrer.
A6: Grå eller lyseblå celle, svart skrift | B6: Formel — regner seg selv. Ikke skriv over den.
A7: Mørkeblå rad med hvit skrift | B7: Kolonneoverskrift.
A9: Ark i arbeidsboka
A10: Målene | B10: Målene fra kapittel 3, omregnet til omsetning, dekningsbidrag og montørtimer.
A11: Handlingsplanen | B11: De ni tiltakene i vårkampanjen, med budsjett regnet av timer og utlegg — og sumlinja lærebokas mal mangler.
A12: Bærer den seg | B12: DET VIKTIGSTE ARKET. Hva planen må gi i økt omsetning for å bære seg, uttrykt både i kroner og i antall anlegg.
A13: Scenario | B13: Tre spørsmål: hva om kampanjen bare treffer delvis, hva om styret kutter halve budsjettet, og hva om timene sprekker.
A14: Din egen plan | B14: Samme oppsett, tomt. Lag handlingsplanen for din egen avdeling.
A16: Tallene som ligger inne er Nordlys Elektro AS sine egne.
A17: Dette arket binder markedsføringssøylen sammen: målene fra kapittel 3, tiltakene fra kapittel 9, og spørsmålet kapittel 10 ender i.
A19: Tallene som ligger inne er et eksempel fra en elektrobedrift. Bytt dem ut med dine egne — alle formler følger med.
A20: Arbeidsregneark til LØM · Fagskolen Oslo, Avdeling Elkraft. Regnearket er øvingsstøtte, ikke et regnskapssystem.
A22: De tre tallene styret skal ha med seg ut av møtet
A23: Hva planen skal gi | B23: Ekstra dekningsbidrag i 2027 hvis begge delmålene nås
A24: Hva planen koster | B24: Vårkampanjen, i egne timer og utlegg
A25: Hva den må gi for å bære seg | B25: Økt omsetning i avdelingen — under dette er kampanjen et tap
A26: Bærer den seg!B12 | B26: Det siste tallet | C26: Økt omsetning som må til for at planen skal bære seg. Dette er tallet du avslutter framlegget med — det gjør spørsmålet om markedsføring konkret i stedet for prinsipielt.
A28: Hvilken oppgave bruker hvilket ark
A29: Oppgave i øvingsheftet | B29: Ark | C29: Celler du endrer og leser av
A30: A1 · Er kampanjen verdt det den koster? | B30: Bærer den seg | C30: Les av B5, B6 og B7. Nullpunktet står i B12 og B13.
A31: A2 · Klasseoppgave: skriv handlingsplanen | B31: Din egen plan | C31: Legg inn timekostnader i C4 og E4, og fyll ut rad 7 til 14. Summen kommer i F15, og nullpunktet i F21.
A32: 2 · Handlingsplanen og summen læreboka ikke oppgir | B32: Handlingsplanen | C32: Endre C7 til E15. Les av budsjettet i kolonne F, summen i F16, timeandelen i F19 og sammenlikningen med lærebokas tabell 10.1 i rad 24 til 28.
A33: 3 · Gjennomføring og evaluering | B33: Scenario | C33: Scenario A: endre måloppnåelsen i kolonne A og les av nettoen i kolonne D. Scenario C: sett timesprekken og les av det nye nullpunktet.
A34: 4 · Skriv handlingsplanen for din egen avdeling | B34: Din egen plan | C34: Hele arket. Kravene står nederst: navngitt ansvarlig, budsjett regnet av timer, internt tiltak før eksternt, og evaluering midt i perioden.
A35: 5 · Eksamensnær: ti minutter for styret | B35: Bærer den seg og Scenario | C35: De tre tallene står i «Bærer den seg» B5, B6 og B12. Scenario B er innvendingen styret kommer med.
A37: Kontrollradene
A38: Hvert ark har en kontrollblokk nederst. Står det OK, henger tallene sammen. Står det AVVIK, farges cellen rød, og teksten sier hva som ikke går opp.
A39: To unntak: kontrollen på om kuttet er lønnsomt i scenario B skal vise AVVIK med anslagene som ligger inne — det er selve svaret til styret — og kontrollen i «Din egen plan» står på AVVIK til du har fylt inn dine egne tall.
A40: Kontroller i arbeidsboka: Målene C20, Målene C21, Målene C22, Handlingsplanen C32, Handlingsplanen C33, Handlingsplanen C34, Handlingsplanen C35, Bærer den seg C29, Bærer den seg C30, Bærer den seg C31, Bærer den seg C32, Scenario C17, Scenario C18, Scenario C34, Scenario C35, Scenario C51, Scenario C52, Din egen plan C24, Din egen plan C26
A42: Kilder
A43: Hjertnes, Frode: Markedsføring, organisasjon og ledelse for LØM-emnet, 4. utgave, kapittel 10 «Markedsplanen — et sammendrag», avsnitt 10.1 til 10.7, med tabell 10.1.
A44: AVVIK: tabell 10.1 lister ti budsjettposter, men oppgir ingen sum. Summen er etterregnet til 357 000 kroner; se avviksregisteret for pensumet, oppslag 39.
A45: Volumer, priser, dekningsbidrag og mål er de samme som i Markedsføring kapittel 3. Timekostnadene er utledet av bedriftens egne lønns- og kalkyletall fra Økonomistyring kapittel 2 og 5. Bransjetall: NHO Elektro, Lønnsomhetsrapport 2025, gjengitt i Elektro 24-7 19.08.2026 (hentet 10.09.2026). De 809 er bedriftene i datagrunnlaget, ikke bransjen. NHO Elektro oppgir ikke svarprosent.
A46: Nordlys Elektro AS er en konstruert casebedrift.

Sheet Målene
A1: Hva markedsplanen skal gi
A2: Målene fra kapittel 3, omregnet til omsetning, dekningsbidrag og montørtimer.
A4: 1 · Prisene og dekningsbidragene
A5: Solcelleanlegg: pris uten mva. | B5: 51360 | C5: Dekningsbidrag | D5: 4400 | F5: Fra Økonomistyring kapittel 7. De samme tallene som i Markedsføring kapittel 3 og 6.
A6: Ladepunkt: pris uten mva. | B6: 8830 | C6: Dekningsbidrag | D6: 1050
A7: Montørtimer per solcelleanlegg | B7: 14 | C7: Per ladepunkt | D7: 2
A9: 2 · Volumene: 2026 mot målet for 2027
B10: 2026 | C10: Mål 2027 | D10: Endring | E10: Endring i prosent | F10: Hva raden betyr
A11: Solcelleanlegg | B11: 34 | C11: 42 | D11: =C11-B11 | E11: =C11/B11-1 | F11: Hovedmålet er tjue prosent vekst i begge produktene.
A12: Ladepunkt | B12: 180 | C12: 215 | D12: =C12-B12 | E12: =C12/B12-1
A14: = Omsetning i avdelingen | B14: =B11*$B$5+B12*$B$6 | C14: =C11*$B$5+C12*$B$6 | D14: =C14-B14 | E14: =C14/B14-1 | F14: Dette er beløpet kampanjen skal skape.
A15: = Dekningsbidrag | B15: =B11*$D$5+B12*$D$6 | C15: =C11*$D$5+C12*$D$6 | D15: =C15-B15 | E15: =C15/B15-1 | F15: Og dette er beløpet kampanjen skal måles mot.
A16: Dekningsgrad | B16: =B15/B14 | C16: =C15/C14 | D16: =D15/D14 | F16: Kolonne D er den marginale dekningsgraden: hvor mye av hver ny omsetningskrone som blir dekningsbidrag.
A17: = Montørtimer | B17: =B11*$B$7+B12*$D$7 | C17: =C11*$B$7+C12*$D$7 | D17: =C17-B17 | E17: =C17/B17-1 | F17: Kapasiteten planen krever. Kampanjen koster timer; leveransen koster flere.
A19: Kontroll
A20: Vokser begge produktene? | C20: =IF(AND(D11>0,D12>0),"OK — begge produktene har et mål over fjorårets volum","AVVIK: et vekstmål der volumet ikke vokser, er ikke et vekstmål")
A21: Ligger den marginale dekningsgraden nær avdelingens egen? | C21: =IF(ABS(D16-B16)<0.02,"OK — veksten kommer i samme produktmiks som i dag","AVVIK: den marginale dekningsgraden avviker fra dagens. Da endrer veksten produktmiksen, og det bør sies")
A22: Er timene innenfor det avdelingen kan levere? | C22: =IF(D17>0,"OK — målet krever flere montørtimer, og de må hentes et sted. Se arket Scenario","AVVIK: målet krever ikke flere timer — kontroller volumene")
A24: Prøv dette: sett målet for ladepunkt i C12 til 300. Se hva som skjer med montørtimene i D17 — og spør deg om avdelingen har dem.
A25: Kilde: Hjertnes, Markedsføring, organisasjon og ledelse for LØM-emnet, 4. utg., kap. 10.3 om markedsmål. Volumer, priser og dekningsbidrag er Nordlys Elektro AS sine egne, fra Markedsføring kapittel 3 og Økonomistyring kapittel 7.

Sheet Handlingsplanen
A1: Handlingsplanen: hva tiltakene koster
A2: Hver post regnes av timer og utlegg. Ingen budsjettsum er skrevet inn.
A4: Timekostnader | B4: Administrasjonstime | C4: 327.43 | D4: Montørtime | E4: 640 | H4: Utledet av bedriftens egne lønnstall, Økonomistyring kapittel 2 og 5.
A6: Uke | B6: Aktivitet | C6: Adm.timer | D6: Montørtimer | E6: Utlegg | F6: Budsjett | G6: Ansvarlig | H6: Det tiltaket skal føre til
A7: 3 | B7: Idémyldring i ledermøtet: hvilke borettslag skal kampanjen treffe? | C7: 6 | D7: 0 | E7: 0 | F7: =C7*$C$4+D7*$E$4+E7 | G7: Kari Nordlund (KN) | H7: Hovedmål: minst én signert rammeavtale om lading innen 30.06.2027
A8: 4 | B8: Kartlegging: alle borettslag i bydelen med over 20 leiligheter og uten ladeanlegg | C8: 10 | D8: 0 | E8: 0 | F8: =C8*$C$4+D8*$E$4+E8 | G8: Ida Haugen (IH) | H8: Liste med 24 navngitte styreledere
A9: 5 | B9: Referansearket lages og trykkes: tre gjennomførte anlegg, Enova-satsen og én pris | C9: 8 | D9: 0 | E9: 2400 | F9: =C9*$C$4+D9*$E$4+E9 | G9: IH | H9: Ett ark som også ligger i alle servicebilene
A10: 6 | B10: Brev til de 24 styrelederne, med oppfølgingstelefon uka etter | C10: 12 | D10: 0 | E10: 1900 | F10: =C10*$C$4+D10*$E$4+E10 | G10: KN | H10: Minst ti styrer som vil ha besøk
A11: 7 | B11: Internt oppstartsmøte: hva alle atten skal svare når en kunde spør om solceller | C11: 3 | D11: 14 | E11: 0 | F11: =C11*$C$4+D11*$E$4+E11 | G11: KN + Tom Berg (TB) | H11: Alle ansatte kjenner kampanjen før kunden gjør det
A12: 8–11 | B12: Åtte besøk hos styrer, med befaring på taket | C12: 24 | D12: 0 | E12: 1600 | F12: =C12*$C$4+D12*$E$4+E12 | G12: KN + TB | H12: Åtte tilbud sendt ut
A13: 12 | B13: Underveisevaluering: antall besøk, antall tilbud og treffprosent | C13: 4 | D13: 0 | E13: 0 | F13: =C13*$C$4+D13*$E$4+E13 | G13: KN + IH | H13: Justere kampanjen mens den fortsatt varer
A14: 20 | B14: Forhandling og signering av rammeavtale | C14: 6 | D14: 0 | E14: 0 | F14: =C14*$C$4+D14*$E$4+E14 | G14: KN | H14: Delmål 1.3: minst 20 ladepunkt
A15: 26 | B15: Sluttevaluering mot delmål 1.2 og 1.3, og beslutning om kampanjen skal gjentas | C15: 5 | D15: 0 | E15: 0 | F15: =C15*$C$4+D15*$E$4+E15 | G15: KN + IH | H15: Skriftlig notat til styret
B16: = Sum | C16: =SUM(C7:C15) | D16: =SUM(D7:D15) | E16: =SUM(E7:E15) | F16: =SUM(F7:F15) | H16: Denne linja mangler i lærebokas tabell 10.1. En plan uten sum kan ingen ta stilling til.
A18: Hva budsjettet består av
B19: Andel av budsjettet som er egne timer | F19: =(F16-E16)/F16 | H19: En liten bedrift kan ikke kjøpe seg markedsføring. Den må bruke folkene sine, og de er dyre.
B20: Dyreste enkelttiltak | F20: =MAX(F7:F15) | G20: =INDEX(A7:A15,MATCH(MAX(F7:F15),F7:F15,0)) | H20: Kolonne G viser hvilken uke det ligger i.
B21: Avdelingens omsetning i 2026 | F21: =Målene!B14
B22: Kampanjen som andel av omsetningen | F22: =F16/F21
A24: Til sammenlikning: lærebokas tabell 10.1
B25: Bygghandel AS, omsetning 2023 | F25: 660000000
B26: Sum av de ti budsjettpostene i tabell 10.1 | F26: 357000 | H26: Læreboka lister postene, men summerer dem ikke. Summen er etterregnet; se avviksregisteret, oppslag 39.
B27: Bygghandels kampanje som andel av omsetningen | F27: =F26/F25
B28: Nordlys' andel delt på Bygghandels | F28: =F22/F27 | H28: Så mange ganger så stor andel av omsetningen. Ikke fordi Nordlys sløser, men fordi markedsføring har et kostnadsgulv.
B29: Hva kampanjen ville kostet med Bygghandels andel | F29: =F21*F27 | H29: Ikke nok til å skrive brevet. Gulvet ligger høyere enn dette.
A31: Kontroll
A32: Er hver budsjettpost regnet av timer og utlegg? | C32: =IF(ABS(F7-(C7*$C$4+D7*$E$4+E7))<0.01,"OK — budsjettpostene er regnet, ikke gjettet","AVVIK: en budsjettpost stemmer ikke med timene og utleggene")
A33: Har planen en sum? | C33: =IF(F16>0,"OK — planen har en budsjettsum. Det er den linja lærebokas mal mangler","AVVIK: en handlingsplan uten sum kan ingen ta stilling til")
A34: Har hvert tiltak en navngitt ansvarlig? | C34: =IF(COUNTA(G7:G15)=9,"OK — hvert tiltak har en navngitt ansvarlig, ikke en avdeling","AVVIK: et tiltak mangler ansvarlig. Da blir det ikke gjort")
A35: Kommer det interne tiltaket før de første kundebesøkene? | C35: =IF(A11<A12,"OK — det interne oppstartsmøtet ligger før styrebesøkene. Kundene skal ikke få et budskap de ansatte ikke kjenner","AVVIK: rekkefølgen er snudd")
A37: Prøv dette: sett montørtimene på det interne oppstartsmøtet i D11 til null. Se hva budsjettet blir — og tenk gjennom hva som skjer med kampanjen.
A38: Kilde: Hjertnes kap. 10.5 om handlingsplanen, med tabell 10.1. Timekostnadene er utledet av Nordlys' egne lønnstall.

Sheet Bærer den seg
A1: Hva planen må gi i økt omsetning for å bære seg
A2: Det ene tallet som binder hele markedsplanen sammen.
A4: 1 · De to sidene
A5: Hva planen koster: kampanjebudsjettet | B5: =Handlingsplanen!F16
A6: Hva planen skal gi: ekstra dekningsbidrag ved full måloppnåelse | B6: =Målene!D15
A7: Kampanjen som andel av det ekstra dekningsbidraget | B7: =B5/B6 | D7: Diskusjonsstoppet i økta handlet om nettopp dette tallet.
A9: 2 · Nullpunktet
A10: Økt omsetning ved full måloppnåelse | B10: =Målene!D14
A11: Marginal dekningsgrad | B11: =B6/B10 | D11: Hvor mye av hver ny omsetningskrone som blir dekningsbidrag.
A12: = ØKT OMSETNING SOM MÅ TIL FOR AT PLANEN SKAL BÆRE SEG | B12: =B5/B11 | D12: Dette er tallet du avslutter framlegget til styret med. Under dette er kampanjen et tap.
A13: = Som andel av målet | B13: =B12/B10 | D13: Kampanjen trenger altså ikke å lykkes helt for å bære seg.
A15: 3 · Det samme tallet, uttrykt i anlegg
A16: Solcelleanlegg som må til alene | B16: =B5/Målene!D5
A17: Ladepunkt som må til alene | B17: =B5/Målene!D6 | D17: To måter å si det samme på. Velg den styret forstår raskest.
A18: Ekstra solcelleanlegg i målet | B18: =Målene!D11
A19: Ekstra ladepunkt i målet | B19: =Målene!D12
A21: 4 · Kapasiteten planen krever
A22: Montørtimer kampanjen selv binder | B22: =Handlingsplanen!D16
A23: Montørtimer leveransen binder i tillegg | B23: =Målene!D17
A24: = Til sammen | B24: =B22+B23 | D24: Kampanjen er den billige delen. Å levere det den selger, er den dyre.
A25: Fakturerte montørtimer i bedriften | B25: 14400
A26: Som andel av bedriftens montørtimer | B26: =B24/B25
A28: Kontroll
A29: Bærer planen seg ved full måloppnåelse? | C29: =IF(B6>B5,"OK — det ekstra dekningsbidraget er større enn det kampanjen koster","AVVIK: kampanjen koster mer enn den kan gi. Da må planen eller målene justeres")
A30: Ligger nullpunktet innenfor målet? | C30: =IF(B12<B10,"OK — kampanjen bærer seg før målet er nådd helt","AVVIK: kampanjen bærer seg først hvis målet overoppfylles")
A31: Gir de to måtene å regne nullpunktet på samme svar? | C31: =IF(ABS(B13-B7)<0.0001,"OK — nullpunktet i omsetning og nullpunktet i dekningsbidrag gir samme måloppnåelse","AVVIK: de to regnemåtene er ikke enige")
A32: Krever leveransen flere timer enn kampanjen? | C32: =IF(B23>B22,"OK — å levere målet binder flere montørtimer enn kampanjen selv gjør","AVVIK: kontroller timetallene")
A34: Prøv dette: sett kampanjebudsjettet opp ved å legge til fire timer på styrebesøkene i arket Handlingsplanen. Se hvor mye mer omsetning planen da må skape.
A35: Kilde: Hjertnes kap. 10.5 og 10.6 om budsjettering og evaluering. Dekningsbidrag og montørtimer: Nordlys Elektro AS, Økonomistyring kapittel 5 og 7.

Sheet Scenario
A1: Tre scenarioer
A2: Hva om kampanjen bare treffer delvis, hva om styret kutter, og hva om timene sprekker?
A4: Scenario A · hva om kampanjen bare treffer delvis?
A5: Nullpunktsraden er markert. Under den er kampanjen et tap.
A7: Måloppnåelse | B7: Økt omsetning | C7: Ekstra dekningsbidrag | D7: Netto etter kampanjen | E7: Solcelleanlegg | F7: Ladepunkt
A8: 0 | B8: =A8*'Bærer den seg'!$B$10 | C8: =A8*'Bærer den seg'!$B$6 | D8: =C8-'Bærer den seg'!$B$5 | E8: =A8*Målene!$D$11 | F8: =A8*Målene!$D$12
A9: 0.25 | B9: =A9*'Bærer den seg'!$B$10 | C9: =A9*'Bærer den seg'!$B$6 | D9: =C9-'Bærer den seg'!$B$5 | E9: =A9*Målene!$D$11 | F9: =A9*Målene!$D$12
A10: 0.5 | B10: =A10*'Bærer den seg'!$B$10 | C10: =A10*'Bærer den seg'!$B$6 | D10: =C10-'Bærer den seg'!$B$5 | E10: =A10*Målene!$D$11 | F10: =A10*Målene!$D$12
A11: ='Bærer den seg'!B13 | B11: =A11*'Bærer den seg'!$B$10 | C11: =A11*'Bærer den seg'!$B$6 | D11: =C11-'Bærer den seg'!$B$5 | E11: =A11*Målene!$D$11 | F11: =A11*Målene!$D$12 | G11: Nullpunktet
A12: 0.75 | B12: =A12*'Bærer den seg'!$B$10 | C12: =A12*'Bærer den seg'!$B$6 | D12: =C12-'Bærer den seg'!$B$5 | E12: =A12*Målene!$D$11 | F12: =A12*Målene!$D$12
A13: 1 | B13: =A13*'Bærer den seg'!$B$10 | C13: =A13*'Bærer den seg'!$B$6 | D13: =C13-'Bærer den seg'!$B$5 | E13: =A13*Målene!$D$11 | F13: =A13*Målene!$D$12
A14: 1.25 | B14: =A14*'Bærer den seg'!$B$10 | C14: =A14*'Bærer den seg'!$B$6 | D14: =C14-'Bærer den seg'!$B$5 | E14: =A14*Målene!$D$11 | F14: =A14*Målene!$D$12
A16: Kontroll
A17: Gir nullpunktsraden netto null? | C17: =IF(ABS(D11)<1,"OK — raden med nullpunktet gir nøyaktig null igjen etter kampanjen","AVVIK: nullpunktsraden stemmer ikke med arket Bærer den seg")
A18: Snur tabellen fra tap til gevinst? | C18: =IF(AND(D8<0,D14>0),"OK — tabellen snur fra tap til gevinst, og nullpunktet ligger imellom","AVVIK: utvid trappen så nullpunktet kommer med")
A21: Scenario B · styret kutter halve kampanjebudsjettet
A22: Halve budsjettet betyr halve tiltakene. Spørsmålet er hvilke, og hva det gjør med måloppnåelsen.
A24: Andel av budsjettet styret godkjenner | B24: 0.5
A25: = Budsjett etter kuttet | B25: ='Bærer den seg'!B5*B24
A26: Måloppnåelse du tror et halvert budsjett gir | B26: 0.5 | E26: Et anslag. Halvparten av pengene gir sjelden halvparten av resultatet — det interne tiltaket og kartleggingen må gjøres uansett.
A27: = Ekstra dekningsbidrag da | B27: ='Bærer den seg'!B6*B26
A28: = Netto etter kuttet | B28: =B27-B25
A29: Netto uten kutt, til sammenlikning | B29: ='Bærer den seg'!B6-'Bærer den seg'!B5
A30: = Hva kuttet koster | B30: =B28-B29
A31: Laveste måloppnåelse som forsvarer det halve budsjettet | B31: =B25/'Bærer den seg'!B6 | E31: Et halvert budsjett har et lavere nullpunkt. Det er argumentet for kuttet — og det gjelder bare hvis måloppnåelsen ikke faller like mye.
A33: Kontroll
A34: Bærer den kuttede planen seg? | C34: =IF(B28>0,"OK — også den kuttede planen gir mer enn den koster","AVVIK: den kuttede planen gir mindre enn den koster. Da er kuttet dyrere enn det ser ut")
A35: Er kuttet lønnsomt? | C35: =IF(B30>=0,"OK — kuttet gir bedre netto enn den fulle planen","AVVIK: kuttet koster mer enn det sparer. Det er det du sier til styret")
A36: Her SKAL det stå AVVIK med anslagene som ligger inne. Halve budsjettet gir halve resultatet, og da taper bedriften på kuttet.
A38: Scenario C · timeforbruket sprekker
A39: Det vanligste avviket i en handlingsplan er ikke utleggene. Det er timene.
A41: Faktisk timeforbruk i prosent av planlagt | B41: 1.4
A42: Planlagte administrasjonstimer | B42: =Handlingsplanen!C16
A43: Planlagte montørtimer | B43: =Handlingsplanen!D16
A44: Utlegg, som ikke sprekker | B44: =Handlingsplanen!E16
A45: = Budsjett med faktisk timeforbruk | B45: =(B42*Handlingsplanen!$C$4+B43*Handlingsplanen!$E$4)*B41+B44
A46: = Overskridelse | B46: =B45-'Bærer den seg'!B5
A47: = Nytt nullpunkt i økt omsetning | B47: =B45/'Bærer den seg'!B11
A48: Som andel av målet | B48: =B47/'Bærer den seg'!B10 | E48: Sammenlikn med nullpunktet uten sprekk. Timer som sprekker, flytter nullpunktet — de forsvinner ikke bare i en rapport.
A50: Kontroll
...

Sheet Din egen plan
A1: Din egen handlingsplan
A2: Samme oppsett, tomt. Minst ett internt tiltak og minst én evaluering underveis.
A4: Timekostnader | B4: Administrasjonstime | C4: 0 | D4: Montørtime | E4: 0 | H4: Ta med lønn og sosiale kostnader, ikke bare timelønna. De fleste undervurderer hva egne timer koster.
A6: Uke | B6: Aktivitet | C6: Adm.timer | D6: Montørtimer | E6: Utlegg | F6: Budsjett | G6: Ansvarlig | H6: Det tiltaket skal føre til
C7: 0 | D7: 0 | E7: 0 | F7: =C7*$C$4+D7*$E$4+E7
C8: 0 | D8: 0 | E8: 0 | F8: =C8*$C$4+D8*$E$4+E8
C9: 0 | D9: 0 | E9: 0 | F9: =C9*$C$4+D9*$E$4+E9
C10: 0 | D10: 0 | E10: 0 | F10: =C10*$C$4+D10*$E$4+E10
C11: 0 | D11: 0 | E11: 0 | F11: =C11*$C$4+D11*$E$4+E11
C12: 0 | D12: 0 | E12: 0 | F12: =C12*$C$4+D12*$E$4+E12
C13: 0 | D13: 0 | E13: 0 | F13: =C13*$C$4+D13*$E$4+E13
C14: 0 | D14: 0 | E14: 0 | F14: =C14*$C$4+D14*$E$4+E14
B15: = Sum | F15: =SUM(F7:F14)
A17: Hva planen skal gi
B18: Ekstra dekningsbidrag hvis målet nås | F18: 0
B19: Marginal dekningsgrad | F19: 0
B20: = Kampanjen som andel av det ekstra dekningsbidraget | F20: =IF(F18=0,"",F15/F18)
B21: = Økt omsetning som må til for at planen skal bære seg | F21: =IF(F19=0,"",F15/F19) | H21: Dette er tallet du avslutter med.
A23: Kontroll
A24: Har planen en sum og et mål å måles mot? | C24: =IF(AND(F15>0,F18>0),"OK — planen har både en budsjettsum og et dekningsbidrag å måles mot","AVVIK: fyll inn timekostnader, tiltak og forventet dekningsbidrag først")
A25: Her står det AVVIK til du har fylt inn dine egne tall. Det er meningen: arket er tomt når du får det.
A26: Har hvert tiltak en navngitt ansvarlig? | C26: =IF(COUNTA(G7:G14)=COUNTA(B7:B14),"OK — hvert tiltak du har lagt inn, har en navngitt ansvarlig","AVVIK: et tiltak mangler ansvarlig. «Markedsavdelingen» er ikke et navn")
A28: Fire ting skiller en god plan fra en dårlig: hver linje har en navngitt person, budsjettpostene er regnet av timer, det interne tiltaket kommer FØR det eksterne, og evalueringen ligger midt i perioden.
