Workbook

Sheet Enkelt
A1: Hvor mange oppdrag må til? Den enkle versjonen
A2: Fyll inn de fire gule cellene. Svaret står i den grønne. Alt annet regner seg selv. Vil du gå dypere, ligger hele modellen i arkene bak.
A4: Det du vet
A5: Hva betaler kunden for ett oppdrag, uten mva.? | B5: 18500 | C5: Det som står på fakturaen for ett serviceoppdrag.
A6: Hva koster materiell og montørtimer på ett oppdrag? | B6: 11200 | C6: Det du slipper å betale hvis jobben ikke blir noe av. Det er de variable kostnadene.
A7: Hva koster det som kommer uansett, i løpet av et år? | B7: 2100000 | C7: Verksted, servicebiler, forsikring og lønn til dem som ikke fakturerer. Det er de faste kostnadene.
A8: Hvor mange oppdrag har dere planlagt neste år? | B8: 210 | C8: Antallet du regner med å selge. Full kalender betyr ikke at tallet er høyt nok.
A10: Regnestykket
A11: Dekningsbidrag per oppdrag | B11: =B5-B6 -> 7300 | C11: Pris minus variable kostnader. Det hvert oppdrag legger igjen til de faste kostnadene.
A12: Dekningsgrad | B12: =B11/B5 -> 0.39459459 | C12: Dekningsbidraget i prosent av prisen. Så mange øre av hver krone blir igjen.
A13: Nullpunkt i oppdrag, før avrunding | B13: =B7/B11 -> 287.67123 | C13: Faste kostnader delt på dekningsbidraget.
A14: Nullpunkt i kroner | B14: =B7/B12 -> 5321917.8 | C14: Faste kostnader delt på dekningsGRADEN, ikke på dekningsbidraget.
A16: NULLPUNKT I ANTALL OPPDRAG | B16: =IF(B13>ROUND(B13,0),ROUND(B13,0)+1,ROUND(B13,0)) -> 288 | C16: Rundet opp til hele oppdrag. Et halvt oppdrag finnes ikke.
A17: Resultat med det planlagte antallet | B17: =B8*B11-B7 -> -567000 | C17: Alle dekningsbidragene minus de faste kostnadene. Minus betyr tap.
A18: Risikomargin i antall oppdrag | B18: =B8-B16 -> -78 | C18: Planen minus nullpunktet. Negativ margin betyr at avdelingen allerede taper penger.
A20: Hva svaret betyr
A21: ="Avdelingen må ha "&TEXT(ROUND(B16,0),"0")&" oppdrag før den tjener noe. Med "&TEXT(ROUND(B8,0),"0")&" oppdrag blir resultatet "&TEXT(ROUND(B17,0),"#,##0")&" kroner." -> Avdelingen må ha 288 oppdrag før den tjener noe. Med 210 oppdrag blir resultatet -567,000 kroner.
A23: Prøv selv
A24: 1. Sett planlagt antall (B8) til 320. Hva blir resultatet nå?
A25: 2. Sett prisen (B5) 8 prosent opp, til 19 980. Hvor mye faller nullpunktet?
A26: 3. Hva må B8 minst være for at resultatet skal bli større enn null?
A28: Tallene er serviceavdelingen i Nordlys Elektro AS, de samme som i kapittel 2, 5 og 7. Kilde: Økonomistyring for LØM-emnet, kap. 8.1 og 8.2. Nordlys Elektro AS er en konstruert casebedrift.

Sheet Veiledning
A1: Nullpunktsanalyse
A2: LØM Økonomistyring kap. 8 · arbeidsregneark · Fagskolen Oslo, Avdeling Elkraft
A3: Emne: Teknisk kommunikasjon og ledelse for 1ET-klassene · LØM for 2ET, 2EK, 3EK og 4EK
A4: Fargekode
A5: Gul celle med blå skrift | B5: Inndata — dette er tallene du endrer.
A6: Grå eller lyseblå celle, svart skrift | B6: Formel — regner seg selv. Ikke skriv over den.
A7: Mørkeblå rad med hvit skrift | B7: Kolonneoverskrift.
A9: Ark i arbeidsboka
A10: Enkelt | B10: Start her. Fire gule celler, ett svar. Nullpunktet regnet på den enkleste måten.
A11: Nullpunkt | B11: Kalkulatoren. Pris, variable kostnader og faste kostnader inn — nullpunkt, resultat og risikomargin ut. De andre arkene henter tallene sine herfra.
A12: Spakene | B12: Tre tiltak på samme prosent: prisen opp, variable ned, faste ned. Se hvilken som gir mest, og hvorfor.
A13: Rabatt | B13: Hva en rabatt til én stor kunde gjør med snittpris, nullpunkt og risikomargin — og hva den koster hvis kapasiteten er full.
A14: Scenario | B14: Skal avdelingen legges ned? Hva som faktisk forsvinner, hvor grensen går, og hvilke veier ut som finnes.
A15: Din avdeling | B15: Samme oppsett, tomt. Legg inn tallene for din egen avdeling.
A17: Tallene som ligger inne er serviceavdelingen i Nordlys Elektro AS, den samme avdelingen du møter i kapittel 2, 5 og 7.
A18: Nullpunktet i antall rundes alltid OPP til hele enheter: det er ikke nådd før hele oppdraget er fakturert.
A19: Nullpunktet i kroner regnes av DEKNINGSGRADEN, ikke av dekningsbidraget. Deler du på dekningsbidraget, blir svaret flere hundre ganger for lite.
A21: Tallene som ligger inne er et eksempel fra en elektrobedrift. Bytt dem ut med dine egne — alle formler følger med.
A22: Arbeidsregneark til LØM · Fagskolen Oslo, Avdeling Elkraft. Regnearket er øvingsstøtte, ikke et regnskapssystem.
A24: De tre knappene
A25: Nullpunkt!B5 | B25: Prisen per oppdrag | C25: Den sterkeste spaken: hele påslaget går rett inn i dekningsbidraget.
A26: Nullpunkt!B6 | B26: Variable kostnader per oppdrag | C26: Nest sterkest, fordi beløpet er stort.
A27: Nullpunkt!B9 | B27: Faste kostnader i året | C27: Virker bare på telleren i nullpunktsformelen — og tar med seg kapasitet.
A29: Hvilken oppgave bruker hvilket ark
A30: Oppgave i øvingsheftet | B30: Ark | C30: Celler du endrer og leser av
A31: A1 · Går avdelingen i pluss? | B31: Nullpunkt | C31: Les av B7, B8, B15, B16 og resultatet i B25.
A32: A2 · Klasseoppgave: rabatten fra borettslaget | B32: Rabatt | C32: Endre B5, B6 og B7. Les av B12, C19, C21, C22, C25, C26 og forskjellen i C28.
A33: 1 · Serviceavdelingen i utgangspunktet | B33: Nullpunkt | C33: Endre B5, B6, B9 og B21. Les av B7, B8, B15, B16, B17, B25, B26 og B28.
A34: 2 · Hvor mange oppdrag må Tom skaffe? | B34: Nullpunkt | C34: Sett ønsket resultat i B38 og les av B39 og B40. Kapasiteten står i B12.
A35: 3 · De tre spakene | B35: Spakene | C35: Endre prosenten i B4 og volumet i B5. Les av rad 11, 13, 15, 16 og rangeringen i rad 17.
A36: 4 · Rabatten til borettslaget | B36: Rabatt | C36: Endre B5, B6 og B7. Les av hele sammenlikningen i rad 18 til 28, og fortrengningsregningen i B31 og B32.
A37: 5 · Eksamensnær: skal avdelingen legges ned? | B37: Scenario | C37: Sett felleskostnadsandelen i B6. Les av B7, B8, rad 12 til 17, grensene i B20 til B23, veiene ut i rad 27 og 28, og døråpnereffekten i B36 og B37.
A39: Kontrollradene
A40: Hvert regneark har en kontrollblokk. Står det OK, henger tallene sammen. Står det AVVIK, farges cellen rød, og teksten sier hva som ikke går opp.
A41: Ett unntak: arket «Din avdeling» står på AVVIK til du har fylt inn dine egne tall.
A42: Kontroller i arbeidsboka: Nullpunkt B43, Nullpunkt B44, Nullpunkt B45, Nullpunkt B46, Spakene B21, Spakene B22, Spakene B23, Rabatt B35, Rabatt B36, Rabatt B37, Rabatt B38, Scenario B40, Scenario B41, Scenario B42, Din avdeling B26, Din avdeling B28
A44: Slik henger kapitlene sammen
A45: Nullpunktet er timeprisen fra kapittel 5 sett fra en annen kant. Timeprisen svarer på hva timen må koste; nullpunktet svarer på hvor mange av dem du må selge. Arket Nullpunkt regner om nullpunktet til montørtimer i rad 34 og 35, og andelen du leser der, er den samme faktureringsgraden kapittel 5 handler om. Dekningsbidraget per oppdrag er det samme som rangeres i kapittel 7, og de faste kostnadene er de samme som deles ut i kapittel 2.
A47: Kilder
A48: Hjertnes, J. og Skorpen, K.: Økonomistyring for LØM-emnet (ISBN 978-82-450-5544-3), kapittel 8 «Nullpunktsanalyse», avsnitt 8.1 til 8.4. Formler for nullpunkt, dekningsgrad og risikomargin: formelsamlingen til LØM-emnet.
...

Sheet Nullpunkt
A1: Hvor mange oppdrag må til før avdelingen tjener penger?
A2: Endre de gule cellene. Alt annet regner seg selv.
A4: 1 · Avdelingen
A5: Pris per oppdrag, uten mva. | B5: 18500 | D5: Det kunden betaler for ett serviceoppdrag.
A6: Variable kostnader per oppdrag | B6: 11200 | D6: Materiell og montørtimer som går med til nettopp dette oppdraget.
A7: = Dekningsbidrag per oppdrag | B7: =B5-B6 -> 7300 | D7: Det oppdraget bidrar med til å dekke de faste kostnadene.
A8: Dekningsgrad | B8: =B7/B5 -> 0.39459459 | D8: Dekningsbidraget i prosent av prisen. Brukes til nullpunktet i kroner.
A9: Faste kostnader i året | B9: 2100000 | D9: Løper enten avdelingen har oppdrag eller ikke.
A10: Montørtimer per oppdrag | B10: 6
A11: Montørtimer avdelingen har i året | B11: 2400
A12: Kapasitet i antall oppdrag | B12: =B11/B10 -> 400 | D12: Taket. Over dette må avdelingen ansette.
A14: 2 · Nullpunktet
A15: Nullpunkt i antall oppdrag | B15: =B9/B7 -> 287.67123 | D15: Faste kostnader delt på dekningsbidrag per oppdrag.
A16: avrundet opp til hele oppdrag | B16: =ROUNDUP(B15,0) -> 288 | D16: Nullpunktet er ikke nådd før hele oppdraget er fakturert. Rund alltid OPP.
A17: Nullpunkt i kroner | B17: =B9/B8 -> 5321917.8 | D17: Faste kostnader delt på DEKNINGSGRADEN — ikke på dekningsbidraget.
A18: Kontrollregning: nullpunkt i oppdrag × pris | B18: =B15*B5 -> 5321917.8
A20: 3 · Planen for året
A21: Planlagt antall oppdrag | B21: 210 | D21: Den ene cellen som forteller om avdelingen tjener penger eller ikke.
A22: Salgsinntekt | B22: =B21*B5 -> 3885000
A23: Dekningsbidrag totalt | B23: =B21*B7 -> 1533000
A24: − faste kostnader | B24: =B9 -> 2100000
A25: = Resultat | B25: =B23-B9 -> -567000
A26: Risikomargin i antall oppdrag | B26: =B21-B15 -> -77.671233
A27: Risikomargin i kroner | B27: =B22-B17 -> -1436917.8
A28: Risikomargin i prosent | B28: =B27/B22 -> -0.36986301 | D28: Hvor mye salget kan falle før avdelingen går i minus.
A29: Kapasitetsutnyttelse | B29: =B21*B10/B11 -> 0.525
A30: Dom | D30: =IF(B25>0,"Over nullpunktet — avdelingen tjener penger",IF(B25=0,"Nøyaktig i null","Under nullpunktet — avdelingen taper penger")) -> Under nullpunktet — avdelingen taper penger
A32: 4 · Broen til kapittel 5
A33: Dekningsbidrag per montørtime | B33: =B7/B10 -> 1216.6667 | D33: Sammenlikn med oppdragstypene i kapittel 7.
A34: Nullpunktet i montørtimer | B34: =B15*B10 -> 1726.0274
A35: Andel av kapasiteten nullpunktet krever | B35: =B34/B11 -> 0.71917808 | D35: Dette er faktureringsgraden fra kapittel 5, sett fra en annen kant: så stor del av timene må faktisk selges.
A37: 5 · Hva skal til for et overskudd?
A38: Ønsket resultat | B38: 300000
A39: Oppdrag som må til | B39: =(B9+B38)/B7 -> 328.76712
A40: Økning fra planen | B40: =B39/B21-1 -> 0.56555773 | D40: Er dette realistisk på ett år? Det er sjelden det.
A42: Kontroll
A43: Gir de to nullpunktsformlene samme svar? | B43: =IF(ABS(B17-B18)<1,"OK — nullpunkt i kroner stemmer med nullpunkt i oppdrag ganget med prisen","AVVIK: de to formlene gir ulikt svar — sjekk at du har delt på dekningsgraden og ikke på dekningsbidraget") -> OK — nullpunkt i kroner stemmer med nullpunkt i oppdrag ganget med prisen
A44: Er dekningsbidraget positivt? | B44: =IF(B7>0,"OK — hvert oppdrag bidrar til å dekke de faste kostnadene","AVVIK: negativt dekningsbidrag — da finnes det ikke noe nullpunkt, og hvert oppdrag gjør vondt verre") -> OK — hvert oppdrag bidrar til å dekke de faste kostnadene
A45: Ligger nullpunktet innenfor kapasiteten? | B45: =IF(B16<=B12,"OK — avdelingen kan i det hele tatt nå nullpunktet med de montørene den har","AVVIK: nullpunktet ligger over kapasiteten — da må enten prisen opp, kostnadene ned eller bemanningen opp") -> OK — avdelingen kan i det hele tatt nå nullpunktet med de montørene den har
A46: Henger resultatet sammen med risikomarginen? | B46: =IF(ABS(B27*B8-B25)<1,"OK — risikomarginen i kroner ganget med dekningsgraden er lik resultatet","AVVIK: risikomarginen stemmer ikke med resultatet") -> OK — risikomarginen i kroner ganget med dekningsgraden er lik resultatet
...

Sheet Spakene
A1: Tre spaker, samme prosent, helt ulik virkning
A2: Endre prosenten i B4 og se hvilken spak som gir mest.
A4: Tiltakets størrelse | B4: 0.08 | F4: Samme prosent på alle tre tiltakene. Det er nettopp poenget.
A5: Volum vi måler på, antall oppdrag | B5: 320 | F5: Nivået Tom må opp på for å ha en margin i det hele tatt.
B7: Uten tiltak | C7: A · prisen opp | D7: B · variable ned | E7: C · faste ned | F7: Hva raden betyr
A8: Pris per oppdrag | B8: =Nullpunkt!$B$5 -> 18500 | C8: =Nullpunkt!$B$5*(1+$B$4) -> 19980 | D8: =Nullpunkt!$B$5 -> 18500 | E8: =Nullpunkt!$B$5 -> 18500
A9: Variable kostnader per oppdrag | B9: =Nullpunkt!$B$6 -> 11200 | C9: =Nullpunkt!$B$6 -> 11200 | D9: =Nullpunkt!$B$6*(1-$B$4) -> 10304 | E9: =Nullpunkt!$B$6 -> 11200
A10: Faste kostnader i året | B10: =Nullpunkt!$B$9 -> 2100000 | C10: =Nullpunkt!$B$9 -> 2100000 | D10: =Nullpunkt!$B$9 -> 2100000 | E10: =Nullpunkt!$B$9*(1-$B$4) -> 1932000
A11: = Dekningsbidrag per oppdrag | B11: =B8-B9 -> 7300 | C11: =C8-C9 -> 8780 | D11: =D8-D9 -> 8196 | E11: =E8-E9 -> 7300 | F11: Legg merke til at C ikke rører dekningsbidraget i det hele tatt.
A12: Dekningsgrad | B12: =B11/B8 -> 0.39459459 | C12: =C11/C8 -> 0.43943944 | D12: =D11/D8 -> 0.44302703 | E12: =E11/E8 -> 0.39459459
A13: = Nullpunkt i antall oppdrag | B13: =B10/B11 -> 287.67123 | C13: =C10/C11 -> 239.17995 | D13: =D10/D11 -> 256.22255 | E13: =E10/E11 -> 264.65753
A14: Nullpunkt i kroner | B14: =B10/B12 -> 5321917.8 | C14: =C10/C12 -> 4778815.5 | D14: =D10/D12 -> 4740117.1 | E14: =E10/E12 -> 4896164.4
A15: Resultat ved volumet i B5 | B15: =$B$5*B11-B10 -> 236000 | C15: =$B$5*C11-C10 -> 709600 | D15: =$B$5*D11-D10 -> 522720 | E15: =$B$5*E11-E10 -> 404000
A16: Risikomargin i prosent | B16: =($B$5*B8-B14)/($B$5*B8) -> 0.1010274 | C16: =($B$5*C8-C14)/($B$5*C8) -> 0.25256264 | D16: =($B$5*D8-D14)/($B$5*D8) -> 0.19930454 | E16: =($B$5*E8-E14)/($B$5*E8) -> 0.17294521
A17: Rangering — hvem senker nullpunktet mest | C17: =RANK(C13,$C$13:$E$13,1) -> 1 | D17: =RANK(D13,$C$13:$E$13,1) -> 2 | E17: =RANK(E13,$C$13:$E$13,1) -> 3 | F17: 1 er best. Prisøkningen vinner fordi hele påslaget går rett inn i dekningsbidraget.
A18: Forbedring i resultat mot «uten tiltak» | C18: =C15-$B$15 -> 473600 | D18: =D15-$B$15 -> 286720 | E18: =E15-$B$15 -> 168000
A20: Kontroll
A21: Vinner prisøkningen? | B21: =IF(AND(C13<D13,C13<E13),"OK — prisen opp senker nullpunktet mest av de tre","AVVIK: med disse tallene vinner et annet tiltak — les rangeringen i rad 17 og forklar hvorfor") -> OK — prisen opp senker nullpunktet mest av de tre
A22: Slår variable ned de faste ned? | B22: =IF(D13<E13,"OK — å kutte i de variable kostnadene slår å kutte like mye i de faste, fordi de variable er størst av de to","AVVIK: her er de faste kostnadene per oppdrag større enn de variable — da snur rangeringen, og det er verdt å forklare hvorfor") -> OK — å kutte i de variable kostnadene slår å kutte like mye i de faste, fordi de variable er størst av de to
A23: Senker alle tre tiltakene nullpunktet? | B23: =IF(AND(C13<B13,D13<B13,E13<B13),"OK — alle tre tiltakene virker, de virker bare ulikt mye","AVVIK: et tiltak som ikke senker nullpunktet, er ikke et tiltak — sjekk fortegnet på prosenten i B4") -> OK — alle tre tiltakene virker, de virker bare ulikt mye
A25: Prøv dette: sett prosenten i B4 til det nivået som gjør at tiltak C alene bringer avdelingen over nullpunktet. Se hvor stort kuttet må være.
A26: Kilde: Bok 1 kap. 8.3 om hvordan endringer i pris og kostnader flytter nullpunktet.

Sheet Rabatt
A1: Hva en rabatt gjør med nullpunktet
A2: Et borettslag vil ha mange oppdrag, men til lavere pris. Er det verdt det?
A4: 1 · Tilbudet
A5: Rabatt borettslaget krever | B5: 0.15
A6: Antall oppdrag i avtalen | B6: 40
A7: Samlet volum avdelingen regner med | B7: 320 | E7: Med avtalen. Uten avtalen blir volumet dette minus oppdragene i B6.
A8: Oppdrag til full pris | B8: =B7-B6 -> 280
A10: 2 · Det rabatterte oppdraget
A11: Rabattert pris | B11: =Nullpunkt!$B$5*(1-B5) -> 15725
A12: = Dekningsbidrag per rabattert oppdrag | B12: =B11-Nullpunkt!$B$6 -> 4525 | E12: Fortsatt positivt: hvert rabattert oppdrag bidrar til å dekke faste kostnader.
A13: Dekningsgrad på det rabatterte oppdraget | B13: =B12/B11 -> 0.28775835
A14: Samlet dekningsbidrag fra avtalen | B14: =B6*B12 -> 181000 | E14: Penger som ellers ikke ville kommet inn — hvis kapasiteten er ledig.
A16: 3 · Avdelingen med og uten avtalen
B17: Uten avtalen | C17: Med avtalen | E17: Hva raden betyr
A18: Antall oppdrag | B18: =B8 -> 280 | C18: =B7 -> 320 | E18: Uten avtalen forsvinner de rabatterte oppdragene helt. Det er alternativet.
A19: Gjennomsnittspris | B19: =Nullpunkt!$B$5 -> 18500 | C19: =(B6*B11+B8*Nullpunkt!$B$5)/B7 -> 18153.125
A20: Gjennomsnittlig dekningsbidrag | B20: =B19-Nullpunkt!$B$6 -> 7300 | C20: =C19-Nullpunkt!$B$6 -> 6953.125
A21: Gjennomsnittlig dekningsgrad | B21: =B20/B19 -> 0.39459459 | C21: =C20/C19 -> 0.38302634
A22: Nullpunkt i antall oppdrag | B22: =Nullpunkt!$B$9/B20 -> 287.67123 | C22: =Nullpunkt!$B$9/C20 -> 302.02247 | E22: Rabatten løfter nullpunktet: det skal flere oppdrag til når hvert av dem bidrar med mindre.
A23: Nullpunkt i kroner | B23: =Nullpunkt!$B$9/B21 -> 5321917.8 | C23: =Nullpunkt!$B$9/C21 -> 5482651.7
A24: Salgsinntekt | B24: =B18*B19 -> 5180000 | C24: =C18*C19 -> 5809000
A25: = Resultat | B25: =B18*B20-Nullpunkt!$B$9 -> -56000 | C25: =C18*C20-Nullpunkt!$B$9 -> 125000
A26: Risikomargin i prosent | B26: =(B24-B23)/B24 -> -0.02739726 | C26: =(C24-C23)/C24 -> 0.056179775
A27: Kapasitetsutnyttelse | B27: =B18*Nullpunkt!$B$10/Nullpunkt!$B$11 -> 0.7 | C27: =C18*Nullpunkt!$B$10/Nullpunkt!$B$11 -> 0.8
A28: Forskjell i resultat | C28: =C25-B25 -> 181000 | E28: Skal være lik det samlede dekningsbidraget fra avtalen i B14.
A30: 4 · Og hvis oppdragene fortrenger jobber til full pris?
A31: Resultat hvis de samme oppdragene kunne vært solgt til full pris | B31: =B7*(Nullpunkt!$B$5-Nullpunkt!$B$6)-Nullpunkt!$B$9 -> 236000
A32: Hva rabatten koster da | B32: =C25-B31 -> -111000 | E32: Er kapasiteten full, er rabatten et tap — ikke en gevinst. Spørsmålet er alltid hva alternativet til oppdraget er.
A34: Kontroll
A35: Er det rabatterte oppdraget fortsatt lønnsomt å ta? | B35: =IF(B12>0,"OK — positivt dekningsbidrag: oppdraget bidrar til å dekke faste kostnader du har uansett","AVVIK: rabatten er så stor at oppdraget koster mer enn det gir — si nei uansett kapasitet") -> OK — positivt dekningsbidrag: oppdraget bidrar til å dekke faste kostnader du har uansett
A36: Løfter rabatten nullpunktet? | B36: =IF(C22>B22,"OK — nullpunktet stiger, som det skal når snittprisen faller","AVVIK: en rabatt kan ikke senke nullpunktet") -> OK — nullpunktet stiger, som det skal når snittprisen faller
A37: Stemmer forskjellen i resultat med bidraget fra avtalen? | B37: =IF(ABS(C28-B14)<1,"OK — forskjellen i resultat er nøyaktig dekningsbidraget fra de rabatterte oppdragene","AVVIK: regnestykket henger ikke sammen") -> OK — forskjellen i resultat er nøyaktig dekningsbidraget fra de rabatterte oppdragene
A38: Er det kapasitet til avtalen? | B38: =IF(C27<=1,"OK — avdelingen har montørtimer nok til hele volumet","AVVIK: volumet med avtalen overstiger kapasiteten — da fortrenger de rabatterte oppdragene jobber til full pris, og rad 31 og 32 er svaret") -> OK — avdelingen har montørtimer nok til hele volumet
A40: Prøv dette: skru rabatten i B5 oppover til dekningsbidraget i B12 blir null. Den prosenten er den absolutte grensen — og den ligger langt over det du bør godta.
A41: Kilde: Bok 1 kap. 8.3 og 8.4 om endret pris og om gjennomsnittspris når deler av volumet selges med rabatt.

Sheet Scenario
A1: Skal serviceavdelingen legges ned?
A2: Oppgave 5 i øvingsheftet. Regn først, drøft etterpå.
A4: 1 · De faste kostnadene er ikke én ting
A5: Faste kostnader avdelingen bærer | B5: =Nullpunkt!B9 -> 2100000
A6: Andel som er felleskostnader fordelt fra Nordlys | B6: 0.35 | E6: Kontor, regnskap, IT og daglig leder. Legges avdelingen ned, flyttes disse over på de andre avdelingene — de forsvinner ikke.
A7: Felleskostnader som blir igjen | B7: =B5*B6 -> 735000
A8: Unngåelige faste kostnader | B8: =B5-B7 -> 1365000 | E8: Egen leasingbil, eget lager, egen avdelingsleder. Disse forsvinner med avdelingen.
A10: 2 · De to alternativene
B11: Drive videre | C11: Legge ned | E11: Hva raden betyr
A12: Antall oppdrag | B12: =Nullpunkt!B21 -> 210 | C12: 0
A13: Dekningsbidrag | B13: =B12*Nullpunkt!$B$7 -> 1533000 | C13: =0 -> 0 | E13: Alt dekningsbidraget forsvinner med avdelingen.
A14: − faste kostnader Nordlys sitter igjen med | B14: =B5 -> 2100000 | C14: =B7 -> 735000
A15: = Resultat for Nordlys | B15: =B13-B14 -> -567000 | C15: =C13-C14 -> -735000
A16: Nedleggelse endrer resultatet med | C16: =C15-B15 -> -168000 | E16: Negativt tall: nedleggelse gjør vondt verre.
A17: Dom | E17: =IF(C16>0,"Nedleggelse forbedrer resultatet","Nedleggelse forverrer resultatet — dekningsbidraget som forsvinner er større enn kostnadene som spares") -> Nedleggelse forverrer resultatet — dekningsbidraget som forsvinner er større enn kostnadene som spares
A19: 3 · Hvor går grensen?
A20: Oppdrag som må til for å forsvare at avdelingen drives videre | B20: =B8/Nullpunkt!$B$7 -> 186.9863 | E20: Unngåelige faste kostnader delt på dekningsbidrag per oppdrag. Under dette volumet lønner nedleggelse seg.
A21: Nullpunktet — der avdelingen går i null på papiret | B21: =Nullpunkt!B15 -> 287.67123
A22: Avstanden mellom de to grensene | B22: =B21-B20 -> 100.68493 | E22: Mellom disse to tallene går avdelingen i minus i regnskapet, og skal likevel drives videre. Det er hele poenget i oppgaven.
A23: Hvor avdelingen ligger nå | B23: =Nullpunkt!B21 -> 210 | E23: =IF(B23<B20,"Under nedleggelsesgrensen — nedleggelse er forsvarlig",IF(B23<B21,"Mellom nedleggelsesgrensen og nullpunktet — går i minus, men skal drives videre","Over nullpunktet — tjener penger")) -> Mellom nedleggelsesgrensen og nullpunktet — går i minus, men skal drives videre
A25: 4 · Veiene ut
A26: Styrets krav til overskudd | B26: =Nullpunkt!B38 -> 300000
A27: Oppdrag som må til, uendret pris | B27: =(B5+B26)/Nullpunkt!$B$7 -> 328.76712 | C27: =B27/Nullpunkt!$B$21-1 -> 0.56555773 | E27: Kolonne C: hvor mye volumet må øke fra planen.
A28: Oppdrag som må til med prisen opp | B28: =(B5+B26)/Spakene!$C$11 -> 273.34852 | C28: =B28/Nullpunkt!$B$21-1 -> 0.30165962 | E28: Prisøkningen fra tiltak A i arket Spakene.
A29: Kapasitet i antall oppdrag | B29: =Nullpunkt!B12 -> 400
A30: Er målet mulig innenfor kapasiteten? | E30: =IF(B28<=B29,"Ja — men bare hvis hver eneste montørtime går til fakturerbart arbeid","Nei — da må avdelingen bemannes opp, og de faste kostnadene stiger") -> Ja — men bare hvis hver eneste montørtime går til fakturerbart arbeid
A32: 5 · Det tallene ikke ser: serviceoppdrag som døråpner
A33: Andel serviceoppdrag som fører til et større oppdrag | B33: 0.05 | E33: Didaktisk anslag. Sett ditt eget — poenget er å tvinge fram et tall.
A34: Dekningsbidrag på det større oppdraget | B34: 4400 | E34: Solcelleanlegget fra kapittel 7.
A35: Antall slike oppdrag i året | B35: =Nullpunkt!B21*B33 -> 10.5
A36: Dekningsbidrag serviceavdelingen skaffer andre avdelinger | B36: =B35*B34 -> 46200
A37: Resultat for Nordlys når døråpnereffekten regnes med | B37: =B15+B36 -> -520800 | E37: Fortsatt negativt — men mindre. Og nå er hensynet tallfestet i stedet for å være en påstand.
A39: Kontroll
A40: Går avdelingen faktisk i minus? | B40: =IF(B15<0,"OK — avdelingen går i minus med det volumet som ligger inne. Det er derfor saken er på styrets bord","AVVIK: avdelingen tjener penger — da finnes det ingen sak") -> OK — avdelingen går i minus med det volumet som ligger inne. Det er derfor saken er på styrets bord
A41: Ligger nedleggelsesgrensen under nullpunktet? | B41: =IF(B20<B21,"OK — det finnes et område der avdelingen går i minus og likevel skal drives videre","AVVIK: med disse tallene er nedleggelsesgrensen lik nullpunktet — sjekk felleskostnadsandelen i B6") -> OK — det finnes et område der avdelingen går i minus og likevel skal drives videre
A42: Er døråpnereffekten alene nok? | B42: =IF(B37<0,"OK — døråpnereffekten alene snur ikke underskuddet. Den må kombineres med volum eller pris","AVVIK: med dette anslaget er saken løst av seg selv — sett et mer nøkternt tall i B33") -> OK — døråpnereffekten alene snur ikke underskuddet. Den må kombineres med volum eller pris
A44: Legg merke til hva som skiller de to grensene i rad 20 og 21. Nullpunktet svarer på om avdelingen tjener penger. Nedleggelsesgrensen svarer på om Nordlys er tjent med å ha den. Det er to helt ulike spørsmål, og bare det ene står i læreboka.
A45: Kilde: Bok 1 kap. 8.1 til 8.4, og kapittel 2 om faste og variable kostnader. Skillet mellom unngåelige og ikke-unngåelige faste kostnader følger av bidragsmetoden i kapittel 5. Bransjetall: NHO Elektro, Lønnsomhetsrapport 2025, gjengitt i Elektro 24-7 19.08.2026 (hentet 10.09.2026). De 809 er bedriftene i datagrunnlaget, ikke bransjen. NHO Elektro oppgir ikke svarprosent.

Sheet Din avdeling
A1: Din egen avdeling
A2: Samme regnestykke, ingen tall. Fyll inn de gule cellene.
A4: 1 · Avdelingen
A5: Pris per oppdrag eller per enhet | B5: 0 | D5: Uten mva.
A6: Variable kostnader per oppdrag | B6: 0 | D6: Materiell og lønn som følger oppdraget.
A7: = Dekningsbidrag per oppdrag | B7: =B5-B6 -> 0
A8: Faste kostnader i året | B8: 0 | D8: Husleie, forsikring, leasing, fast lønn.
A9: Timer per oppdrag | B9: 0 | D9: Til kapasitetsregningen.
A10: Timer avdelingen har i året | B10: 0 | D10: Antall ansatte ganget med timene hver av dem selger.
A11: Kapasitet i antall oppdrag | B11: =IF(B9=0,"",B10/B9)
A13: 2 · Nullpunktet
A14: Dekningsgrad | B14: =IF(B5=0,"",B7/B5)
A15: Nullpunkt i antall oppdrag | B15: =IF(B7<=0,"",B8/B7)
A16: avrundet opp | B16: =IF(B7<=0,"",ROUNDUP(B15,0))
A17: Nullpunkt i kroner | B17: =IF(B14="","",B8/B14)
A19: 3 · Planen
A20: Planlagt antall oppdrag | B20: 0
A21: Resultat | B21: =B20*B7-B8 -> 0
A22: Risikomargin i prosent | B22: =IF(OR(B20=0,B5=0),"",(B20*B5-B17)/(B20*B5))
A23: Kapasitetsutnyttelse | B23: =IF(B10=0,"",B20*B9/B10)
A25: Kontroll
A26: Er arket fylt ut? | B26: =IF(B5=0,"AVVIK: fyll inn prisen i B5 før du leser av noe annet",IF(B7<=0,"AVVIK: dekningsbidraget er null eller negativt — sjekk B5 og B6","OK — arket regner på din egen avdeling")) -> AVVIK: fyll inn prisen i B5 før du leser av noe annet
A27: Dette arket starter tomt, så kontrollen står på AVVIK til du har fylt inn tallene.
A28: Ligger nullpunktet innenfor kapasiteten? | B28: =IF(OR(B7<=0,B9=0,B10=0),"OK — fyll inn timer og kapasitet for å få denne kontrollen",IF(B16<=B11,"OK — nullpunktet er mulig å nå med den bemanningen du har","AVVIK: nullpunktet ligger over kapasiteten")) -> OK — fyll inn timer og kapasitet for å få denne kontrollen
A30: Ta arket med på jobb. Nullpunktet er det ene tallet en avdelingsleder bør kunne i hodet før året begynner.
