Workbook

Sheet Enkelt
A1: Overskudd, men lite i banken? Den enkle versjonen
A2: Fyll inn de fem gule cellene. Svaret står i den grønne. Alt annet regner seg selv. Vil du gå dypere, ligger hele modellen i arkene bak.
A4: Det du vet
A5: Hvor mye tjente bedriften i året (årsresultat)? | B5: 928000 | C5: Nederste linje i resultatregnskapet, etter renter og skatt.
A6: Hvor mye er trukket fra i avskrivninger? | B6: 620000 | C6: Verditapet på biler og verktøy. En kostnad, men ingen penger gikk ut i år.
A7: Hvor mye står i banken 31. desember? | B7: 1000000 | C7: Bankinnskudd og kontanter i balansen.
A8: Hvor mye skylder kundene for fakturerte jobber? | B8: 4200000 | C8: Kundefordringer. Jobben er gjort og fakturert, men ikke betalt.
A9: Hvor mye materiell ligger på lageret? | B9: 1400000 | C9: Varelager. Materiellet er betalt, men ikke montert.
A11: Regnestykket
A12: Omløpsmidler i alt | B12: =B7+B8+B9 -> 6600000 | C12: Bank, kundefordringer og varelager.
A13: Del av omløpsmidlene som er penger i banken | B13: =B7/B12 -> 0.15151515 | C13: Resten er materiell og penger andre skylder bedriften.
A14: Grovt anslag på penger driften skapte | B14: =B5+B6 -> 1548000 | C14: Avskrivningene legges tilbake fordi de ikke er utbetalinger. Den fulle beregningen er kontantstrømoppstillingen.
A16: PENGER UNDERVEIS HOS KUNDER OG PÅ LAGER | B16: =B8+B9 -> 5600000 | C16: Kundefordringer pluss varelager. Pengene er ikke borte, de er underveis.
A17: Underveis, ganger det som står i banken | B17: =B16/B7 -> 5.6 | C17: Hvor mange ganger mer som er underveis enn det som står på konto.
A19: Hva svaret betyr
A20: ="Bedriften tjente "&TEXT(ROUND(B5,0),"#,##0")&" kroner, men "&TEXT(ROUND(B16,0),"#,##0")&" kroner står hos kundene og på lageret. Pengene er ikke borte. De er underveis." -> Bedriften tjente 928,000 kroner, men 5,600,000 kroner står hos kundene og på lageret. Pengene er ikke borte. De er underveis.
A22: Prøv selv
A23: 1. Kundene betaler halvparten: sett kundefordringene (B8) til 2 100 000 og banken (B7) til 3 100 000. Hva skjer med andelen penger?
A24: 2. Endre årsresultatet (B5). Hva skjer med pengene underveis?
A25: 3. Sett varelageret (B9) ned med 400 000 og legg beløpet til banken (B7). Hvor mange ganger banken er nå underveis?
A27: Tallene er Nordlys Elektro AS sine for 2026 (faktaarket). Kilde: Økonomistyring for LØM-emnet, kap. 3.2 og 3.3. Nordlys Elektro AS er en konstruert casebedrift.

Sheet Veiledning
A1: Resultat og balanse
A2: LØM Økonomistyring kap. 3 · arbeidsregneark · Fagskolen Oslo, Avdeling Elkraft
A3: Emne: Teknisk kommunikasjon og ledelse for 1ET-klassene · LØM for 2ET, 2EK, 3EK og 4EK
A4: Fargekode
A5: Gul celle med blå skrift | B5: Inndata — dette er tallene du endrer.
A6: Grå eller lyseblå celle, svart skrift | B6: Formel — regner seg selv. Ikke skriv over den.
A7: Mørkeblå rad med hvit skrift | B7: Kolonneoverskrift.
A9: Ark i arbeidsboka
A10: Enkelt | B10: Start her. Fem gule celler, ett svar. Hvorfor overskudd ikke er det samme som penger i banken.
A11: Resultat | B11: Resultatregnskapet til Nordlys Elektro AS for 2026, med alle delsummer som formler og hver post i prosent av salget.
A12: Balanse | B12: Balansen per 31.12.2026. Kontrollraden viser om de to sidene går opp, og de to tommelfingerreglene står ferdig regnet.
A13: Aktivering | B13: Skal innkjøpet i balansen eller rett i resultatet? Regelen med to vilkår, og avskrivningsplanen.
A14: Til kapittel 4 | B14: Broen: de fem tallene fra balansen som nøkkeltallene i kapittel 4 regnes av — og de fire nøkkeltallene som kan regnes av balansen alene.
A15: Min bedrift | B15: Samme to oppstillinger, men tomme. Fyll inn tallene til din egen bedrift.
A16: Scenario | B16: To spørsmål: hvor mye kapital du kan frigjøre uten å selge én time mer, og hva banken ser etter når den leser regnskapet.
A18: Tallene som ligger inne er Nordlys Elektro AS sine egne tall for 2026.
A19: Arket er laget for å brukes på jobben etterpå: bytt ut de gule cellene med dine egne tall.
A20: Merk at Resultat-arket og Balanse-arket er to ulike rapporter. Endrer du et tall i det ene,
A21: endrer det seg ikke automatisk i det andre — akkurat som i virkeligheten må du selv tenke
A22: gjennom hva endringen gjør med den andre rapporten.
A24: Tallene som ligger inne er et eksempel fra en elektrobedrift. Bytt dem ut med dine egne — alle formler følger med.
A25: Arbeidsregneark til LØM · Fagskolen Oslo, Avdeling Elkraft. Regnearket er øvingsstøtte, ikke et regnskapssystem.
A27: Koblingen til kapittel 4
A28: Balanse!B20, E8, E18, B14 og B11 | B28: De fem tallene som går videre | C28: Sum eiendeler, sum egenkapital, sum kortsiktig gjeld, sum omløpsmidler og varelageret. Arket «Til kapittel 4» henter dem og regner ut de fire nøkkeltallene som bare trenger balansen.
A29: LOM_Ovingsark_Okonomistyring_kap04_Nokkeltall_NY.xlsx | B29: Regnearket til kapittel 4 | C29: Bruker nøyaktig den samme balansen og det samme resultatet. Nøkkeltallene der er ikke nye tall — de er disse tallene, delt på hverandre.
A31: Hvilken oppgave bruker hvilket ark
A32: Oppgave i øvingsheftet | B32: Ark | C32: Celler du endrer og leser av
A33: A1 · Overskudd på papiret — hvor ble pengene av? | B33: Balanse | C33: Les av B11, B12, B38, B39 og B40.
A34: A2 · Tre spørsmål til balansen | B34: Balanse | C34: Les av radene 27 til 33 for de to tommelfingerreglene, og B38 for andelen faktiske penger.
A35: A3 · Klasseoppgave: sett opp et regnskap og en balanse | B35: Min bedrift | C35: Legg hennes tall i de gule cellene i kolonne B og E. Kontrollen i B26 skal si OK.
A36: 1 · Sett opp resultatregnskapet | B36: Resultat | C36: Endre B5 til B17. Les av B8, B13, B16 og B18, og kolonne C for prosentene. Sett B15 til 0 for deloppgave e).
A37: 2 · Sett opp balansen, og finn den manglende posten | B37: Balanse, Til kapittel 4 | C37: Endre kolonne B og E i «Balanse». Les av B8, B14, E8, E12, E18, B20, E20 og B23. Arbeidskapitalen står i B33. Deloppgave e) er arket «Til kapittel 4», radene 6 til 10.
A38: 3 · Aktivere eller utgiftsføre? | B38: Aktivering | C38: Endre B5, E5, og pris og levetid i radene 9 til 12. Les av kolonne D og E, og B15, B16 og B17. Avskrivningsplanen står i radene 25 til 31.
A39: 4 · Overskudd på papiret, tomt på konto | B39: Balanse, Scenario | C39: Les av B11, B12 og B38 i «Balanse». Scenario A i arket «Scenario»: endre B10 og B15, og les av B9, B12, B16, B17 og B24.
A40: 5 · Eksamensnær: banken vil se regnskapet | B40: Scenario | C40: Scenario B: endre B35, B36, B37 og B57. Les av B39, B40, B43 til B47, B50 til B53 og B58 til B62.
A42: Kontrollradene
A43: Hvert regneark har en kontrollblokk. Står det OK, henger tallene sammen. Står det AVVIK, farges cellen rød, og teksten sier hva som ikke går opp.
A44: Tre unntak: kontrollen på driftsmarginen i arket «Resultat», og de to første i scenario A og B, skal vise AVVIK med tallene som ligger inne. Der er avviket selve svaret — Nordlys ligger under bransjens driftsmargin og under bransjens egenkapitalandel, og kundene bruker lengre kredittid enn avtalt.
A45: Kontroller i arbeidsboka: Resultat B27, Resultat B28, Resultat B30, Balanse B24, Balanse B29, Balanse B32, Aktivering B20, Aktivering B21, Til kapittel 4 B28, Til kapittel 4 B29, Til kapittel 4 B30, Min bedrift B26, Min bedrift B27, Min bedrift B28, Scenario B27, Scenario B29, Scenario B65, Scenario B67, Scenario B68, Scenario B69
A47: Slik henger kapitlet sammen med resten
...

Sheet Resultat
A1: Resultatregnskap 2026 — Nordlys Elektro AS
A2: Endre de gule cellene. Alle delsummer regner seg selv.
A4: Post | B4: Kroner | C4: Av salget | D4: Hva står det egentlig?
A5: Salgsinntekt | B5: 22400000 | C5: =B5/$B$5 -> 1 | D5: Fakturert til kundene, uten merverdiavgift.
A6: Varekostnad, materiell | B6: 7990000 | C6: =B6/$B$5 -> 0.35669643 | D6: Kabel, skap og kursutstyr fra Polarlys Elektro Grossist AS.
A7: Varekostnad, innleide montører | B7: 400000 | C7: =B7/$B$5 -> 0.017857143 | D7: Innleid hjelp på de store prosjektene.
A8: = Bruttofortjeneste | B8: =B5-B6-B7 -> 14010000 | C8: =B8/$B$5 -> 0.62544643 | D8: Igjen etter materiell og innleie. Her er ingenting annet betalt ennå.
A9: Lønnskostnad | B9: 10660000 | C9: =B9/$B$5 -> 0.47589286 | D9: Lønn, feriepenger, arbeidsgiveravgift og pensjon for 18 ansatte.
A10: Avskrivninger | B10: 620000 | C10: =B10/$B$5 -> 0.027678571 | D10: Verdifall på biler, verktøy og instrumenter. Ingen utbetaling.
A11: Andre driftskostnader | B11: 1386000 | C11: =B11/$B$5 -> 0.061875 | D11: Husleie, strøm, forsikring, regnskapsfører, bilkostnader.
A12: = Sum driftskostnader | B12: =B6+B7+B9+B10+B11 -> 21056000 | C12: =B12/$B$5 -> 0.94 | D12: Alle fire kostnadsgruppene lagt sammen.
A13: = Driftsresultat | B13: =B5-B12 -> 1344000 | C13: =B13/$B$5 -> 0.06 | D13: Det driften selv tjente. Prosenten i kolonne C er driftsmarginen.
A14: Renteinntekter | B14: 56000 | C14: =B14/$B$5 -> 0.0025 | D14: Renter på bankinnskuddet.
A15: Rentekostnader | B15: 210000 | C15: =B15/$B$5 -> 0.009375 | D15: Renter på banklån og kassekreditt. Handler om finansiering, ikke om drift.
A16: = Resultat før skattekostnad | B16: =B13+B14-B15 -> 1190000 | C16: =B16/$B$5 -> 0.053125 | D16: Det Skatteetaten regner skatten av. Brukes i både TKR og EKR i kapittel 4.
A17: Skattekostnad | B17: 262000 | C17: =B17/$B$5 -> 0.011696429 | D17: Selskapsskatt.
A18: = Årsresultat | B18: =B16-B17 -> 928000 | C18: =B18/$B$5 -> 0.041428571 | D18: Det som blir igjen til eierne og til bedriften.
A20: Målt mot bransjen
A21: Driftsmargin, Nordlys | B21: =B13/B5 -> 0.06
A22: Driftsmargin, bransjen | B22: 0.075 | D22: Kilde: NHO Elektro, Lønnsomhetsrapport 2025, gjengitt i Elektro 24-7 19.08.2026 (hentet 10.09.2026). De 809 er bedriftene i datagrunnlaget, ikke bransjen. NHO Elektro oppgir ikke svarprosent.
A23: Differanse i prosentpoeng | B23: =(B21-B22)*100 -> -1.5
A24: Varekostnad og lønn til sammen, av salget | B24: =(B6+B7+B9)/B5 -> 0.85044643 | D24: To poster sluker mesteparten. Derfor slår små endringer hardt ut.
A26: Kontroll
A27: Går resultatoppstillingen opp? | B27: =IF(ABS(B5-B12-B13)<1,"OK — salgsinntekt minus sum driftskostnader er driftsresultatet","AVVIK: delsummene henger ikke sammen") -> OK — salgsinntekt minus sum driftskostnader er driftsresultatet
A28: Ligger driftsmarginen over eller under bransjen? | B28: =IF(B21>=B22,"OK — Nordlys ligger på eller over bransjens driftsmargin","AVVIK: Nordlys ligger under bransjens driftsmargin. Det er riktig med tallene som ligger inne, og det er styrets problem — ikke bankens") -> AVVIK: Nordlys ligger under bransjens driftsmargin. Det er riktig med tallene som ligger inne, og det er styrets problem — ikke bankens
A29: Her SKAL det stå AVVIK med tallene som ligger inne. Nordlys ligger under bransjen, og det er nettopp det kapittel 4 setter tall på.
A30: Er avskrivningene en kostnad uten utbetaling? | B30: =IF(B10>0,"OK — avskrivningene i B10 er en kostnad, men ingen penger gikk ut av kontoen i år. Legg dem tilbake når du vil anslå hvor mye penger driften ga","OK — ingen avskrivninger dette året") -> OK — avskrivningene i B10 er en kostnad, men ingen penger gikk ut av kontoen i år. Legg dem tilbake når du vil anslå hvor mye penger driften ga
A32: Prøv dette
A33: 1. Senk salgsinntekten i B5 med 1 000 000. Hvor mange linjer nedover endrer seg?
A34: 2. Sett den tilbake. Kutt så 200 000 i andre driftskostnader i B11. Hvor mye bedre blir årsresultatet — og hvorfor er det ikke 200 000?
A35: 3. Sett rentekostnaden i B15 til 0. Legg merke til at driftsresultatet ikke rører seg. Det er nettopp poenget med driftsresultatet.
A36: Kilde: oppstillingen følger Økonomistyring for LØM-emnet, kap. 3.3. Tallene er Nordlys Elektro AS 2026.

Sheet Balanse
A1: Balanse per 31.12.2026 — Nordlys Elektro AS
A2: To sider som alltid er like store. Kontrollraden nederst sier fra hvis de ikke er det.
A4: Eiendeler (aktiva) | B4: Kroner | D4: Egenkapital og gjeld (passiva) | E4: Kroner
A5: ANLEGGSMIDLER | D5: EGENKAPITAL
A6: Maskiner, verktøy og instrumenter | B6: 1200000 | D6: Aksjekapital | E6: 300000
A7: Biler | B7: 2400000 | D7: Annen egenkapital | E7: 2610000
A8: Sum anleggsmidler | B8: =SUM(B6:B7) -> 3600000 | D8: Sum egenkapital | E8: =SUM(E6:E7) -> 2910000
A10: OMLØPSMIDLER | D10: LANGSIKTIG GJELD
A11: Varelager | B11: 1400000 | D11: Banklån | E11: 2800000 | F11: Det minst likvide omløpsmiddelet. Trekkes ut i likviditetsgrad 2.
A12: Kundefordringer | B12: 4200000 | D12: Sum langsiktig gjeld | E12: =E11 -> 2800000 | F12: Fakturert, men ikke betalt. Største enkeltpost i balansen.
A13: Bankinnskudd og kontanter | B13: 1000000 | D13: KORTSIKTIG GJELD
A14: Sum omløpsmidler | B14: =SUM(B11:B13) -> 6600000 | D14: Leverandørgjeld | E14: 2100000
D15: Skyldige offentlige avgifter | E15: 1200000 | F15: Merverdiavgift, forskuddstrekk og arbeidsgiveravgift. Faste forfallsdatoer.
D16: Skyldige feriepenger | E16: 890000
D17: Kassekreditt | E17: 300000 | F17: Kortsiktig gjeld — banken kan i prinsippet trekke den tilbake.
D18: Sum kortsiktig gjeld | E18: =SUM(E14:E17) -> 4490000
A20: SUM EIENDELER | B20: =B8+B14 -> 10200000 | D20: SUM EGENKAPITAL OG GJELD | E20: =E8+E12+E18 -> 10200000
A22: Kontroll
A23: Differanse mellom de to sidene | B23: =B20-E20 -> 0
A24: Balanserer den? | B24: =IF(B23=0,"OK — de to sidene er like store","AVVIK: differansen står i B23. Hver krone bedriften rår over, har kommet fra eierne eller fra noen den skylder penger") -> OK — de to sidene er like store
A26: Lærebokas to tommelfingerregler
A27: Egenkapital + langsiktig gjeld | B27: =E8+E12 -> 5710000
A28: mot anleggsmidlene | B28: =B8 -> 3600000
A29: Regel 1 | B29: =IF(B27>B28,"OK — den langsiktige finansieringen dekker anleggsmidlene, og det som er til overs finansierer en del av omløpsmidlene","AVVIK: anleggsmidlene er kortsiktig finansiert — bedriften låner kort og investerer langt") -> OK — den langsiktige finansieringen dekker anleggsmidlene, og det som er til overs finansierer en del av omløpsmidlene
A30: Kortsiktig gjeld | B30: =E18 -> 4490000
A31: mot omløpsmidlene | B31: =B14 -> 6600000
A32: Regel 2 | B32: =IF(B30<B31,"OK — omløpsmidlene dekker den kortsiktige gjelden","AVVIK: den kortsiktige gjelden er større enn omløpsmidlene — bedriften er ille ute") -> OK — omløpsmidlene dekker den kortsiktige gjelden
A33: = Arbeidskapital | B33: =B14-E18 -> 2110000 | F33: Omløpsmidler minus kortsiktig gjeld. Samme tall som marginen i regel 2.
A35: Egenkapitalen som differanse
A36: Sum eiendeler minus all gjeld | B36: =B20-(E12+E18) -> 2910000 | F36: Samme tall som sum egenkapital i E8. Egenkapital er ikke en konto — det er det som blir igjen.
A38: Hvor mye av omløpsmidlene er faktiske penger? | B38: =B13/B14 -> 0.15151515 | F38: Resten er materiell på lager og penger andre skylder deg.
A39: Bundet i lager og kundefordringer | B39: =B11+B12 -> 5600000
A40: Ganger bankinnskuddet | B40: =B39/B13 -> 5.6
A42: Prøv dette: sett kundefordringene i B12 til halvparten, som om kundene hadde betalt. Balansen slutter å balansere — og det er riktig. Pengene måtte i så fall dukket opp et annet sted, for eksempel som økt bankinnskudd i B13.
A43: Kilde: oppstillingen følger Økonomistyring for LØM-emnet, kap. 3.2. Tallene er Nordlys Elektro AS.

Sheet Aktivering
A1: Skal innkjøpet i balansen eller rett i resultatet?
A2: Endre pris og levetid i de gule cellene og se hva regelen svarer.
A4: 1 · Regelen
A5: Beløpsgrense | B5: 30000 | D5: Levetidsgrense, år | E5: 3 | F5: BEGGE vilkårene må være oppfylt for aktiveringsplikt.
A6: Kilde: skatteloven § 14-40 (Lovdata). Læreboka omtaler de samme to grensene i avsnitt 3.2.
A8: Innkjøp | B8: Pris | C8: Levetid, år | D8: Aktiveres? | E8: Kostnad i år 1 | F8: Hva skjer
A9: Servicebil | B9: 450000 | C9: 5 | D9: =IF(AND(B9>=$B$5,C9>=$E$5),"JA — i balansen","NEI — rett i resultatet") -> JA — i balansen | E9: =IF(AND(B9>=$B$5,C9>=$E$5),B9/C9,B9) -> 90000 | F9: Over beløpsgrensen og lang levetid. Aktiveres og avskrives lineært.
A10: Varmekamera til feilsøking | B10: 42000 | C10: 6 | D10: =IF(AND(B10>=$B$5,C10>=$E$5),"JA — i balansen","NEI — rett i resultatet") -> JA — i balansen | E10: =IF(AND(B10>=$B$5,C10>=$E$5),B10/C10,B10) -> 7000 | F10: Over beløpsgrensen og lang levetid. Samme behandling som bilen.
A11: Boremaskin | B11: 3500 | C11: 3 | D11: =IF(AND(B11>=$B$5,C11>=$E$5),"JA — i balansen","NEI — rett i resultatet") -> NEI — rett i resultatet | E11: =IF(AND(B11>=$B$5,C11>=$E$5),B11/C11,B11) -> 3500 | F11: Under beløpsgrensen. Hele beløpet utgiftsføres med én gang.
A12: Kabel og sikringsmateriell montert hos kunde | B12: 38000 | C12: 0 | D12: =IF(AND(B12>=$B$5,C12>=$E$5),"JA — i balansen","NEI — rett i resultatet") -> NEI — rett i resultatet | E12: =IF(AND(B12>=$B$5,C12>=$E$5),B12/C12,B12) -> 38000 | F12: Ikke et driftsmiddel i det hele tatt — brukt opp på en jobb. Varekostnad.
A14: 2 · Hva året faktisk koster
A15: Sum belastet resultatet i år 1 | B15: =SUM(E9:E12) -> 138500
A16: Sum ut av bankkontoen i år 1 | B16: =SUM(B9:B12) -> 533500
A17: = Differanse | B17: =B16-B15 -> 395000 | F17: Penger brukt, men ennå ikke kostnadsført. Nettopp denne differansen er grunnen til at overskudd og penger på konto ikke er det samme.
A19: Kontroll
A20: Er det brukt mer penger enn det som er kostnadsført? | B20: =IF(B17>0,"OK — differansen i B17 ligger i balansen som anleggsmidler og kostnadsføres over flere år","OK — alt som er kjøpt, er også kostnadsført i år") -> OK — differansen i B17 ligger i balansen som anleggsmidler og kostnadsføres over flere år
A21: Skal kabelen aktiveres? | B21: =IF(D12="NEI — rett i resultatet","OK — kabelen er montert hos kunden og brukt opp. Den er ikke et driftsmiddel, uansett hvor mye den koster","AVVIK: kabelen er ikke et driftsmiddel og skal aldri aktiveres — sett levetiden i C12 til 0") -> OK — kabelen er montert hos kunden og brukt opp. Den er ikke et driftsmiddel, uansett hvor mye den koster
A23: 3 · Avskrivningsplan for servicebilen
A24: År | B24: Avskrivning | C24: Bokført verdi ved årets slutt
A25: År 1 | B25: =IF(1<=$C$9,$E$9,0) -> 90000 | C25: =MAX($B$9-$E$9*MIN(1,$C$9),0) -> 360000 | E25: Lineær avskrivning: samme beløp hvert år, og bokført verdi null når levetiden er ute.
A26: År 2 | B26: =IF(2<=$C$9,$E$9,0) -> 90000 | C26: =MAX($B$9-$E$9*MIN(2,$C$9),0) -> 270000 | E26: Endre levetiden i C9 og se hvordan planen forskyver seg.
A27: År 3 | B27: =IF(3<=$C$9,$E$9,0) -> 90000 | C27: =MAX($B$9-$E$9*MIN(3,$C$9),0) -> 180000
A28: År 4 | B28: =IF(4<=$C$9,$E$9,0) -> 90000 | C28: =MAX($B$9-$E$9*MIN(4,$C$9),0) -> 90000
A29: År 5 | B29: =IF(5<=$C$9,$E$9,0) -> 90000 | C29: =MAX($B$9-$E$9*MIN(5,$C$9),0) -> 0
A30: År 6 | B30: =IF(6<=$C$9,$E$9,0) -> 0 | C30: =MAX($B$9-$E$9*MIN(6,$C$9),0) -> 0
A31: År 7 | B31: =IF(7<=$C$9,$E$9,0) -> 0 | C31: =MAX($B$9-$E$9*MIN(7,$C$9),0) -> 0
A33: Merk: avskrivning er ikke en utbetaling. Pengene forsvant da bilen ble kjøpt — kolonne B fordeler bare kostnaden over årene bilen brukes.
A34: Kilde: Økonomistyring for LØM-emnet, kap. 3.2. Aktiveringsgrensene følger skatteloven § 14-40 (Lovdata): kostpris minst 30 000 kroner OG økonomisk levetid minst 3 år. Oppstillingsplanene følger regnskapsloven kapittel 6 (Lovdata).

Sheet Til kapittel 4
A1: Fra balansen til nøkkeltallene
A2: Nøkkeltallene i kapittel 4 er ikke nye tall. De er denne balansen, delt på hverandre.
A4: 1 · De fem tallene som går videre
A5: Post | B5: Kroner | C5: Hva den brukes til i kapittel 4
A6: Sum eiendeler (totalkapital) | B6: =Balanse!B20 -> 10200000 | C6: Nevneren i totalkapitalrentabiliteten og i egenkapitalandelen.
A7: Sum egenkapital | B7: =Balanse!E8 -> 2910000 | C7: Nevneren i egenkapitalrentabiliteten, telleren i egenkapitalandelen.
A8: Sum kortsiktig gjeld | B8: =Balanse!E18 -> 4490000 | C8: Nevneren i begge likviditetsgradene.
A9: Sum omløpsmidler | B9: =Balanse!B14 -> 6600000 | C9: Telleren i likviditetsgrad 1.
A10: Varelager | B10: =Balanse!B11 -> 1400000 | C10: Trekkes ut av telleren i likviditetsgrad 2 — det er det minst likvide.
A12: 2 · De fire nøkkeltallene som regnes av balansen alene
A13: Nøkkeltall | B13: Slik regnes det | C13: Verdi | D13: Normtall eller bransje | E13: Vurdering
A14: Egenkapitalandel | B14: Egenkapital / totalkapital | C14: =B7/B6 -> 0.28529412 | D14: 0.362 | E14: =IF(C14>=D14,"På eller over bransjen","Under bransjen") -> Under bransjen
A15: Gjeldsgrad | B15: Sum gjeld / egenkapital | C15: =(B6-B7)/B7 -> 2.5051546 | D15: 5 | E15: =IF(C15<=D15,"Innenfor grensen","Over grensen") -> Innenfor grensen
A16: Likviditetsgrad 1 | B16: Omløpsmidler / kortsiktig gjeld | C16: =B9/B8 -> 1.4699332 | D16: 2 | E16: =IF(C16>=D16,"Over normtallet","Under normtallet") -> Under normtallet
A17: Likviditetsgrad 2 | B17: (Omløpsmidler − varelager) / kortsiktig gjeld | C17: =(B9-B10)/B8 -> 1.1581292 | D17: 1 | E17: =IF(C17>=D17,"Over normtallet","Under normtallet") -> Over normtallet
A19: 3 · Gjennomsnittstallene rentabiliteten regnes av
A20: Totalkapital 01.01.2026 (fra fjorårets balanse) | B20: 9400000
A21: Totalkapital 31.12.2026 | B21: =B6 -> 10200000
A22: = Gjennomsnittlig totalkapital | B22: =(B20+B21)/2 -> 9800000 | C22: Nevneren i totalkapitalrentabiliteten.
A23: Egenkapital 01.01.2026 | B23: =B7-Resultat!B18 -> 1982000 | C23: Årets overskudd er lagt til egenkapitalen, så vi trekker det fra igjen.
A24: Egenkapital 31.12.2026 | B24: =B7 -> 2910000
A25: = Gjennomsnittlig egenkapital | B25: =(B23+B24)/2 -> 2446000 | C25: Nevneren i egenkapitalrentabiliteten.
A27: Kontroll
A28: Er de fem tallene hentet fra balansen i dette regnearket? | B28: =IF(AND(B6=Balanse!B20,B7=Balanse!E8,B8=Balanse!E18,B9=Balanse!B14,B10=Balanse!B11),"OK — alle fem er formler mot arket Balanse. Endrer du en post der, endrer nøkkeltallet seg her","AVVIK: en av koblingene er brutt") -> OK — alle fem er formler mot arket Balanse. Endrer du en post der, endrer nøkkeltallet seg her
A29: Er egenkapitalandelen mellom null og hundre prosent? | B29: =IF(AND(C14>0,C14<1),"OK — egenkapitalandelen er en andel av totalkapitalen","AVVIK: egenkapitalen kan ikke være større enn totalkapitalen eller negativ") -> OK — egenkapitalandelen er en andel av totalkapitalen
A30: Er likviditetsgrad 2 lavere enn likviditetsgrad 1? | B30: =IF(C17<=C16,"OK — grad 2 er alltid lavest, fordi varelageret er trukket ut","AVVIK: varelageret kan ikke være negativt") -> OK — grad 2 er alltid lavest, fordi varelageret er trukket ut
A32: Dette er hele koblingen mellom kapittel 3 og kapittel 4: nøkkeltallene er ikke nye opplysninger. De er de samme tallene, satt opp mot hverandre, slik at de kan sammenliknes med i fjor og med bransjen.
A33: De tre siste nøkkeltallene — driftsmargin, totalkapitalrentabilitet og egenkapitalrentabilitet — trenger også tall fra resultatregnskapet. De regnes i regnearket til kapittel 4, LOM_Ovingsark_Okonomistyring_kap04_Nokkeltall_NY.xlsx, av nøyaktig den samme balansen og det samme resultatet.
A34: Kilde: Økonomistyring for LØM-emnet, kap. 3.2 og kap. 4.2. Bransjetall: NHO Elektro, Lønnsomhetsrapport 2025, gjengitt i Elektro 24-7 19.08.2026 (hentet 10.09.2026). De 809 er bedriftene i datagrunnlaget, ikke bransjen. NHO Elektro oppgir ikke svarprosent.

Sheet Min bedrift
A1: Din egen bedrift
A2: Hent tallene fra proff.no eller Brønnøysundregistrenes regnskapsregister og fyll inn de gule cellene.
A4: Bedrift | B4: Skriv inn navnet her | D4: Regnskapsår | E4: 2026
A6: Resultatregnskap | B6: Kroner | C6: Av salget | D6: Balanse | E6: Kroner
A7: Driftsinntekter | B7: 0 | C7: =IF($B$7=0,"",B7/$B$7) | D7: Sum anleggsmidler | E7: 0
A8: Varekostnad | B8: 0 | C8: =IF($B$7=0,"",B8/$B$7) | D8: Varelager | E8: 0
A9: = Bruttofortjeneste | B9: =B7-B8 -> 0 | C9: =IF($B$7=0,"",B9/$B$7) | D9: Kundefordringer | E9: 0
A10: Lønnskostnad | B10: 0 | C10: =IF($B$7=0,"",B10/$B$7) | D10: Bankinnskudd og kontanter | E10: 0
A11: Avskrivninger | B11: 0 | C11: =IF($B$7=0,"",B11/$B$7) | D11: = Sum omløpsmidler | E11: =SUM(E8:E10) -> 0
A12: Andre driftskostnader | B12: 0 | C12: =IF($B$7=0,"",B12/$B$7) | D12: = SUM EIENDELER | E12: =E7+E11 -> 0
A13: = Driftsresultat | B13: =B9-B10-B11-B12 -> 0 | C13: =IF($B$7=0,"",B13/$B$7) | D13: Sum egenkapital | E13: 0
A14: Netto finansposter (renteinntekter minus rentekostnader) | B14: 0 | D14: Langsiktig gjeld | E14: 0
A15: = Resultat før skattekostnad | B15: =B13+B14 -> 0 | D15: Kortsiktig gjeld | E15: 0
A16: Skattekostnad | B16: 0 | D16: = SUM EGENKAPITAL OG GJELD | E16: =E13+E14+E15 -> 0
A17: = Årsresultat | B17: =B15-B16 -> 0 | C17: =IF($B$7=0,"",B17/$B$7) | D17: Differanse | E17: =E12-E16 -> 0 | F17: Skal være 0. Er den ikke det, har du glemt en post.
A19: Det du skal se etter
A20: Driftsmargin | B20: =IF($B$7=0,"",B13/$B$7) | D20: Bransjen ligger på | E20: 0.075
A21: Lønnsandel av omsetningen | B21: =IF($B$7=0,"",B10/$B$7) | F21: Den største enkeltposten i de fleste installasjonsbedrifter.
A22: Egenkapitalandel | B22: =IF(E12=0,"",E13/E12) | D22: Bransjen ligger på | E22: 0.362
A23: Arbeidskapital | B23: =IF(E12=0,"",E11-E15) | F23: Omløpsmidler minus kortsiktig gjeld. Må være positiv.
A25: Kontroll
A26: Balanserer din balanse? | B26: =IF(E12=0,"Ikke fylt ut ennå",IF(E17=0,"OK — de to sidene er like store","AVVIK: differansen står i E17 — du har glemt en post")) -> Ikke fylt ut ennå
A27: Er anleggsmidlene langsiktig finansiert? | B27: =IF(E12=0,"Ikke fylt ut ennå",IF(E13+E14>E7,"OK — egenkapital og langsiktig gjeld dekker anleggsmidlene","AVVIK: anleggsmidlene er kortsiktig finansiert")) -> Ikke fylt ut ennå
A28: Dekker omløpsmidlene den kortsiktige gjelden? | B28: =IF(E12=0,"Ikke fylt ut ennå",IF(E11>E15,"OK — arbeidskapitalen er positiv","AVVIK: den kortsiktige gjelden er større enn omløpsmidlene")) -> Ikke fylt ut ennå
A30: Får du ikke tak i alle postene, spør regnskapsføreren om «resultat og balanse for i fjor og året før». Det er alt du trenger — og to år er bedre enn ett, fordi retningen sier mer enn nivået.

Sheet Scenario
A1: To scenarioer
A2: Endre de gule cellene og se hva som skjer. Alle tall hentes fra arkene Resultat og Balanse.
A4: Scenario A · hvor mye kan du frigjøre uten å selge én time mer?
A5: Oppgave 4 i øvingsheftet. Kapitalen ligger i kundefordringer og på lager — her ser du hva den er verdt i kroner.
A7: Salgsinntekt | B7: =Resultat!B5 -> 22400000
A8: Kundefordringer i dag | B8: =Balanse!B12 -> 4200000
A9: Faktisk kredittid til kundene, dager | B9: =B8/B7*365 -> 68.4375 | E9: Kundefordringene omregnet til dager med omsetning.
A10: Kredittid du sikter mot, dager | B10: 20 | E10: Endre denne og se hva som frigjøres.
A11: = Kundefordringer ved den kredittiden | B11: =B7*B10/365 -> 1227397.3
A12: = Frigjort kapital | B12: =B8-B11 -> 2972602.7 | E12: Penger som kommer inn på konto, uten at én time til er solgt.
A14: Varelager i dag | B14: =Balanse!B11 -> 1400000
A15: Reduksjon i varelager du sikter mot | B15: 0.2
A16: = Frigjort kapital fra lageret | B16: =B14*B15 -> 280000
A17: = Sum frigjort | B17: =B12+B16 -> 3252602.7
A18: Bankinnskudd i dag | B18: =Balanse!B13 -> 1000000
A19: Bankinnskudd etterpå | B19: =B18+B17 -> 4252602.7
A21: Grovt anslag på penger fra driften i året
A22: Årsresultat | B22: =Resultat!B18 -> 928000
A23: + Avskrivninger | B23: =Resultat!B10 -> 620000
A24: = Penger fra drift, grovt anslag | B24: =B22+B23 -> 1548000 | E24: Avskrivninger er en kostnad uten utbetaling, og legges derfor tilbake.
A26: Kontroll
A27: Er faktisk kredittid lengre enn den du sikter mot? | B27: =IF(B9>B10,"AVVIK: kundene bruker lengre tid enn avtalt. Differansen er penger Nordlys låner ut gratis","OK — kundene betaler innenfor den kredittiden du sikter mot") -> AVVIK: kundene bruker lengre tid enn avtalt. Differansen er penger Nordlys låner ut gratis
A28: Her SKAL det stå AVVIK med tallene som ligger inne. Det er hele poenget i oppgave 4 og i oppgave 5.
A29: Er det frigjorte beløpet større enn bankinnskuddet? | B29: =IF(B17>B18,"OK — det ligger mer penger i kundefordringer og lager enn på konto. Det er der du henter likviditet først","OK — bankinnskuddet er større enn det du kan frigjøre") -> OK — det ligger mer penger i kundefordringer og lager enn på konto. Det er der du henter likviditet først
A32: Scenario B · banken leser regnskapet
A33: Oppgave 5 i øvingsheftet. Alle nøkkeltallene regnes av balansen i dette regnearket — de samme kapittel 4 bruker.
A35: Kassekredittramme i dag | B35: 1000000
A36: Ny ramme det søkes om | B36: 2000000
A37: Avtalt kredittid til kundene, dager | B37: 20
A38: Trukket på kassekreditten ved årsskiftet | B38: =Balanse!E17 -> 300000
A39: Utnyttelse av rammen | B39: =B38/B35 -> 0.3
A40: = Økning det søkes om | B40: =B36-B35 -> 1000000
A42: Det banken ser på først
A43: Egenkapitalandel | B43: ='Til kapittel 4'!C14 -> 0.28529412 | C43: ='Til kapittel 4'!D14 -> 0.362 | E43: Kolonne C: bransjen. Det er egenkapitalen som må tape før det blir bankens penger.
A44: Likviditetsgrad 1 | B44: ='Til kapittel 4'!C16 -> 1.4699332 | C44: ='Til kapittel 4'!D16 -> 2
A45: Likviditetsgrad 2 | B45: ='Til kapittel 4'!C17 -> 1.1581292 | C45: ='Til kapittel 4'!D17 -> 1
A46: Gjeldsgrad | B46: ='Til kapittel 4'!C15 -> 2.5051546 | C46: ='Til kapittel 4'!D15 -> 5
A47: Arbeidskapital | B47: =Balanse!B33 -> 2110000
A49: Spørsmålet banken kommer til å stille
A50: Faktisk kredittid til kundene, dager | B50: =Balanse!B12/Resultat!B5*365 -> 68.4375
...
