Workbook

Sheet Veiledning
A1: Delbudsjetter og hovedbudsjetter
A2: LØM Økonomistyring kap. 9 · arbeidsregneark · Fagskolen Oslo, Avdeling Elkraft
A3: Emne: Teknisk kommunikasjon og ledelse for 1ET-klassene · LØM for 2ET, 2EK, 3EK og 4EK
A4: Fargekode
A5: Gul celle med blå skrift | B5: Inndata — dette er tallene du endrer.
A6: Grå eller lyseblå celle, svart skrift | B6: Formel — regner seg selv. Ikke skriv over den.
A7: Mørkeblå rad med hvit skrift | B7: Kolonneoverskrift.
A9: Ark i arbeidsboka
A10: Salgsbudsjett | B10: Motoren. Fakturerte montørtimer ganget med timeprisen, pluss materiell med påslag. Alt annet henger i dette arket.
A11: Materiellbudsjett | B11: Fra materiellsalg til inntakskost til varekjøp. Her ser du forskjellen på hva bedriften BRUKER og hva den KJØPER.
A12: Lønnsbudsjett | B12: Antall folk ganget med månedslønn, pluss feriepenger og arbeidsgiveravgift. Og de tre ulike tidspunktene pengene går ut.
A13: Andre kostnader | B13: Kostnadsbudsjettet, delt i en variabel del som følger salget og en fast del som løper uansett.
A14: Investering og finans | B14: Investeringsbudsjett, avskrivningsbudsjett og finansbudsjett. Avdrag, investering og utbytte samlet på ett sted.
A15: Mva-budsjett | B15: Seks terminer. Utgående avgift fra salgsbudsjettet, inngående fra alle de andre. Aldri en kostnad, alltid en utbetaling.
A16: Resultatbudsjett | B16: Hovedbudsjett 1. Ikke én gul celle — hver linje er hentet fra et delbudsjett.
A17: Likviditetsbudsjett | B17: Hovedbudsjett 2. Tolv måneder, satt opp i tre nivåer: drift, finansiering og investering.
A18: Balansebudsjett | B18: Hovedbudsjett 3. Inngående balanse, budsjettert endring, utgående balanse. Prøven på om de to andre henger sammen.
A19: Budsjettkontroll | B19: 2026 mot budsjettet, delbudsjett for delbudsjett. De to siste kolonnene er tomme — de er dine.
A20: Scenario | B20: Fire knapper: omsetningsvekst, lønnsvekst og de to kredittidene. Se hva hver av dem gjør med resultatet og med kontoen.
A22: Tallene som ligger inne er budsjettet Nordlys Elektro AS har lagt for 2027, og budsjettkontrollen for 2026. Samme bedrift som i alle ti kapitlene i Bok 1.
A23: Rekkefølgen på fanene er rekkefølgen du bygger et budsjett i: delbudsjettene først, hovedbudsjettene etterpå.
A24: Vil du bruke arbeidsboka på din egen bedrift, bytter du ut de gule cellene i de seks delbudsjettene. Hovedbudsjettene følger etter av seg selv.
A26: Tallene som ligger inne er et eksempel fra en elektrobedrift. Bytt dem ut med dine egne — alle formler følger med.
A27: Arbeidsregneark til LØM · Fagskolen Oslo, Avdeling Elkraft. Regnearket er øvingsstøtte, ikke et regnskapssystem.
A29: Hva denne arbeidsboka gjør som den andre ikke gjør
A30: Arbeidsboka «Budsjett» viser resultatbudsjettet og likviditetsbudsjettet ferdig oppstilt, og lar deg skru på kredittiden. Denne arbeidsboka viser hvor tallene i dem kommer fra: seks delbudsjetter som bygger seg opp til tre hovedbudsjetter. Bruk «Budsjett» når du skal forstå forskjellen på resultat og likviditet. Bruk denne når du skal sette opp et budsjett selv.
A31: De to bøkene gir samme driftsresultat for 2027. Bunnen i likviditetsbudsjettet skiller seg med noen tusen kroner, fordi andre driftskostnader her er delt i en variabel og en fast del og derfor fordeler seg litt annerledes over året. Årssummene er de samme.
A33: Veien gjennom arbeidsboka
A34: Steg | B34: Ark | C34: Hva du gjør
A35: 1 · Hvor mye skal vi selge? | B35: Salgsbudsjett | C35: Legg inn fakturerte montørtimer og materiellsalg per måned. Dette er den eneste gjetningen i hele budsjettet — alt annet følger av den.
A36: 2 · Hva må vi kjøpe inn? | B36: Materiellbudsjett | C36: Materiellsalget delt på påslaget gir inntakskosten. Legg til innleie, juster for lagerendring, og du har innkjøpsbudsjettet.
A37: 3 · Hva koster folkene? | B37: Lønnsbudsjett | C37: Antall ganget med månedslønn, pluss feriepenger og arbeidsgiveravgift.
A38: 4 · Hva koster resten? | B38: Andre kostnader | C38: Del posten i det som følger salget og det som løper uansett.
A39: 5 · Hva skal vi kjøpe og betale ned? | B39: Investering og finans | C39: Investering, avskrivninger, avdrag, renter, utbytte og forhåndsskatt.
A40: 6 · Hva skylder vi staten? | B40: Mva-budsjett | C40: Utgående minus inngående avgift, termin for termin.
A41: 7 · Tjener vi penger? | B41: Resultatbudsjett | C41: Les av. Ikke skriv. Hele arket er formler.
A42: 8 · Har vi penger? | B42: Likviditetsbudsjett | C42: Les av bunnen i B67 og måneden i B68. Sammenlikn med driftsresultatet i B75.
A43: 9 · Henger det sammen? | B43: Balansebudsjett | C43: Går sum eiendeler opp mot sum egenkapital og gjeld, er budsjettet konsistent.
A44: 10 · Hva gikk galt i fjor? | B44: Budsjettkontroll | C44: Avvik i kroner og prosent per delbudsjett. Skriv forklaringen selv.
A45: 11 · Hva om det går annerledes? | B45: Scenario | C45: Fire knapper. To flytter resultatet, alle fire flytter kontoen.
...

Sheet Salgsbudsjett
A1: Salgsbudsjett 2027
A2: Motoren. Alt annet i arbeidsboka henger i dette arket — både det bedriften tjener og det som kommer inn på konto.
A4: 1 · Forutsetningene
A5: Timepris ut, kroner per fakturert montørtime | B5: 890 | O5: Prisen kunden betaler for én montørtime, uten merverdiavgift. Den er bygd opp fra kostnadene i kapittel 5.
A6: Materiellpåslag | B6: 0.2 | O6: Det Nordlys legger oppå innkjøpsprisen på materiellet. Påslaget skal dekke svinn, lagerplass og bestillingsarbeid.
A7: Merverdiavgiftssats | B7: 0.25 | O7: Alminnelig sats. Merverdiavgift er ikke en kostnad — den kreves inn fra kunden og sendes videre til staten.
A8: Vekst i omsetningen, hentet fra arket Scenario | B8: =Scenario!$B$6 | O8: Står på null i grunnbudsjettet. Skru på den i arket Scenario.
A9: = Vekstfaktor | B9: =1+B8
A11: 2 · Salgsbudsjettet måned for måned
A12: Post | B12: År | C12: Jan | D12: Feb | E12: Mar | F12: Apr | G12: Mai | H12: Jun | I12: Jul | J12: Aug | K12: Sep | L12: Okt | M12: Nov | N12: Des | O12: Kommentar
A13: Månedsnummer | C13: =1 | D13: =2 | E13: =3 | F13: =4 | G13: =5 | H13: =6 | I13: =7 | J13: =8 | K13: =9 | L13: =10 | M13: =11 | N13: =12
A14: Fakturerte montørtimer | B14: =SUM(C14:N14) | C14: 1154 | D14: 1347 | E14: 1411 | F14: 1347 | G14: 1282 | H14: 1282 | I14: 770 | J14: 1218 | K14: 1347 | L14: 1411 | M14: 1475 | N14: 1346 | O14: Timene montørene får skrevet på en kunde. Tynn januar, stille juli, tunge høstmåneder — slik året ser ut i en installasjonsbedrift.
A15: Timeomsetning | B15: =SUM(C15:N15) | C15: =C14*$B$5*$B$9 | D15: =D14*$B$5*$B$9 | E15: =E14*$B$5*$B$9 | F15: =F14*$B$5*$B$9 | G15: =G14*$B$5*$B$9 | H15: =H14*$B$5*$B$9 | I15: =I14*$B$5*$B$9 | J15: =J14*$B$5*$B$9 | ... N15: =N14*$B$5*$B$9 | O15: Timer ganget med timepris.
A16: Materiellsalg til kunde, grunnbudsjett | B16: =SUM(C16:N16) | C16: 772940 | D16: 901170 | E16: 944210 | F16: 901170 | G16: 859020 | H16: 859020 | I16: 514700 | J16: 815980 | K16: 901170 | L16: 944210 | M16: 987250 | N16: 902060 | O16: Materiellet slik det står på fakturaen til kunden, altså med påslaget på.
A17: Materiellomsetning | B17: =SUM(C17:N17) | C17: =C16*$B$9 | D17: =D16*$B$9 | E17: =E16*$B$9 | F17: =F16*$B$9 | G17: =G16*$B$9 | H17: =H16*$B$9 | I17: =I16*$B$9 | J17: =J16*$B$9 | ... N17: =N16*$B$9
A18: = Salgsinntekt uten merverdiavgift | B18: =SUM(C18:N18) | C18: =C15+C17 | D18: =D15+D17 | E18: =E15+E17 | F18: =F15+F17 | G18: =G15+G17 | H18: =H15+H17 | I18: =I15+I17 | J18: =J15+J17 | ... N18: =N15+N17 | O18: Denne linja går rett inn i resultatbudsjettet.
A19: + Utgående merverdiavgift | B19: =SUM(C19:N19) | C19: =C18*$B$7 | D19: =D18*$B$7 | E19: =E18*$B$7 | F19: =F18*$B$7 | G19: =G18*$B$7 | H19: =H18*$B$7 | I19: =I18*$B$7 | J19: =J18*$B$7 | ... N19: =N18*$B$7 | O19: Går inn i mva-budsjettet.
A20: = Salgsinntekt inkl. merverdiavgift | B20: =SUM(C20:N20) | C20: =C18+C19 | D20: =D18+D19 | E20: =E18+E19 | F20: =F18+F19 | G20: =G18+G19 | H20: =H18+H19 | I20: =I18+I19 | J20: =J18+J19 | ... N20: =N18+N19 | O20: Dette er beløpet kunden betaler, og det er dette som kommer inn på konto — men først når kunden har betalt.
A21: Grunnbudsjettet, uten vekst | B21: =SUM(C21:N21) | C21: =C14*$B$5+C16 | D21: =D14*$B$5+D16 | E21: =E14*$B$5+E16 | F21: =F14*$B$5+F16 | G21: =G14*$B$5+G16 | H21: =H14*$B$5+H16 | I21: =I14*$B$5+I16 | J21: =J14*$B$5+J16 | ... N21: =N14*$B$5+N16 | O21: Salget slik det er budsjettert, før scenarioknappene. Brukes av kostnadsbudsjettet til å skille faste fra variable kostnader.
A23: 3 · Kontroll
A24: Salgsinntekten Nordlys har budsjettert for 2027 | B24: 24000000
A25: Treffer grunnbudsjettet det budsjettet sier? | B25: =IF(ABS(B21-B24)<1,"OK — salgsbudsjettet summerer seg til den salgsinntekten bedriften har lagt inn","AVVIK: timene, timeprisen eller materiellsalget gir ikke den budsjetterte salgsinntekten")
A26: Blir det materiell å selge i alle månedene? | B26: =IF(MIN(C16:N16)>0,"OK — alle månedene har både timer og materiell","AVVIK: én av månedene har negativt materiellsalg — da er timene eller timeprisen satt for høyt")
A27: Summerer månedene seg til året? | B27: =IF(ABS(SUM(C18:N18)-B18)<1,"OK — de tolv månedene summerer seg til årsbudsjettet","AVVIK: månedene og året gir ulik salgsinntekt")
A29: Prøv dette: flytt 200 timer fra juli til august. Salgsinntekten for året står stille, men se hva som skjer med driftsresultatet i juli i resultatbudsjettet — de faste kostnadene løper uansett.
A30: Kilde: Bok 1 kap. 9.2. Timepris og materiellpåslag er de samme som i kapittel 5. Hjertnes, J. og Skorpen, K.: Økonomistyring for LØM-emnet (ISBN 978-82-450-5544-3), kapittel 9 «Budsjettering og budsjettkontroll»

Sheet Materiellbudsjett
A1: Materiell- og innkjøpsbudsjett 2027
A2: Forbruk er ikke det samme som innkjøp. Det er innkjøpet som skal betales.
A4: 1 · Forutsetningene
A5: Materiellpåslag | B5: =Salgsbudsjett!$B$6 | O5: Hentet fra salgsbudsjettet. Endrer du satsen der, endrer den seg her.
A6: Merverdiavgiftssats | B6: =Salgsbudsjett!$B$7
A7: Vekstfaktor | B7: =Salgsbudsjett!$B$9
A9: 2 · Fra materiellsalg til varekjøp
A10: Post | B10: År | C10: Jan | D10: Feb | E10: Mar | F10: Apr | G10: Mai | H10: Jun | I10: Jul | J10: Aug | K10: Sep | L10: Okt | M10: Nov | N10: Des | O10: Kommentar
A11: Månedsnummer | C11: =1 | D11: =2 | E11: =3 | F11: =4 | G11: =5 | H11: =6 | I11: =7 | J11: =8 | K11: =9 | L11: =10 | M11: =11 | N11: =12
A12: Materiellomsetning, fra salgsbudsjettet | B12: =SUM(C12:N12) | C12: =Salgsbudsjett!C17 | D12: =Salgsbudsjett!D17 | E12: =Salgsbudsjett!E17 | F12: =Salgsbudsjett!F17 | G12: =Salgsbudsjett!G17 | H12: =Salgsbudsjett!H17 | I12: =Salgsbudsjett!I17 | J12: =Salgsbudsjett!J17 | ... N12: =Salgsbudsjett!N17
A13: = Materiellforbruk, inntakskost | B13: =SUM(C13:N13) | C13: =C12/(1+$B$5) | D13: =D12/(1+$B$5) | E13: =E12/(1+$B$5) | F13: =F12/(1+$B$5) | G13: =G12/(1+$B$5) | H13: =H12/(1+$B$5) | I13: =I12/(1+$B$5) | J13: =J12/(1+$B$5) | ... N13: =N12/(1+$B$5) | O13: Vi går baklengs gjennom påslaget: 20 prosent oppå inntakskosten betyr at fakturabeløpet deles på 1,20. Dette er det Nordlys selv betaler Polarlys Elektro Grossist AS for varene.
A14: Innleide montører, grunnbudsjett | B14: =SUM(C14:N14) | C14: 31068.75 | D14: 36246.88 | E14: 37972.92 | F14: 36246.88 | G14: 34520.83 | H14: 34520.83 | I14: 20712.5 | J14: 32794.79 | K14: 36246.88 | L14: 37972.92 | M14: 39698.96 | N14: 36246.88 | O14: Andre firmaer Nordlys leier inn på store prosjekter. Posten sto på 3 660 000 kroner i 2026.
A15: Innleide montører | B15: =SUM(C15:N15) | C15: =C14*$B$7 | D15: =D14*$B$7 | E15: =E14*$B$7 | F15: =F14*$B$7 | G15: =G14*$B$7 | H15: =H14*$B$7 | I15: =I14*$B$7 | J15: =J14*$B$7 | ... N15: =N14*$B$7
A16: = Varekostnad | B16: =SUM(C16:N16) | C16: =C13+C15 | D16: =D13+D15 | E16: =E13+E15 | F16: =F13+F15 | G16: =G13+G15 | H16: =H13+H15 | I16: =I13+I15 | J16: =J13+J15 | ... N16: =N13+N15 | O16: Dette er FORBRUKET, og det er denne linja som går inn i resultatbudsjettet.
A17: Planlagt lagerendring | B17: =SUM(C17:N17) | C17: 0 | D17: 0 | E17: 0 | F17: 0 | G17: 0 | H17: 0 | I17: 0 | J17: 0 | K17: 0 | L17: 0 | M17: 0 | N17: 0 | O17: Null betyr at lageret er like stort 31. desember som 1. januar. Skal lageret bygges opp, må du kjøpe mer enn du bruker — sett for eksempel 50 000 i hver måned og se hva det gjør med kontoen.
A18: = Varekjøp uten merverdiavgift | B18: =SUM(C18:N18) | C18: =C16+C17 | D18: =D16+D17 | E18: =E16+E17 | F18: =F16+F17 | G18: =G16+G17 | H18: =H16+H17 | I18: =I16+I17 | J18: =J16+J17 | ... N18: =N16+N17 | O18: Dette er INNKJØPET. Det er dette som skal betales, ikke forbruket.
A19: + Inngående merverdiavgift | B19: =SUM(C19:N19) | C19: =C18*$B$6 | D19: =D18*$B$6 | E19: =E18*$B$6 | F19: =F18*$B$6 | G19: =G18*$B$6 | H19: =H18*$B$6 | I19: =I18*$B$6 | J19: =J18*$B$6 | ... N19: =N18*$B$6 | O19: Går inn i mva-budsjettet og trekkes fra den utgående avgiften.
A20: = Varekjøp inkl. merverdiavgift | B20: =SUM(C20:N20) | C20: =C18+C19 | D20: =D18+D19 | E20: =E18+E19 | F20: =F18+F19 | G20: =G18+G19 | H20: =H18+H19 | I20: =I18+I19 | J20: =J18+J19 | ... N20: =N18+N19 | O20: Regningen fra grossisten. Den går inn i likviditetsbudsjettet.
A22: Bruttofortjeneste i kroner | B22: =SUM(C22:N22) | C22: =Salgsbudsjett!C18-C16 | D22: =Salgsbudsjett!D18-D16 | E22: =Salgsbudsjett!E18-E16 | F22: =Salgsbudsjett!F18-F16 | G22: =Salgsbudsjett!G18-G16 | H22: =Salgsbudsjett!H18-H16 | I22: =Salgsbudsjett!I18-I16 | J22: =Salgsbudsjett!J18-J16 | ... N22: =Salgsbudsjett!N18-N16
A23: Bruttofortjeneste i prosent | B23: =B22/Salgsbudsjett!B18 | C23: =C22/Salgsbudsjett!C18 | D23: =D22/Salgsbudsjett!D18 | E23: =E22/Salgsbudsjett!E18 | F23: =F22/Salgsbudsjett!F18 | G23: =G22/Salgsbudsjett!G18 | H23: =H22/Salgsbudsjett!H18 | I23: =I22/Salgsbudsjett!I18 | ... N23: =N22/Salgsbudsjett!N18 | O23: Det som blir igjen av salget når varene er betalt. Alt annet — lønn, husleie, bil — skal dekkes av disse kronene.
A25: 3 · Kontroll
A26: Bruttofortjenesten Nordlys har budsjettert | B26: 0.625
A27: Treffer budsjettet bruttofortjenesten? | B27: =IF(ABS(B23-B26)<0.001,"OK — materiellpåslaget og innleien gir nøyaktig den bruttofortjenesten budsjettet forutsetter","AVVIK: bruttofortjenesten stemmer ikke med forutsetningen i B26")
A28: Er varekjøpet større eller mindre enn forbruket? | B28: =IF(ABS(B17)<1,"OK — lageret er uendret, så varekjøp og vareforbruk er like store","MERK — lageret endrer seg. Da er varekjøpet noe annet enn vareforbruket, og det er nettopp poenget")
A29: Blir noen av postene negative? | B29: =IF(MIN(C18:N18)>=0,"OK — alle månedene har et varekjøp som gir mening","AVVIK: én måned får negativt varekjøp — lagerendringen er satt for lav")
A31: Regelen: resultatbudsjettet skal ha vareFORBRUKET. Likviditetsbudsjettet skal ha vareINNKJØPET. Er lageret uendret, er de like store — og da er det lett å tro at de alltid er det.
A32: Kilde: Bok 1 kap. 9.4.3. Materiellpåslaget står i kapittel 5.

Sheet Lønnsbudsjett
A1: Lønnsbudsjett 2027
A2: Én lønn, tre tidspunkter: når den koster, når den utbetales, og når avgiftene forfaller.
A4: 1 · Forutsetningene
A5: Antall montører og lærlinger | B5: 14 | O5: 12 montører og 2 lærlinger. Det er disse timene som faktureres.
A6: Gjennomsnittlig månedslønn, montør eller lærling | B6: 39500 | O6: Gjennomsnittet i casebedriften. Kronene i Nordlys er holdt små og runde for at regnestykkene skal gå an å følge i hodet — i en virkelig elektrobedrift ligger månedslønna høyere. Bytt tallet med ditt eget; oppsettet er det samme.
A7: Antall i administrasjon og ledelse | B7: 4 | O7: Daglig leder, driftsleder service, formann prosjekt og kalkulatør.
A8: Gjennomsnittlig månedslønn, administrasjon | B8: 36750
A9: Feriepengesats | B9: 0.12 | O9: Lovens normalsats. 14,3 prosent for arbeidstakere over 60 år.
A10: Arbeidsgiveravgiftssats | B10: 0.141 | O10: Sats for Oslo. Satsen bestemmes av hvor virksomheten ligger, og går helt ned til null i deler av Nord-Troms og Finnmark.
A11: Lønnsvekst, hentet fra arket Scenario | B11: =Scenario!$B$7
A12: = Lønnsfaktor | B12: =1+B11
A13: Skyldige feriepenger 31.12.2026 | B13: 890000 | O13: Opptjent i 2026, kostnadsført i 2026, utbetalt i 2027. Ikke en krone av dette er kostnad i 2027 — men pengene går ut av kontoen.
A14: Måneden feriepengene utbetales | B14: 6
A15: Skyldig arbeidsgiveravgift 6. termin 2026 | B15: 136000 | O15: Avgiften på november- og desemberlønna 2026. Forfaller 15. januar 2027.
A17: 2 · Lønnskostnaden måned for måned
A18: Post | B18: År | C18: Jan | D18: Feb | E18: Mar | F18: Apr | G18: Mai | H18: Jun | I18: Jul | J18: Aug | K18: Sep | L18: Okt | M18: Nov | N18: Des | O18: Kommentar
A19: Månedsnummer | C19: =1 | D19: =2 | E19: =3 | F19: =4 | G19: =5 | H19: =6 | I19: =7 | J19: =8 | K19: =9 | L19: =10 | M19: =11 | N19: =12
A20: Produksjonslønn | B20: =SUM(C20:N20) | C20: =$B$5*$B$6*$B$12 | D20: =$B$5*$B$6*$B$12 | E20: =$B$5*$B$6*$B$12 | F20: =$B$5*$B$6*$B$12 | G20: =$B$5*$B$6*$B$12 | H20: =$B$5*$B$6*$B$12 | I20: =$B$5*$B$6*$B$12 | J20: =$B$5*$B$6*$B$12 | ... N20: =$B$5*$B$6*$B$12
A21: Administrasjonslønn | B21: =SUM(C21:N21) | C21: =$B$7*$B$8*$B$12 | D21: =$B$7*$B$8*$B$12 | E21: =$B$7*$B$8*$B$12 | F21: =$B$7*$B$8*$B$12 | G21: =$B$7*$B$8*$B$12 | H21: =$B$7*$B$8*$B$12 | I21: =$B$7*$B$8*$B$12 | J21: =$B$7*$B$8*$B$12 | ... N21: =$B$7*$B$8*$B$12
A22: = Brutto lønn | B22: =SUM(C22:N22) | C22: =C20+C21 | D22: =D20+D21 | E22: =E20+E21 | F22: =F20+F21 | G22: =G20+G21 | H22: =H20+H21 | I22: =I20+I21 | J22: =J20+J21 | ... N22: =N20+N21 | O22: Det som står på lønnsslippen før skattetrekk.
A23: + Feriepenger opptjent | B23: =SUM(C23:N23) | C23: =C22*$B$9 | D23: =D22*$B$9 | E23: =E22*$B$9 | F23: =F22*$B$9 | G23: =G22*$B$9 | H23: =H22*$B$9 | I23: =I22*$B$9 | J23: =J22*$B$9 | ... N23: =N22*$B$9 | O23: Retten opptjenes hver gang lønn utbetales. Kostnaden hører til i 2027, pengene går ut i 2028.
A24: + Arbeidsgiveravgift | B24: =SUM(C24:N24) | C24: =(C22+C23)*$B$10 | D24: =(D22+D23)*$B$10 | E24: =(E22+E23)*$B$10 | F24: =(F22+F23)*$B$10 | G24: =(G22+G23)*$B$10 | H24: =(H22+H23)*$B$10 | I24: =(I22+I23)*$B$10 | J24: =(J22+J23)*$B$10 | ... N24: =(N22+N23)*$B$10 | O24: Regnes av både lønn og feriepenger.
A25: = Lønnskostnad | B25: =SUM(C25:N25) | C25: =C22+C23+C24 | D25: =D22+D23+D24 | E25: =E22+E23+E24 | F25: =F22+F23+F24 | G25: =G22+G23+G24 | H25: =H22+H23+H24 | I25: =I22+I23+I24 | J25: =J22+J23+J24 | ... N25: =N22+N23+N24 | O25: Denne linja går inn i resultatbudsjettet.
A27: 3 · Når pengene går ut
A28: Utbetalt lønn, inkludert forskuddstrekk | B28: =SUM(C28:N28) | C28: =C22 | D28: =D22 | E28: =E22 | F28: =F22 | G28: =G22 | H28: =H22 | I28: =I22 | J28: =J22 | ... N28: =N22 | O28: Forskuddstrekket betales til Skatteetaten senest første virkedag etter lønnsutbetalingen (skattetrekkskontoen ble avviklet 1.1.2026). Pengene forlater derfor kassen samme måned som lønna, ikke ved neste termin.
A29: Utbetalt feriepenger opptjent i 2026 | B29: =SUM(C29:N29) | C29: =IF(C19=$B$14,$B$13,0) | D29: =IF(D19=$B$14,$B$13,0) | E29: =IF(E19=$B$14,$B$13,0) | F29: =IF(F19=$B$14,$B$13,0) | G29: =IF(G19=$B$14,$B$13,0) | H29: =IF(H19=$B$14,$B$13,0) | I29: =IF(I19=$B$14,$B$13,0) | J29: =IF(J19=$B$14,$B$13,0) | ... N29: =IF(N19=$B$14,$B$13,0) | O29: Én måned i året går det ut nesten to månedslønner. Dette er måneden mange bedrifter oppdager at de har for lite på konto.
A30: Arbeidsgiveravgift til betaling | B30: =SUM(C30:N30) | C30: =IF(C19=1,$B$15,0)+IF(C19=$B$14+1,$B$13*$B$10,0) | D30: =IF(D19=1,$B$15,0)+IF(D19=$B$14+1,$B$13*$B$10,0) | E30: =IF(E19=1,$B$15,0)+IF(AND(MOD(E19,2)=1,E19>=3),(C22+D22)*$B$10,0)+IF(E19=$B$14+1,$B$13*$B$10,0) | F30: =IF(F19=1,$B$15,0)+IF(AND(MOD(F19,2)=1,F19>=3),(D22+E22)*$B$10,0)+IF(F19=$B$14+1,$B$13*$B$10,0) | G30: =IF(G19=1,$B$15,0)+IF(AND(MOD(G19,2)=1,G19>=3),(E22+F22)*$B$10,0)+IF(G19=$B$14+1,$B$13*$B$10,0) | H30: =IF(H19=1,$B$15,0)+IF(AND(MOD(H19,2)=1,H19>=3),(F22+G22)*$B$10,0)+IF(H19=$B$14+1,$B$13*$B$10,0) | I30: =IF(I19=1,$B$15,0)+IF(AND(MOD(I19,2)=1,I19>=3),(G22+H22)*$B$10,0)+IF(I19=$B$14+1,$B$13*$B$10,0) | J30: =IF(J19=1,$B$15,0)+IF(AND(MOD(J19,2)=1,J19>=3),(H22+I22)*$B$10,0)+IF(J19=$B$14+1,$B$13*$B$10,0) | K30: =IF(K19=1,$B$15,0)+IF(AND(MOD(K19,2)=1,K19>=3),(I22+J22)*$B$10,0)+IF(K19=$B$14+1,$B$13*$B$10,0) | L30: =IF(L19=1,$B$15,0)+IF(AND(MOD(L19,2)=1,L19>=3),(J22+K22)*$B$10,0)+IF(L19=$B$14+1,$B$13*$B$10,0) | ... N30: =IF(N19=1,$B$15,0)+IF(AND(MOD(N19,2)=1,N19>=3),(L22+M22)*$B$10,0)+IF(N19=$B$14+1,$B$13*$B$10,0) | O30: Seks terminer à to måneder, forfall den 15. i måneden etter terminslutt. Januar bærer terminen fra 2026, og måneden etter feriepengeutbetalingen bærer avgiften på feriepengene.
A31: = Sum utbetalinger fra lønnsbudsjettet | B31: =SUM(C31:N31) | C31: =C28+C29+C30 | D31: =D28+D29+D30 | E31: =E28+E29+E30 | F31: =F28+F29+F30 | G31: =G28+G29+G30 | H31: =H28+H29+H30 | I31: =I28+I29+I30 | J31: =J28+J29+J30 | ... N31: =N28+N29+N30
A33: 4 · Det som blir stående som gjeld 31.12.2027
A34: Skyldige feriepenger | B34: =SUM(C23:N23) | O34: Alt som er opptjent i 2027 og skal utbetales sommeren 2028.
A35: Skyldig arbeidsgiveravgift | B35: =(M22+N22)*$B$10+B34*$B$10 | O35: Avgiften på november- og desemberlønna, som forfaller 15. januar 2028, pluss avgiften på årets feriepenger.
A36: = Sum | B36: =B34+B35
A38: 5 · Kontroll
A39: Månedslønna budsjettet forutsetter | B39: 700000
A40: Summerer de to gruppene seg til den? | B40: =IF(ABS(C22-B39*B12)<1,"OK — de to gruppene summerer seg til den månedslønna budsjettet forutsetter","AVVIK: antall eller lønnsnivå gir ikke budsjettets månedslønn")
A41: Går arbeidsgiveravgiften opp? | B41: =IF(ABS(($B$15+B24+$B$13*$B$10)-(B30+B35))<1,"OK — inngående gjeld, årets avgift OG avgiften på fjorårets feriepenger er til sammen nøyaktig det som er betalt pluss det som skyldes 31.12","AVVIK: arbeidsgiveravgiften går ikke opp mellom kostnad, betaling og gjeld")
A42: Er feriepengene i 2027 en kostnad? | B42: =IF(ABS(B29-B13)<1,"OK — det som utbetales i 2027 er feriepengene fra 2026. De ble kostnadsført i fjor og står ikke i årets resultatbudsjett","AVVIK: utbetalingen stemmer ikke med den skyldige posten fra 2026")
A44: Tre tidspunkter for den samme lønnskrona: den koster i måneden den tjenes opp, den utbetales samme måned, men feriepengedelen først året etter, og arbeidsgiveravgiften på begge deler enda seinere.
A45: Kilde: Bok 1 kap. 9.4.4 til 9.4.6. Forfallsreglene følger skattebetalingsloven (Lovdata).

Sheet Andre kostnader
A1: Kostnadsbudsjett 2027 — andre driftskostnader
A2: Noen kostnader følger oppdragene. Andre løper uansett. Skillet avgjør hva som skjer når salget svikter.
A4: 1 · Forutsetningene
A5: Andre driftskostnader for året | B5: 1500000 | O5: Drivstoff, bompenger, forbruksmateriell, husleie, forsikring, IT og telefon, regnskapsfører, kurs og sertifisering.
A6: Variabel andel av salget | B6: 0.017232143 | O6: Så stor andel av salget gikk til drivstoff og forbruksmateriell i 2026. Disse kronene følger oppdragene.
A7: Salgsinntekt i grunnbudsjettet | B7: =Salgsbudsjett!$B$21
A8: = Variable andre kostnader for året | B8: =B6*B7
A9: = Faste andre kostnader for året | B9: =B5-B8 | O9: Det som blir igjen. Husleia kommer hver måned enten montørene er ute på jobb eller ikke.
A10: Merverdiavgiftssats | B10: =Salgsbudsjett!$B$7
A11: Andel av posten som er avgiftspliktig | B11: 1 | O11: Forsikring og en del gebyrer er uten merverdiavgift. Sett andelen ned hvis du vil regne mer nøyaktig.
A13: 2 · Kostnadsbudsjettet måned for måned
A14: Post | B14: År | C14: Jan | D14: Feb | E14: Mar | F14: Apr | G14: Mai | H14: Jun | I14: Jul | J14: Aug | K14: Sep | L14: Okt | M14: Nov | N14: Des | O14: Kommentar
A15: Månedsnummer | C15: =1 | D15: =2 | E15: =3 | F15: =4 | G15: =5 | H15: =6 | I15: =7 | J15: =8 | K15: =9 | L15: =10 | M15: =11 | N15: =12
A16: Variable andre kostnader | B16: =SUM(C16:N16) | C16: =Salgsbudsjett!C18*$B$6 | D16: =Salgsbudsjett!D18*$B$6 | E16: =Salgsbudsjett!E18*$B$6 | F16: =Salgsbudsjett!F18*$B$6 | G16: =Salgsbudsjett!G18*$B$6 | H16: =Salgsbudsjett!H18*$B$6 | I16: =Salgsbudsjett!I18*$B$6 | J16: =Salgsbudsjett!J18*$B$6 | ... N16: =Salgsbudsjett!N18*$B$6 | O16: Følger salget. Lav i juli, høy i november.
A17: Faste andre kostnader | B17: =SUM(C17:N17) | C17: =$B$9/12 | D17: =$B$9/12 | E17: =$B$9/12 | F17: =$B$9/12 | G17: =$B$9/12 | H17: =$B$9/12 | I17: =$B$9/12 | J17: =$B$9/12 | ... N17: =$B$9/12 | O17: Like store hver måned.
A18: = Andre driftskostnader | B18: =SUM(C18:N18) | C18: =C16+C17 | D18: =D16+D17 | E18: =E16+E17 | F18: =F16+F17 | G18: =G16+G17 | H18: =H16+H17 | I18: =I16+I17 | J18: =J16+J17 | ... N18: =N16+N17 | O18: Denne linja går inn i resultatbudsjettet.
A19: + Inngående merverdiavgift | B19: =SUM(C19:N19) | C19: =C18*$B$11*$B$10 | D19: =D18*$B$11*$B$10 | E19: =E18*$B$11*$B$10 | F19: =F18*$B$11*$B$10 | G19: =G18*$B$11*$B$10 | H19: =H18*$B$11*$B$10 | I19: =I18*$B$11*$B$10 | J19: =J18*$B$11*$B$10 | ... N19: =N18*$B$11*$B$10
A20: = Utbetaling inkl. merverdiavgift | B20: =SUM(C20:N20) | C20: =C18+C19 | D20: =D18+D19 | E20: =E18+E19 | F20: =F18+F19 | G20: =G18+G19 | H20: =H18+H19 | I20: =I18+I19 | J20: =J18+J19 | ... N20: =N18+N19 | O20: Her forutsettes det at regningene betales i den måneden de kommer.
A22: 3 · Kontroll
A23: Summerer variable og faste seg til årsbeløpet? | B23: =IF(ABS(B8+B9-B5)<1,"OK — de variable og de faste summerer seg til det årsbeløpet som er budsjettert","AVVIK: delingen går ikke opp")
A24: Er de faste kostnadene positive? | B24: =IF(B9>0,"OK — det er en fast del igjen etter at de variable er trukket fra","AVVIK: den variable andelen er satt så høyt at det ikke er noen faste kostnader igjen")
A26: Prøv dette: sett omsetningsveksten i arket Scenario til minus 20 prosent. De variable kostnadene faller, de faste gjør det ikke. Det er derfor et dårlig år svir mer enn omsetningstallet alene skulle tilsi.
A27: Kilde: Bok 1 kap. 9.2 og kap. 9.4.8. Delingen i faste og variable er den samme som i kapittel 2 og kapittel 8.

Sheet Investering og finans
A1: Investerings- og finansbudsjett 2027
A2: De tre postene som tapper kontoen uten å stå i resultatbudsjettet: avdrag, investering og utbytte. Og den ene kostnaden som ikke tapper kontoen: avskrivninger.
A4: 1 · Investeringsbudsjettet
A5: Kjøpesum uten merverdiavgift | B5: 480000 | O5: Feilsøkings- og termograferingsutstyr — investeringen du regner nåverdien av i kapittel 10.
A6: Måneden utstyret kjøpes i | B6: 3 | O6: Sett den til 9 og se hva det gjør med bunnen i likviditetsbudsjettet.
A7: Merverdiavgiftssats | B7: =Salgsbudsjett!$B$7
A8: = Utbetaling inkl. merverdiavgift | B8: =B5*(1+B7) | O8: Hele beløpet går ut av kontoen i kjøpsmåneden. Ingen krone av det er kostnad — kostnaden kommer som avskrivninger over levetiden.
A9: Salg av driftsmidler i 2027 | B9: 0
A10: Måneden driftsmidler selges i | B10: 12
A12: 2 · Avskrivningsbudsjettet
A13: Varige driftsmidler 1.1.2027 | B13: 3600000 | O13: Maskiner og verktøy pluss biler, slik de står i balansen 31.12.2026.
A14: + Årets investering | B14: =B5
A15: − Årets avskrivninger | B15: 680000 | O15: Den eneste kostnaden i hele arbeidsboka som ikke koster penger. Den står i resultatbudsjettet og ingen andre steder.
A16: = Bokført verdi 31.12.2027 | B16: =B13+B14-B15
A18: 3 · Finansbudsjettet
A19: Banklån 1.1.2027 | B19: 2800000
A20: Avdrag per kvartal | B20: 140000 | O20: Avdrag er nedbetaling av gjeld, ikke kostnad. Pengene går ut, men resultatet rører seg ikke.
A21: Rentekostnader per kvartal | B21: 52500 | O21: Renten er kostnad. Den står i resultatbudsjettet.
A22: Renteinntekter per kvartal | B22: 14000
A23: Nye lån i 2027 | B23: 0 | O23: Null i grunnbudsjettet. Låner bedriften til investeringen, legger du beløpet inn her og ser bunnen løfte seg.
A24: Måneden nye lån utbetales i | B24: 1
A25: Utbytte i 2027 | B25: 0 | O25: Utbytte er ikke kostnad. Det er eierne som tar ut av egenkapitalen.
A26: Måneden utbyttet utbetales i | B26: 6
A27: Forhåndsskatt, halvparten i februar og halvparten i april | B27: 262000 | O27: Aksjeselskaper betaler etterskuddsvis. Dette er skatten for 2026, betalt 15. februar og 15. april 2027.
A28: Kassekredittramme | B28: 1500000
A29: Kassekreditt trukket 1.1.2027 | B29: 300000
A30: Kassekredittrente | B30: 0.08
A31: = Banklån 31.12.2027 | B31: =B19-B20*4+B23
A33: 4 · Måned for måned
A34: Post | B34: År | C34: Jan | D34: Feb | E34: Mar | F34: Apr | G34: Mai | H34: Jun | I34: Jul | J34: Aug | K34: Sep | L34: Okt | M34: Nov | N34: Des | O34: Kommentar
A35: Månedsnummer | C35: =1 | D35: =2 | E35: =3 | F35: =4 | G35: =5 | H35: =6 | I35: =7 | J35: =8 | K35: =9 | L35: =10 | M35: =11 | N35: =12
A36: Avskrivninger | B36: =SUM(C36:N36) | C36: =$B$15/12 | D36: =$B$15/12 | E36: =$B$15/12 | F36: =$B$15/12 | G36: =$B$15/12 | H36: =$B$15/12 | I36: =$B$15/12 | J36: =$B$15/12 | ... N36: =$B$15/12 | O36: Til resultatbudsjettet. Aldri til likviditetsbudsjettet.
A37: Investering inkl. merverdiavgift | B37: =SUM(C37:N37) | C37: =IF(C35=$B$6,$B$8,0) | D37: =IF(D35=$B$6,$B$8,0) | E37: =IF(E35=$B$6,$B$8,0) | F37: =IF(F35=$B$6,$B$8,0) | G37: =IF(G35=$B$6,$B$8,0) | H37: =IF(H35=$B$6,$B$8,0) | I37: =IF(I35=$B$6,$B$8,0) | J37: =IF(J35=$B$6,$B$8,0) | ... N37: =IF(N35=$B$6,$B$8,0) | O37: Til likviditetsbudsjettet. Aldri til resultatbudsjettet.
A38: Inngående merverdiavgift på investeringen | B38: =SUM(C38:N38) | C38: =IF(C35=$B$6,$B$5*$B$7,0) | D38: =IF(D35=$B$6,$B$5*$B$7,0) | E38: =IF(E35=$B$6,$B$5*$B$7,0) | F38: =IF(F35=$B$6,$B$5*$B$7,0) | G38: =IF(G35=$B$6,$B$5*$B$7,0) | H38: =IF(H35=$B$6,$B$5*$B$7,0) | I38: =IF(I35=$B$6,$B$5*$B$7,0) | J38: =IF(J35=$B$6,$B$5*$B$7,0) | ... N38: =IF(N35=$B$6,$B$5*$B$7,0) | O38: Til mva-budsjettet. Avgiften på investeringen får bedriften igjen.
A39: Salg av driftsmidler | B39: =SUM(C39:N39) | C39: =IF(C35=$B$10,$B$9,0) | D39: =IF(D35=$B$10,$B$9,0) | E39: =IF(E35=$B$10,$B$9,0) | F39: =IF(F35=$B$10,$B$9,0) | G39: =IF(G35=$B$10,$B$9,0) | H39: =IF(H35=$B$10,$B$9,0) | I39: =IF(I35=$B$10,$B$9,0) | J39: =IF(J35=$B$10,$B$9,0) | ... N39: =IF(N35=$B$10,$B$9,0)
A40: Avdrag | B40: =SUM(C40:N40) | C40: =IF(MOD(C35,3)=0,$B$20,0) | D40: =IF(MOD(D35,3)=0,$B$20,0) | E40: =IF(MOD(E35,3)=0,$B$20,0) | F40: =IF(MOD(F35,3)=0,$B$20,0) | G40: =IF(MOD(G35,3)=0,$B$20,0) | H40: =IF(MOD(H35,3)=0,$B$20,0) | I40: =IF(MOD(I35,3)=0,$B$20,0) | J40: =IF(MOD(J35,3)=0,$B$20,0) | ... N40: =IF(MOD(N35,3)=0,$B$20,0)
A41: Rentekostnader | B41: =SUM(C41:N41) | C41: =IF(MOD(C35,3)=0,$B$21,0) | D41: =IF(MOD(D35,3)=0,$B$21,0) | E41: =IF(MOD(E35,3)=0,$B$21,0) | F41: =IF(MOD(F35,3)=0,$B$21,0) | G41: =IF(MOD(G35,3)=0,$B$21,0) | H41: =IF(MOD(H35,3)=0,$B$21,0) | I41: =IF(MOD(I35,3)=0,$B$21,0) | J41: =IF(MOD(J35,3)=0,$B$21,0) | ... N41: =IF(MOD(N35,3)=0,$B$21,0)
A42: Renteinntekter | B42: =SUM(C42:N42) | C42: =IF(MOD(C35,3)=0,$B$22,0) | D42: =IF(MOD(D35,3)=0,$B$22,0) | E42: =IF(MOD(E35,3)=0,$B$22,0) | F42: =IF(MOD(F35,3)=0,$B$22,0) | G42: =IF(MOD(G35,3)=0,$B$22,0) | H42: =IF(MOD(H35,3)=0,$B$22,0) | I42: =IF(MOD(I35,3)=0,$B$22,0) | J42: =IF(MOD(J35,3)=0,$B$22,0) | ... N42: =IF(MOD(N35,3)=0,$B$22,0)
A43: Nye lån | B43: =SUM(C43:N43) | C43: =IF(C35=$B$24,$B$23,0) | D43: =IF(D35=$B$24,$B$23,0) | E43: =IF(E35=$B$24,$B$23,0) | F43: =IF(F35=$B$24,$B$23,0) | G43: =IF(G35=$B$24,$B$23,0) | H43: =IF(H35=$B$24,$B$23,0) | I43: =IF(I35=$B$24,$B$23,0) | J43: =IF(J35=$B$24,$B$23,0) | ... N43: =IF(N35=$B$24,$B$23,0)
A44: Utbytte | B44: =SUM(C44:N44) | C44: =IF(C35=$B$26,$B$25,0) | D44: =IF(D35=$B$26,$B$25,0) | E44: =IF(E35=$B$26,$B$25,0) | F44: =IF(F35=$B$26,$B$25,0) | G44: =IF(G35=$B$26,$B$25,0) | H44: =IF(H35=$B$26,$B$25,0) | I44: =IF(I35=$B$26,$B$25,0) | J44: =IF(J35=$B$26,$B$25,0) | ... N44: =IF(N35=$B$26,$B$25,0)
...

Sheet Mva-budsjett
A1: Merverdiavgiftsbudsjett 2027
A2: Merverdiavgift er aldri en kostnad. Den er penger bedriften krever inn for staten — og holder på en stund.
A4: 1 · Forutsetningene
A5: Merverdiavgiftssats | B5: =Salgsbudsjett!$B$7
A6: Skyldig merverdiavgift 6. termin 2026 | B6: 1064000 | O6: Avgiften for november og desember 2026. Forfaller 10. februar 2027, altså i årets andre måned.
A8: 2 · Mva-budsjettet, termin for termin
A9: Termin | B9: Månedene | C9: Utgående mva. på salget | D9: Inngående mva. på varekjøp | E9: Inngående mva. på andre kostnader | F9: Inngående mva. på investering | G9: Netto å betale | H9: Forfaller i måned nr | I9: Kommentar
A10: Termin 1 | B10: Jan–Feb | C10: =Salgsbudsjett!C19+Salgsbudsjett!D19 | D10: =Materiellbudsjett!C19+Materiellbudsjett!D19 | E10: ='Andre kostnader'!C19+'Andre kostnader'!D19 | F10: ='Investering og finans'!C38+'Investering og finans'!D38 | G10: =C10-D10-E10-F10 | H10: =4 | I10: Forfall er én måned og ti dager etter at terminen er slutt. Januar–februar forfaller altså 10. april.
A11: Termin 2 | B11: Mar–Apr | C11: =Salgsbudsjett!E19+Salgsbudsjett!F19 | D11: =Materiellbudsjett!E19+Materiellbudsjett!F19 | E11: ='Andre kostnader'!E19+'Andre kostnader'!F19 | F11: ='Investering og finans'!E38+'Investering og finans'!F38 | G11: =C11-D11-E11-F11 | H11: =6
A12: Termin 3 | B12: Mai–Jun | C12: =Salgsbudsjett!G19+Salgsbudsjett!H19 | D12: =Materiellbudsjett!G19+Materiellbudsjett!H19 | E12: ='Andre kostnader'!G19+'Andre kostnader'!H19 | F12: ='Investering og finans'!G38+'Investering og finans'!H38 | G12: =C12-D12-E12-F12 | H12: =8 | I12: Terminen med investeringen i får lavere netto, fordi bedriften får igjen avgiften på utstyret.
A13: Termin 4 | B13: Jul–Aug | C13: =Salgsbudsjett!I19+Salgsbudsjett!J19 | D13: =Materiellbudsjett!I19+Materiellbudsjett!J19 | E13: ='Andre kostnader'!I19+'Andre kostnader'!J19 | F13: ='Investering og finans'!I38+'Investering og finans'!J38 | G13: =C13-D13-E13-F13 | H13: =10
A14: Termin 5 | B14: Sep–Okt | C14: =Salgsbudsjett!K19+Salgsbudsjett!L19 | D14: =Materiellbudsjett!K19+Materiellbudsjett!L19 | E14: ='Andre kostnader'!K19+'Andre kostnader'!L19 | F14: ='Investering og finans'!K38+'Investering og finans'!L38 | G14: =C14-D14-E14-F14 | H14: =12
A15: Termin 6 | B15: Nov–Des | C15: =Salgsbudsjett!M19+Salgsbudsjett!N19 | D15: =Materiellbudsjett!M19+Materiellbudsjett!N19 | E15: ='Andre kostnader'!M19+'Andre kostnader'!N19 | F15: ='Investering og finans'!M38+'Investering og finans'!N38 | G15: =C15-D15-E15-F15 | H15: =14 | I15: Måned nummer 14 betyr februar 2028. Denne terminen blir stående som skyldig merverdiavgift i balansebudsjettet.
A17: 3 · Utbetaling måned for måned
A18: Post | B18: År | C18: Jan | D18: Feb | E18: Mar | F18: Apr | G18: Mai | H18: Jun | I18: Jul | J18: Aug | K18: Sep | L18: Okt | M18: Nov | N18: Des | O18: Kommentar
A19: Månedsnummer | C19: =1 | D19: =2 | E19: =3 | F19: =4 | G19: =5 | H19: =6 | I19: =7 | J19: =8 | K19: =9 | L19: =10 | M19: =11 | N19: =12
A20: Merverdiavgift til betaling | B20: =SUM(C20:N20) | C20: =IF(C19=2,$B$6,0)+SUMIF($H$10:$H$15,C19,$G$10:$G$15) | D20: =IF(D19=2,$B$6,0)+SUMIF($H$10:$H$15,D19,$G$10:$G$15) | E20: =IF(E19=2,$B$6,0)+SUMIF($H$10:$H$15,E19,$G$10:$G$15) | F20: =IF(F19=2,$B$6,0)+SUMIF($H$10:$H$15,F19,$G$10:$G$15) | G20: =IF(G19=2,$B$6,0)+SUMIF($H$10:$H$15,G19,$G$10:$G$15) | H20: =IF(H19=2,$B$6,0)+SUMIF($H$10:$H$15,H19,$G$10:$G$15) | I20: =IF(I19=2,$B$6,0)+SUMIF($H$10:$H$15,I19,$G$10:$G$15) | J20: =IF(J19=2,$B$6,0)+SUMIF($H$10:$H$15,J19,$G$10:$G$15) | ... N20: =IF(N19=2,$B$6,0)+SUMIF($H$10:$H$15,N19,$G$10:$G$15) | O20: Går inn i likviditetsbudsjettet. Seks utbetalinger i året, og den første gjelder fjoråret.
A22: 4 · Det som blir stående som gjeld 31.12.2027
A23: Skyldig merverdiavgift, 6. termin 2027 | B23: =G15
A25: 5 · Kontroll
A26: Går avgiften opp mellom påløpt, betalt og skyldig? | B26: =IF(ABS(($B$6+SUM(G10:G15))-(B20+B23))<1,"OK — inngående skyldig avgift pluss årets seks terminer er nøyaktig det som er betalt pluss det som skyldes 31.12","AVVIK: merverdiavgiften går ikke opp")
A27: Skylder bedriften avgift i alle terminene? | B27: =IF(MIN(G10:G15)>0,"OK — salget er større enn kjøpene i alle terminene, så bedriften skylder avgift hver gang","AVVIK: én termin gir avgift til gode. Da får bedriften penger tilbake, og det tar halvannen måned")
A28: Er merverdiavgift en kostnad? | B28: =IF(B20>0,"OK — og svaret er nei. Ikke én krone av dette står i resultatbudsjettet. Det er likevel det nest største beløpet som går ut av kontoen","AVVIK: her er noe koblet feil")
A30: Kilde: Bok 1 kap. 9.4.7. Terminene og forfallsfristene følger merverdiavgiftsloven og skattebetalingsloven (Lovdata). Alminnelig sats er 25 prosent; næringsmidler 15 prosent og persontransport, overnatting og kino 12 prosent.

Sheet Resultatbudsjett
A1: Resultatbudsjett 2027 — hovedbudsjett
A2: Legg merke til én ting: det finnes ikke én eneste gul celle i dette arket. Hver linje er hentet fra et delbudsjett.
A4: 1 · Resultatbudsjettet
A5: Post | B5: År | C5: Jan | D5: Feb | E5: Mar | F5: Apr | G5: Mai | H5: Jun | I5: Jul | J5: Aug | K5: Sep | L5: Okt | M5: Nov | N5: Des | O5: Hentet fra
A6: Månedsnummer | C6: =1 | D6: =2 | E6: =3 | F6: =4 | G6: =5 | H6: =6 | I6: =7 | J6: =8 | K6: =9 | L6: =10 | M6: =11 | N6: =12
A7: Salgsinntekt | B7: =SUM(C7:N7) | C7: =Salgsbudsjett!C18 | D7: =Salgsbudsjett!D18 | E7: =Salgsbudsjett!E18 | F7: =Salgsbudsjett!F18 | G7: =Salgsbudsjett!G18 | H7: =Salgsbudsjett!H18 | I7: =Salgsbudsjett!I18 | J7: =Salgsbudsjett!J18 | ... N7: =Salgsbudsjett!N18 | O7: Salgsbudsjettet, rad 18
A8: − Varekostnad | B8: =SUM(C8:N8) | C8: =Materiellbudsjett!C16 | D8: =Materiellbudsjett!D16 | E8: =Materiellbudsjett!E16 | F8: =Materiellbudsjett!F16 | G8: =Materiellbudsjett!G16 | H8: =Materiellbudsjett!H16 | I8: =Materiellbudsjett!I16 | J8: =Materiellbudsjett!J16 | ... N8: =Materiellbudsjett!N16 | O8: Materiellbudsjettet, rad 16 — forbruket, ikke innkjøpet
A9: = Bruttofortjeneste | B9: =SUM(C9:N9) | C9: =C7-C8 | D9: =D7-D8 | E9: =E7-E8 | F9: =F7-F8 | G9: =G7-G8 | H9: =H7-H8 | I9: =I7-I8 | J9: =J7-J8 | ... N9: =N7-N8
A10: Bruttofortjeneste i prosent | B10: =B9/B7 | C10: =C9/C7 | D10: =D9/D7 | E10: =E9/E7 | F10: =F9/F7 | G10: =G9/G7 | H10: =H9/H7 | I10: =I9/I7 | ... N10: =N9/N7
A11: − Lønnskostnad | B11: =SUM(C11:N11) | C11: =Lønnsbudsjett!C25 | D11: =Lønnsbudsjett!D25 | E11: =Lønnsbudsjett!E25 | F11: =Lønnsbudsjett!F25 | G11: =Lønnsbudsjett!G25 | H11: =Lønnsbudsjett!H25 | I11: =Lønnsbudsjett!I25 | J11: =Lønnsbudsjett!J25 | ... N11: =Lønnsbudsjett!N25 | O11: Lønnsbudsjettet, rad 25
A12: − Avskrivninger | B12: =SUM(C12:N12) | C12: ='Investering og finans'!C36 | D12: ='Investering og finans'!D36 | E12: ='Investering og finans'!E36 | F12: ='Investering og finans'!F36 | G12: ='Investering og finans'!G36 | H12: ='Investering og finans'!H36 | I12: ='Investering og finans'!I36 | J12: ='Investering og finans'!J36 | ... N12: ='Investering og finans'!N36 | O12: Avskrivningsbudsjettet — den eneste kostnaden uten utbetaling
A13: − Andre driftskostnader | B13: =SUM(C13:N13) | C13: ='Andre kostnader'!C18 | D13: ='Andre kostnader'!D18 | E13: ='Andre kostnader'!E18 | F13: ='Andre kostnader'!F18 | G13: ='Andre kostnader'!G18 | H13: ='Andre kostnader'!H18 | I13: ='Andre kostnader'!I18 | J13: ='Andre kostnader'!J18 | ... N13: ='Andre kostnader'!N18 | O13: Kostnadsbudsjettet, rad 18
A14: = Sum driftskostnader | B14: =SUM(C14:N14) | C14: =C8+C11+C12+C13 | D14: =D8+D11+D12+D13 | E14: =E8+E11+E12+E13 | F14: =F8+F11+F12+F13 | G14: =G8+G11+G12+G13 | H14: =H8+H11+H12+H13 | I14: =I8+I11+I12+I13 | J14: =J8+J11+J12+J13 | ... N14: =N8+N11+N12+N13
A15: = Driftsresultat | B15: =SUM(C15:N15) | C15: =C7-C14 | D15: =D7-D14 | E15: =E7-E14 | F15: =F7-F14 | G15: =G7-G14 | H15: =H7-H14 | I15: =I7-I14 | J15: =J7-J14 | ... N15: =N7-N14
A16: Driftsmargin | B16: =B15/B7 | C16: =C15/C7 | D16: =D15/D7 | E16: =E15/E7 | F16: =F15/F7 | G16: =G15/G7 | H16: =H15/H7 | I16: =I15/I7 | ... N16: =N15/N7 | O16: Se juli: samme faste kostnader, halve omsetningen.
A17: + Renteinntekter | B17: =SUM(C17:N17) | C17: ='Investering og finans'!C42 | D17: ='Investering og finans'!D42 | E17: ='Investering og finans'!E42 | F17: ='Investering og finans'!F42 | G17: ='Investering og finans'!G42 | H17: ='Investering og finans'!H42 | I17: ='Investering og finans'!I42 | J17: ='Investering og finans'!J42 | ... N17: ='Investering og finans'!N42
A18: − Rentekostnader | B18: =SUM(C18:N18) | C18: ='Investering og finans'!C41 | D18: ='Investering og finans'!D41 | E18: ='Investering og finans'!E41 | F18: ='Investering og finans'!F41 | G18: ='Investering og finans'!G41 | H18: ='Investering og finans'!H41 | I18: ='Investering og finans'!I41 | J18: ='Investering og finans'!J41 | ... N18: ='Investering og finans'!N41 | O18: Bare renten. Avdraget står ikke her.
A19: = Resultat før skatt | B19: =SUM(C19:N19) | C19: =C15+C17-C18 | D19: =D15+D17-D18 | E19: =E15+E17-E18 | F19: =F15+F17-F18 | G19: =G15+G17-G18 | H19: =H15+H17-H18 | I19: =I15+I17-I18 | J19: =J15+J17-J18 | ... N19: =N15+N17-N18
A21: 2 · Skatt og årsresultat
A22: − Budsjettert skattekostnad | B22: ='Investering og finans'!$B$27 | O22: Vi budsjetterer skatten lik den forhåndsskatten bedriften faktisk betaler i året. Da er skatten både kostnadsført og betalt i 2027, og balansebudsjettet går opp uten en post for utsatt betalbar skatt.
A23: = Budsjettert årsresultat | B23: =B19-B22 | O23: Dette beløpet legges til egenkapitalen i balansebudsjettet.
A24: Skattesats for aksjeselskap | B24: 0.22
A25: Til sammenlikning: skatten regnet med den satsen | B25: =B19*B24 | O25: En mer nøyaktig skatteberegning ville brukt dette tallet. Da forfaller skatten først i 2028, og budsjettet trenger en egen gjeldspost for den. Satsen på 22 prosent står i kapittel 1.
A27: 3 · Kontroll
A28: Summerer månedene seg til året? | B28: =IF(ABS(SUM(C15:N15)-B15)<1,"OK — de tolv månedene summerer seg til årsbudsjettet","AVVIK: månedene og året gir ulikt driftsresultat")
A29: Er hele resultatbudsjettet bygd av delbudsjetter? | B29: =IF(ABS(B7-Salgsbudsjett!B18)+ABS(B8-Materiellbudsjett!B16)+ABS(B11-Lønnsbudsjett!B25)+ABS(B13-'Andre kostnader'!B18)<1,"OK — hver linje er hentet fra sitt delbudsjett. Ingen tall er skrevet inn her","AVVIK: en linje henter ikke fra delbudsjettet sitt")
A30: Viser budsjettet overskudd? | B30: =IF(B15>0,"OK — budsjettet viser overskudd. Gå så til likviditetsbudsjettet og se om det er penger på konto","AVVIK: budsjettet går i minus. Da er det ikke likviditeten som er hovedproblemet")
A32: Her ser du hele poenget med delbudsjetter: hovedbudsjettet er ikke et tall noen har funnet på. Det er summen av seks mindre budsjetter, og hvert av dem har en person i bedriften som eier det.
A33: Kilde: Bok 1 kap. 9.2 og 9.3.

Sheet Likviditetsbudsjett
A1: Likviditetsbudsjett 2027 — hovedbudsjett
A2: Samme bedrift, samme år, helt annet svar. Satt opp i tre nivåer: drift, finansiering og investering.
A4: 1 · Kredittidene
A5: Kredittid til kundene, dager | B5: =Scenario!$B$8 | O5: Hentet fra arket Scenario. Dette er den ene forutsetningen som avgjør året.
A6: Kredittid hos grossisten, dager | B6: =Scenario!$B$9 | O6: Virker motsatt vei: lengre kreditt her hjelper på kontoen.
A8: Andel av et salg som innbetales
A9: i salgsmåneden | B9: =IF($B$5<=30,(30-$B$5)/30,0) | O9: Læreboka regner tretti dager per måned og jevnt salg gjennom måneden. Ved 20 dagers kredittid kommer en tredel inn samme måned og to tredeler måneden etter.
A10: måneden etter | B10: =IF($B$5<=30,$B$5/30,MAX(0,(60-$B$5)/30))
A11: to måneder etter | B11: =IF($B$5<=30,0,MIN(1,($B$5-30)/30))
A12: Andel av et varekjøp som utbetales
A13: i kjøpsmåneden | B13: =IF($B$6<=30,(30-$B$6)/30,0)
A14: måneden etter | B14: =IF($B$6<=30,$B$6/30,MAX(0,(60-$B$6)/30))
A15: to måneder etter | B15: =IF($B$6<=30,0,MIN(1,($B$6-30)/30))
A17: 2 · Inngående poster
A18: Bankinnskudd 1.1.2027 | B18: 1000000
A19: Kundefordringer 1.1.2027 | B19: 4200000 | O19: Svarer til 54 dagers salg, ikke 20. Tallet sto i balansen hele tida.
A20: herav innbetalt i januar | B20: 0.6
A21: Leverandørgjeld 1.1.2027 | B21: 2100000
A22: Kassekredittramme | B22: ='Investering og finans'!$B$28
A23: Kassekreditt trukket 1.1.2027 | B23: ='Investering og finans'!$B$29
A25: 3 · Innbetalinger fra driften
A26: Post | B26: År | C26: Jan | D26: Feb | E26: Mar | F26: Apr | G26: Mai | H26: Jun | I26: Jul | J26: Aug | K26: Sep | L26: Okt | M26: Nov | N26: Des | O26: Kommentar
A27: Månedsnummer | C27: =1 | D27: =2 | E27: =3 | F27: =4 | G27: =5 | H27: =6 | I27: =7 | J27: =8 | K27: =9 | L27: =10 | M27: =11 | N27: =12
A28: Salgsinntekt inkl. merverdiavgift | B28: =SUM(C28:N28) | C28: =Salgsbudsjett!C20 | D28: =Salgsbudsjett!D20 | E28: =Salgsbudsjett!E20 | F28: =Salgsbudsjett!F20 | G28: =Salgsbudsjett!G20 | H28: =Salgsbudsjett!H20 | I28: =Salgsbudsjett!I20 | J28: =Salgsbudsjett!J20 | ... N28: =Salgsbudsjett!N20 | O28: Fakturert beløp. Ikke det samme som innbetalt.
A29: Innbetalt fra årets salg | B29: =SUM(C29:N29) | C29: =C28*$B$9 | D29: =D28*$B$9+C28*$B$10 | E29: =E28*$B$9+D28*$B$10+C28*$B$11 | F29: =F28*$B$9+E28*$B$10+D28*$B$11 | G29: =G28*$B$9+F28*$B$10+E28*$B$11 | H29: =H28*$B$9+G28*$B$10+F28*$B$11 | I29: =I28*$B$9+H28*$B$10+G28*$B$11 | J29: =J28*$B$9+I28*$B$10+H28*$B$11 | K29: =K28*$B$9+J28*$B$10+I28*$B$11 | L29: =L28*$B$9+K28*$B$10+J28*$B$11 | ... N29: =N28*$B$9+M28*$B$10+L28*$B$11
A30: Innbetalt fra kundefordringene 1.1. | B30: =SUM(C30:N30) | C30: =$B$19*$B$20 | D30: =$B$19*(1-$B$20) | E30: =0 | F30: =0 | G30: =0 | H30: =0 | I30: =0 | J30: =0 | K30: =0 | L30: =0 | ... N30: =0
A31: Renteinntekter | B31: =SUM(C31:N31) | C31: ='Investering og finans'!C42 | D31: ='Investering og finans'!D42 | E31: ='Investering og finans'!E42 | F31: ='Investering og finans'!F42 | G31: ='Investering og finans'!G42 | H31: ='Investering og finans'!H42 | I31: ='Investering og finans'!I42 | J31: ='Investering og finans'!J42 | ... N31: ='Investering og finans'!N42
A32: = Sum innbetalinger | B32: =SUM(C32:N32) | C32: =C29+C30+C31 | D32: =D29+D30+D31 | E32: =E29+E30+E31 | F32: =F29+F30+F31 | G32: =G29+G30+G31 | H32: =H29+H30+H31 | I32: =I29+I30+I31 | J32: =J29+J30+J31 | ... N32: =N29+N30+N31
A34: 4 · Utbetalinger fra driften
A35: Varekjøp inkl. merverdiavgift | B35: =SUM(C35:N35) | C35: =Materiellbudsjett!C20 | D35: =Materiellbudsjett!D20 | E35: =Materiellbudsjett!E20 | F35: =Materiellbudsjett!F20 | G35: =Materiellbudsjett!G20 | H35: =Materiellbudsjett!H20 | I35: =Materiellbudsjett!I20 | J35: =Materiellbudsjett!J20 | ... N35: =Materiellbudsjett!N20 | O35: Bestilt beløp. Ikke det samme som betalt.
A36: Til leverandørene | B36: =SUM(C36:N36) | C36: =C35*$B$13+$B$21 | D36: =D35*$B$13+C35*$B$14 | E36: =E35*$B$13+D35*$B$14+C35*$B$15 | F36: =F35*$B$13+E35*$B$14+D35*$B$15 | G36: =G35*$B$13+F35*$B$14+E35*$B$15 | H36: =H35*$B$13+G35*$B$14+F35*$B$15 | I36: =I35*$B$13+H35*$B$14+G35*$B$15 | J36: =J35*$B$13+I35*$B$14+H35*$B$15 | K36: =K35*$B$13+J35*$B$14+I35*$B$15 | L36: =L35*$B$13+K35*$B$14+J35*$B$15 | ... N36: =N35*$B$13+M35*$B$14+L35*$B$15 | O36: Januar bærer også hele leverandørgjelda fra 2026.
A37: Lønn | B37: =SUM(C37:N37) | C37: =Lønnsbudsjett!C28 | D37: =Lønnsbudsjett!D28 | E37: =Lønnsbudsjett!E28 | F37: =Lønnsbudsjett!F28 | G37: =Lønnsbudsjett!G28 | H37: =Lønnsbudsjett!H28 | I37: =Lønnsbudsjett!I28 | J37: =Lønnsbudsjett!J28 | ... N37: =Lønnsbudsjett!N28
A38: Feriepenger | B38: =SUM(C38:N38) | C38: =Lønnsbudsjett!C29 | D38: =Lønnsbudsjett!D29 | E38: =Lønnsbudsjett!E29 | F38: =Lønnsbudsjett!F29 | G38: =Lønnsbudsjett!G29 | H38: =Lønnsbudsjett!H29 | I38: =Lønnsbudsjett!I29 | J38: =Lønnsbudsjett!J29 | ... N38: =Lønnsbudsjett!N29
A39: Arbeidsgiveravgift | B39: =SUM(C39:N39) | C39: =Lønnsbudsjett!C30 | D39: =Lønnsbudsjett!D30 | E39: =Lønnsbudsjett!E30 | F39: =Lønnsbudsjett!F30 | G39: =Lønnsbudsjett!G30 | H39: =Lønnsbudsjett!H30 | I39: =Lønnsbudsjett!I30 | J39: =Lønnsbudsjett!J30 | ... N39: =Lønnsbudsjett!N30
A40: Merverdiavgift | B40: =SUM(C40:N40) | C40: ='Mva-budsjett'!C20 | D40: ='Mva-budsjett'!D20 | E40: ='Mva-budsjett'!E20 | F40: ='Mva-budsjett'!F20 | G40: ='Mva-budsjett'!G20 | H40: ='Mva-budsjett'!H20 | I40: ='Mva-budsjett'!I20 | J40: ='Mva-budsjett'!J20 | ... N40: ='Mva-budsjett'!N20
A41: Andre driftskostnader inkl. merverdiavgift | B41: =SUM(C41:N41) | C41: ='Andre kostnader'!C20 | D41: ='Andre kostnader'!D20 | E41: ='Andre kostnader'!E20 | F41: ='Andre kostnader'!F20 | G41: ='Andre kostnader'!G20 | H41: ='Andre kostnader'!H20 | I41: ='Andre kostnader'!I20 | J41: ='Andre kostnader'!J20 | ... N41: ='Andre kostnader'!N20
A42: Rentekostnader | B42: =SUM(C42:N42) | C42: ='Investering og finans'!C41 | D42: ='Investering og finans'!D41 | E42: ='Investering og finans'!E41 | F42: ='Investering og finans'!F41 | G42: ='Investering og finans'!G41 | H42: ='Investering og finans'!H41 | I42: ='Investering og finans'!I41 | J42: ='Investering og finans'!J41 | ... N42: ='Investering og finans'!N41
A43: Forhåndsskatt | B43: =SUM(C43:N43) | C43: ='Investering og finans'!C45 | D43: ='Investering og finans'!D45 | E43: ='Investering og finans'!E45 | F43: ='Investering og finans'!F45 | G43: ='Investering og finans'!G45 | H43: ='Investering og finans'!H45 | I43: ='Investering og finans'!I45 | J43: ='Investering og finans'!J45 | ... N43: ='Investering og finans'!N45
A44: = Sum utbetalinger fra driften | B44: =SUM(C44:N44) | C44: =SUM(C36:C43) | D44: =SUM(D36:D43) | E44: =SUM(E36:E43) | F44: =SUM(F36:F43) | G44: =SUM(G36:G43) | H44: =SUM(H36:H43) | I44: =SUM(I36:I43) | J44: =SUM(J36:J43) | ... N44: =SUM(N36:N43)
A45: = A · Netto likviditetsendring fra driften | B45: =SUM(C45:N45) | C45: =C32-C44 | D45: =D32-D44 | E45: =E32-E44 | F45: =F32-F44 | G45: =G32-G44 | H45: =H32-H44 | I45: =I32-I44 | J45: =J32-J44 | ... N45: =N32-N44 | O45: Klarer driften å forsyne seg selv med penger? Dette er linja banken ser på først.
...

Sheet Balansebudsjett
A1: Balansebudsjett 31.12.2027 — hovedbudsjett
A2: Det tredje hovedbudsjettet. Sjelden i oppgaver, men det er dette banken vil se ved en større lånesøknad.
A4: 1 · To beløp som betales i 2027, men hører hjemme i 2026
A5: Forhåndsskatt for 2026 | B5: ='Investering og finans'!$B$27
A6: Arbeidsgiveravgift på feriepengene fra 2026 | B6: =Lønnsbudsjett!$B$13*Lønnsbudsjett!$B$10
A7: Balansen for 2026 i denne casen har avsatt feriepengene, men verken skatten eller arbeidsgiveravgiften på feriepengene. Begge betales i 2027. Skatten løser vi ved å budsjettere den som årets skattekostnad. Avgiften trekkes fra egenkapitalen på egen linje under. I et ekte regnskap ville begge stått som kortsiktig gjeld 31.12.2026 — det er nettopp det en avsetning er til for.
A9: 2 · Balansebudsjettet
A10: Post | B10: 31.12.2026 | C10: Budsjettert endring i 2027 | D10: 31.12.2027 | E10: Hvor tallet kommer fra
A11: EIENDELER
A12: Varige driftsmidler | B12: 3600000 | C12: ='Investering og finans'!$B$5-'Investering og finans'!$B$15 | D12: =B12+C12 | E12: Investeringsbudsjettet minus avskrivningsbudsjettet.
A13: Varelager | B13: 1400000 | C13: =SUM(Materiellbudsjett!C17:N17) | D13: =B13+C13 | E13: Den planlagte lagerendringen i materiellbudsjettet.
A14: Kundefordringer | B14: =Likviditetsbudsjett!$B$19 | C14: =Likviditetsbudsjett!B28-Likviditetsbudsjett!B29-Likviditetsbudsjett!B30 | D14: =B14+C14 | E14: Fakturert i året minus innbetalt i året. Det som står igjen, er det kundene skylder ved årsskiftet.
A15: Bankinnskudd | B15: =Likviditetsbudsjett!$B$18 | C15: =D15-B15 | D15: =Likviditetsbudsjett!N63 | E15: Utgående beholdning i desember i likviditetsbudsjettet.
A16: = Sum eiendeler | B16: =SUM(B12:B15) | C16: =SUM(C12:C15) | D16: =SUM(D12:D15)
A18: EGENKAPITAL OG GJELD
A19: Aksjekapital | B19: 300000 | C19: =0 | D19: =B19+C19
A20: Annen egenkapital | B20: 2610000 | C20: =Resultatbudsjett!$B$23-$B$6 | D20: =B20+C20 | E20: Budsjettert årsresultat, minus arbeidsgiveravgiften på fjorårets feriepenger fra rad 6.
A21: = Sum egenkapital | B21: =B19+B20 | C21: =C19+C20 | D21: =D19+D20
A22: Banklån | B22: ='Investering og finans'!$B$19 | C22: ='Investering og finans'!$B$23-'Investering og finans'!$B$20*4 | D22: =B22+C22 | E22: Nye lån minus fire kvartalsavdrag, fra finansbudsjettet.
A23: Leverandørgjeld | B23: =Likviditetsbudsjett!$B$21 | C23: =Likviditetsbudsjett!B35-Likviditetsbudsjett!B36 | D23: =B23+C23 | E23: Kjøpt i året minus betalt i året.
A24: Skyldig merverdiavgift | B24: ='Mva-budsjett'!$B$6 | C24: =D24-B24 | D24: ='Mva-budsjett'!$B$23 | E24: 6. termin 2027, som forfaller 10. februar 2028.
A25: Skyldig arbeidsgiveravgift | B25: =Lønnsbudsjett!$B$15 | C25: =D25-B25 | D25: =Lønnsbudsjett!$B$35 | E25: Avgiften på november- og desemberlønna pluss avgiften på årets feriepenger.
A26: Skyldige feriepenger | B26: =Lønnsbudsjett!$B$13 | C26: =D26-B26 | D26: =Lønnsbudsjett!$B$34 | E26: Alt som er opptjent i 2027 og utbetales sommeren 2028.
A27: Kassekreditt | B27: ='Investering og finans'!$B$29 | C27: =D27-B27 | D27: =B27+Likviditetsbudsjett!N62 | E27: Det som alt var trukket, pluss det året tvinger fram.
A28: = Sum gjeld | B28: =SUM(B22:B27) | C28: =SUM(C22:C27) | D28: =SUM(D22:D27)
A29: = Sum egenkapital og gjeld | B29: =B21+B28 | C29: =C21+C28 | D29: =D21+D28
A31: 3 · Nøkkeltall ut av balansebudsjettet
A32: Egenkapitalandel 31.12.2026 | B32: =B21/B16
A33: Egenkapitalandel 31.12.2027 | B33: =D21/D16 | E33: Dette er tallet banken ser på. Et overskuddsår løfter det uten at bedriften har gjort annet enn å tjene penger.
A34: Likviditetsgrad 1 · 31.12.2027 | B34: =(D13+D14+D15)/(D23+D24+D25+D26+D27) | E34: Omløpsmidler delt på kortsiktig gjeld, slik du regnet det i kapittel 4. Normtallet er 2.
A36: 4 · Kontroll
A37: Går den inngående balansen opp? | B37: =IF(ABS(B16-B29)<1,"OK — balansen 31.12.2026 går opp","AVVIK: den inngående balansen går ikke opp")
A38: Går balansebudsjettet opp? | B38: =IF(ABS(D16-D29)<1,"OK — eiendelene er nøyaktig like store som egenkapital og gjeld. Budsjettet henger sammen","AVVIK: eiendelene og finansieringen spriker. Da er en av postene budsjettert feil")
A39: Vokser egenkapitalen? | B39: =IF(D21>B21,"OK — egenkapitalen vokser gjennom året fordi bedriften budsjetterer med overskudd","AVVIK: egenkapitalen krymper. Da tar bedriften ut mer enn den tjener")
A41: Balansebudsjettet er prøven på om de to andre hovedbudsjettene henger sammen. Går det opp, er resultatbudsjettet og likviditetsbudsjettet enige med hverandre. Går det ikke opp, er én av dem feil.
A42: Kilde: Bok 1 kap. 9.2. Nøkkeltallene er de samme som i kapittel 4.

Sheet Budsjettkontroll
A1: Budsjettkontroll 2026 — delbudsjett for delbudsjett
A2: Avviket peker på et sted. Det sier ikke hvorfor. De to siste kolonnene er dine — det er der jobben ligger.
A5: Post | B5: Delbudsjett | C5: Hvem eier det | D5: Budsjett 2026 | E5: Regnskap 2026 | F5: Avvik i kroner | G5: Avvik i prosent | H5: Andel av salget, budsjett | I5: Andel av salget, regnskap | J5: Hva skyldes avviket? | K5: Hva gjør vi med det?
A6: Salgsinntekt | B6: Salgsbudsjettet | C6: Ida Haugen, kalkulatør | D6: 22000000 | E6: 22400000 | F6: =E6-D6 | G6: =F6/D6
A7: Varekostnad | B7: Materiell- og innkjøpsbudsjettet | C7: Ronny Fjeld, formann | D7: 8240000 | E7: 8390000 | F7: =D7-E7 | G7: =F7/D7 | H7: =D7/$D$6 | I7: =E7/$E$6
A8: Lønnskostnad | B8: Lønnsbudsjettet | C8: Kari Nordlund, daglig leder | D8: 10460000 | E8: 10660000 | F8: =D8-E8 | G8: =F8/D8 | H8: =D8/$D$6 | I8: =E8/$E$6
A9: Avskrivninger | B9: Avskrivningsbudsjettet | C9: Kari Nordlund, daglig leder | D9: 640000 | E9: 620000 | F9: =D9-E9 | G9: =F9/D9 | H9: =D9/$D$6 | I9: =E9/$E$6
A10: Andre driftskostnader | B10: Kostnadsbudsjettet | C10: Kari Nordlund, daglig leder | D10: 1250000 | E10: 1386000 | F10: =D10-E10 | G10: =F10/D10 | H10: =D10/$D$6 | I10: =E10/$E$6
A12: = Sum driftskostnader | D12: =SUM(D7:D10) | E12: =SUM(E7:E10) | F12: =D12-E12 | G12: =F12/D12
A13: = Driftsresultat | D13: =D6-D12 | E13: =E6-E12 | F13: =E13-D13 | G13: =F13/D13
A15: Slik leser du tabellen
A16: Et positivt avvik er alltid godt nytt for bedriften: mer inntekt enn budsjettert, eller lavere kostnad. Et negativt avvik er det motsatte. Kolonnen med avvik i kroner er regnet slik at fortegnet alltid betyr det samme, uansett om raden er en inntekt eller en kostnad.
A17: De to siste kolonnene er nøkkelen. Selger bedriften mer enn budsjettert, MÅ varekostnaden og lønnskostnaden også bli høyere — det er et mengdeavvik, og det er ingens feil. Er derimot andelen av salget en annen enn budsjettert, har noe reelt flyttet seg. Da er det et prisavvik, og da har det en adresse.
A19: Hvor avviket faktisk kommer fra
A20: Mersalg mot budsjett | D20: =E6-D6
A21: Varekostnad ved budsjettert andel, gitt det faktiske salget | D21: =E6*H7
A22: Faktisk varekostnad | D22: =E7
A23: Rent prisavvik på varekostnaden | D23: =D21-D22 | J23: Nær null. Innkjøpet har gått som planlagt.
A24: Andre driftskostnader ved budsjettert andel | D24: =E6*H10
A25: Faktiske andre driftskostnader | D25: =E10
A26: Rent avvik på andre driftskostnader | D26: =D24-D25 | J26: Her ligger pengene. Denne posten skal forklares med bilag.
A28: Kontroll
A29: Ble salget høyere enn budsjettert? | B29: =IF(F6>0,"OK — bedriften solgte mer enn planlagt. Da MÅ varekostnaden og lønnskostnaden også være høyere","AVVIK: salget sviktet. Da er kostnadsavvikene en annen historie")
A30: Er varekostnadsandelen den samme? | B30: =IF(ABS(H7-I7)<0.01,"OK — varekostnaden utgjør nesten nøyaktig samme andel av salget som budsjettert. Materiellbudsjettet har holdt","AVVIK: varekostnadsandelen har flyttet seg. Da er det et prisavvik, og da er innkjøperen riktig adressat")
A31: Hvilket delbudsjett har faktisk sviktet? | B31: =IF(ABS(I10-H10)>ABS(I7-H7),"OK — kostnadsbudsjettet har flyttet seg mest som andel av salget. Det er der du skal be om en spesifikasjon","AVVIK: her er det materiellbudsjettet som har flyttet seg mest")
A33: Fyll ut kolonne J og K for hver rad. Et avvik uten forklaring er bare et tall. Et avvik med forklaring og et tiltak er styring.
A34: Kilde: Bok 1 kap. 9.8 og 9.9. Tallene er de samme som i arbeidsboka «Budsjett».

Sheet Scenario
A1: Scenario — fire knapper
A2: Skru på forutsetningene og se hva som skjer med resultatet og med kontoen. De to svarer ikke likt.
A4: 1 · Knappene
A5: Endre disse fire cellene. Alt annet i arbeidsboka regner seg om.
A6: Vekst i omsetningen mot grunnbudsjettet | B6: 0 | G6: Virker på salgsbudsjettet. Både timeomsetning og materiellsalg vokser, og dermed også varekostnaden og de variable andre kostnadene.
A7: Lønnsvekst mot grunnbudsjettet | B7: 0 | G7: Virker på lønnsbudsjettet. Husk at feriepenger og arbeidsgiveravgift følger med oppover.
A8: Kredittid til kundene, dager | B8: 20 | G8: Virker bare på likviditetsbudsjettet. Resultatet rører seg ikke med en eneste krone.
A9: Kredittid hos grossisten, dager | B9: 30 | G9: Samme sak, men motsatt vei.
A11: 2 · Hva knappene gjør med resultatet
A12: Salgsinntekt | B12: =Resultatbudsjett!B7
A13: Sum driftskostnader | B13: =Resultatbudsjett!B14
A14: Driftsresultat | B14: =Resultatbudsjett!B15 | G14: Kredittidene i B8 og B9 kan du sette til hva du vil — disse fire tallene rører seg ikke.
A15: Driftsmargin | B15: =Resultatbudsjett!B16
A16: Budsjettert årsresultat | B16: =Resultatbudsjett!B23
A18: 3 · Hva knappene gjør med kontoen
A19: Laveste beholdning gjennom året | B19: =Likviditetsbudsjett!B67
A20: Måneden det skjer i | B20: =Likviditetsbudsjett!B68
A21: Måneder i minus | B21: =Likviditetsbudsjett!B69
A22: Største trekk på kassekreditten | B22: =Likviditetsbudsjett!B70
A23: Andel av kassekredittrammen som er brukt | B23: =Likviditetsbudsjett!B72
A24: Renter på kassekreditten gjennom året | B24: =Likviditetsbudsjett!B73
A25: Bankinnskudd 31.12.2027 | B25: =Balansebudsjett!D15
A26: Egenkapitalandel 31.12.2027 | B26: =Balansebudsjett!B33
A28: 4 · Fire oppsett å prøve
A29: Sett inn verdiene i rad 6 til 9, les av tallene over, og skriv dem i de gule kolonnene her. Da har du hele tabellen, regnet av deg selv.
A30: Oppsett | B30: Omsetningsvekst | C30: Lønnsvekst | D30: Kredittid kunder | E30: Driftsresultat du leser av | F30: Bunn du leser av | G30: Hva oppsettet forteller
A31: Grunnbudsjettet | B31: 0 | C31: 0 | D31: 20 | E31: 0 | F31: 0 | G31: Slik Kari har lagt budsjettet. Overskudd, og penger på konto hele året.
A32: Kundene betaler som de gjorde i 2026 | B32: 0 | C32: 0 | D32: 54 | E32: 0 | F32: 0 | G32: Samme resultat, tom konto. Ingenting er endret unntatt når pengene kommer.
