Workbook

Sheet Enkelt
A1: Har vi penger på konto i januar? Den enkle versjonen
A2: Fyll inn de fem gule cellene. Svaret står i den grønne. Alt annet regner seg selv. Vil du gå dypere, ligger hele modellen i arkene bak.
A4: Det du vet
A5: Hvor mye står på konto 1. januar? | B5: 982650 | C5: Bankinnskuddet når året starter.
A6: Hvor mye selger dere for i januar, uten mva.? | B6: 1800000 | C6: Tallet fra salgsbudsjettet. Kunden betaler 25 prosent mva. på toppen.
A7: Hvor mange dager har kundene på seg til å betale? | B7: 20 | C7: Kredittiden på fakturaen. Arket regner med 30 dager i måneden, slik læreboka gjør.
A8: Hvor mye av det kundene skyldte fra i fjor, kommer inn i januar? | B8: 2520000 | C8: Fakturaer fra desember som betales i januar.
A9: Hvor mye går ut av kontoen i januar? | B9: 3092250 | C9: Leverandørgjeld fra i fjor, lønn, arbeidsgiveravgift og andre driftskostnader.
A11: Regnestykket
A12: Januarsalget med mva. | B12: =B6*1.25 -> 2250000 | C12: Det kunden faktisk betaler. Det er dette beløpet som havner på kontoen.
A13: Del av salget som betales samme måned | B13: =MAX(0,(30-B7)/30) -> 0.33333333 | C13: Ved 20 dager kommer en tredel inn samme måned. Resten kommer senere.
A14: Inn fra januarsalget i januar | B14: =B12*B13 -> 750000 | C14: Salget med mva. ganger andelen som betales samme måned.
A15: Sum inn i januar | B15: =B8+B14 -> 3270000 | C15: Gamle fordringer pluss det som kommer inn fra januarsalget.
A16: Inn minus ut i januar | B16: =B15-B9 -> 177750 | C16: Endringen i beholdning. Minus betyr at kontoen synker.
A18: PENGER PÅ KONTO 31. JANUAR | B18: =B5+B16 -> 1160400 | C18: Det som sto på konto, pluss endringen i måneden. Minus betyr at kontoen er tom.
A19: Januarsalg som kommer inn senere | B19: =B12-B14 -> 1500000 | C19: Tjent i januar, men ikke betalt ennå. Det står i overskuddet, men ikke på kontoen.
A21: Hva svaret betyr
A22: ="Ved månedsslutt står det "&TEXT(ROUND(B18,0),"#,##0")&" kroner på konto. Av januarsalget er "&TEXT(ROUND(B19,0),"#,##0")&" kroner tjent, men ikke betalt ennå." -> Ved månedsslutt står det 1,160,400 kroner på konto. Av januarsalget er 1,500,000 kroner tjent, men ikke betalt ennå.
A24: Prøv selv
A25: 1. Sett kredittiden (B7) til 30 dager. Hva skjer med kontoen 31. januar?
A26: 2. Endrer kredittiden overskuddet i resultatbudsjettet? Begrunn svaret.
A27: 3. Hvor mye kan utbetalingene (B9) bli før kontoen går i minus?
A29: Tallene er januar i likviditetsbudsjettet til Nordlys Elektro AS for 2027 (sammendraget). Kilde: Økonomistyring for LØM-emnet, kap. 9.6. Nordlys Elektro AS er en konstruert casebedrift.

Sheet Veiledning
A1: Budsjettering og budsjettkontroll
A2: LØM Økonomistyring kap. 9 · arbeidsregneark · Fagskolen Oslo, Avdeling Elkraft
A3: Emne: Teknisk kommunikasjon og ledelse for 1ET-klassene · LØM for 2ET, 2EK, 3EK og 4EK
A4: Fargekode
A5: Gul celle med blå skrift | B5: Inndata — dette er tallene du endrer.
A6: Grå eller lyseblå celle, svart skrift | B6: Formel — regner seg selv. Ikke skriv over den.
A7: Mørkeblå rad med hvit skrift | B7: Kolonneoverskrift.
A9: Ark i arbeidsboka
A10: Enkelt | B10: Start her. Fem gule celler, ett svar. Pengene på konto i januar regnet på den enkleste måten.
A11: Resultatbudsjett | B11: Hva bedriften tjener, år og måned for måned. Salgsprofilen og satsene er de gule cellene.
A12: Likviditet | B12: Når pengene beveger seg. Tolv måneder, alle innbetalinger og utbetalinger. Kredittiden til kundene står i B5 — det er den ene cellen som avgjør året.
A13: Budsjettkontroll | B13: 2026 målt mot budsjettet: avvik i kroner, i prosent og som andel av salget. Den siste kolonnen er den som avslører hvem som eier avviket.
A14: Scenario | B14: Tre scenarioer: hva kredittiden gjør med året, de fire tiltakene fra lærebokas liste, og kvartalet der budsjettet sprakk.
A16: Tallene som ligger inne er budsjettet Nordlys Elektro AS har lagt for 2027, og budsjettkontrollen for 2026. Samme bedrift som i alle ti kapitlene i Økonomistyring for LØM-emnet.
A17: Alle inndataceller er gule. Vil du bruke arket på din egen bedrift, bytter du dem ut — salgsprofilen, satsene, de inngående postene og forfallsmånedene.
A18: Merverdiavgift og arbeidsgiveravgift forfaller terminvis. Terminene er bygd inn i arket, og du ser dem i blokka fra rad 35 i arket Likviditet.
A20: Tallene som ligger inne er et eksempel fra en elektrobedrift. Bytt dem ut med dine egne — alle formler følger med.
A21: Arbeidsregneark til LØM · Fagskolen Oslo, Avdeling Elkraft. Regnearket er øvingsstøtte, ikke et regnskapssystem.
A23: Den ene knappen
A24: Likviditet!B5 | B24: Kredittid til kundene | C24: Endrer hele årets kontobeholdning. Resultatbudsjettet står helt stille. Det er kapitlets viktigste poeng, og det er bygd inn i arket.
A25: Likviditet!B29 | B25: Måneden investeringen kjøpes i | C25: Tiltak B i klasseoppgaven. Sett den til 9 og se bunnen flytte seg.
A26: Likviditet!B6 | B26: Kredittid hos grossisten | C26: Tiltak D. Virker motsatt vei av kundekredittiden.
A28: Hvilken oppgave bruker hvilket ark
A29: Oppgave i øvingsheftet | B29: Ark | C29: Celler du endrer og leser av
A30: A1 · Går kontoen tom? | B30: Likviditet | C30: Endre B5 og les av B73, B74 og B75. Sammenlikn med B80, som ikke rører seg.
A31: A2 · Hvilken av de tre er en kostnad? | B31: Likviditet | C31: Se rad 57, 59 og 61: feriepenger, merverdiavgift og avdrag. Ingen av dem finnes i arket Resultatbudsjett.
A32: A3 · Klasseoppgave: Kari skal i banken | B32: Scenario | C32: Scenario B, rad 25 til 28. Prøv ett tiltak om gangen i arket Likviditet og skriv bunnen i kolonne C.
A33: 1 · Når kommer pengene inn? | B33: Likviditet | C33: Endre B5 og les av andelene i B9, B10 og B11, og innbetalingene i rad 47 og 48.
A34: 2 · Resultatbudsjettet for 2027 | B34: Resultatbudsjett | C34: Endre B8, B10, B11, B12, B14 og B15. Les av rad 19 til 26.
A35: 3 · Likviditetsbudsjettet for første kvartal | B35: Likviditet | C35: Kolonne C, D og E er januar, februar og mars. Les av sum inn i rad 50, sum ut i rad 64 og beholdningen i rad 69. Deloppgave d) løser du ved å sette B5 til 54.
A36: 4 · Budsjettkontroll: hvem har skylda? | B36: Budsjettkontroll | C36: Endre B6 til C10. Les av avvikene i kolonne D og E, andelene i F og G, og oppsplittingen i rad 16 til 22.
A37: 5 · Eksamensnær: budsjettet sprekker i mars | B37: Scenario | C37: Scenario C, rad 35 til 39, og november-regningen i rad 42 til 46.
A39: Kontrollradene
A40: Hvert regneark har en kontrollblokk. Står det OK, henger tallene sammen. Står det AVVIK, farges cellen rød, og teksten sier hva som ikke går opp.
A41: Merk kontrollen i Likviditet!B86: den sier fra når kassekredittrammen sprenges. Setter du kredittiden høyt nok, slår den ut — og da er det for seint å ringe banken.
A42: Kontroller i arbeidsboka: Resultatbudsjett B32, Resultatbudsjett B33, Resultatbudsjett B34, Likviditet B83, Likviditet B84, Likviditet B85, Likviditet B86, Likviditet B87, Budsjettkontroll B25, Budsjettkontroll B26, Budsjettkontroll B27, Scenario B49, Scenario B50, Scenario B51
A44: Slik henger kapitlene sammen
A45: Budsjettet bygger på kalkylen fra kapittel 5: salgsinntekten er fakturerte timer ganget med timeprisen, pluss materiell med påslag. Kundefordringene og kredittiden er de samme som binder kapital i kapittel 6. Investeringen i mars er den du regner nåverdien av i kapittel 10. Og avviksanalysen bakerst er den samme regnskapslesingen som i kapittel 3 og 4 — bare sett framover i tid.
A47: Kilder
A48: Hjertnes, J. og Skorpen, K.: Økonomistyring for LØM-emnet (ISBN 978-82-450-5544-3), kapittel 9 «Budsjettering og budsjettkontroll», avsnitt 9.1 til 9.8. Forfallsregler for merverdiavgift og arbeidsgiveravgift: skattebetalingsloven og merverdiavgiftsloven (Lovdata).
...

Sheet Resultatbudsjett
A1: Resultatbudsjett 2027
A2: Hva bedriften tjener. Endre de gule cellene — merk at ingen av dem sier noe om NÅR pengene beveger seg.
A4: 1 · Forutsetningene
A5: Post | B5: År | C5: Jan | D5: Feb | E5: Mar | F5: Apr | G5: Mai | H5: Jun | I5: Jul | J5: Aug | K5: Sep | L5: Okt | M5: Nov | N5: Des | O5: Kommentar
A6: Månedsnummer | C6: =1 -> 1 | D6: =2 -> 2 | E6: =3 -> 3 | F6: =4 -> 4 | G6: =5 -> 5 | H6: =6 -> 6 | I6: =7 -> 7 | J6: =8 -> 8 | K6: =9 -> 9 | L6: =10 -> 10 | M6: =11 -> 11 | N6: =12 -> 12
A7: Salg uten mva. | B7: =SUM(C7:N7) -> 24000000 | C7: 1800000 | D7: 2100000 | E7: 2200000 | F7: 2100000 | G7: 2000000 | H7: 2000000 | I7: 1200000 | J7: 1900000 | K7: 2100000 | L7: 2200000 | M7: 2300000 | N7: 2100000 | O7: Salgsprofilen gjennom året: tynn januar, stille juli, tunge høstmåneder.
A8: Bruttofortjeneste | B8: 0.625 | O8: Det som blir igjen av salget etter varekostnaden.
A9: Varekostnad | B9: =SUM(C9:N9) -> 9000000 | C9: =C7*(1-$B$8) -> 675000 | D9: =D7*(1-$B$8) -> 787500 | E9: =E7*(1-$B$8) -> 825000 | F9: =F7*(1-$B$8) -> 787500 | G9: =G7*(1-$B$8) -> 750000 | H9: =H7*(1-$B$8) -> 750000 | I9: =I7*(1-$B$8) -> 450000 | J9: =J7*(1-$B$8) -> 712500 | ... N9: =N7*(1-$B$8) -> 787500 | O9: Følger salget. Lageret forutsettes uendret gjennom året.
A10: Lønn per måned | B10: 700000
A11: Feriepengesats | B11: 0.12
A12: Arbeidsgiveravgift | B12: 0.141
A13: = Lønnskostnad for året | B13: =B10*12*(1+B11)*(1+B12) -> 10734528 | O13: Lønn pluss feriepenger pluss arbeidsgiveravgift av begge deler.
A14: Avskrivninger for året | B14: 680000
A15: Andre driftskostnader for året | B15: 1500000
A16: Merverdiavgiftssats | B16: 0.25
A18: 2 · Resultatbudsjettet
A19: Salgsinntekt | B19: =B7 -> 24000000 | C19: =C7 -> 1800000 | D19: =D7 -> 2100000 | E19: =E7 -> 2200000 | F19: =F7 -> 2100000 | G19: =G7 -> 2000000 | H19: =H7 -> 2000000 | I19: =I7 -> 1200000 | ... N19: =N7 -> 2100000
A20: − Varekostnad | B20: =B9 -> 9000000 | C20: =C9 -> 675000 | D20: =D9 -> 787500 | E20: =E9 -> 825000 | F20: =F9 -> 787500 | G20: =G9 -> 750000 | H20: =H9 -> 750000 | I20: =I9 -> 450000 | ... N20: =N9 -> 787500
A21: − Lønnskostnad | B21: =B13 -> 10734528 | C21: =$B$13/12 -> 894544 | D21: =$B$13/12 -> 894544 | E21: =$B$13/12 -> 894544 | F21: =$B$13/12 -> 894544 | G21: =$B$13/12 -> 894544 | H21: =$B$13/12 -> 894544 | I21: =$B$13/12 -> 894544 | J21: =$B$13/12 -> 894544 | ... N21: =$B$13/12 -> 894544
A22: − Avskrivninger | B22: =B14 -> 680000 | C22: =$B$14/12 -> 56666.667 | D22: =$B$14/12 -> 56666.667 | E22: =$B$14/12 -> 56666.667 | F22: =$B$14/12 -> 56666.667 | G22: =$B$14/12 -> 56666.667 | H22: =$B$14/12 -> 56666.667 | I22: =$B$14/12 -> 56666.667 | J22: =$B$14/12 -> 56666.667 | ... N22: =$B$14/12 -> 56666.667 | O22: Ikke-betalbar kostnad. Den står IKKE i likviditetsbudsjettet.
A23: − Andre driftskostnader | B23: =B15 -> 1500000 | C23: =$B$15/12 -> 125000 | D23: =$B$15/12 -> 125000 | E23: =$B$15/12 -> 125000 | F23: =$B$15/12 -> 125000 | G23: =$B$15/12 -> 125000 | H23: =$B$15/12 -> 125000 | I23: =$B$15/12 -> 125000 | J23: =$B$15/12 -> 125000 | ... N23: =$B$15/12 -> 125000
A24: = Sum driftskostnader | B24: =SUM(B20:B23) -> 21914528 | C24: =SUM(C20:C23) -> 1751210.7 | D24: =SUM(D20:D23) -> 1863710.7 | E24: =SUM(E20:E23) -> 1901210.7 | F24: =SUM(F20:F23) -> 1863710.7 | G24: =SUM(G20:G23) -> 1826210.7 | H24: =SUM(H20:H23) -> 1826210.7 | I24: =SUM(I20:I23) -> 1526210.7 | ... N24: =SUM(N20:N23) -> 1863710.7
A25: = Driftsresultat | B25: =B19-B24 -> 2085472 | C25: =C19-C24 -> 48789.333 | D25: =D19-D24 -> 236289.33 | E25: =E19-E24 -> 298789.33 | F25: =F19-F24 -> 236289.33 | G25: =G19-G24 -> 173789.33 | H25: =H19-H24 -> 173789.33 | I25: =I19-I24 -> -326210.67 | ... N25: =N19-N24 -> 236289.33
A26: Driftsmargin | B26: =B25/B19 -> 0.086894667 | C26: =C25/C19 -> 0.027105185 | D26: =D25/D19 -> 0.11251873 | E26: =E25/E19 -> 0.13581333 | F26: =F25/F19 -> 0.11251873 | G26: =G25/G19 -> 0.086894667 | H26: =H25/H19 -> 0.086894667 | I26: =I25/I19 -> -0.27184222 | ... N26: =N25/N19 -> 0.11251873 | O26: Legg merke til juli: lav omsetning, samme faste kostnader.
A28: 3 · Første kvartal
A29: Driftsresultat januar til mars | B29: =SUM(C25:E25) -> 583868 | O29: Positivt. Og likevel kan kontoen være tom — se arket Likviditet.
A31: Kontroll
A32: Summerer månedene seg til året? | B32: =IF(ABS(SUM(C25:N25)-B25)<1,"OK — de tolv månedene summerer seg til årsbudsjettet","AVVIK: månedene og året gir ulikt driftsresultat") -> OK — de tolv månedene summerer seg til årsbudsjettet
A33: Er driftsresultatet positivt? | B33: =IF(B25>0,"OK — budsjettet viser overskudd","AVVIK: budsjettet går i minus — da er det ikke likviditeten som er hovedproblemet") -> OK — budsjettet viser overskudd
A34: Er bruttofortjenesten mulig? | B34: =IF(AND(B8>0,B8<1),"OK — bruttofortjenesten ligger mellom null og hundre prosent","AVVIK: umulig bruttofortjeneste i B8") -> OK — bruttofortjenesten ligger mellom null og hundre prosent
A36: Prøv dette: endre salget i en enkelt måned og se at driftsresultatet flytter seg. Gå så til arket Likviditet og endre kredittiden i B5 — der flytter kontobeholdningen seg uten at ett eneste tall her endrer seg.
A37: Kilde: Økonomistyring for LØM-emnet kap. 9.2 og 9.3. Tallene er budsjettet Nordlys Elektro AS har lagt for 2027.

Sheet Likviditet
A1: Likviditetsbudsjett 2027
A2: Når pengene beveger seg. Samme bedrift, samme år, helt annet svar.
A4: 1 · De to knappene
A5: Kredittid til kundene, dager | B5: 20 | O5: DETTE er cellen. Endre den, og hele året flytter seg.
A6: Kredittid hos grossisten, dager | B6: 30 | O6: Motsatt vei: lengre kreditt her hjelper på kontoen.
A8: Andel av et salg som innbetales
A9: i salgsmåneden | B9: =IF($B$5<=30,(30-$B$5)/30,0) -> 0.33333333 | O9: Læreboka regner tretti dager per måned og jevnt salg gjennom måneden.
A10: måneden etter | B10: =IF($B$5<=30,$B$5/30,MAX(0,(60-$B$5)/30)) -> 0.66666667
A11: to måneder etter | B11: =IF($B$5<=30,0,MIN(1,($B$5-30)/30)) -> 0
A12: Andel av et varekjøp som utbetales
A13: i kjøpsmåneden | B13: =IF($B$6<=30,(30-$B$6)/30,0) -> 0
A14: måneden etter | B14: =IF($B$6<=30,$B$6/30,MAX(0,(60-$B$6)/30)) -> 1
A15: to måneder etter | B15: =IF($B$6<=30,0,MIN(1,($B$6-30)/30)) -> 0
A17: 2 · Inngående størrelser
A18: Bankinnskudd 1. januar | B18: 982650
A19: Kundefordringer 1. januar | B19: 4200000 | O19: Svarer til 54 dagers salg, ikke 20. Det burde vært et varsel allerede i november.
A20: herav inn i januar | B20: 0.6
A21: Leverandørgjeld 1. januar, forfaller i januar | B21: 2100000
A22: Skyldig arbeidsgiveravgift 6. termin 2026, forfaller 15. januar | B22: 136000
A23: Skyldig merverdiavgift 6. termin 2026, forfaller 10. februar | B23: 1064000
A24: Skyldige feriepenger, utbetales i juni | B24: 890000
A25: Forhåndsskatt, halvparten i februar og halvparten i april | B25: 256850
A26: Renter og avdrag per kvartal | B26: 192500
A27: Renteinntekter per kvartal | B27: 14000
A28: Investering, kjøpesum uten mva. | B28: 480000
A29: Investeringen kjøpes i måned nummer | B29: 3 | O29: Endre til 9 og se hva som skjer med bunnen. Det er tiltak B i klasseoppgaven.
A30: Kassekredittramme | B30: 1500000
A31: Kassekreditt allerede trukket 1. januar | B31: 300000
A32: Kassekredittrente | B32: 0.08
A34: 3 · Merverdiavgiftsterminene
A35: Termin | B35: Måneder | C35: Utgående mva. | D35: Inngående mva. | E35: Netto å betale | F35: Forfaller i måned nr
A36: Termin 1 | B36: Jan–Feb | C36: =(Resultatbudsjett!C7+Resultatbudsjett!D7)*Resultatbudsjett!$B$16 -> 975000 | D36: =(Resultatbudsjett!C9+Resultatbudsjett!D9+2*Resultatbudsjett!$B$15/12+IF(AND($B$29>=1,$B$29<=2),$B$28,0))*Resultatbudsjett!$B$16 -> 428125 | E36: =C36-D36 -> 546875 | F36: =4 -> 4 | H36: Utgående mva. på salget minus inngående mva. på varekjøp, andre driftskostnader og investeringen. Forfaller én måned og ti dager etter terminen er slutt.
A37: Termin 2 | B37: Mar–Apr | C37: =(Resultatbudsjett!E7+Resultatbudsjett!F7)*Resultatbudsjett!$B$16 -> 1075000 | D37: =(Resultatbudsjett!E9+Resultatbudsjett!F9+2*Resultatbudsjett!$B$15/12+IF(AND($B$29>=3,$B$29<=4),$B$28,0))*Resultatbudsjett!$B$16 -> 585625 | E37: =C37-D37 -> 489375 | F37: =6 -> 6
A38: Termin 3 | B38: Mai–Jun | C38: =(Resultatbudsjett!G7+Resultatbudsjett!H7)*Resultatbudsjett!$B$16 -> 1000000 | D38: =(Resultatbudsjett!G9+Resultatbudsjett!H9+2*Resultatbudsjett!$B$15/12+IF(AND($B$29>=5,$B$29<=6),$B$28,0))*Resultatbudsjett!$B$16 -> 437500 | E38: =C38-D38 -> 562500 | F38: =8 -> 8
A39: Termin 4 | B39: Jul–Aug | C39: =(Resultatbudsjett!I7+Resultatbudsjett!J7)*Resultatbudsjett!$B$16 -> 775000 | D39: =(Resultatbudsjett!I9+Resultatbudsjett!J9+2*Resultatbudsjett!$B$15/12+IF(AND($B$29>=7,$B$29<=8),$B$28,0))*Resultatbudsjett!$B$16 -> 353125 | E39: =C39-D39 -> 421875 | F39: =10 -> 10
A40: Termin 5 | B40: Sep–Okt | C40: =(Resultatbudsjett!K7+Resultatbudsjett!L7)*Resultatbudsjett!$B$16 -> 1075000 | D40: =(Resultatbudsjett!K9+Resultatbudsjett!L9+2*Resultatbudsjett!$B$15/12+IF(AND($B$29>=9,$B$29<=10),$B$28,0))*Resultatbudsjett!$B$16 -> 465625 | E40: =C40-D40 -> 609375 | F40: =12 -> 12
A42: 4 · Innbetalinger
A43: Post | B43: År | C43: Jan | D43: Feb | E43: Mar | F43: Apr | G43: Mai | H43: Jun | I43: Jul | J43: Aug | K43: Sep | L43: Okt | M43: Nov | N43: Des | O43: Kommentar
A44: Månedsnummer | C44: =1 -> 1 | D44: =2 -> 2 | E44: =3 -> 3 | F44: =4 -> 4 | G44: =5 -> 5 | H44: =6 -> 6 | I44: =7 -> 7 | J44: =8 -> 8 | K44: =9 -> 9 | L44: =10 -> 10 | M44: =11 -> 11 | N44: =12 -> 12
A45: Salg uten mva. | B45: =SUM(C45:N45) -> 24000000 | C45: =Resultatbudsjett!C7 -> 1800000 | D45: =Resultatbudsjett!D7 -> 2100000 | E45: =Resultatbudsjett!E7 -> 2200000 | F45: =Resultatbudsjett!F7 -> 2100000 | G45: =Resultatbudsjett!G7 -> 2000000 | H45: =Resultatbudsjett!H7 -> 2000000 | I45: =Resultatbudsjett!I7 -> 1200000 | J45: =Resultatbudsjett!J7 -> 1900000 | ... N45: =Resultatbudsjett!N7 -> 2100000
...

Sheet Budsjettkontroll
A1: Budsjettkontroll 2026
A2: Hva som ble annerledes enn planlagt — og hvem som faktisk eier avviket.
A5: Post | B5: Budsjett 2026 | C5: Regnskap 2026 | D5: Avvik i kroner | E5: Avvik i prosent | F5: Andel av salget, budsjett | G5: Andel av salget, regnskap | H5: Hva raden forteller
A6: Salgsinntekt | B6: 22000000 | C6: 22400000 | D6: =C6-B6 -> 400000 | E6: =D6/B6 -> 0.018181818 | H6: Positivt avvik: bedriften solgte mer enn planlagt.
A7: Varekostnad | B7: 8240000 | C7: 8390000 | D7: =B7-C7 -> -150000 | E7: =D7/B7 -> -0.018203883 | F7: =B7/$B$6 -> 0.37454545 | G7: =C7/$C$6 -> 0.37455357 | H7: Negativt i kroner — men se de to siste kolonnene før du konkluderer.
A8: Lønnskostnad | B8: 10460000 | C8: 10660000 | D8: =B8-C8 -> -200000 | E8: =D8/B8 -> -0.019120459 | F8: =B8/$B$6 -> 0.47545455 | G8: =C8/$C$6 -> 0.47589286 | H8: Samme sak: mer salg krever flere timer.
A9: Avskrivninger | B9: 640000 | C9: 620000 | D9: =B9-C9 -> 20000 | E9: =D9/B9 -> 0.03125 | F9: =B9/$B$6 -> 0.029090909 | G9: =C9/$C$6 -> 0.027678571 | H9: Liten post, og den følger ikke salget.
A10: Andre driftskostnader | B10: 1250000 | C10: 1386000 | D10: =B10-C10 -> -136000 | E10: =D10/B10 -> -0.1088 | F10: =B10/$B$6 -> 0.056818182 | G10: =C10/$C$6 -> 0.061875 | H10: Her har noe faktisk flyttet seg. Dette er posten Kari skal spørre om.
A12: = Sum driftskostnader | B12: =SUM(B7:B10) -> 20590000 | C12: =SUM(C7:C10) -> 21056000 | D12: =B12-C12 -> -466000 | E12: =D12/B12 -> -0.022632346
A13: = Driftsresultat | B13: =B6-B12 -> 1410000 | C13: =C6-C12 -> 1344000 | D13: =C13-B13 -> -66000 | E13: =D13/B13 -> -0.046808511 | H13: Negativt avvik, til tross for at salget ble høyere enn budsjettert.
A15: Hvor avviket faktisk kommer fra
A16: Mersalg mot budsjett | B16: =C6-B6 -> 400000
A17: Varekostnad ved budsjettert andel, gitt det faktiske salget | B17: =C6*F7 -> 8389818.2
A18: Faktisk varekostnad | B18: =C7 -> 8390000
A19: Rent prisavvik på varekostnaden | B19: =B17-B18 -> -181.81818 | H19: Nær null: innkjøpet har gått som planlagt. Kroneavviket er et mengdeavvik.
A20: Andre driftskostnader ved budsjettert andel | B20: =C6*F10 -> 1272727.3
A21: Faktiske andre driftskostnader | B21: =C10 -> 1386000
A22: Rent avvik på andre driftskostnader | B22: =B20-B21 -> -113272.73 | H22: Her ligger pengene. Dette er posten som skal forklares med bilag.
A24: Kontroll
A25: Ble salget høyere enn budsjettert? | B25: =IF(D6>0,"OK — bedriften solgte mer enn planlagt. Da MÅ varekostnaden og lønnskostnaden også være høyere","AVVIK: salget sviktet — da er kostnadsavvikene en annen historie") -> OK — bedriften solgte mer enn planlagt. Da MÅ varekostnaden og lønnskostnaden også være høyere
A26: Er varekostnadsandelen den samme? | B26: =IF(ABS(F7-G7)<0.01,"OK — varekostnaden utgjør nesten nøyaktig samme andel av salget som budsjettert. Innkjøpet har gått som planlagt","AVVIK: varekostnadsandelen har flyttet seg — da er det et prisavvik, og da er innkjøperen riktig adressat") -> OK — varekostnaden utgjør nesten nøyaktig samme andel av salget som budsjettert. Innkjøpet har gått som planlagt
A27: Hvilken post har faktisk flyttet seg? | B27: =IF(ABS(G10-F10)>ABS(G7-F7),"OK — andre driftskostnader har flyttet seg mest som andel av salget. Det er der Kari skal be om en spesifikasjon","AVVIK: her er det varekostnaden som har flyttet seg mest") -> OK — andre driftskostnader har flyttet seg mest som andel av salget. Det er der Kari skal be om en spesifikasjon
A29: Avviksanalysen peker på stedet. Den gir ikke svaret. Det siste finner du bare ved å se på bilagene.
A30: Kilde: Økonomistyring for LØM-emnet kap. 9.8 om budsjettkontroll og avviksanalyse.

Sheet Scenario
A1: Tre scenarioer
A2: Samme resultatbudsjett. Helt ulike år på konto.
A4: Scenario A · hva kredittiden gjør med året
A5: Sett kredittiden i Likviditet!B5 til hver av verdiene under og les av bunnen. Radene her viser det arket regner nå.
A7: Kredittid som ligger inne nå | B7: =Likviditet!B5 -> 20
A8: Laveste kontobeholdning | B8: =Likviditet!B73 -> 1160400
A9: Måneden det skjer i | B9: =Likviditet!B74 -> Jan
A10: Måneder i minus | B10: =Likviditet!B75 -> 0
A11: Driftsresultat i resultatbudsjettet | B11: =Resultatbudsjett!B25 -> 2085472 | F11: Står stille uansett. Skriv ned bunnen for hver kredittid du prøver.
A13: Kredittid | B13: Hva den svarer til | C13: Skriv inn bunnen du leser av | E13: Hva raden betyr
A14: 20 | B14: 20 dager | C14: 0 | E14: Budsjettets egen forutsetning.
A15: 30 | B15: 30 dager | C15: 0 | E15: Én måned. Vanlig avtalt frist hos større kunder.
A16: 35 | B16: 35 dager | C16: 0 | E16: Kredittiden har glidd litt.
A17: 45 | B17: 45 dager | C17: 0 | E17: Her går kontoen i minus for første gang. Ved 44 dager er det 24 533 kroner igjen på det verste.
A18: 54 | B18: 54 dager | C18: 0 | E18: Som kundene faktisk betalte i 2026.
A20: Kolonne C er din egen notatkolonne: sett kredittiden i Likviditet!B5, les av Likviditet!B73 og skriv tallet inn her. Da har du hele tabellen fra økta, regnet av deg selv.
A22: Scenario B · de fire tiltakene
A23: Utgangspunktet er at kundene bruker 54 dager, som de gjorde i 2026.
A24: Tiltak | B24: Slik gjør du det i arket | C24: Bunn du leser av | E24: Hva tiltaket koster
A25: A · kortere kredittid til kundene | B25: Sett Likviditet!B5 til 20 | C25: 0 | E25: ingenting i kroner — bare at noen fakturerer samme dag og purrer etter fjorten dager
A26: B · utsette investeringen | B26: Sett Likviditet!B29 til 9 | C26: 0 | E26: et halvt år uten det utstyret skulle tjene penger på — regn på det i kapittel 10
A27: C · utvidet kassekreditt | B27: Sett Likviditet!B30 høyere | C27: 0 | E27: renter, og problemet er like stort neste år
A28: D · lengre kreditt hos grossisten | B28: Sett Likviditet!B6 til 45 | C28: 0 | E28: mulige kontantrabatter, og problemet flyttes til leverandøren
A30: Prøv ett tiltak om gangen, og sett arket tilbake mellom hver gang. Skriv bunnen i kolonne C. Så prøver du to av dem sammen.
A32: Scenario C · mars sprekker
A33: Første kvartal, budsjettert mot slik det faktisk gikk.
B34: Budsjettert | C34: Faktisk | D34: Avvik | E34: Hva raden betyr
A35: Kredittid til kundene, dager | B35: 20 | C35: 54 | D35: =C35-B35 -> 34 | E35: Den ene forutsetningen som velter kvartalet.
A36: Innbetalt i kvartalet | B36: 10005667 | C36: 6989000 | D36: =C36-B36 -> -3016666.7 | E36: Sett kredittiden i Likviditet!B5 og les av SUM(C50:E50) for å regne begge selv.
A37: Utbetalt i kvartalet | B37: =SUM(Likviditet!C64:E64) -> 8815200 | C37: =B37 -> 8815200 | D37: =C37-B37 -> 0 | E37: Nøyaktig det samme. Regningene bryr seg ikke om når kundene betaler.
A38: Beholdning 31. mars | B38: =Likviditet!B18+B36-B37 -> 2173116.7 | C38: =Likviditet!B18+C36-C37 -> -843550 | D38: =C38-B38 -> -3016666.7
A39: Driftsresultat i kvartalet | B39: =Resultatbudsjett!B29 -> 583868 | C39: =B39 -> 583868 | D39: =0 -> 0 | E39: Uendret. Regnskapet viser overskudd i et kvartal der kontoen gikk tom.
A41: Hva burde vært gjort i november?
A42: Kundefordringer 31.12.2026 | B42: =Likviditet!B19 -> 4200000
A43: Salg 2026 inkl. mva. | B43: 28000000
A44: Kredittiden regnskapet allerede viste | B44: =B42*360/B43 -> 54
A45: Kredittiden budsjettet forutsatte | B45: =B35 -> 20
A46: Bom | B46: =B44-B45 -> 34 | E46: Tallet sto i balansen hele tida. Ingen regnet på det.
A48: Kontroll
A49: Er hele avviket i mars et innbetalingsavvik? | B49: =IF(ABS(D38-D36)<1,"OK — hele avviket kommer fra innbetalingene. Utbetalingene er de samme","AVVIK: da er det mer enn kredittiden som har endret seg") -> OK — hele avviket kommer fra innbetalingene. Utbetalingene er de samme
...
