Workbook

Sheet Enkelt
A1: Hva koster en rabatt? Den enkle versjonen
A2: Fyll inn de fire gule cellene. Svaret står i den grønne. Alt annet regner seg selv. Vil du gå dypere, ligger hele modellen i arkene bak.
A4: Det du vet
A5: Hva koster jobben kunden i dag, uten mva.? | B5: 26611.2 | C5: Sikringsskapbyttet: selvkost pluss 12 prosent fortjeneste.
A6: Hva koster timer, materiell og kjøring på jobben? | B6: 19560 | C6: De variable kostnadene. Ikke ta med andelen av kontoret her.
A7: Hvor stor er jobbens andel av kontor og biler? | B7: 4200 | C7: Det som løper uansett. Brukes bare til å se fortjenesten til slutt.
A8: Hvor stor rabatt ber kunden om? | B8: 0.1 | C8: Skriv for eksempel 10 %. Prøv også 5 % og 20 %.
A10: Regnestykket
A11: Dekningsbidrag per jobb i dag | B11: =B5-B6 -> 7051.2 | C11: Prisen minus de variable kostnadene. Det jobben gir til kontor og fortjeneste.
A12: Ny pris med rabatten | B12: =B5*(1-B8) -> 23950.08 | C12: Prisen kunden får.
A13: Nytt dekningsbidrag per jobb | B13: =B12-B6 -> 4390.08 | C13: Kostnadene er de samme. Hele rabatten går av dekningsbidraget.
A14: Så mye faller dekningsbidraget | B14: =1-B13/B11 -> 0.37739959 | C14: Sammenlikn med rabatten. Fallet er alltid større.
A16: SÅ MANGE FLERE JOBBER MÅ DERE SELGE | B16: =B11/B13-1 -> 0.60616663 | C16: Gammelt dekningsbidrag delt på nytt, minus én. Rundt 61 prosent med tallene som står inne.
A17: Fortjeneste over selvkost etter rabatten | B17: =B12-B6-B7 -> 190.08 | C17: Før rabatten var den 2 851,20 kroner.
A19: Hva svaret betyr
A20: ="Gir dere "&TEXT(B8,"0.0 %")&" rabatt, må dere selge "&TEXT(B16,"0.0 %")&" flere jobber for å sitte igjen med like mye dekningsbidrag." -> Gir dere 10.0 % rabatt, må dere selge 60.6 % flere jobber for å sitte igjen med like mye dekningsbidrag.
A21: ="Fortjenesten over selvkost på hver jobb er da bare "&TEXT(ROUND(B17,2),"#,##0.00")&" kroner." -> Fortjenesten over selvkost på hver jobb er da bare 190.08 kroner.
A23: Prøv selv
A24: 1. Sett rabatten i B8 til 5 %. Hvor mange flere jobber må dere selge nå?
A25: 2. Sett rabatten til 20 %. Hva skjer med svaret, og med fortjenesten i B17?
A26: 3. Hvor stor rabatt kan du gi før fortjenesten i B17 blir null?
A28: Tallene er sikringsskapkalkylen til Nordlys Elektro AS (sammendraget og regnearket til kap. 7, fra Økonomistyring for LØM-emnet, kap. 5). Kilde: Markedsføring, organisasjon og ledelse for LØM-emnet, kap. 7. Nordlys Elektro AS er en konstruert casebedrift.

Sheet Veiledning
A1: Pris som konkurransevirkemiddel
A2: LØM Markedsføring kap. 7 · arbeidsregneark · Fagskolen Oslo, Avdeling Elkraft
A3: Emne: Teknisk kommunikasjon og ledelse for 1ET-klassene · LØM for 2ET, 2EK, 3EK og 4EK
A4: Fargekode
A5: Gul celle med blå skrift | B5: Inndata — dette er tallene du endrer.
A6: Grå eller lyseblå celle, svart skrift | B6: Formel — regner seg selv. Ikke skriv over den.
A7: Mørkeblå rad med hvit skrift | B7: Kolonneoverskrift.
A9: Ark i arbeidsboka
A10: Enkelt | B10: Start her. Fire gule celler, ett svar. Hva en rabatt koster, regnet på den enkleste måten.
A11: Gulv, tak og pris | B11: Kalkylen på sikringsskapbyttet. De tre grensene, og hvor konkurrentene ligger.
A12: Pris og dekningsbidrag | B12: Hva som skjer med dekningsbidrag, dekningsgrad og fortjeneste når prisen justeres.
A13: Hvor mye må volumet øke | B13: DET VIKTIGSTE ARKET. Regnestykket ingen gjør før de gir rabatt.
A14: Prisdifferensiering | B14: Fem priser på den samme montørtimen, med dekningsbidrag og kriterium.
A15: Scenario | B15: Tre spørsmål: hva avslaget koster på jobben, hva det koster på hele bedriften, og hva du kan tilby i stedet.
A16: Din egen prisliste | B16: Samme oppsett, tomt. Legg inn tallene fra din egen bedrift.
A18: Tallene som ligger inne er Nordlys Elektro AS sine egne for 2026.
A19: Kalkylen på sikringsskapet er den samme som i Økonomistyring kapittel 5.
A21: Tallene som ligger inne er et eksempel fra en elektrobedrift. Bytt dem ut med dine egne — alle formler følger med.
A22: Arbeidsregneark til LØM · Fagskolen Oslo, Avdeling Elkraft. Regnearket er øvingsstøtte, ikke et regnskapssystem.
A24: De tre grensene
A25: 1 · Variable kostnader | B25: Det absolutte gulvet. Under dette taper du på hver eneste jobb.
A26: 2 · Selvkost | B26: Gulvet på lang sikt. Under dette dekkes ikke husleie og administrasjon.
A27: 3 · Konkurrentenes pris | B27: Taket — men bare hvis kunden ser tjenestene som like.
A29: Den ene formelen å huske
A30: Nødvendig volumfaktor | B30: gammelt dekningsbidrag delt på nytt dekningsbidrag | C30: Rabatt tas ikke fra prisen. Den tas fra dekningsbidraget, og det er derfor volumkravet blir så mye større enn rabatten.
A32: Hvilken oppgave bruker hvilket ark
A33: Oppgave i øvingsheftet | B33: Ark | C33: Celler du endrer og leser av
A34: A2 · Når er det riktig å tape en jobb på pris? | B34: Gulv, tak og pris | C34: Les av de to gulvene i B14 og B15 og konkurrenttilbudene i C27 til C29.
A35: A3 · Klasseoppgave: sett prisen på tre oppdrag | B35: Prisdifferensiering | C35: Endre faktorene i B11 til B15 og les av dekningsbidraget per time i kolonne E. Rammeavtalen regnes i B25.
A36: 2 · Gulvet, taket og prisen imellom | B36: Gulv, tak og pris | C36: Endre B5 til B11. Les av B14, B15, B17, B18, B21 og B22, og konkurrenttilbudene i C27 til C29.
A37: 3 · Hva et prisavslag faktisk koster | B37: Pris og dekningsbidrag og Hvor mye må volumet øke | C37: Endre B5 til B8 i «Hvor mye må volumet øke». Les av B17, B19, B22 og B23, og hele rabattstigen i rad 29 til 34. Ladepunktet står i rad 36 til 43.
A38: 4 · Tre kunder, tre priser | B38: Prisdifferensiering | C38: Endre faktorene i kolonne B. Les av kolonne E og F, og volumkravet til rammeavtalen i B25.
A39: 5 · Eksamensnær: ti prosent for å signere i dag | B39: Scenario | C39: Sett avslaget i B7 og antall framtidige jobber i B21. Les av B15, B17, B18, B22 og B23 i scenario A, B38, B45 og B46 i scenario B, og hele tabellen i scenario C.
A41: Kontrollradene
A42: Hvert ark har en kontrollblokk nederst. Står det OK, henger tallene sammen. Står det AVVIK, farges cellen rød, og teksten sier hva som ikke går opp.
A43: Tre unntak: kontrollen i «Gulv, tak og pris» C44 og de to i scenario B, C50 og C52, skal vise AVVIK med tallene som ligger inne. Der er avviket selve svaret — jobben kan ikke vinnes på pris, prisavslaget kan ikke tas igjen på volum, og ti prosent på alt snur overskuddet til underskudd.
A44: Kontroller i arbeidsboka: Gulv, tak og pris C41, Gulv, tak og pris C42, Gulv, tak og pris C43, Gulv, tak og pris C44, Pris og dekningsbidrag C15, Pris og dekningsbidrag C16, Hvor mye må volumet øke C51, Hvor mye må volumet øke C52, Hvor mye må volumet øke C53, Prisdifferensiering C32, Prisdifferensiering C33, Prisdifferensiering C34, Scenario C26, Scenario C27, Scenario C50, Scenario C52, Scenario C65, Scenario C66
A46: Kilder
A47: Hjertnes, Frode: Markedsføring, organisasjon og ledelse for LØM-emnet, 4. utgave, kapittel 7 «Pris som konkurransevirkemiddel», avsnitt 7.1 til 7.5.
A48: Kalkyle, driftstall og elastisitet: Nordlys Elektro AS, Økonomistyring kapittel 2, 3 og 5. Bransjetall: NHO Elektro, Lønnsomhetsrapport 2025, gjengitt i Elektro 24-7 19.08.2026 (hentet 10.09.2026). De 809 er bedriftene i datagrunnlaget, ikke bransjen. NHO Elektro oppgir ikke svarprosent.
...

Sheet Gulv, tak og pris
A1: Sikringsskapbytte i enebolig — fra kostnad til kundepris
A2: Endre de gule cellene. Alt annet regner seg selv.
A4: Kalkylen
A5: Montørtimer på jobben | B5: 14
A6: Timekostnad (lønn, sosiale kostnader, bil og verktøy) | B6: 640
A7: Materiell, inntakskost | B7: 9800
A8: Kjøring | B8: 800
A9: Indirekte kostnader (andel av kontor, administrasjon og biler) | B9: 4200
A10: Fortjeneste i prosent av selvkost | B10: 0.12
A11: Merverdiavgift | B11: 0.25
A13: De tre grensene
A14: = Variable (direkte) kostnader | B14: =B5*B6+B7+B8 -> 19560 | D14: ABSOLUTT GULV. Under dette taper du penger på hver eneste jobb.
A15: = Selvkost | B15: =B14+B9 -> 23760 | D15: GULV PÅ LANG SIKT. Under dette dekkes ikke det som løper uansett.
A16: + Fortjeneste | B16: =B15*B10 -> 2851.2
A17: = Pris eksklusive merverdiavgift | B17: =B15+B16 -> 26611.2
A18: = Pris til kunden, inklusive merverdiavgift | B18: =B17*(1+B11) -> 33264
A20: Dekningsbidraget på jobben
A21: = Dekningsbidrag (pris minus VARIABLE kostnader) | B21: =B17-B14 -> 7051.2 | D21: De indirekte kostnadene trekkes IKKE fra her. De er ikke variable.
A22: = Dekningsgrad | B22: =IF(B17=0,0,B21/B17) -> 0.26497114
A23: = Fortjeneste over selvkost | B23: =B17-B15 -> 2851.2
A25: Hva de andre tok på den samme jobben
A26: Tilbud | B26: Inkl. mva. | C26: Eks. mva. | D26: Merk
A27: Det billigste tilbudet kunden hentet inn | B27: 30500 | C27: =B27/(1+$B$11) -> 24400 | D27: Taket hvis kunden ser de tre tjenestene som like.
A28: Nordlys Elektro AS | B28: =B18 -> 33264 | C28: =B28/(1+$B$11) -> 26611.2 | D28: Kalkylen over. Regnes ut, ikke skrevet inn.
A29: Det dyreste tilbudet kunden hentet inn | B29: 35900 | C29: =B29/(1+$B$11) -> 28720 | D29: Taket hvis kunden ser en forskjell og betaler for den.
A31: = Laveste konkurrenttilbud, eks. mva. | B31: =MIN(C27,C29) -> 24400
A32: = Høyeste konkurrenttilbud, eks. mva. | B32: =MAX(C27,C29) -> 28720
A33: = Hvem av tilbudene er lavest? (INDEX/MATCH) | C33: =INDEX(A27:A29,MATCH(MIN(C27:C29),C27:C29,0)) -> Det billigste tilbudet kunden hentet inn
A34: = Handlingsrommet over selvkost, opp til høyeste tilbud | B34: =B32-B15 -> 4960
A35: = Hvor mye det laveste tilbudet ligger over vår selvkost | B35: =B31-B15 -> 640 | D35: =IF(B35<0,"Det laveste tilbudet ligger UNDER vår selvkost. Denne jobben kan vi ikke vinne på pris.",IF(B35<B16,"Det laveste tilbudet ligger over selvkost, men under vår fortjeneste. Matcher vi, jobber vi nesten gratis.","Det er rom for å matche og fortsatt tjene penger.")) -> Det laveste tilbudet ligger over selvkost, men under vår fortjeneste. Matcher vi, jobber vi nesten gratis.
A37: Kostnadene gir gulvet. Konkurrentene gir taket. Kundens betalingsvilje bestemmer hvor i mellomrommet du havner.
A38: De to konkurrenttilbudene er konstruert for undervisningen. Kalkylen er Nordlys' egen, fra Økonomistyring kapittel 5.
A40: Kontroll
A41: Går kalkylestigen oppover? | C41: =IF(AND(B14<B15,B15<B17,B17<B18),"OK — variable kostnader, selvkost, pris uten mva. og pris til kunden stiger i riktig rekkefølge","AVVIK: kalkylen går ikke oppover — kontroller postene") -> OK — variable kostnader, selvkost, pris uten mva. og pris til kunden stiger i riktig rekkefølge
A42: Er de indirekte kostnadene holdt utenfor dekningsbidraget? | C42: =IF(ABS(B21-(B17-B14))<0.01,"OK — dekningsbidraget er pris minus VARIABLE kostnader","AVVIK: dekningsbidraget er regnet av feil kostnadsgrunnlag") -> OK — dekningsbidraget er pris minus VARIABLE kostnader
A43: Ligger prisen over begge gulvene? | C43: =IF(B17>=B15,"OK — prisen dekker selvkost og gir fortjeneste",IF(B17>=B14,"AVVIK: prisen ligger mellom de to gulvene — forsvarlig bare ved ledig kapasitet, aldri som listepris","AVVIK: prisen ligger under de variable kostnadene — si nei")) -> OK — prisen dekker selvkost og gir fortjeneste
A44: Kan jobben vinnes på pris alene? | C44: =IF(B35>=B16,"OK — det laveste tilbudet ligger over vår selvkost pluss fortjeneste. Jobben kan vinnes på pris","AVVIK: det laveste tilbudet gir oss ikke rom for fortjeneste. Skal jobben vinnes, må tilbudet endres — ikke prisen") -> AVVIK: det laveste tilbudet gir oss ikke rom for fortjeneste. Skal jobben vinnes, må tilbudet endres — ikke prisen
A45: Her SKAL det stå AVVIK med tallene som ligger inne. Det er hele poenget i kapitlet: taket ligger ikke der du tror.

Sheet Pris og dekningsbidrag
A1: Hva én prosent på prisen gjør med dekningsbidraget
A2: Pris og kostnader hentes fra arket «Gulv, tak og pris». Marker A5:B12 og sett inn et linjediagram.
A4: Endring i pris | B4: Pris | C4: Dekningsbidrag | D4: Dekningsgrad | E4: Fortjeneste over selvkost | F4: Volumet må øke | G4: Hva det betyr
A5: -0.2 | B5: ='Gulv, tak og pris'!$B$17*(1+A5) -> 21288.96 | C5: =B5-'Gulv, tak og pris'!$B$14 -> 1728.96 | D5: =IF(B5=0,0,C5/B5) -> 0.081213925 | E5: =B5-'Gulv, tak og pris'!$B$15 -> -2471.04 | F5: =IF(C5<=0,"",'Gulv, tak og pris'!$B$21/C5-1) -> 3.0782898 | G5: Under selvkost. Bidrar til de faste kostnadene, men bygger ikke bedriften.
A6: -0.15 | B6: ='Gulv, tak og pris'!$B$17*(1+A6) -> 22619.52 | C6: =B6-'Gulv, tak og pris'!$B$14 -> 3059.52 | D6: =IF(B6=0,0,C6/B6) -> 0.13526016 | E6: =B6-'Gulv, tak og pris'!$B$15 -> -1140.48 | F6: =IF(C6<=0,"",'Gulv, tak og pris'!$B$21/C6-1) -> 1.3046752 | G6: Under selvkost. Forsvarlig bare i en helt tom uke.
A7: -0.1 | B7: ='Gulv, tak og pris'!$B$17*(1+A7) -> 23950.08 | C7: =B7-'Gulv, tak og pris'!$B$14 -> 4390.08 | D7: =IF(B7=0,0,C7/B7) -> 0.18330127 | E7: =B7-'Gulv, tak og pris'!$B$15 -> 190.08 | F7: =IF(C7<=0,"",'Gulv, tak og pris'!$B$21/C7-1) -> 0.60616663 | G7: Så vidt over selvkost. Fortjenesten er praktisk talt borte.
A8: -0.05 | B8: ='Gulv, tak og pris'!$B$17*(1+A8) -> 25280.64 | C8: =B8-'Gulv, tak og pris'!$B$14 -> 5720.64 | D8: =IF(B8=0,0,C8/B8) -> 0.22628541 | E8: =B8-'Gulv, tak og pris'!$B$15 -> 1520.64 | F8: =IF(C8<=0,"",'Gulv, tak og pris'!$B$21/C8-1) -> 0.23258936 | G8: Halvparten av fortjenesten er igjen.
A9: 0 | B9: ='Gulv, tak og pris'!$B$17*(1+A9) -> 26611.2 | C9: =B9-'Gulv, tak og pris'!$B$14 -> 7051.2 | D9: =IF(B9=0,0,C9/B9) -> 0.26497114 | E9: =B9-'Gulv, tak og pris'!$B$15 -> 2851.2 | F9: =IF(C9<=0,"",'Gulv, tak og pris'!$B$21/C9-1) -> 0 | G9: Listeprisen. Selvkost pluss avtalt fortjeneste.
A10: 0.05 | B10: ='Gulv, tak og pris'!$B$17*(1+A10) -> 27941.76 | C10: =B10-'Gulv, tak og pris'!$B$14 -> 8381.76 | D10: =IF(B10=0,0,C10/B10) -> 0.29997251 | E10: =B10-'Gulv, tak og pris'!$B$15 -> 4181.76 | F10: =IF(C10<=0,"",'Gulv, tak og pris'!$B$21/C10-1) -> -0.1587447 | G10: Fem prosent mer pris gir nesten femti prosent mer fortjeneste.
A11: 0.1 | B11: ='Gulv, tak og pris'!$B$17*(1+A11) -> 29272.32 | C11: =B11-'Gulv, tak og pris'!$B$14 -> 9712.32 | D11: =IF(B11=0,0,C11/B11) -> 0.33179195 | E11: =B11-'Gulv, tak og pris'!$B$15 -> 5512.32 | F11: =IF(C11<=0,"",'Gulv, tak og pris'!$B$21/C11-1) -> -0.27399427 | G11: Nå tåler du å tape en av fire jobber og likevel tjene like mye.
A13: Legg merke til hvor mye brattere kolonne C og E faller enn kolonne B. Prisen faller ti prosent; dekningsbidraget faller nesten fire ganger så mye.
A14: Kontroll
A15: Faller dekningsbidraget brattere enn prisen? | C15: =IF(ABS(C7/C9-1)>ABS(A7-A9),"OK — dekningsbidraget faller brattere enn prisen. Det er hele mekanismen i kapitlet","AVVIK: kontroller de variable kostnadene i arket Gulv, tak og pris") -> OK — dekningsbidraget faller brattere enn prisen. Det er hele mekanismen i kapitlet
A16: Stemmer listeprisraden med kalkylen? | C16: =IF(ABS(B9-'Gulv, tak og pris'!B17)<0.01,"OK — raden med null endring gir samme pris som kalkylen","AVVIK: raden med null endring stemmer ikke med kalkylen") -> OK — raden med null endring gir samme pris som kalkylen

Sheet Hvor mye må volumet øke
A1: Regnestykket ingen gjør før de gir rabatt
A2: Legg inn din egen pris og dine egne variable kostnader i de gule cellene.
A4: Jobben du vurderer å gi rabatt på
A5: Pris i dag, eks. mva. | B5: 26611.2
A6: Variable kostnader per jobb | B6: 19560 | D6: Timer, materiell og kjøring. IKKE andelen av kontoret.
A7: Antall slike jobber i året i dag | B7: 40
A8: Rabatten kunden ber om | B8: 0.1
A10: Slik det er i dag
A11: = Dekningsbidrag per jobb | B11: =B5-B6 -> 7051.2
A12: = Dekningsgrad | B12: =IF(B5=0,0,B11/B5) -> 0.26497114
A13: = Samlet dekningsbidrag i året | B13: =B11*B7 -> 282048
A15: Slik det blir med rabatten
A16: = Ny pris | B16: =B5*(1-B8) -> 23950.08
A17: = Nytt dekningsbidrag per jobb | B17: =B16-B6 -> 4390.08
A18: = Ny dekningsgrad | B18: =IF(B16=0,0,B17/B16) -> 0.18330127
A19: = Fall i dekningsbidrag per jobb | B19: =IF(B11=0,0,B17/B11-1) -> -0.37739959 | D19: Sammenlikn dette tallet med rabatten i B8. Det er alltid større.
A21: Hva som må til for å komme ut i null
A22: = Nødvendig volumfaktor (gammelt DB delt på nytt DB) | B22: =IF(B17<=0,"",B11/B17) -> 1.6061666
A23: = Volumet må øke | B23: =IF(B17<=0,"",B22-1) -> 0.60616663
A24: = Antall jobber dere da må selge | B24: =IF(B17<=0,"",ROUNDUP(B7*B22,0)) -> 65
A25: = Så mange flere jobber enn i dag | B25: =IF(B17<=0,"",B24-B7) -> 25 | D25: =IF(B17<=0,"Prisen er nå under de variable kostnadene. Da finnes det ingen volumøkning som redder jobben.",IF(B23>0.5,"Over femti prosent flere jobber. Det skjer ikke. Rabatten er for stor.",IF(B23>0.2,"Krevende, men mulig hvis kapasiteten står ledig.","Overkommelig."))) -> Over femti prosent flere jobber. Det skjer ikke. Rabatten er for stor.
A27: Hele rabattstigen, med tallene over
A28: Rabatt | B28: Ny pris | C28: Nytt DB per jobb | D28: Volumet må øke | E28: Antall jobber som må selges
A29: 0.02 | B29: =$B$5*(1-A29) -> 26078.976 | C29: =B29-$B$6 -> 6518.976 | D29: =IF(C29<=0,"",$B$11/C29-1) -> 0.08164227 | E29: =IF(C29<=0,"",ROUNDUP($B$7*$B$11/C29,0)) -> 44
A30: 0.05 | B30: =$B$5*(1-A30) -> 25280.64 | C30: =B30-$B$6 -> 5720.64 | D30: =IF(C30<=0,"",$B$11/C30-1) -> 0.23258936 | E30: =IF(C30<=0,"",ROUNDUP($B$7*$B$11/C30,0)) -> 50
A31: 0.1 | B31: =$B$5*(1-A31) -> 23950.08 | C31: =B31-$B$6 -> 4390.08 | D31: =IF(C31<=0,"",$B$11/C31-1) -> 0.60616663 | E31: =IF(C31<=0,"",ROUNDUP($B$7*$B$11/C31,0)) -> 65
A32: 0.15 | B32: =$B$5*(1-A32) -> 22619.52 | C32: =B32-$B$6 -> 3059.52 | D32: =IF(C32<=0,"",$B$11/C32-1) -> 1.3046752 | E32: =IF(C32<=0,"",ROUNDUP($B$7*$B$11/C32,0)) -> 93
A33: 0.2 | B33: =$B$5*(1-A33) -> 21288.96 | C33: =B33-$B$6 -> 1728.96 | D33: =IF(C33<=0,"",$B$11/C33-1) -> 3.0782898 | E33: =IF(C33<=0,"",ROUNDUP($B$7*$B$11/C33,0)) -> 164
A34: 0.25 | B34: =$B$5*(1-A34) -> 19958.4 | C34: =B34-$B$6 -> 398.4 | D34: =IF(C34<=0,"",$B$11/C34-1) -> 16.698795 | E34: =IF(C34<=0,"",ROUNDUP($B$7*$B$11/C34,0)) -> 708
A36: To prosent rabatt ser lite ut. Se hva den krever av volum, og sammenlikn med hvor mye mer arbeid det er.
A38: Nordlys' eget eksempel: ladepunktet
A39: Pris før | B39: 8830 | C39: Antall før | D39: 180
A40: Pris etter | B40: 8400 | C40: Antall etter | D40: 215
A41: Variable enhetskostnader | B41: 7780
A43: = Omsetning før / etter / endring | B43: =B39*D39 -> 1589400 | C43: =B40*D40 -> 1806000 | D43: =C43-B43 -> 216600
A44: = Dekningsbidrag før / etter / endring | B44: =(B39-$B$41)*D39 -> 189000 | C44: =(B40-$B$41)*D40 -> 133300 | D44: =C44-B44 -> -55700
A45: = Antall som måtte vært solgt for å berge dekningsbidraget | B45: =ROUNDUP(B44/(B40-$B$41),0) -> 305
A46: = Så mange flere enn de faktisk solgte | B46: =B45-D40 -> 90
A48: Omsetningen steg. Dekningsbidraget falt. Elastisk etterspørsel sier noe om omsetningen, ingenting om fortjenesten.
A50: Kontroll
...

Sheet Prisdifferensiering
A1: Samme montørtime, fem priser
A2: Timepris og timekostnad er Nordlys' egne. Multiplikatorene er konstruert for undervisningen — endre dem og se hva som skjer.
A4: Utgangspunktet
A5: Ordinær timepris, eks. mva. | B5: 890
A6: Ordinær timekostnad | B6: 640
A7: Overtidsfaktor på timekostnaden ved kveld, natt og helg | B7: 1.5
A8: = Ordinær dekningsgrad | B8: =IF(B5=0,0,(B5-B6)/B5) -> 0.28089888
A10: Når | B10: Faktor | C10: Pris | D10: Timekostnad | E10: DB per time | F10: Dekningsgrad | G10: Kriteriet i boka
A11: Rammeavtale, borettslag og næringsbygg | B11: 0.9 | C11: =$B$5*B11 -> 801 | D11: =IF(A11="",0,$B$6*IF(B11>=1.4,$B$7,1)) -> 640 | E11: =C11-D11 -> 161 | F11: =IF(C11=0,0,E11/C11) -> 0.20099875 | G11: Kundene kjøper ulike mengder
A12: Ordinært oppdrag, avtalt dagtid | B12: 1 | C12: =$B$5*B12 -> 890 | D12: =IF(A12="",0,$B$6*IF(B12>=1.4,$B$7,1)) -> 640 | E12: =C12-D12 -> 250 | F12: =IF(C12=0,0,E12/C12) -> 0.28089888 | G12: Referansepris — ingen differensiering
A13: Hasteoppdrag samme dag, innenfor arbeidstid | B13: 1.3 | C13: =$B$5*B13 -> 1157 | D13: =IF(A13="",0,$B$6*IF(B13>=1.4,$B$7,1)) -> 640 | E13: =C13-D13 -> 517 | F13: =IF(C13=0,0,E13/C13) -> 0.44684529 | G13: Kundene kjøper til ulikt tidspunkt
A14: Avtalt kveldsarbeid etter kl. 16 | B14: 1.4 | C14: =$B$5*B14 -> 1246 | D14: =IF(A14="",0,$B$6*IF(B14>=1.4,$B$7,1)) -> 960 | E14: =C14-D14 -> 286 | F14: =IF(C14=0,0,E14/C14) -> 0.22953451 | G14: Kundene kjøper til ulikt tidspunkt
A15: Utrykning natt og helg | B15: 2 | C15: =$B$5*B15 -> 1780 | D15: =IF(A15="",0,$B$6*IF(B15>=1.4,$B$7,1)) -> 960 | E15: =C15-D15 -> 820 | F15: =IF(C15=0,0,E15/C15) -> 0.46067416 | G15: Kundene kjøper til ulikt tidspunkt
A17: Oppslag og summering
A18: Slå opp en variant (skriv nummeret 1–5) | B18: 3
A19: = Varianten heter (INDEX) | C19: =INDEX($A$11:$A$15,$B$18) -> Hasteoppdrag samme dag, innenfor arbeidstid
A20: = og gir dette dekningsbidraget per time | B20: =INDEX($E$11:$E$15,$B$18) -> 517
A21: = Høyeste DB per time i tabellen, og hvilken variant det er (INDEX/MATCH) | B21: =MAX($E$11:$E$15) -> 820 | C21: =INDEX($A$11:$A$15,MATCH(MAX($E$11:$E$15),$E$11:$E$15,0)) -> Utrykning natt og helg
A22: = Samlet DB fra alle timer som prises på kjøpstidspunkt (SUMIFS) | B22: =SUMIFS($E$11:$E$15,$G$11:$G$15,"Kundene kjøper til ulikt tidspunkt") -> 1623 | D22: Summen av dekningsbidraget per time for de tre tidsvariantene.
A24: Rammeavtalen mot ordinær pris
A25: = Så mange flere timer må rammeavtalen fylle for å gi like mye | B25: =IF(E11<=0,"",E12/E11-1) -> 0.55279503 | D25: Lønner seg bare hvis avtalen fyller timer som ellers stod tomme.
A26: = Kveldspris som ville holdt den ordinære dekningsgraden | B26: =IF($B$8>=1,"",D14/(1-$B$8)) -> 1335 | D26: Stiger kostnaden femti prosent, må prisen også stige femti prosent.
A28: Legg merke til kveldsarbeidet: førti prosent påslag gir LAVERE dekningsgrad enn dagtid, fordi timekostnaden steg femti prosent.
A29: Det gir likevel flere kroner i dekningsbidrag per time. Etter bidragsmetoden er kveldstimen verdt å ta — hvis den kommer i TILLEGG til dagtimene, ikke i stedet for dem.
A31: Kontroll
A32: Gir alle fem variantene positivt dekningsbidrag? | C32: =IF(MIN(E11:E15)>0,"OK — alle fem variantene dekker sin egen timekostnad","AVVIK: en variant med negativt dekningsbidrag per time skal ikke stå i prislista") -> OK — alle fem variantene dekker sin egen timekostnad
A33: Gir rammeavtalen svakere bidrag enn ordinær pris? | C33: =IF(E11<E12,"OK — rammeavtalen gir mindre per time, og må derfor fylle timer som ellers stod tomme","AVVIK: en rammeavtale som gir mer per time enn listeprisen, er ikke en rabatt") -> OK — rammeavtalen gir mindre per time, og må derfor fylle timer som ellers stod tomme
A34: Gir kveldstimen lavere dekningsgrad enn dagtid? | C34: =IF(F14<F12,"OK — førti prosent påslag gir LAVERE dekningsgrad, fordi timekostnaden steg femti prosent","AVVIK: kontroller overtidsfaktoren i B7") -> OK — førti prosent påslag gir LAVERE dekningsgrad, fordi timekostnaden steg femti prosent

Sheet Scenario
A1: Tre scenarioer
A2: «Ti prosent, så signerer jeg i dag.» Hva svarer du, og hva koster ja?
A4: Scenario A · kunden ber om avslag på denne jobben
A5: Sikringsskapbyttet fra arket «Gulv, tak og pris». Alle tall hentes derfra.
A7: Avslaget kunden ber om | B7: 0.1 | E7: Den gule cellen. Prøv fem prosent, og prøv femten.
A8: Pris uten mva. i dag | B8: ='Gulv, tak og pris'!B17 -> 26611.2
A9: Variable kostnader | B9: ='Gulv, tak og pris'!B14 -> 19560
A10: Selvkost | B10: ='Gulv, tak og pris'!B15 -> 23760
A11: Dekningsbidrag i dag | B11: =B8-B9 -> 7051.2
A13: Avslaget i kroner | B13: =B8*B7 -> 2661.12
A14: Ny pris uten mva. | B14: =B8-B13 -> 23950.08
A15: = Nytt dekningsbidrag | B15: =B14-B9 -> 4390.08
A16: Fall i dekningsbidrag | B16: =IF(B11=0,"",B15/B11-1) -> -0.37739959 | E16: Sammenlikn med avslaget i B7. Fallet er alltid større.
A17: = Fortjeneste over selvkost etter avslaget | B17: =B14-B10 -> 190.08 | E17: Dette er det kunden egentlig ber om: hele fortjenesten på jobben.
A18: = Nødvendig volumøkning for å komme ut likt | B18: =IF(B15<=0,"umulig",B11/B15-1) -> 0.60616663
A20: Og så presedensen — kostnaden ingen kalkyle viser
A21: Antall jobber du regner med hos den samme kunden framover | B21: 5 | E21: Et borettslag har flere leiligheter. Prisen du gir i dag, er utgangspunktet for neste forhandling.
A22: = Hva avslaget koster over alle jobbene | B22: =B13*B21 -> 13305.6
A23: Andel av dekningsbidraget på de samme jobbene | B23: =IF(B11=0,"",B22/(B11*B21)) -> 0.37739959
A25: Kontroll
A26: Er det dekningsbidrag igjen etter avslaget? | C26: =IF(B15>0,"OK — jobben bidrar fortsatt til de faste kostnadene","AVVIK: prisen er under de variable kostnadene. Si nei uansett hvor tom kalenderen er") -> OK — jobben bidrar fortsatt til de faste kostnadene
A27: Er fortjenesten borte? | C27: =IF(B17>0,"OK — det er fortsatt fortjeneste igjen over selvkost","AVVIK: hele fortjenesten på jobben er spist opp. Jobben dekker kostnadene og ingenting mer") -> OK — det er fortsatt fortjeneste igjen over selvkost
A30: Scenario B · det samme avslaget på alt bedriften selger
A31: Kunden er ikke alene. Hva om alle får det samme?
A33: Salgsinntekt 2026 | B33: 22400000
A34: Sum driftskostnader 2026 | B34: 21056000
A35: = Driftsresultat i dag | B35: =B33-B34 -> 1344000
A36: = Driftsmargin | B36: =B35/B33 -> 0.06 | E36: Dette tallet er også det største generelle prisavslaget bedriften tåler før driftsresultatet er null.
A37: Salgsinntekt etter avslaget | B37: =B33*(1-B7) -> 20160000
A38: = Driftsresultat etter avslaget | B38: =B37-B34 -> -896000
A39: Endring i driftsresultat | B39: =B38-B35 -> -2240000 | E39: Legg merke til at fallet er nøyaktig det tapte salgsbeløpet. Ingen kostnad har endret seg.
A40: Bruttofortjeneste i prosent av salg | B40: 0.47991071
A41: = Volumfaktor som må til for å berge bruttofortjenesten | B41: =IF((1-B7-(1-B40))<=0,"umulig",B40/(1-B7-(1-B40))) -> 1.2632197
A42: Fakturerte montørtimer i dag | B42: 14400
A43: Tilgjengelige montørtimer i året | B43: 20340
A44: = Timer som da må faktureres | B44: =IF(ISNUMBER(B41),B42*B41,"umulig") -> 18190.364
A45: = Faktureringsgrad det krever | B45: =IF(ISNUMBER(B41),B44/B43,"umulig") -> 0.89431486
A46: Faktureringsgrad i dag | B46: =B42/B43 -> 0.7079646
A47: Høyeste faktureringsgrad som er realistisk i bransjen | B47: 0.8 | E47: De best drevne installasjonsbedriftene ligger her. Over dette finnes ikke i praksis.
A49: Kontroll
...

Sheet Din egen prisliste
A1: Din egen bedrift
A2: Samme oppsett som de tre første arkene, men tomt. Fyll inn tallene fra en jobb dere selv har priset.
A4: Jobben
A5: Montørtimer på jobben | B5: 0 | C5: Timene dere fakturerer, ikke timene dere bruker.
A6: Timekostnad | B6: 0 | C6: Lønn med sosiale kostnader, bil, verktøy. Spør regnskapsføreren.
A7: Materiell, inntakskost | B7: 0 | C7: Det dere betalte grossisten, uten påslag.
A8: Kjøring og annet direkte | B8: 0 | C8: Alt som følger av at nettopp denne jobben gjøres.
A9: Indirekte kostnader | B9: 0 | C9: Andelen av kontor, administrasjon og biler.
A10: Fortjeneste i prosent av selvkost | B10: 0 | C10: Hva bedriften faktisk krever.
A12: Resultat
A13: = Variable kostnader (det absolutte gulvet) | B13: =B5*B6+B7+B8 -> 0
A14: = Selvkost (gulvet på lang sikt) | B14: =B13+B9 -> 0
A15: = Pris eks. mva. | B15: =B14*(1+B10) -> 0
A16: = Pris til kunden inkl. 25 % mva. | B16: =B15*1.25 -> 0
A17: = Dekningsbidrag | B17: =B15-B13 -> 0
A18: = Dekningsgrad | B18: =IF(B15=0,0,B17/B15) -> 0
A20: Hva tåler dere?
A21: Rabatt kunden ber om | B21: 0.1
A22: = Nytt dekningsbidrag | B22: =B15*(1-B21)-B13 -> 0
A23: = Volumet må øke | B23: =IF(OR(B17<=0,B22<=0),"",B17/B22-1) | C23: =IF(B17<=0,"Fyll inn tallene over.",IF(B22<=0,"Prisen er da under de variable kostnadene. Ingen volumøkning redder jobben.","Så mye mer må dere selge for å komme ut i null.")) -> Fyll inn tallene over.
A25: Og de to spørsmålene regnearket ikke kan svare på: hva tar konkurrentene på den samme jobben, og hva er den verdt for kunden?
A26: Det første kan dere finne ut. Det andre må dere spørre om — og da skal dere spørre om hva som er viktigst: datoen, prisen eller at det blir gjort riktig. De færreste svarer pris.
