Workbook

Sheet Veiledning
A1: Grossist eller direkte
A2: LØM Markedsføring kap. 8 · arbeidsregneark · Fagskolen Oslo, Avdeling Elkraft
A3: Emne: Teknisk kommunikasjon og ledelse for 1ET-klassene · LØM for 2ET, 2EK, 3EK og 4EK
A4: Fargekode
A5: Gul celle med blå skrift | B5: Inndata — dette er tallene du endrer.
A6: Grå eller lyseblå celle, svart skrift | B6: Formel — regner seg selv. Ikke skriv over den.
A7: Mørkeblå rad med hvit skrift | B7: Kolonneoverskrift.
A9: Ark i arbeidsboka
A10: Verdikjeden | B10: Hva materiellet koster gjennom hvert ledd, fra produsent til kundens faktura, og hva mellomleddet sparer av kundeforhold.
A11: Grossistens jobb | B11: Kredittfunksjonen, lagerfunksjonen og leveringssikkerheten, tallfestet.
A12: Direkte innkjøp | B12: DET VIKTIGSTE ARKET. Rabatten mot kostnadene som følger med, og rabatten som ville gitt balanse.
A13: Scenario | B13: To spørsmål: ved hvilket volum snur direkte innkjøp, og er lageravtalen grossisten tilbyr en god avtale?
A15: Tallene som ligger inne er Nordlys Elektro AS sine egne for 2026.
A16: Materiellkjøp, varelager, kredittdager og avkastningskrav er de samme som i Økonomistyring kapittel 2, 3 og 10.
A18: Tallene som ligger inne er et eksempel fra en elektrobedrift. Bytt dem ut med dine egne — alle formler følger med.
A19: Arbeidsregneark til LØM · Fagskolen Oslo, Avdeling Elkraft. Regnearket er øvingsstøtte, ikke et regnskapssystem.
A21: Den ene innsikten
A22: Direkte innkjøp!B25 | B22: Rabatten som ville gitt balanse | C22: Grossisten er ikke en kostnad du kan fjerne. Den er en jobb noen må gjøre. Denne cellen sier hva den jobben er verdt, målt i rabattprosent — og den er større enn rabatten produsenten tilbyr.
A23: Scenario!B13 | B23: Vendepunktet | C23: Materiellvolumet der direkte innkjøp snur fra tap til gevinst. Under det er svaret nei; over det er det ja. Svaret er altså ikke «aldri» — det er «ikke ennå».
A25: Hvilken oppgave bruker hvilket ark
A26: Oppgave i øvingsheftet | B26: Ark | C26: Celler du endrer og leser av
A27: A1 · Bør Nordlys kjøpe direkte fra produsent? | B27: Direkte innkjøp | C27: Les av B7, B21, B24 og B25. Kontrollraden i C30 står med vilje på AVVIK.
A28: A2 · Klasseoppgave: tegn verdikjeden | B28: Verdikjeden | C28: Les kolonne B og C. Relasjonsregnestykket står i B23 til B27.
A29: 1 · Direkte fra produsent, indirekte til kunden | B29: Verdikjeden | C29: Sett rabatten ved direktekjøp i B6 til null, og se hva som skjer med grossistleddet i kolonne C. Les av kolonne B, C og D.
A30: 2 · Grossistens funksjoner | B30: Grossistens jobb | C30: Endre B5, B6, B12, B18, B19 og B20. Les av B7, B9, B13, B14, B21 og B22.
A31: 3 · Regnestykket bak direkte innkjøp | B31: Direkte innkjøp | C31: Endre B6, B11, B17 og B18. Les av B14, B16, B19, B20, B21, B24 og B25.
A32: 4 · Hvem eier kunden? | B32: Verdikjeden | C32: Endre B23 og B24, og les av B25 til B27.
A33: 5 · Eksamensnær: bedre pris mot større lager | B33: Scenario | C33: Scenario A: les av B11, B12, B13 og B15 og volumtabellen. Scenario B: endre rabatten, lageret, lagerholdsprosenten og ukuransandelen, og les av nettoen med og uten ukurans.
A35: Kontrollradene
A36: Hvert ark har en kontrollblokk nederst. Står det OK, henger tallene sammen. Står det AVVIK, farges cellen rød, og teksten sier hva som ikke går opp.
A37: To unntak: kontrollen i «Direkte innkjøp» C30 og kontrollen på ukurans i scenario B skal vise AVVIK med tallene som ligger inne. Der er avviket selve svaret.
A38: Kontroller i arbeidsboka: Verdikjeden C30, Verdikjeden C31, Verdikjeden C32, Grossistens jobb C28, Grossistens jobb C29, Direkte innkjøp C29, Direkte innkjøp C30, Direkte innkjøp C32, Scenario C27, Scenario C28, Scenario C29, Scenario C63, Scenario C64, Scenario C66
A40: Kilder
A41: Hjertnes, Frode: Markedsføring, organisasjon og ledelse for LØM-emnet, 4. utgave, kapittel 8 «Distribusjon som konkurransevirkemiddel», avsnitt 8.1 til 8.5, med figur 8.1.
A42: Materiellkjøp, varelager, leverandørgjeld, kredittdager, avkastningskrav og dekningsbidrag: Nordlys Elektro AS, Økonomistyring kapittel 2, 3, 8 og 10. Påslaget for sosiale kostnader: tabell 2.4 i læreboka. Bransjetall: NHO Elektro, Lønnsomhetsrapport 2025, gjengitt i Elektro 24-7 19.08.2026 (hentet 10.09.2026). De 809 er bedriftene i datagrunnlaget, ikke bransjen. NHO Elektro oppgir ikke svarprosent.
A43: Konstruert for undervisningen: antall produsenter og installasjonsbedrifter, lagerstørrelsen ved direkte innkjøp, bemanningen, hasteandelen, lagerholdsprosenten og ukuransandelen. Alle står i gule celler og kan endres.

Sheet Verdikjeden
A1: Hva materiellet koster gjennom hvert ledd
A2: Materiellet på ett sikringsskapbytte, fra fabrikk til kundens faktura.
A4: 1 · Forutsetninger
A5: Grossistens pris til Nordlys (inntakskost) | B5: 9800 | E5: Det Nordlys faktisk betaler Polarlys Elektro Grossist AS for materiellet på jobben.
A6: Rabatt ved kjøp rett fra produsent, i hele kvanta | B6: 0.1 | E6: Det produsenten kan gi når Nordlys tar hele kvanta selv.
A7: Nordlys' påslag på materiell | B7: 0.2
A8: Merverdiavgift | B8: 0.25
A10: 2 · Prisen gjennom leddene
A11: Ledd | B11: Pris | C11: Lagt på i dette leddet | D11: Andel av sluttprisen | E11: Hva leddet gjør for pengene
A12: Produsent | B12: =B5*(1-B6) | D12: =B12/$B$15 | E12: Lager varen. Prisen Nordlys ville fått rett fra fabrikk, i hele kvanta.
A13: Grossist | B13: =B5 | C13: =B13-B12 | D13: =B13/$B$15 | E13: Bryter ned kvanta, holder lager, gir kreditt og leverer neste dag. Se arket «Grossistens jobb».
A14: Installatør, pris uten mva. | B14: =B13*(1+B7) | C14: =B14-B13 | D14: =B14/$B$15 | E14: Kjører, bærer, monterer, dokumenterer og garanterer. Påslaget dekker også risikoen for feilbestilling.
A15: Sluttkunde, pris med mva. | B15: =B14*(1+B8) | C15: =B15-B14 | D15: =B15/$B$15 | E15: Staten. Merverdiavgiften er ikke et ledd, men den står på fakturaen.
A17: 3 · De to marginene
A18: Grossistens bruttofortjeneste i prosent av sin salgspris | B18: =C13/B13 | E18: Dette er nøyaktig direkterabatten: den rabatten produsenten kan gi, er den marginen grossisten tar.
A19: Nordlys' avanse i prosent av inntakskost | B19: =C14/B13
A20: Nordlys' bruttofortjeneste i prosent av pris uten mva. | B20: =C14/B14 | E20: Samme kroner, mindre prosent. Nevneren er ulik — det er det samme skillet som i Økonomistyring kapittel 5.
A22: 4 · Mellomleddet reduserer antall kundeforhold
A23: Produsenter og merker Nordlys bruker i løpet av et år | B23: 40
A24: Installasjonsbedrifter i regionen som handler samme sted | B24: 25
A25: Kundeforhold UTEN mellomledd (alle mot alle) | B25: =B23*B24
A26: Kundeforhold MED mellomledd (alle mot én) | B26: =B23+B24
A27: = Relasjoner spart | B27: =B25-B26 | C27: =B27/B25 | E27: Figur 8.1 i boka. Et mellomledd er ikke en kostnad — det er en forenkling, og den kan regnes.
A29: Kontroll
A30: Stiger prisen gjennom leddene? | C30: =IF(AND(B12<B13,B13<B14,B14<B15),"OK — prisen stiger leddvis fra produsent til sluttkunde","AVVIK: et ledd tar negativ margin. Kontroller prosentene i B6 og B7")
A31: Er bruttofortjenesten lavere enn avansen? | C31: =IF(B20<B19,"OK — bruttofortjenesten i prosent av pris er lavere enn avansen i prosent av inntakskost, som den skal","AVVIK: kontroller nevnerne i B19 og B20")
A32: Sparer mellomleddet relasjoner? | C32: =IF(B26<B25,"OK — mellomleddet reduserer antall kundeforhold","AVVIK: med så få aktører lønner ikke mellomleddet seg på relasjoner alene")
A34: Prøv dette: sett antall produsenter i B23 til tre. Da er mellomleddet nesten uten verdi på dette punktet — og du ser hvorfor store entreprenører kjøper direkte.
A35: Kilde: Hjertnes, Markedsføring, organisasjon og ledelse for LØM-emnet, 4. utg., kap. 8.1 og 8.2, med figur 8.1. Materiellprisen er Nordlys Elektro AS sin egen, fra Økonomistyring kapittel 5.

Sheet Grossistens jobb
A1: Hva grossisten gjør — og hva det ville kostet å gjøre det selv
A2: Seks funksjoner. Tre av dem lar seg tallfeste.
A4: 1 · Kredittfunksjonen
A5: Materiellkjøp i året | B5: 7990000
A6: Kredittdager hos grossisten | B6: 30
A7: = Leverandørkreditt i gjennomsnitt | B7: =B5*B6/365 | D7: Så mye av driften finansierer grossisten — rentefritt.
A8: Bedriftens avkastningskrav | B8: 0.1
A9: = Hva den kreditten er verdt i året | B9: =B7*B8 | D9: Renten Nordlys slipper å betale på den samme kapitalen.
A11: 2 · Lagerfunksjonen
A12: Nordlys' eget varelager | B12: 1400000
A13: = Lagerets omløpshastighet | B13: =B5/B12 | D13: Hvor mange ganger lageret skiftes ut i løpet av et år.
A14: = Gjennomsnittlig lagringstid, dager | B14: =365/B13 | D14: Så lenge ligger en vare på lageret før den brukes. Jo lengre, jo mer kapital er bundet — og jo større er risikoen for ukurans.
A15: Kapital bundet i lageret, kostnad i året | B15: =B12*B8
A17: 3 · Leveringssikkerheten
A18: Planlagte serviceoppdrag i året | B18: 210
A19: Andel som forutsetter levering neste dag | B19: 0.2
A20: Dekningsbidrag per serviceoppdrag | B20: 7300
A21: = Oppdrag som står og faller med leveringen | B21: =B18*B19
A22: = Dekningsbidrag som står på spill | B22: =B21*B20 | D22: Dette er verdien av at grossisten har varen på hylla i dag.
A24: 4 · De tre funksjonene til sammen
A25: = Hva grossisten er verdt i året, regnet på disse tre | B25: =B9+B22 | D25: Kredittverdien og det sikrede dekningsbidraget. Kompetanse, sortiment og returrett kommer i tillegg og lar seg ikke tallfeste her.
A27: Kontroll
A28: Henger lagringstiden sammen med omløpshastigheten? | C28: =IF(ABS(B13*B14-365)<0.01,"OK — omløpshastighet ganger lagringstid er 365 dager","AVVIK: de to tallene henger ikke sammen")
A29: Er kreditten større enn null? | C29: =IF(B7>0,"OK — grossisten finansierer en del av driften","AVVIK: uten kredittdager finansierer grossisten ingenting")
A31: Prøv dette: sett kredittdagene i B6 til null. Det er situasjonen ved direkte innkjøp fra produsent, som gjerne krever forskuddsbetaling.
A32: Kilde: Hjertnes kap. 8.3 om grossistens funksjoner. Materiellkjøp, varelager og kredittdager: Nordlys Elektro AS, Økonomistyring kapittel 2 og 3.

Sheet Direkte innkjøp
A1: Lønner det seg å hoppe over grossisten?
A2: Rabatten er ekte. Spørsmålet er om den er stor nok.
A4: 1 · Gevinsten
A5: Materiellkjøp i året | B5: ='Grossistens jobb'!B5
A6: Rabatt ved kjøp rett fra produsent | B6: 0.1
A7: = Rabatt i kroner | B7: =B5*B6 | D7: Dette er tallet selgeren viser deg. Det er riktig — det er bare ikke hele regnestykket.
A9: 2 · Kostnadene som følger med
A10: Varelager i dag | B10: ='Grossistens jobb'!B12
A11: Varelager som må til ved direkte innkjøp | B11: 3500000 | D11: Produsentene selger i hele kvanta. Lageret må mer enn dobles.
A12: = Økning i varelager | B12: =B11-B10
A13: Leverandørkreditt som faller bort | B13: ='Grossistens jobb'!B7 | D13: Produsentene krever forskuddsbetaling. Kreditten forsvinner.
A14: = Samlet kapitalbinding | B14: =B12+B13
A15: Avkastningskrav | B15: ='Grossistens jobb'!B8
A16: = Kapitalkostnad i året | B16: =B14*B15
A17: Lagermedarbeider i halv stilling, bruttolønn | B17: 320000
A18: Sosiale kostnader i prosent av bruttolønn | B18: 0.468
A19: = Lønnskostnad | B19: =B17*(1+B18) | D19: Påslaget er lærebokas eget, fra tabell 2.4 i Økonomistyring.
A20: = Tapt dekningsbidrag på hasteoppdrag | B20: ='Grossistens jobb'!B22
A21: = Sum ekstrakostnader | B21: =B16+B19+B20
A23: 3 · Svaret
A24: = Netto ved direkte innkjøp | B24: =B7-B21
A25: Rabatten som ville gitt balanse | B25: =B21/B5 | D25: Så stor måtte rabatten vært for at direkte innkjøp skulle gå i null med dagens volum. Sammenlikn med B6.
A26: Dom | D26: =IF(B24>0,"Direkte innkjøp lønner seg med disse forutsetningene","Rabatten er ekte, men den er ikke stor nok. Grossisten gjør en jobb Nordlys måtte gjort selv")
A28: Kontroll
A29: Summerer ekstrakostnadene seg riktig? | C29: =IF(ABS(B21-(B16+B19+B20))<0.01,"OK — de tre kostnadslinjene summerer seg til sum ekstrakostnader","AVVIK: summen stemmer ikke med linjene over")
A30: Er rabatten stor nok? | C30: =IF(B6>=B25,"OK — rabatten dekker ekstrakostnadene","AVVIK: rabatten er lavere enn den rabatten som gir balanse. Direkte innkjøp taper penger med dagens volum")
A31: Her SKAL det stå AVVIK med tallene som ligger inne. Det er hele svaret på diskusjonsstoppet i økta: rabatten er ekte, den er bare ikke stor nok.
A32: Er kapitalbindingen regnet av begge delene? | C32: =IF(ABS(B14-(B12+B13))<0.01,"OK — kapitalbindingen er økt lager pluss bortfalt kreditt","AVVIK: kapitalbindingen stemmer ikke")
A34: Prøv dette: sett rabatten i B6 opp til den prosenten som står i B25. Da går regnestykket i null — og du ser nøyaktig hva grossistens jobb er verdt.
A35: Kilde: Hjertnes kap. 8.3 og 8.4. Forutsetningene om lagerstørrelse, bemanning og hasteandel er konstruert for undervisningen og oppgitt i de gule cellene. Materiellkjøp, varelager, kredittdager, avkastningskrav og dekningsbidrag er Nordlys' egne tall.

Sheet Scenario
A1: To scenarioer
A2: Ved hvilket volum snur det — og er lageravtalen grossisten tilbyr en god avtale?
A4: Scenario A · ved hvilket volum snur direkte innkjøp?
A5: Rabatten følger volumet. Det gjør kapitalbindingen også. Lagermedarbeideren og de tapte hasteoppdragene gjør det ikke.
A7: Lagerandel i dag (varelager delt på materiellkjøp) | B7: ='Direkte innkjøp'!B10/'Direkte innkjøp'!B5
A8: Lagerandel ved direkte innkjøp | B8: ='Direkte innkjøp'!B11/'Direkte innkjøp'!B5
A9: Kredittandel som faller bort (kredittdager delt på 365) | B9: ='Grossistens jobb'!B6/365
A10: = Kapital bundet per krone materiell | B10: =B8-B7+B9
A11: = Gevinst per krone materiell, etter kapitalkostnad | B11: ='Direkte innkjøp'!B6-B10*'Direkte innkjøp'!B15 | E11: Rabatten minus renten på kapitalen den binder. Dette er marginen som skal dekke de faste kostnadene.
A12: = Faste kostnader ved direkte innkjøp | B12: ='Direkte innkjøp'!B19+'Direkte innkjøp'!B20 | E12: Lagermedarbeideren og det tapte dekningsbidraget. De kommer uansett hvor mye materiell dere kjøper.
A13: = VENDEPUNKTET: materiellkjøp som gir null | B13: =IF(B11<=0,"finnes ikke",B12/B11)
A14: Materiellkjøp i dag | B14: ='Direkte innkjøp'!B5
A15: = Så mye måtte materiellkjøpet øke | B15: =IF(B11<=0,"",B13/B14-1)
A17: Materiellkjøp | B17: Andel av dagens | C17: Rabatt etter kapitalkostnad | D17: Faste kostnader | E17: Netto ved direkte innkjøp
A18: =B18*$B$14 | B18: 0.5 | C18: =A18*$B$11 | D18: =$B$12 | E18: =C18-D18
A19: =B19*$B$14 | B19: 0.75 | C19: =A19*$B$11 | D19: =$B$12 | E19: =C19-D19
A20: =B20*$B$14 | B20: 1 | C20: =A20*$B$11 | D20: =$B$12 | E20: =C20-D20
A21: =B21*$B$14 | B21: 1.25 | C21: =A21*$B$11 | D21: =$B$12 | E21: =C21-D21
A22: =B22*$B$14 | B22: 1.5 | C22: =A22*$B$11 | D22: =$B$12 | E22: =C22-D22
A23: =B23*$B$14 | B23: 1.75 | C23: =A23*$B$11 | D23: =$B$12 | E23: =C23-D23
A24: =B24*$B$14 | B24: 2 | C24: =A24*$B$11 | D24: =$B$12 | E24: =C24-D24
A26: Kontroll
A27: Gir dagens volum det samme som oppstillingen i arket Direkte innkjøp? | C27: =IF(ABS($B$14*$B$11-$B$12-'Direkte innkjøp'!B24)<1,"OK — vendepunktsmodellen gir samme netto som oppstillingen","AVVIK: modellen og oppstillingen er ikke enige")
A28: Ligger vendepunktet over dagens volum? | C28: =IF(NOT(ISNUMBER($B$13)),"AVVIK: rabatten dekker ikke engang kapitalkostnaden. Da finnes det ikke noe vendepunkt",IF($B$13>$B$14,"OK — direkte innkjøp lønner seg først ved et større materiellvolum enn Nordlys har i dag","AVVIK: da lønner direkte innkjøp seg allerede"))
A29: Snur tabellen fra minus til pluss? | C29: =IF(AND(E18<0,E24>0),"OK — tabellen snur fra tap til gevinst, og vendepunktet ligger et sted imellom","AVVIK: utvid volumtrappen så vendepunktet kommer med")
A32: Scenario B · grossisten tilbyr bedre pris mot større lager
A33: Den eksamensnære oppgaven. Nordlys beholder grossisten, men tar over en del av lagerholdet.
A35: Rabatt grossisten tilbyr på alt materiell | B35: 0.03 | E35: Den gule cellen. Prøv to prosent, og prøv fire.
A36: Varelager avtalen krever | B36: 2600000
A37: Varelager i dag | B37: ='Direkte innkjøp'!B10
A38: = Økning i varelager | B38: =B36-B37
A40: Gevinsten
A41: = Rabatt i kroner i året | B41: ='Direkte innkjøp'!B5*B35
A43: Kostnadene
A44: Kapitalkostnad på det økte lageret | B44: =B38*'Direkte innkjøp'!B15
A45: Lagerhold i prosent av lagerverdien | B45: 0.06 | E45: Forsikring, plass, telling og svinn. Kommer i tillegg til renten på kapitalen.
A46: Lagerholdskostnad | B46: =B38*B45
A47: = Sum kostnader | B47: =B44+B46
A49: Svaret
A50: = Netto på avtalen | B50: =B41-B47
...
