Workbook

Sheet Enkelt
A1: Hva koster det å fylle én stilling? Den enkle versjonen
A2: Fyll inn de åtte gule cellene. Svaret står i den grønne. Alt annet regner seg selv. Vil du gå dypere, med fadder, opplæring og en ansettelse som går galt, ligger hele modellen i arkene bak.
A4: Det du vet
A5: Hva koster annonsen i fagpresse og på nett? | B5: 12000 | C5: Den eneste posten noen sender faktura for.
A6: Hva tjener lederen som ansetter, i året? | B6: 555000 | C6: Lønn før sosiale kostnader. Hos Nordlys er det daglig leder som ansetter.
A7: Hvor mye kommer i tillegg til lønna i sosiale kostnader? | B7: 0.468 | C7: Feriepenger, arbeidsgiveravgift, pensjon og mer. Satsen er den samme som i Økonomistyring for LØM-emnet, kap. 2.
A8: Hvor mange timer er lederen på jobb i året? | B8: 1695 | C8: Etter ferie, helligdager og kurs.
A9: Hvor mange timer bruker lederen på hele ansettelsen? | B9: 30 | C9: Behovsanalyse, annonse, søknader, intervjuer, tilbud og introduksjon.
A10: Hvor mange måneder står stillingen tom? | B10: 4 | C10: Fra oppsigelsen til den nye er på plass.
A11: Hvor mange timer fakturerer en montør i året? | B11: 1200 | C11: Bare timene som står på en faktura.
A12: Hva koster en time for kunden, uten mva.? | B12: 890 | C12: Timeprisen. En time som ikke blir solgt, kommer aldri tilbake.
A14: Regnestykket
A15: Hva en time av lederens tid koster | B15: =B6*(1+B7)/B8 -> 480.67257 | C15: Lønn med sosiale kostnader, delt på timene lederen er på jobb.
A16: Kostnad for lederens tid | B16: =B15*B9 -> 14420.177 | C16: Timekostnaden ganger timene på ansettelsen.
A17: Direkte kostnad: annonse og ledertid | B17: =B5+B16 -> 26420.177 | C17: Det folk svarer når de blir spurt hva en ansettelse koster.
A18: Fakturerbare timer som forsvinner | B18: =B11*B10/12 -> 400 | C18: Timer i året delt på 12, ganger månedene stillingen står tom.
A19: Tapt fakturering mens stillingen står tom | B19: =B18*B12 -> 356000 | C19: Forutsetter at oppdragene fantes. Disse timene står ikke på noen faktura.
A21: DET KOSTER Å FYLLE STILLINGEN | B21: =B17+B19 -> 382420.18 | C21: Direkte kostnad pluss tapt fakturering. Fadder og opplæring kommer i tillegg.
A22: Andel som er tapte timer | B22: =B19/B21 -> 0.93091322 | C22: Den delen av prisen ingen ser.
A24: Hva svaret betyr
A25: ="Å fylle én stilling koster "&TEXT(ROUND(B21,0),"#,##0")&" kroner. Bare "&TEXT(ROUND(B17,0),"#,##0")&" kroner av det er annonse og ledertid. Resten er timer som aldri ble fakturert." -> Å fylle én stilling koster 382,420 kroner. Bare 26,420 kroner av det er annonse og ledertid. Resten er timer som aldri ble fakturert.
A27: Prøv selv
A28: 1. Sett månedene stillingen står tom (B10) til 2. Hvor mye billigere blir det?
A29: 2. Bruk ti timer til på en ekstra intervjurunde (B9 = 40). Hvor mye dyrere blir ansettelsen?
A30: 3. Hva må B10 være for at det skal koste over en halv million kroner?
A32: Tallene er Nordlys Elektro AS sine for 2026 (faktaarket og sammendraget). Kilde: Markedsføring, organisasjon og ledelse for LØM-emnet, kap. 18. Sosiale kostnader: Økonomistyring for LØM-emnet, kap. 2. Nordlys Elektro AS er en konstruert casebedrift.

Sheet Veiledning
A1: Hva en feilansettelse koster
A2: LØM Organisasjon og ledelse kap. 18 · arbeidsregneark · Fagskolen Oslo, Avdeling Elkraft
A3: Emne: Teknisk kommunikasjon og ledelse for 1ET-klassene · LØM for 2ET, 2EK, 3EK og 4EK
A4: Fargekode
A5: Gul celle med blå skrift | B5: Inndata — dette er tallene du endrer.
A6: Grå eller lyseblå celle, svart skrift | B6: Formel — regner seg selv. Ikke skriv over den.
A7: Mørkeblå rad med hvit skrift | B7: Kolonneoverskrift.
A9: Ark i arbeidsboka
A10: Enkelt | B10: Start her. Åtte gule celler, ett svar. Hva det koster å fylle én stilling, regnet på den enkleste måten.
A11: Timen og lønna | B11: Grunnlaget. Lønn, sosiale kostnader, timer og timepris inn — timekostnad og dekningsbidrag ut. Her ligger den ene cellen du styrer alt fra: B25.
A12: Prosessen | B12: Hva én ansettelse koster når alt går bra: annonse, ledertid, månedene stillingen står tom, fadderens timer og opplæringsperioden.
A13: Feilansettelsen | B13: DET VIKTIGSTE ARKET. Den nye slutter før opplæringen er over, og alt må gjøres om igjen. Nederst: hvor mange ekstra intervjurunder du får for prisen av én bom.
A14: Scenario | B14: Tre spørsmål: hvor raskt blir han produktiv, hvor lenge står stillingen tom, og er den interne billigere enn den eksterne?
A15: Din egen bedrift | B15: Samme oppsett, tomt. Legg inn tallene fra din egen arbeidsplass.
A17: Tallene som ligger inne er Nordlys Elektro AS' egne tall for 2026.
A19: HVORFOR DETTE REGNEARKET FINNES:
A20: Rekruttering er en beslutning med en prislapp, og prislappen er den delen
A21: studentene ikke ser. Annonsen er den eneste posten noen sender en faktura for.
A22: Resten er timer som ikke ble solgt — og de står ikke i noe regnskap.
A24: DEN ENE ERKJENNELSEN:
A25: Grundighet i utvelgelsen koster ledertimer. Å bomme koster montørårsverk.
A26: Det er ikke et argument for å bruke evig tid — det er et argument for å vite
A27: hva den tredje intervjurunden er verdt.
A29: KONSTRUERT FOR UNDERVISNINGEN: hvor mye den nye fakturerer i opplærings-
A30: perioden, hvor mye av dagen fadderen bruker i ukene 2 til 4, og at ansettelsen
A31: ryker etter fire måneder. Alt annet er utledet: lønna av produksjonslønna i
... A39: Den ene knappen
A40: 'Timen og lønna'!B25 | B40: Timepris til kunden, uten mva. | C40: Endrer du denne cellen, følger arkene Prosessen, Feilansettelsen og Scenario med. Alle tapstall i arbeidsboka er timer ganget med denne prisen.
A42: Hvilken oppgave bruker hvilket ark
A43: Oppgave i øvingsheftet | B43: Ark | C43: Celler du endrer og leser av
A44: A1 · Internt eller eksternt? | B44: Scenario | C44: Scenario C nederst: endre C-kolonnen og les av forskjellen i B-raden «Forskjell».
A45: A2 · Klasseoppgave: finn feilen i stillingsannonsen | B45: — | C45: Ingen regning. Oppgaven løses i heftet.
A46: A3 · Fire ting Ronny vil ta opp | B46: — | C46: Ingen regning. Oppgaven løses i heftet.
A47: 1 · Personalpolitikken Nordlys ikke har skrevet ned | B47: — | C47: Ingen regning. Oppgaven løses i heftet.
A48: 2 · Intervjuet, panelet og den første arbeidsdagen | B48: Prosessen | C48: Les av ledertimene i B11. Det er timene hele rekrutteringsprosessen tar, og intervjuene er den største enkeltposten i dem.
A49: 3 · Medarbeidersamtalen med Sara | B49: — | C49: Ingen regning. Oppgaven løses i heftet.
A50: 4 · Ansettelseskalkylen: hva koster det egentlig? | B50: Prosessen og Feilansettelsen | C50: Endre Prosessen B16, B28 og B29, og les av B34 og B35. Gå så til Feilansettelsen: endre B5 og B6, og les av B25, B27, B28 og B31. Punkt d) leser du i B36.
A51: 5 · Eksamensnær: to montører, tre søkere og én lærling | B51: Feilansettelsen og Scenario | C51: Les av Feilansettelsen B27 og B36, og bruk scenario A og C til å begrunne anbefalingen.
A53: Kontrollradene
A54: Hvert regneark har en kontrollblokk nederst. Står det OK, henger tallene sammen. Står det AVVIK, farges cellen rød, og teksten sier hva som ikke går opp.
...

Sheet Timen og lønna
A1: Hva koster en montørtime, og hva er den verdt?
A2: Endre de gule cellene. Alt annet regner seg selv.
A4: 1 · Lønna
A5: Grunnlønn til montører og lærlinger, ett år (før sosiale kostnader) | B5: 5750000 | D5: Lønnsposten i resultatregnskapet for 2026 (8 440 000 kr, jf. kapittel 3) inkluderer feriepenger og avgifter. Her er grunnlønna: 8 440 000 / 1,468.
A6: Antall utførende (montører og lærlinger) | B6: 14 | D6: De som fakturerer timer. Administrasjonen ligger i en annen post.
A7: = Årslønn per utførende | B7: =IF(B6=0,0,B5/B6) -> 410714.29 | D7: Snittet, ikke tarifflønna til en enkelt montør. Et kostnadsanslag skal bruke snittet.
A9: Sosiale kostnader — påslag på lønna
A10: Post | B10: Sats | D10: Merknad
A11: Feriepenger, inkludert arbeidsgiveravgift | B11: 0.137
A12: Arbeidsgiveravgift på lønn | B12: 0.141
A13: Pensjonspremie | B13: 0.08
A14: Arbeidsgiveravgift på pensjon | B14: 0.011
A15: Lønn for bevegelige helligdager, høytidsdager m.m. | B15: 0.045
A16: Premie til yrkesskadetrygd | B16: 0.004
A17: Sykepenger i arbeidsgiverperioden | B17: 0.05
A18: = Samlet påslag | B18: =SUM(B11:B17) -> 0.468 | D18: Satsene er de samme som i kapittel 2 og kapittel 20.
A20: 2 · Timene
A21: = Lønnskostnad per utførende, ett år | B21: =B7*(1+B18) -> 602928.57
A22: Tilgjengelige timer per montør per år | B22: 1695 | D22: Årsverket etter ferie, helligdager, kurs og annet fravær.
A23: Fakturerte timer per montør per år | B23: 1200 | D23: Timene som faktisk står på en faktura. Resten går til kjøring, henting, dokumentasjon og venting.
A24: = Faktureringsgrad | B24: =IF(B22=0,0,B23/B22) -> 0.7079646 | D24: Kapittel 5s viktigste tall, og det er det samme her.
A25: Timepris til kunden, uten mva. | B25: 890 | D25: DEN ENE KNAPPEN. Endrer du denne, følger alle de andre arkene med.
A26: = Lønnskostnad per fakturert time | B26: =IF(B23=0,0,B21/B23) -> 502.44048
A27: = Dekningsbidrag per fakturert time | B27: =B25-B26 -> 387.55952 | D27: Det timen bidrar med til å dekke alt annet bedriften har av kostnader.
A28: = Omsetning én montør skaper på ett år | B28: =B23*B25 -> 1068000 | D28: Måltallet resten av arbeidsboka regner mot. En time som ikke blir solgt, kommer aldri tilbake.
A30: Kontroll
A31: Er timeprisen høyere enn lønnskostnaden per time? | D31: =IF(B27>0,"OK — timen gir positivt dekningsbidrag","AVVIK: timen koster mer enn den selges for. Da hjelper ingen rekruttering") -> OK — timen gir positivt dekningsbidrag
A32: Ligger faktureringsgraden innenfor det som er mulig? | D32: =IF(AND(B24>0.4,B24<0.95),"OK — faktureringsgraden er realistisk","AVVIK: faktureringsgraden er utenfor et realistisk område") -> OK — faktureringsgraden er realistisk
A34: Kilde: Hjertnes, Markedsføring, organisasjon og ledelse for LØM-emnet, 4. utg., kap. 18. Lønnstall og timer er Nordlys Elektro AS' egne, jf. kapittel 2, 3 og 5. Satsene for sosiale kostnader: Økonomistyring for LØM-emnet, tabell 2.4.

Sheet Prosessen
A1: Hva koster det å ansette én montør — når alt går bra?
A2: Bare den øverste posten kommer på en faktura. Resten er timer som ikke ble solgt.
A4: 1 · Det som kommer på en faktura
A5: Annonse i fagpresse og på nett | B5: 12000 | D5: Den eneste posten noen ber om betaling for.
A7: 2 · Ledelsens tid
A8: Lederlønn per år | B8: 555000 | D8: Administrasjonslønna delt på antall i administrasjonen.
A9: = Med sosiale kostnader | B9: =B8*(1+'Timen og lønna'!$B$18) -> 814740
A10: = Timekostnad for lederen | B10: =IF('Timen og lønna'!$B$22=0,0,B9/'Timen og lønna'!$B$22) -> 480.67257
A11: Timer lederen bruker på hele prosessen, sju trinn | B11: 30 | D11: Behovsanalyse, annonse, gjennomgang av søknader, intervjuer, referanser, tilbud og introduksjon. Sett inn deres eget tall.
A12: = Kostnad for ledelsens tid | B12: =B10*B11 -> 14420.177
A13: = Direkte kostnad, til sammen | B13: =B5+B12 -> 26420.177 | D13: Dette er tallet folk oppgir når de blir spurt hva en ansettelse koster. Det er under fem prosent av svaret.
A15: 3 · Månedene stillingen står tom
A16: Måneder fra oppsigelsen til den nye er på plass | B16: 4 | D16: Oppsigelsestid, utlysing, intervjurunder og oppsigelsestid hos den nye arbeidsgiveren. Fire måneder er nøkternt.
A17: = Fakturerbare timer som forsvinner | B17: ='Timen og lønna'!$B$23*B16/12 -> 400
A18: = Tapt fakturering | B18: =B17*'Timen og lønna'!$B$25 -> 356000 | D18: Forutsetter at oppdragene faktisk fantes. Er ordreboka tom, koster vakansen ingenting — og da skulle dere ikke ansatt.
A20: 4 · Fadderens tid
A21: Uker der fadderen går sammen med den nye | B21: 1 | D21: Uke 1 i introduksjonsprogrammet: kjører sammen med fadderen.
A22: Uker med fadderen tilgjengelig på telefon | B22: 3 | D22: Uke 2 til 4 i introduksjonsprogrammet.
A23: Andel av arbeidsdagen fadderen bruker i de ukene | B23: 0.2
A24: = Fakturerbare timer fadderen mister | B24: ='Timen og lønna'!$B$23/52*(B21+B22*B23) -> 36.923077
A25: = Tapt fakturering | B25: =B24*'Timen og lønna'!$B$25 -> 32861.538 | D25: Fadderen er en av de dyktigste dere har. Det er nettopp derfor han er fadder, og derfor timene hans er dyre.
A27: 5 · Opplæringsperioden
A28: Måneder før den nye er like produktiv som de andre | B28: 6 | D28: Introduksjonsprogrammet slutter i måned 6, med den første ordentlige medarbeidersamtalen.
A29: Hvor mye han fakturerer i snitt i den perioden | B29: 0.5 | D29: Av det en erfaren montør fakturerer. Prøv 30 % og 70 % og se hva det gjør med totalen.
A30: = Timer i perioden, ved full produktivitet | B30: ='Timen og lønna'!$B$23*B28/12 -> 600
A31: = Timer som ikke blir fakturert | B31: =B30*(1-B29) -> 300
A32: = Tapt fakturering | B32: =B31*'Timen og lønna'!$B$25 -> 267000
A34: = HELE ANSETTELSEN, når alt går bra | B34: =B13+B18+B25+B32 -> 682281.72
A35: = Andel som ingen faktura viser | B35: =IF(B34=0,0,1-B13/B34) -> 0.96127673
A36: = Tilsvarer så mange fakturerte timer | B36: =IF('Timen og lønna'!$B$25=0,0,B34/'Timen og lønna'!$B$25) -> 766.60867
A37: = Tilsvarer så mange montørårsverk | B37: =IF('Timen og lønna'!$B$28=0,0,B34/'Timen og lønna'!$B$28) -> 0.63884056
A39: Kontroll
A40: Går summen opp? | D40: =IF(ABS(B34-(B13+B18+B25+B32))<0.01,"OK — de fire postene summerer seg til totalen","AVVIK: summen stemmer ikke med postene over") -> OK — de fire postene summerer seg til totalen
A41: Er det meste av kostnaden usynlig? | D41: =IF(B35>0.8,"OK — over 80 prosent av kostnaden kommer aldri på en faktura","AVVIK: den direkte kostnaden er blitt uvanlig stor. Sjekk vakansen og opplæringsperioden") -> OK — over 80 prosent av kostnaden kommer aldri på en faktura
A42: Er opptrappingen realistisk? | D42: =IF(AND(B29>0.1,B29<0.9),"OK — den nye leverer verken ingenting eller alt fra dag én","AVVIK: en opptrapping under 10 eller over 90 prosent er ikke et realistisk anslag") -> OK — den nye leverer verken ingenting eller alt fra dag én
A44: Kilde: Hjertnes, Markedsføring, organisasjon og ledelse for LØM-emnet, 4. utg., kap. 18 avsnitt 18.2 om rekrutteringsprosessens sju trinn og 18.2.6 om introduksjon og opplæring. Timer og timepris er Nordlys Elektro AS' egne.

Sheet Feilansettelsen
A1: Og hva koster det når det ikke går bra?
A2: Samme prosess, men den nye slutter før opplæringen er over — og alt må gjøres om igjen.
A4: Forutsetningen
A5: Måneder før ansettelsen ryker | B5: 4 | D5: Enten sier han opp selv, eller dere blir enige om at det ikke fungerer. Årsaken spiller ingen rolle for regnestykket.
A6: Måneder med lønn i oppsigelsestiden | B6: 1 | D6: Fristen følger arbeidsavtalen og arbeidsmiljøloven — se kapittel 20 og regnearket der.
A7: = Lønnskostnad per måned | B7: ='Timen og lønna'!$B$21/12 -> 50244.048
A9: Runde 1 — den som ikke ble noe av
A10: Direkte kostnad: annonse og ledertid | B10: =Prosessen!$B$13 -> 26420.177
A11: Månedene stillingen sto tom før han begynte | B11: =Prosessen!$B$18 -> 356000
A12: Fadderens tid | B12: =Prosessen!$B$25 -> 32861.538
A13: = Timer som ikke ble fakturert mens han var her | B13: ='Timen og lønna'!$B$23*B5/12*(1-Prosessen!$B$29) -> 200
A14: = Tapt fakturering i de månedene | B14: =B13*'Timen og lønna'!$B$25 -> 178000 | D14: Han fakturerte noe. Det som mangler, er differansen opp til en erfaren montør.
A15: = Lønn i oppsigelsestiden, uten produksjon | B15: =B7*B6 -> 50244.048
A16: = Runde 1, til sammen | B16: =B10+B11+B12+B14+B15 -> 643525.76
A18: Runde 2 — alt om igjen
A19: Direkte kostnad, en gang til | B19: =Prosessen!$B$13 -> 26420.177
A20: Månedene stillingen står tom, en gang til | B20: =Prosessen!$B$18 -> 356000
A21: Fadderens tid, en gang til | B21: =Prosessen!$B$25 -> 32861.538
A22: Opplæringsperioden, denne gangen hele veien | B22: =Prosessen!$B$32 -> 267000
A23: = Runde 2, til sammen | B23: =B19+B20+B21+B22 -> 682281.72
A25: = FEILANSETTELSEN, TIL SAMMEN | B25: =B16+B23 -> 1325807.5
A26: Til sammenlikning: én ansettelse som gikk bra | B26: =Prosessen!$B$34 -> 682281.72
A27: = Merkostnaden ved å velge feil | B27: =B25-B26 -> 643525.76
A28: = Feilansettelsen målt mot den riktige | B28: =IF(B26=0,0,B25/B26) -> 1.9431966 | D28: Ganger så dyrt. Ikke prosent — ganger.
A29: = Andel som ingen faktura viser | B29: =IF(B25=0,0,1-(B10+B19)/B25) -> 0.96014478
A30: = Tilsvarer så mange fakturerte timer | B30: =IF('Timen og lønna'!$B$25=0,0,B25/'Timen og lønna'!$B$25) -> 1489.6713
A31: = Tilsvarer så mange montørårsverk | B31: =IF('Timen og lønna'!$B$28=0,0,B25/'Timen og lønna'!$B$28) -> 1.2413928
A33: Hva én ekstra intervjurunde koster
A34: Ledertimer på én ekstra runde med de tre beste | B34: 10
A35: = Kostnad for én ekstra runde | B35: =B34*Prosessen!$B$10 -> 4806.7257
A36: = Så mange ekstra runder for prisen av én bom | B36: =IF(B35=0,0,B27/B35) -> 133.88028 | D36: Dette er hele poenget med arket. Grundighet i utvelgelsen er nesten gratis. Å bomme er det ikke.
A38: Kontroll
A39: Koster feilansettelsen mer enn den riktige? | D39: =IF(B25>B26,"OK — feilansettelsen koster mer enn ansettelsen som gikk bra","AVVIK: da er noe galt med forutsetningene. Sjekk B5 og B6") -> OK — feilansettelsen koster mer enn ansettelsen som gikk bra
A40: Ryker ansettelsen før opplæringen er ferdig? | D40: =IF(B5<Prosessen!$B$28,"OK — han slutter før opplæringsperioden er over, som er poenget i scenarioet","AVVIK: slutter han etter at opplæringen er ferdig, er dette ikke lenger en feilansettelse — det er en oppsigelse") -> OK — han slutter før opplæringsperioden er over, som er poenget i scenarioet
A41: Er én ekstra intervjurunde billigere enn å bomme? | D41: =IF(B36>10,"OK — det er plass til mange ekstra runder før de koster like mye som én feilansettelse","AVVIK: her er noe galt. Én runde skal koste en brøkdel av én bom") -> OK — det er plass til mange ekstra runder før de koster like mye som én feilansettelse
A43: Merk: arket regner ikke på det som ikke lar seg regne — kunden som ikke kom tilbake, laget som mistet driven, og den som sluttet fordi den nye ikke fungerte. Tallet i B25 er derfor et minimum.
A44: Kilde: Hjertnes, Markedsføring, organisasjon og ledelse for LØM-emnet, 4. utg., kap. 18 avsnitt 18.2. Læreboka er tydelig på hva en dårlig kobling koster — konflikter, mistilpasning og svekket selvbilde — men setter ingen tall på det. Det gjør dette arket.

Sheet Scenario
A1: Tre scenarioer
A2: Endre de gule cellene og se hva som skjer med totalen.
A4: Scenario A · hvor raskt blir han produktiv?
A5: Alt annet er likt. Det eneste som endrer seg, er hvor mye den nye fakturerer i opplæringsperioden.
A7: Opptrapping | B7: Timer som ikke faktureres | C7: Tapt fakturering | D7: Hele ansettelsen | E7: Hva raden betyr
A8: 0.3 | B8: =Prosessen!$B$30*(1-A8) -> 420 | C8: =B8*'Timen og lønna'!$B$25 -> 373800 | D8: =Prosessen!$B$13+Prosessen!$B$18+Prosessen!$B$25+C8 -> 789081.72 | E8: Ingen fadder, ingen plan. Han finner ut av det selv.
A9: 0.5 | B9: =Prosessen!$B$30*(1-A9) -> 300 | C9: =B9*'Timen og lønna'!$B$25 -> 267000 | D9: =Prosessen!$B$13+Prosessen!$B$18+Prosessen!$B$25+C9 -> 682281.72 | E9: Nordlys i dag: fadder i én uke, og et program som slutter i måned 6.
A10: 0.7 | B10: =Prosessen!$B$30*(1-A10) -> 180 | C10: =B10*'Timen og lønna'!$B$25 -> 160200 | D10: =Prosessen!$B$13+Prosessen!$B$18+Prosessen!$B$25+C10 -> 575481.72 | E10: Strukturert program, fadder hele veien, og oppgaver som passer nivået.
A11: 0.85 | B11: =Prosessen!$B$30*(1-A11) -> 90 | C11: =B11*'Timen og lønna'!$B$25 -> 80100 | D11: =Prosessen!$B$13+Prosessen!$B$18+Prosessen!$B$25+C11 -> 495381.72 | E11: Han kom fra en tilsvarende bedrift og kjente arbeidsmåten fra før.
A14: Scenario B · hvor lenge står stillingen tom?
A15: Den dyreste posten i hele arket, og den ingen fører regnskap over.
A16: Måneder tom | B16: Timer som forsvinner | C16: Tapt fakturering | D16: Hele ansettelsen | E16: Hva raden betyr
A17: 1 | B17: ='Timen og lønna'!$B$23*A17/12 -> 100 | C17: =B17*'Timen og lønna'!$B$25 -> 89000 | D17: =Prosessen!$B$13+C17+Prosessen!$B$25+Prosessen!$B$32 -> 415281.72 | E17: Dere hadde en kandidat klar. Sjelden, og det skyldes som regel flaks.
A18: 2 | B18: ='Timen og lønna'!$B$23*A18/12 -> 200 | C18: =B18*'Timen og lønna'!$B$25 -> 178000 | D18: =Prosessen!$B$13+C18+Prosessen!$B$25+Prosessen!$B$32 -> 504281.72 | E18: Utlysingen lå ute før den forrige sluttet.
A19: 4 | B19: ='Timen og lønna'!$B$23*A19/12 -> 400 | C19: =B19*'Timen og lønna'!$B$25 -> 356000 | D19: =Prosessen!$B$13+C19+Prosessen!$B$25+Prosessen!$B$32 -> 682281.72 | E19: Nordlys i dag. Nøkternt for en installasjonsbedrift.
A20: 7 | B20: ='Timen og lønna'!$B$23*A20/12 -> 700 | C20: =B20*'Timen og lønna'!$B$25 -> 623000 | D20: =Prosessen!$B$13+C20+Prosessen!$B$25+Prosessen!$B$32 -> 949281.72 | E20: Dere fant ingen kvalifisert, og måtte lyse ut på nytt.
A23: Scenario C · intern eller ekstern?
A24: Den interne kjenner kundene, anleggene og rutinene fra første dag — men montørstillingen hans må fylles likevel.
B25: Ekstern | C25: Intern | E25: Hva raden betyr
A26: Måneder stillingen står tom | B26: =Prosessen!$B$16 -> 4 | C26: =0 -> 0 | E26: Den interne er allerede på huset. Vakansen er null.
A27: Opptrapping i opplæringsperioden | B27: =Prosessen!$B$29 -> 0.5 | C27: =0.85 -> 0.85 | E27: Den interne kan faget og anleggene. Det som er nytt, er ledelsen.
A28: Annonse | B28: =Prosessen!$B$13-Prosessen!$B$12 -> 12000 | C28: =0 -> 0 | E28: Intern utlysing koster ingenting i annonse.
A29: Ledertid | B29: =Prosessen!$B$12 -> 14420.177 | C29: =Prosessen!$B$12/2 -> 7210.0885 | E29: Halve prosessen: dere kjenner ham, og referansesjekken er unødvendig.
A30: = Tapt fakturering, vakanse | B30: ='Timen og lønna'!$B$23*B26/12*'Timen og lønna'!$B$25 -> 356000 | C30: ='Timen og lønna'!$B$23*C26/12*'Timen og lønna'!$B$25 -> 0
A31: = Tapt fakturering, opplæring | B31: =Prosessen!$B$30*(1-B27)*'Timen og lønna'!$B$25 -> 267000 | C31: =Prosessen!$B$30*(1-C27)*'Timen og lønna'!$B$25 -> 80100
A32: = HELE ANSETTELSEN | B32: =B28+B29+Prosessen!$B$25+B30+B31 -> 682281.72 | C32: =C28+C29+Prosessen!$B$25+C30+C31 -> 120171.63
A33: = Forskjell | B33: =B32-C32 -> 562110.09 | E33: Så mye billigere er den interne — før du har regnet på montørstillingen hans, som må fylles uansett.
A35: Les tabellene slik
A36: Scenario A: opptrappingen er den eneste av de tre knappene bedriften styrer helt selv. Et introduksjonsprogram koster noen timer og betaler seg på uker.
A37: Scenario B: vakansen er den dyreste posten i hele arket, og den er nesten alltid lengre enn folk tror. Den korteste veien til å redusere den er å lyse ut før den forrige har sluttet.
A38: Scenario C: den interne er billigere — men regnestykket er ikke ferdig. Montørstillingen hans må fylles, og da har bedriften fortsatt en rekrutteringsprosess, bare på et lavere nivå. Det er derfor svaret på «internt eller eksternt» ikke er et tall.
A40: Kontroll
A41: Stiger kostnaden når opptrappingen går saktere? | E41: =IF(D8>D11,"OK — lavere opptrapping gir høyere kostnad","AVVIK: tabellen i scenario A skal falle nedover") -> OK — lavere opptrapping gir høyere kostnad
A42: Stiger kostnaden når vakansen blir lengre? | E42: =IF(D20>D17,"OK — lengre vakanse gir høyere kostnad","AVVIK: tabellen i scenario B skal stige nedover") -> OK — lengre vakanse gir høyere kostnad
A43: Stemmer «Nordlys i dag»-raden med arket Prosessen? | E43: =IF(ABS(D9-Prosessen!$B$34)<1,"OK — raden gir samme sum som arket Prosessen","AVVIK: raden stemmer ikke med arket Prosessen") -> OK — raden gir samme sum som arket Prosessen
A44: Er den interne billigere enn den eksterne? | E44: =IF(B33>0,"OK — den interne er billigst i denne oppstillingen","AVVIK: da er forutsetningene endret. Se på opptrappingen i rad 27") -> OK — den interne er billigst i denne oppstillingen
A46: Kilde: Hjertnes, Markedsføring, organisasjon og ledelse for LØM-emnet, 4. utg., kap. 18 avsnitt 18.2.1 om intern og ekstern rekruttering. Tallene er Nordlys Elektro AS' egne.

Sheet Din egen bedrift
A1: Din egen bedrift — samme oppsett, tomt
A2: Fyll inn tallene fra din egen arbeidsplass. Formlene er de samme.
A4: Grunnlaget
A5: Årslønn per utførende | B5: 0 | D5: Lønnsposten delt på antall som fakturerer timer.
A6: Påslag for sosiale kostnader | B6: 0 | D6: Feriepenger, arbeidsgiveravgift, pensjon, helligdager, yrkesskade og sykepenger.
A7: Fakturerte timer per montør per år | B7: 0 | D7: Hent tallet fra timeregistreringen, ikke fra magefølelsen.
A8: Timepris til kunden, uten mva. | B8: 0
A9: = Lønnskostnad per utførende | B9: =B5*(1+B6) -> 0
A10: = Omsetning én montør skaper på ett år | B10: =B7*B8 -> 0
A12: Ansettelsen
A13: Annonse | B13: 0
A14: Ledertimer på hele prosessen | B14: 0
A15: Timekostnad for lederen | B15: 0
A16: Måneder stillingen står tom | B16: 0
A17: Uker fadderen går sammen med den nye | B17: 0
A18: Måneder før den nye er like produktiv | B18: 0
A19: Hvor mye han fakturerer i snitt i den perioden | B19: 0
A20: = Direkte kostnad | B20: =B13+B14*B15 -> 0
A21: = Tapt fakturering, vakanse | B21: =B7*B16/12*B8 -> 0
A22: = Tapt fakturering, fadder | B22: =B7/52*B17*B8 -> 0
A23: = Tapt fakturering, opplæring | B23: =B7*B18/12*(1-B19)*B8 -> 0
A24: = HELE ANSETTELSEN | B24: =B20+B21+B22+B23 -> 0
A25: = Tilsvarer så mange montørårsverk | B25: =IF(B10=0,0,B24/B10) -> 0
A27: Kontroll
A28: Er alle feltene fylt ut? | D28: =IF(OR(B5=0,B7=0,B8=0),"AVVIK: fyll ut lønn, timer og timepris øverst før du leser av totalen","OK — grunnlaget er fylt ut") -> AVVIK: fyll ut lønn, timer og timepris øverst før du leser av totalen
A29: Gir timen positivt dekningsbidrag? | D29: =IF(B7=0,"AVVIK: fyll ut fakturerte timer",IF(B8>B9/B7,"OK — timeprisen dekker lønnskostnaden per fakturert time","AVVIK: timeprisen dekker ikke engang lønna. Se kapittel 5")) -> AVVIK: fyll ut fakturerte timer
A31: Tips: det tallet folk oftest bommer på, er antall måneder stillingen faktisk står tom. Tell fra den dagen oppsigelsen kom, ikke fra den dagen annonsen sto ute.
