Workbook

Sheet Enkelt
A1: Hvor mye kan svaret bomme? Den enkle versjonen
A2: Fyll inn de fire gule cellene. Svaret står i den grønne. Alt annet regner seg selv. Vil du gå dypere, ligger hele modellen i arkene bak.
A4: Det du vet
A5: Hvor mange kunder kunne du ha spurt? | B5: 214 | C5: Hele kundelista. Det er populasjonen: alle du vil vite noe om.
A6: Hvor mange sendte du til eller ringte? | B6: 60 | C6: Alle du prøvde å spørre, også de som ikke svarte.
A7: Hvor mange svarte? | B7: 12 | C7: Det er dette tallet som avgjør hvor sikkert svaret er. Ikke antall spurte.
A8: Hvor mange av dem sa at de var fornøyde? | B8: 11 | C8: Tell bare blant dem som svarte.
A10: Regnestykket
A11: Svarprosent | B11: =B7/B6 -> 0.2 | C11: Svar delt på spurte. Står den ikke i rapporten, var den som regel lav.
A12: Frafall: de som ikke svarte | B12: =B6-B7 -> 48 | C12: Frafallet er sjelden en tilfeldig gruppe. Det gjør svaret skjevt.
A13: Andel fornøyde blant dem som svarte | B13: =B8/B7 -> 0.91666667 | C13: Del på antall svar, ikke på antall spurte.
A15: FEILMARGIN I VERSTE FALL, PROSENTPOENG (±) | B15: =100*1.96*(0.25/B7)^0.5*((B5-B7)/(B5-1))^0.5 -> 27.549983 | C15: Så mye kan svaret bomme fordi du spurte noen og ikke alle, med 95 prosent sikkerhet. Formelen er et tillegg til læreboka.
A16: Så mange må du spørre for å få 67 svar | B16: =67/B11 -> 335 | C16: 67 svar gir ±10 prosentpoeng med 214 kunder. Er tallet større enn kundelista, er metoden umulig.
A18: Hva svaret betyr
A19: ="Av dem som svarte, sa "&TEXT(B13,"0.0 %")&" at de var fornøyde. Men med "&TEXT(ROUND(B7,0),"#,##0")&" svar kan det sanne tallet i verste fall ligge "&TEXT(ROUND(B15,1),"0.0")&" prosentpoeng høyere eller lavere. Skjevheten fra frafallet kommer i tillegg." -> Av dem som svarte, sa 91.7 % at de var fornøyde. Men med 12 svar kan det sanne tallet i verste fall ligge 27.5 prosentpoeng høyere eller lavere. Skjevheten fra frafallet kommer i tillegg.
A21: Prøv selv
A22: 1. Legg inn telefonrunden: B6 = 90, B7 = 67 og B8 = 48. Hva skjer med feilmarginen?
A23: 2. Sett B7 lik B5. Hvorfor blir feilmarginen null?
A24: 3. Hvor mange svar trenger du for å komme under 20 prosentpoeng? Prøv deg fram i B7.
A26: Tallene er Karis e-postundersøkelse fra januar 2026 (sammendraget til kap. 4). Kilde: Markedsføring, organisasjon og ledelse for LØM-emnet, kap. 4.5. Feilmarginen er et tillegg til læreboka (standard utvalgsteori). Nordlys Elektro AS er en konstruert casebedrift.

Sheet Veiledning
A1: Utvalg, svarprosent og feilmargin
A2: LØM Markedsføring kap. 4 · arbeidsregneark · Fagskolen Oslo, Avdeling Elkraft
A3: Emne: Teknisk kommunikasjon og ledelse for 1ET-klassene · LØM for 2ET, 2EK, 3EK og 4EK
A4: Fargekode
A5: Gul celle med blå skrift | B5: Inndata — dette er tallene du endrer.
A6: Grå eller lyseblå celle, svart skrift | B6: Formel — regner seg selv. Ikke skriv over den.
A7: Mørkeblå rad med hvit skrift | B7: Kolonneoverskrift.
A9: Ark i arbeidsboka
A10: Enkelt | B10: Start her. Fire gule celler, ett svar. Hvor mye en kundeundersøkelse kan bomme, regnet på den enkleste måten.
A11: Feilmargin | B11: Hovedarket. Legg inn antall utsendte, antall svar og antall ja, og se hvor mye svaret kan bomme. Her ligger cellene du styrer alt fra: B5 til B9.
A12: Hvor mange må svare | B12: Feilmarginen ved ulike utvalgsstørrelser. Kurven flater ut, og det er hele poenget.
A13: To undersøkelser | B13: Karis e-post mot telefonrunden — samme bedrift, samme år, to ulike svar.
A14: Scenario | B14: Tre spørsmål: hva svarprosenten gjør med om undersøkelsen er mulig, hva presisjon koster, og hva skjevhet gjør med svaret.
A15: Din egen undersøkelse | B15: Samme oppsett, tomt. Legg inn tallene fra din egen bedrift.
A17: Tallene som ligger inne er de to undersøkelsene Kari Nordlund gjorde i 2026.
A19: MERK: feilmarginen står IKKE i læreboka. Hjertnes kap. 4.5 og 4.7.3 sier at
A20: gyldigheten bestemmes av utvalgets størrelse og sammensetning, men tallfester det
A21: ikke. Formelen her er standard utvalgsteori og er tatt med for å gjøre bokas eget
A22: poeng målbart. Der arket og læreboka skulle stå mot hverandre, gjelder læreboka.
A24: To ting formelen IKKE fikser:
A25: 1) Skjevhet. Er utvalget ikke trukket tilfeldig, er tallet presist regnet på feil folk.
A26: Scenario C i arket «Scenario» viser hvor galt det kan bli.
A27: 2) Små tall. Under 30 svar er feilmarginen et varsel om usikkerhet, ikke en presis grense.
A29: Tallene som ligger inne er et eksempel fra en elektrobedrift. Bytt dem ut med dine egne — alle formler følger med.
A30: Arbeidsregneark til LØM · Fagskolen Oslo, Avdeling Elkraft. Regnearket er øvingsstøtte, ikke et regnskapssystem.
A32: De fem knappene
A33: Feilmargin!B5 | B33: Populasjon | C33: Hvor mange du kunne ha spurt. Endrer endelighetskorreksjonen i hele arbeidsboka.
A34: Feilmargin!B6 | B34: Antall spurt | C34: Antall forsøk. Sammen med B7 gir den svarprosenten.
A35: Feilmargin!B7 | B35: Antall SVAR | C35: Det tallet som bestemmer usikkerheten. Ikke antall du spurte.
A36: Feilmargin!B9 | B36: z-verdi | C36: Sikkerhetsnivået. 1,96 er det vanlige.
A37: Feilmargin!B30 | B37: Ønsket feilmargin | C37: Hva du krever av presisjon. Styrer scenario A og B.
A39: Hvilken oppgave bruker hvilket ark
A40: Oppgave i øvingsheftet | B40: Ark | C40: Celler du endrer og leser av
A41: A1 · Kan Kari si at kundene er fornøyde, med tolv svar? | B41: Feilmargin | C41: Tallene ligger inne. Se hva feilmarginen i B20 blir.
A42: A2 · Hva er galt med å spørre bare de kundene du likte? | B42: Scenario | C42: Scenario C: sett andelen ja blant dem som ikke svarte, og se hva den sanne andelen blir.
A43: 1 · Hva tolv svar er verdt | B43: Feilmargin | C43: Legg inn B5, B6, B7 og B8. Les av svarprosenten i B12, andelen ja i B14, feilmarginen i B19 og B20 og intervallet i B21 og B22.
A44: 2 · To undersøkelser, samme bedrift | B44: To undersøkelser | C44: Endre B8 til B10 og C8 til C10. Les av rad 12 til 17, og dommen i D19.
A45: 3 · Hva presisjon koster | B45: Hvor mange må svare og Scenario | C45: Tabellen i «Hvor mange må svare» gir deloppgave a) direkte. Scenario A: endre svarprosentene i B8, C8 og D8 og les av rad 11 til 13. Scenario B er tabellen over hva presisjon koster.
A46: 4 · Sjekkliste: fra spørsmål til rapport | B46: — | C46: Denne oppgaven fyller du ut i heftet. Den bruker ikke regnearket.
A47: 5 · Eksamensnær: hvorfor taper vi anbud? | B47: Scenario | C47: Scenario A gir deg hva metoden koster i antall du må spørre. Scenario C gir deg argumentet for hvem du må spørre. Bruk «Din egen undersøkelse» hvis du vil regne på din egen bedrift.
...

Sheet Feilmargin
A1: Hvor mye kan svaret bomme?
A2: Endre de gule cellene. Alt annet regner seg selv.
A4: 1 · Undersøkelsen
A5: Populasjon: hvor mange kunne du ha spurt? | B5: 214 | C5: 214 kunder — de 34 som fikk solcelleanlegg og de 180 som fikk ladepunkt i 2026
A6: Antall du sendte til eller ringte | B6: 60
A7: Antall som SVARTE | B7: 12 | C7: Det er dette tallet som avgjør usikkerheten — ikke antall du spurte.
A8: Antall av dem som svarte ja | B8: 11
A9: z-verdi (sikkerhetsnivå) | B9: 1.96 | C9: 1,645 gir 90 % sikkerhet · 1,96 gir 95 % · 2,576 gir 99 %
A11: 2 · Hva du fikk inn
A12: = Svarprosent | B12: =IF(B6=0,0,B7/B6) -> 0.2 | C12: Står den ikke i rapporten, er det som regel fordi den var lav.
A13: = Frafall (de som ikke svarte) | B13: =B6-B7 -> 48 | C13: Frafallet er sjelden en tilfeldig gruppe. Det gjør resultatet skjevt, ikke bare unøyaktig.
A14: = Andelen som svarte ja | B14: =IF(B7=0,0,B8/B7) -> 0.91666667
A15: = Utvalgets andel av populasjonen | B15: =IF(B5=0,0,B7/B5) -> 0.056074766
A17: 3 · Feilmarginen
A18: Endelighetskorreksjon | B18: =IF(B5<=1,1,SQRT(MAX(0,(B5-MIN(B7,B5))/(B5-1)))) -> 0.97383613 | C18: Spør du en stor del av en kort kundeliste, er usikkerheten mindre enn formelen ellers sier.
A19: = Feilmargin ved den andelen dere målte | B19: =IF(B7<=0,0,B9*SQRT(B14*(1-B14)/B7)*B18) -> 0.15228826
A20: = Feilmargin i verste fall (50/50) | B20: =IF(B7<=0,0,B9*SQRT(0.25/B7)*B18) -> 0.27549983 | C20: Usikkerheten er størst når svarene fordeler seg jevnt. Bruk dette tallet når du er i tvil.
A21: = Nedre grense for det sanne svaret | B21: =MAX(0,B14-B19) -> 0.76437841
A22: = Øvre grense for det sanne svaret | B22: =MIN(1,B14+B19) -> 1
A23: Konklusjonen du har lov til å trekke | C23: =IF(B7=0,"Ingen svar — ingen konklusjon.","Det sanne tallet ligger et sted mellom "&SUBSTITUTE(TEXT(B21*100,"0.0"),".",",")&" % og "&SUBSTITUTE(TEXT(B22*100,"0.0"),".",",")&" %, med "&IF(B9<1.8,"90",IF(B9<2.2,"95","99"))&" % sikkerhet.") -> Det sanne tallet ligger et sted mellom 76,4 % og 100,0 %, med 95 % sikkerhet.
A25: 4 · Advarsler | C25: =IF(B7<30,"FÆRRE ENN 30 SVAR: formelen forutsetter et større utvalg. Bruk tallet som et varsel om usikkerhet, ikke som en presis grense.","") -> FÆRRE ENN 30 SVAR: formelen forutsetter et større utvalg. Bruk tallet som et varsel om usikkerhet, ikke som en presis grense.
C26: =IF(B12<0.4,"LAV SVARPROSENT: de som ikke svarte er sjelden en tilfeldig gruppe. Feilmarginen fanger ikke opp skjevheten.","") -> LAV SVARPROSENT: de som ikke svarte er sjelden en tilfeldig gruppe. Feilmarginen fanger ikke opp skjevheten.
C27: =IF(B20>0.1,"FEILMARGINEN ER STØRRE ENN TI PROSENTPOENG: du kan ikke skille mellom to alternativer som ligger nær hverandre.","") -> FEILMARGINEN ER STØRRE ENN TI PROSENTPOENG: du kan ikke skille mellom to alternativer som ligger nær hverandre.
A29: 5 · Hvor mange svar trenger dere?
A30: Ønsket feilmargin | B30: 0.1
A31: Nødvendig antall svar, uten hensyn til liten populasjon | B31: =IF(B30<=0,0,ROUNDUP(B9^2*0.25/B30^2,0)) -> 97
A32: = Nødvendig antall SVAR | B32: =IF(B31=0,0,ROUNDUP(B31*B5/(B31+B5-1),0)) -> 67
A33: = Antall dere må spørre, med svarprosenten over | B33: =IF(B12=0,0,ROUNDUP(B32/B12,0)) -> 335 | C33: =IF(B33>B5,"Flere enn det finnes kunder. Med denne svarprosenten er undersøkelsen umulig — svarprosenten må opp.","Gjennomførbart.") -> Flere enn det finnes kunder. Med denne svarprosenten er undersøkelsen umulig — svarprosenten må opp.
A35: Kontroll
A36: Er tallene logisk mulige? | B36: =IF(AND(B7<=B6,B8<=B7,B6<=B5),"OK — svar er færre enn spurte, ja er færre enn svar, og ingen er spurt to ganger","AVVIK: flere svar enn spurte, flere ja enn svar, eller flere spurte enn det finnes kunder") -> OK — svar er færre enn spurte, ja er færre enn svar, og ingen er spurt to ganger
A37: Ligger konfidensintervallet innenfor null og hundre? | B37: =IF(AND(B21>=0,B22<=1,B21<=B22),"OK — intervallet er mulig","AVVIK: intervallet sprenger null eller hundre prosent") -> OK — intervallet er mulig
A38: Er utvalget stort nok til at formelen er til å stole på? | B38: =IF(B7>=30,"OK — tretti svar eller mer, formelen er til å stole på","AVVIK: under tretti svar. Det er ikke en regnefeil, men tallet er et varsel om usikkerhet og ikke en presis grense") -> AVVIK: under tretti svar. Det er ikke en regnefeil, men tallet er et varsel om usikkerhet og ikke en presis grense
A39: Med tallene som ligger inne SKAL det stå AVVIK her. Det er hele poenget med Karis e-post i januar: tolv svar er for få til å konkludere.
A41: Prøv dette: sett svarprosenten opp ved å bytte e-post med telefon — sett B6 til 90 og B7 til 67 — og se hvor mye smalere intervallet blir.
A42: Kilde: Hjertnes, F.: Markedsføring, organisasjon og ledelse for LØM-emnet, 4. utg., kap. 4.5, 4.6 og 4.7.3. Feilmarginformelen er standard utvalgsteori og et tillegg til læreboka. Populasjonen er Nordlys Elektro AS sine egne kunder i 2026.

Sheet Hvor mange må svare
A1: Feilmarginen ved ulike utvalgsstørrelser
A2: Populasjon og z-verdi hentes fra arket «Feilmargin». Marker A5:C14 og sett inn et linjediagram hvis du vil se kurven.
A4: Antall svar | B4: Andel av populasjonen | C4: Feilmargin (50/50) | D4: Uten korreksjon | E4: Hva det betyr i praksis
A5: 10 | B5: =IF(Feilmargin!$B$5=0,0,A5/Feilmargin!$B$5) -> 0.046728972 | C5: =IF(A5<=0,0,Feilmargin!$B$9*SQRT(0.25/A5)*IF(Feilmargin!$B$5<=1,1,SQRT(MAX(0,(Feilmargin!$B$5-MIN(A5,Feilmargin!$B$5))/(Feilmargin!$B$5-1))))) -> 0.3032853 | D5: =IF(A5<=0,0,Feilmargin!$B$9*SQRT(0.25/A5)) -> 0.30990321 | E5: Du kan ikke skille mellom en av tre og to av tre.
A6: 12 | B6: =IF(Feilmargin!$B$5=0,0,A6/Feilmargin!$B$5) -> 0.056074766 | C6: =IF(A6<=0,0,Feilmargin!$B$9*SQRT(0.25/A6)*IF(Feilmargin!$B$5<=1,1,SQRT(MAX(0,(Feilmargin!$B$5-MIN(A6,Feilmargin!$B$5))/(Feilmargin!$B$5-1))))) -> 0.27549983 | D6: =IF(A6<=0,0,Feilmargin!$B$9*SQRT(0.25/A6)) -> 0.28290163 | E6: Karis e-post i januar. Nesten ingen konklusjon tåler dette.
A7: 20 | B7: =IF(Feilmargin!$B$5=0,0,A7/Feilmargin!$B$5) -> 0.093457944 | C7: =IF(A7<=0,0,Feilmargin!$B$9*SQRT(0.25/A7)*IF(Feilmargin!$B$5<=1,1,SQRT(MAX(0,(Feilmargin!$B$5-MIN(A7,Feilmargin!$B$5))/(Feilmargin!$B$5-1))))) -> 0.20913279 | D7: =IF(A7<=0,0,Feilmargin!$B$9*SQRT(0.25/A7)) -> 0.21913466 | E7: Fortsatt for grovt til å velge mellom to alternativer.
A8: 30 | B8: =IF(Feilmargin!$B$5=0,0,A8/Feilmargin!$B$5) -> 0.14018692 | C8: =IF(A8<=0,0,Feilmargin!$B$9*SQRT(0.25/A8)*IF(Feilmargin!$B$5<=1,1,SQRT(MAX(0,(Feilmargin!$B$5-MIN(A8,Feilmargin!$B$5))/(Feilmargin!$B$5-1))))) -> 0.16629705 | D8: =IF(A8<=0,0,Feilmargin!$B$9*SQRT(0.25/A8)) -> 0.1789227 | E8: Her begynner formelen å bli til å stole på.
A9: 50 | B9: =IF(Feilmargin!$B$5=0,0,A9/Feilmargin!$B$5) -> 0.23364486 | C9: =IF(A9<=0,0,Feilmargin!$B$9*SQRT(0.25/A9)*IF(Feilmargin!$B$5<=1,1,SQRT(MAX(0,(Feilmargin!$B$5-MIN(A9,Feilmargin!$B$5))/(Feilmargin!$B$5-1))))) -> 0.12161109 | D9: =IF(A9<=0,0,Feilmargin!$B$9*SQRT(0.25/A9)) -> 0.13859293 | E9: Nå kan du se store forskjeller, men ikke små.
A10: 67 | B10: =IF(Feilmargin!$B$5=0,0,A10/Feilmargin!$B$5) -> 0.31308411 | C10: =IF(A10<=0,0,Feilmargin!$B$9*SQRT(0.25/A10)*IF(Feilmargin!$B$5<=1,1,SQRT(MAX(0,(Feilmargin!$B$5-MIN(A10,Feilmargin!$B$5))/(Feilmargin!$B$5-1))))) -> 0.099462081 | D10: =IF(A10<=0,0,Feilmargin!$B$9*SQRT(0.25/A10)) -> 0.11972606 | E10: Karis telefonrunde i mars. Ti prosentpoeng — nok til å bestemme seg.
A11: 100 | B11: =IF(Feilmargin!$B$5=0,0,A11/Feilmargin!$B$5) -> 0.46728972 | C11: =IF(A11<=0,0,Feilmargin!$B$9*SQRT(0.25/A11)*IF(Feilmargin!$B$5<=1,1,SQRT(MAX(0,(Feilmargin!$B$5-MIN(A11,Feilmargin!$B$5))/(Feilmargin!$B$5-1))))) -> 0.071694972 | D11: =IF(A11<=0,0,Feilmargin!$B$9*SQRT(0.25/A11)) -> 0.098 | E11: Presist nok for de fleste beslutninger en installatør står i.
A12: 150 | B12: =IF(Feilmargin!$B$5=0,0,A12/Feilmargin!$B$5) -> 0.70093458 | C12: =IF(A12<=0,0,Feilmargin!$B$9*SQRT(0.25/A12)*IF(Feilmargin!$B$5<=1,1,SQRT(MAX(0,(Feilmargin!$B$5-MIN(A12,Feilmargin!$B$5))/(Feilmargin!$B$5-1))))) -> 0.043861212 | D12: =IF(A12<=0,0,Feilmargin!$B$9*SQRT(0.25/A12)) -> 0.080016665 | E12: Dyrt. Du har ringt sytti prosent av kundelista.
A13: 214 | B13: =IF(Feilmargin!$B$5=0,0,A13/Feilmargin!$B$5) -> 1 | C13: =IF(A13<=0,0,Feilmargin!$B$9*SQRT(0.25/A13)*IF(Feilmargin!$B$5<=1,1,SQRT(MAX(0,(Feilmargin!$B$5-MIN(A13,Feilmargin!$B$5))/(Feilmargin!$B$5-1))))) -> 0 | D13: =IF(A13<=0,0,Feilmargin!$B$9*SQRT(0.25/A13)) -> 0.066991421 | E13: Du har spurt alle. Da finnes det ingen utvalgsusikkerhet igjen.
A15: Legg merke til formen på kurven: de første tretti svarene halverer usikkerheten. De neste hundre gjør knapt noe.
A16: Presisjon er dyrt. Litt presisjon er billig. Det er hele grunnen til at en liten bedrift kan gjøre nyttige undersøkelser selv.
A17: Kolonnen «Uten korreksjon» viser hva feilmarginen ville vært hvis kundelista var uendelig lang. Forskjellen er poenget: en liten bedrift med få kunder får mer ut av hvert svar enn et meningsmålingsbyrå gjør.
A19: Kontroll
A20: Faller feilmarginen når utvalget vokser? | C20: =IF(C5>C13,"OK — feilmarginen faller nedover i tabellen","AVVIK: tabellen skal falle nedover. Sjekk at antallet svar stiger") -> OK — feilmarginen faller nedover i tabellen
A21: Er feilmarginen null når alle er spurt? | C21: =IF(A13<Feilmargin!$B$5,"OK — nederste rad er mindre enn populasjonen, så det er fortsatt utvalgsusikkerhet igjen",IF(C13<0.0001,"OK — spør du alle, er det ingen utvalgsusikkerhet igjen","AVVIK: spør du alle, skal feilmarginen være null")) -> OK — spør du alle, er det ingen utvalgsusikkerhet igjen
A22: Senker endelighetskorreksjonen feilmarginen? | C22: =IF(C5<D5,"OK — korreksjonen gir lavere feilmargin enn formelen uten den","AVVIK: korreksjonen skal senke feilmarginen, ikke heve den") -> OK — korreksjonen gir lavere feilmargin enn formelen uten den
A24: Kilde: Hjertnes kap. 4.5 om utvalgets størrelse. Formelen er et tillegg til læreboka.

Sheet To undersøkelser
A1: Samme bedrift, samme spørsmål, to svar
A2: Kolonnene er Karis to undersøkelser. Se hva som skiller dem.
B4: E-posten i januar | C4: Telefonrunden i mars | D4: Hva forskjellen kommer av
A5: Utvalgsmetode | B5: Bekvemmelighetsutvalg | C5: Enkelt, tilfeldig utvalg | D5: Trukket eller ikke. Det er det viktigste valget i hele undersøkelsen.
A6: Metode | B6: E-post | C6: Telefon | D6: Telefon gir høyere svarprosent, men ingen anonymitet.
A7: Populasjon | B7: =Feilmargin!$B$5 -> 214 | C7: =Feilmargin!$B$5 -> 214
A8: Antall spurt | B8: 60 | C8: 90
A9: Antall svar | B9: 12 | C9: 67
A10: Antall som svarte ja | B10: 11 | C10: 48
A12: = Svarprosent | B12: =IF(B8=0,0,B9/B8) -> 0.2 | C12: =IF(C8=0,0,C9/C8) -> 0.74444444 | D12: Fire av fem svarte ikke på e-posten. Tre av fire svarte på telefonen.
A13: = Andel som svarte ja | B13: =IF(B9=0,0,B10/B9) -> 0.91666667 | C13: =IF(C9=0,0,C10/C9) -> 0.71641791 | D13: Det høyeste tallet kommer fra den dårligste undersøkelsen. Det er ikke tilfeldig.
A14: = Feilmargin i verste fall | B14: =IF(B9<=0,0,Feilmargin!$B$9*SQRT(0.25/B9)*IF(B7<=1,1,SQRT(MAX(0,(B7-MIN(B9,B7))/(B7-1))))) -> 0.27549983 | C14: =IF(C9<=0,0,Feilmargin!$B$9*SQRT(0.25/C9)*IF(C7<=1,1,SQRT(MAX(0,(C7-MIN(C9,C7))/(C7-1))))) -> 0.099462081 | D14: Nesten tre ganger så stor usikkerhet i den første.
A15: = Nedre grense | B15: =MAX(0,B13-B14) -> 0.64116684 | C15: =MAX(0,C13-C14) -> 0.61695583
A16: = Øvre grense | B16: =MIN(1,B13+B14) -> 1 | C16: =MIN(1,C13+C14) -> 0.81587999 | D16: Intervallene overlapper. De to undersøkelsene motsier altså ikke hverandre.
A17: = Bredden på intervallet, i prosentpoeng | B17: =B16-B15 -> 0.35883316 | C17: =C16-C15 -> 0.19892416
A19: Hvilken av dem tør du bruke i markedsplanen? | D19: =IF(C14<B14,"Telefonrunden. Ikke fordi tallet er penere — det er lavere — men fordi utvalget er trukket og usikkerheten er mindre.","E-posten.") -> Telefonrunden. Ikke fordi tallet er penere — det er lavere — men fordi utvalget er trukket og usikkerheten er mindre.
A21: Kontroll
A22: Har den store undersøkelsen minst usikkerhet? | B22: =IF(C14<B14,"OK — flere svar gir smalere intervall","AVVIK: undersøkelsen med flest svar skal ha minst feilmargin") -> OK — flere svar gir smalere intervall
A23: Overlapper intervallene? | B23: =IF(AND(B15<=C16,C15<=B16),"OK — intervallene overlapper, så de to undersøkelsene motsier ikke hverandre","AVVIK: intervallene overlapper ikke. Da måler de to undersøkelsene noe forskjellig, og det må forklares") -> OK — intervallene overlapper, så de to undersøkelsene motsier ikke hverandre
A24: Gir den dårligste undersøkelsen det hyggeligste svaret? | B24: =IF(B13>C13,"OK — e-posten gir det høyeste tallet. Det er hovedgrunnen til at dårlige undersøkelser overlever i bedrifter: de bekrefter det ledelsen håpet på","AVVIK: her gir den store undersøkelsen det høyeste tallet. Da mister sammenlikningen sitt viktigste poeng") -> OK — e-posten gir det høyeste tallet. Det er hovedgrunnen til at dårlige undersøkelser overlever i bedrifter: de bekrefter det ledelsen håpet på
A26: Merk at den første undersøkelsen ga det HYGGELIGSTE svaret. Et tall som bekrefter det ledelsen håpet på, blir sjelden etterprøvd.

Sheet Scenario
A1: Tre scenarioer
A2: Endre de gule cellene og se hva som skjer. Alle tall hentes fra arket «Feilmargin».
A4: Scenario A · svarprosenten avgjør om undersøkelsen er mulig
A5: Målet er det samme i alle tre kolonnene. Det eneste som endrer seg, er hvor stor del som svarer.
B7: E-post | C7: Telefon | D7: Personlig oppsøk | E7: Hva raden betyr
A8: Svarprosent | B8: 0.2 | C8: 0.74444444 | D8: 0.95 | E8: De gule cellene er scenarioene. Endre dem fritt.
A9: Ønsket feilmargin | B9: =Feilmargin!$B$30 -> 0.1 | C9: =Feilmargin!$B$30 -> 0.1 | D9: =Feilmargin!$B$30 -> 0.1
A10: Nødvendig antall SVAR | B10: =Feilmargin!$B$32 -> 67 | C10: =Feilmargin!$B$32 -> 67 | D10: =Feilmargin!$B$32 -> 67 | E10: Det samme uansett metode. Formelen bryr seg om svar, ikke om hvordan du spurte.
A11: = Antall du må spørre | B11: =IF(B8=0,0,ROUNDUP(B10/B8,0)) -> 335 | C11: =IF(C8=0,0,ROUNDUP(C10/C8,0)) -> 90 | D11: =IF(D8=0,0,ROUNDUP(D10/D8,0)) -> 71
A12: Andel av hele kundelista | B12: =B11/Feilmargin!$B$5 -> 1.5654206 | C12: =C11/Feilmargin!$B$5 -> 0.42056075 | D12: =D11/Feilmargin!$B$5 -> 0.3317757
A13: Dom | B13: =IF(B11>Feilmargin!$B$5,"Umulig — ikke nok kunder","Gjennomførbart") -> Umulig — ikke nok kunder | C13: =IF(C11>Feilmargin!$B$5,"Umulig — ikke nok kunder","Gjennomførbart") -> Gjennomførbart | D13: =IF(D11>Feilmargin!$B$5,"Umulig — ikke nok kunder","Gjennomførbart") -> Gjennomførbart | E13: Med tjue prosent svar må du spørre flere enn du har. Det er ikke en dyr undersøkelse — det er en umulig en.
A15: Kontroll
A16: Krever lavere svarprosent at flere spørres? | B16: =IF(AND(B8<C8,B11>C11),"OK — lavere svarprosent krever at flere spørres","AVVIK: sjekk at e-postkolonnen har lavere svarprosent enn telefonkolonnen") -> OK — lavere svarprosent krever at flere spørres
A17: Hva som SKAL stå her med tallene som ligger inne | B17: =IF(B11>Feilmargin!$B$5,"OK — e-postrunden er umulig. Det er hele poenget med svarprosenten","AVVIK: e-postrunden er gjennomførbar. Da er svarprosenten satt for høyt til å bære poenget") -> OK — e-postrunden er umulig. Det er hele poenget med svarprosenten
A20: Scenario B · hva presisjon koster
A21: Halverer du feilmarginen, firedobler du antall svar. Se hvor fort det blir dyrt.
A23: Ønsket feilmargin | B23: Nødvendige svar | C23: Må spørres på telefon | D23: Andel av kundelista | E23: Hva det betyr
A24: 0.2 | B24: =IF(A24<=0,0,ROUNDUP(ROUNDUP(Feilmargin!$B$9^2*0.25/A24^2,0)*Feilmargin!$B$5/(ROUNDUP(Feilmargin!$B$9^2*0.25/A24^2,0)+Feilmargin!$B$5-1),0)) -> 23 | C24: =ROUNDUP(B24/Scenario!$C$8,0) -> 31 | D24: =C24/Feilmargin!$B$5 -> 0.14485981 | E24: Grovt. Nok til å se om noe er stort eller lite.
A25: 0.15 | B25: =IF(A25<=0,0,ROUNDUP(ROUNDUP(Feilmargin!$B$9^2*0.25/A25^2,0)*Feilmargin!$B$5/(ROUNDUP(Feilmargin!$B$9^2*0.25/A25^2,0)+Feilmargin!$B$5-1),0)) -> 36 | C25: =ROUNDUP(B25/Scenario!$C$8,0) -> 49 | D25: =C25/Feilmargin!$B$5 -> 0.22897196 | E25: Fortsatt grovt, men billig.
A26: 0.1 | B26: =IF(A26<=0,0,ROUNDUP(ROUNDUP(Feilmargin!$B$9^2*0.25/A26^2,0)*Feilmargin!$B$5/(ROUNDUP(Feilmargin!$B$9^2*0.25/A26^2,0)+Feilmargin!$B$5-1),0)) -> 67 | C26: =ROUNDUP(B26/Scenario!$C$8,0) -> 90 | D26: =C26/Feilmargin!$B$5 -> 0.42056075 | E26: Målet Kari satte. Nok til å bestemme seg.
A27: 0.05 | B27: =IF(A27<=0,0,ROUNDUP(ROUNDUP(Feilmargin!$B$9^2*0.25/A27^2,0)*Feilmargin!$B$5/(ROUNDUP(Feilmargin!$B$9^2*0.25/A27^2,0)+Feilmargin!$B$5-1),0)) -> 138 | C27: =ROUNDUP(B27/Scenario!$C$8,0) -> 186 | D27: =C27/Feilmargin!$B$5 -> 0.86915888 | E27: Presist. Nå må du ringe mesteparten av kundelista.
A28: 0.03 | B28: =IF(A28<=0,0,ROUNDUP(ROUNDUP(Feilmargin!$B$9^2*0.25/A28^2,0)*Feilmargin!$B$5/(ROUNDUP(Feilmargin!$B$9^2*0.25/A28^2,0)+Feilmargin!$B$5-1),0)) -> 179 | C28: =ROUNDUP(B28/Scenario!$C$8,0) -> 241 | D28: =C28/Feilmargin!$B$5 -> 1.1261682 | E28: Meningsmålingsnivå. Her finnes ikke nok kunder.
A30: Kontroll
A31: Krever mindre feilmargin flere svar? | B31: =IF(B28>B24,"OK — mindre feilmargin krever flere svar","AVVIK: tabellen skal stige nedover") -> OK — mindre feilmargin krever flere svar
A32: Er det nok kunder til den strengeste raden? | B32: =IF(C28>Feilmargin!$B$5,"OK — den strengeste raden krever flere enn det finnes kunder. Det er grensen for hva en liten bedrift kan måle","AVVIK: selv den strengeste raden er mulig. Da er tabellen for snill til å vise grensen") -> OK — den strengeste raden krever flere enn det finnes kunder. Det er grensen for hva en liten bedrift kan måle
A35: Scenario C · skjevhet — det formelen ikke kan rette opp
A36: De som ikke svarte, er sjelden like de som svarte. Her setter du inn hva DE ville svart, og ser hva det sanne tallet blir.
A38: Antall som svarte | B38: =Feilmargin!$B$7 -> 12
A39: Andel ja blant dem som svarte | B39: =Feilmargin!$B$14 -> 0.91666667
A40: Antall som IKKE svarte | B40: =Feilmargin!$B$6-Feilmargin!$B$7 -> 48
A41: Andel ja blant dem som ikke svarte | B41: 0.4 | E41: Dette er gjettingen. Sett den lik andelen over hvis du tror frafallet er tilfeldig — og spør deg selv om du virkelig tror det.
A42: = Sann andel ja blant alle du spurte | B42: =IF((B38+B40)=0,0,(B38*B39+B40*B41)/(B38+B40)) -> 0.50333333
A43: = Skjevhet i prosentpoeng | B43: =B39-B42 -> 0.41333333 | E43: Så mye for høyt eller lavt måler undersøkelsen, bare fordi frafallet ikke er tilfeldig.
A44: Feilmarginen ved den målte andelen | B44: =Feilmargin!$B$19 -> 0.15228826
A45: Er skjevheten større enn feilmarginen? | B45: =IF(ABS(B43)>B44,"JA","Nei") -> JA | E45: Står det JA, er skjevheten et større problem enn utvalgsstørrelsen — og da hjelper det ikke å spørre flere.
A47: Kontroll
A48: Er skjevheten regnet riktig? | B48: =IF(ABS((B38*B39+B40*B41)-(B38+B40)*B42)<0.000001,"OK — de to gruppene veier riktig i snittet","AVVIK: vektingen av de to gruppene går ikke opp") -> OK — de to gruppene veier riktig i snittet
A49: Hva som SKAL stå her med tallene som ligger inne | B49: =IF(ABS(B43)>B44,"OK — skjevheten er større enn feilmarginen. Et større utvalg ville ikke reddet denne undersøkelsen","AVVIK: skjevheten er mindre enn feilmarginen. Prøv en lavere andel ja blant dem som ikke svarte, og se hva som skjer") -> OK — skjevheten er større enn feilmarginen. Et større utvalg ville ikke reddet denne undersøkelsen
A51: Ti tusen svar fra bare fornøyde kunder er like skjevt som tolv. Et stort utvalg reparerer ikke et skjevt et — og ingen formel i dette arket kan si hvor skjevt det er. Det er derfor trekningen er viktigere enn antallet.
A52: Kilde: Hjertnes kap. 4.6 om utvalgsmetodene og 4.7.3 om gyldighet og pålitelighet. Vektingen i scenario C er standard utvalgsteori og et tillegg til læreboka.

Sheet Din egen undersøkelse
A1: Din egen bedrift
A2: Samme oppsett som arket «Feilmargin», men tomt. Fyll inn tallene fra en undersøkelse dere selv har gjort.
A4: 1 · Undersøkelsen
A5: Populasjon: hvor mange kunne dere ha spurt? | B5: 0 | C5: Alle kundene, alle som ba om tilbud, eller alle i markedet? Velg, og skriv det ned.
A6: Antall dere sendte til eller ringte | B6: 0 | C6: Antall forsøk, ikke antall svar.
A7: Antall som SVARTE | B7: 0 | C7: Dette tallet bestemmer usikkerheten.
A8: Antall av dem som svarte ja | B8: 0 | C8: Ja til det ene spørsmålet dere bryr dere mest om.
A9: z-verdi (sikkerhetsnivå) | B9: 1.96 | C9: 1,645 gir 90 % sikkerhet · 1,96 gir 95 % · 2,576 gir 99 %
A11: 2 · Resultat
A12: = Svarprosent | B12: =IF(B6=0,0,B7/B6) -> 0
A13: = Andelen som svarte ja | B13: =IF(B7=0,0,B8/B7) -> 0
A14: = Feilmargin ved den andelen dere målte | B14: =IF(OR(B7<=0,B5<=1),0,B9*SQRT(B13*(1-B13)/B7)*IF(B5<=1,1,SQRT(MAX(0,(B5-MIN(B7,B5))/(B5-1))))) -> 0
A15: = Feilmargin i verste fall (50/50) | B15: =IF(OR(B7<=0,B5<=1),0,B9*SQRT(0.25/B7)*IF(B5<=1,1,SQRT(MAX(0,(B5-MIN(B7,B5))/(B5-1))))) -> 0
A16: = Nedre grense | B16: =MAX(0,B13-B14) -> 0
A17: = Øvre grense | B17: =MIN(1,B13+B14) -> 0
A19: Konklusjonen dere har lov til å trekke | C19: =IF(B7=0,"Fyll inn tallene over.","Mellom "&SUBSTITUTE(TEXT(B16*100,"0.0"),".",",")&" % og "&SUBSTITUTE(TEXT(B17*100,"0.0"),".",",")&" % av populasjonen svarer ja — så langt tallene rekker.") -> Fyll inn tallene over.
C20: =IF(AND(B7>0,B7<30),"Under 30 svar. Formelen er et varsel, ikke en presisjon.","")
A22: Kontroll
A23: Er tallene logisk mulige? | B23: =IF(B5=0,"Fyll inn tallene over.",IF(AND(B7<=B6,B8<=B7,B6<=B5),"OK — tallene henger sammen","AVVIK: flere svar enn spurte, flere ja enn svar, eller flere spurte enn det finnes i populasjonen")) -> Fyll inn tallene over.
A24: Er svarprosenten høy nok til at frafallet ikke dominerer? | B24: =IF(B6=0,"Fyll inn tallene over.",IF(B12>=0.4,"OK — over førti prosent svarte","AVVIK: lav svarprosent. De som ikke svarte er sjelden en tilfeldig gruppe, og feilmarginen fanger ikke opp skjevheten")) -> Fyll inn tallene over.
A26: Og det arket ikke kan svare på: ble utvalget trukket tilfeldig? Er det ikke det, er tallet over presist regnet på feil folk.
A27: Fikk dere aldri vite svarprosenten i en undersøkelse noen andre gjorde for dere, er det i seg selv et funn.
