Workbook

Sheet Enkelt
A1: Hvilken jobb skal få de ledige timene? Den enkle versjonen
A2: Fyll inn de fem gule cellene. Svaret står i den grønne. Alt annet regner seg selv. Vil du gå dypere, ligger alle fire oppdragstypene og månedsplanen i arkene bak.
A4: Det du vet
A5: Hvor mange ledige montørtimer har du? | B5: 14 | C5: Timene er det knappe. Alt annet har dere nok av.
A6: Hva gir ett solcelleanlegg i dekningsbidrag? | B6: 4400 | C6: Pris minus det jobben koster i seg selv.
A7: Hvor mange timer tar ett solcelleanlegg? | B7: 14 | C7: Montørtimer på jobben.
A8: Hva gir ett ladepunkt i dekningsbidrag? | B8: 1050 | C8: Den lille jobben. Minst per oppdrag.
A9: Hvor mange timer tar ett ladepunkt? | B9: 2 | C9: Montørtimer på jobben.
A11: Regnestykket
A12: Solcelleanlegg: kroner per montørtime | B12: =B6/B7 -> 314.28571 | C12: Dekningsbidraget delt på timene. Det er regelen.
A13: Ladepunkt: kroner per montørtime | B13: =B8/B9 -> 525 | C13: Samme brøk for den lille jobben.
A14: Dekningsbidrag hvis timene går til solcelle | B14: =B5*B12 -> 4400 | C14: De ledige timene ganger kroner per time.
A15: Dekningsbidrag hvis timene går til ladepunkt | B15: =B5*B13 -> 7350 | C15: Med 14 timer rekker montørene sju ladepunkt.
A17: LADEPUNKT MINUS SOLCELLE, I KRONER | B17: =B15-B14 -> 2950 | C17: Positivt tall: ladepunktene gir mest. Negativt: solcelleanlegget gir mest.
A18: Så mange ganger så lønnsomt per time | B18: =B13/B12 -> 1.6704545 | C18: Ladepunktets kroner per time delt på solcelleanleggets.
A20: Hva svaret betyr
A21: ="På de samme "&TEXT(ROUND(B5,0),"0")&" timene gir ladepunktene "&TEXT(ROUND(B17,0),"#,##0")&" kroner mer enn solcelleanlegget. Når timene er knappe, er det timen som skal prises." -> På de samme 14 timene gir ladepunktene 2,950 kroner mer enn solcelleanlegget. Når timene er knappe, er det timen som skal prises.
A23: Prøv selv
A24: 1. Hva må B6 være for at solcelleanlegget skal gi like mye per time som ladepunktet?
A25: 2. Sett B9 til 3. Er ladepunktet fortsatt best?
A26: 3. Ingenting er knapt lenger, og du kan ta alle jobbene. Betyr B17 fortsatt noe? Hvorfor ikke?
A28: Tallene er Nordlys Elektro AS sine (sammendraget og arket «Rangering»). Kilde: Økonomistyring for LØM-emnet, kap. 7.1 og 7.2. Nordlys Elektro AS er en konstruert casebedrift.

Sheet Veiledning
A1: Knapp faktor — hvilket oppdrag skal du ta først?
A2: LØM Økonomistyring kap. 7 · arbeidsregneark · Fagskolen Oslo, Avdeling Elkraft
A3: Emne: Teknisk kommunikasjon og ledelse for 1ET-klassene · LØM for 2ET, 2EK, 3EK og 4EK
A4: Fargekode
A5: Gul celle med blå skrift | B5: Inndata — dette er tallene du endrer.
A6: Grå eller lyseblå celle, svart skrift | B6: Formel — regner seg selv. Ikke skriv over den.
A7: Mørkeblå rad med hvit skrift | B7: Kolonneoverskrift.
A9: Ark i arbeidsboka
A10: Enkelt | B10: Start her. Fem gule celler, ett svar. Hvilken jobb som skal få de ledige timene.
A11: Rangering | B11: De fire oppdragstypene med begge måltallene og alle tre rangeringene. Her ligger de gule cellene alt annet henter fra.
A12: Produktvalg | B12: Planen når montørtimene er flaskehalsen: riktig rangering mot fella, og hva forskjellen koster i året.
A13: Materiell knapp | B13: Samme måned, men grossisten er flaskehalsen. Rangeringen snur, og montørtimer blir stående ubrukt.
A14: Scenario | B14: To rammeavtaler om de samme timene. Hva koster det å velge feil, hvor mye rabatt tåler valget, og hvor mye volumsvikt?
A15: Din bedrift | B15: Samme oppsett, tomt. Legg inn dine egne oppdragstyper.
A17: Tallene som ligger inne er ordreboka til Nordlys Elektro AS i mars, den samme bedriften du møter i alle ti kapitlene i Bok 1.
A18: Rangeringene regnes med RANK, og planene fylles ovenfra og ned med INDEX og MATCH. Snur du et tall, snur rangeringen og planen med den.
A19: Merk: dekningsbidraget per oppdrag er regnet ETTER montørlønn, fordi montørlønna er en variabel kostnad i en installasjonsbedrift.
A21: Tallene som ligger inne er et eksempel fra en elektrobedrift. Bytt dem ut med dine egne — alle formler følger med.
A22: Arbeidsregneark til LØM · Fagskolen Oslo, Avdeling Elkraft. Regnearket er øvingsstøtte, ikke et regnskapssystem.
A24: De fire knappene
A25: Rangering!B6:B9 | B25: Dekningsbidrag per oppdrag | C25: Endrer rangeringen, planene og begge scenarioene.
A26: Rangering!C6:C9 | B26: Montørtimer per oppdrag | C26: Nevneren i det viktigste måltallet.
A27: Rangering!E6:E9 | B27: Etterspørsel i måneden | C27: Taket. Uten et tak finnes det ikke noe prioriteringsproblem.
A28: Produktvalg!B5 | B28: Kapasiteten i timer | C28: Sett den høyt nok, og hele rangeringen slutter å bety noe.
A30: Hvilken oppgave bruker hvilket ark
A31: Oppgave i øvingsheftet | B31: Ark | C31: Celler du endrer og leser av
A32: A1 · Duellen: 14 timer, to måter | B32: Rangering | C32: Les av F6 til F9 og duellblokka i rad 15 til 20.
A33: A2 · Når skal rangeringen ikke avgjøre? | B33: Produktvalg | C33: Les av C37 til C40: hvem som faktisk gir fra seg timene, og hva ett oppdrag ekstra koster.
A34: A3 · Klasseoppgave: montørtimene i mars | B34: Produktvalg | C34: Les av hele planen i rad 12 til 16 og forskjellen i C31 til C34.
A35: 1 · Fire oppdragstyper, én knapp faktor | B35: Rangering | C35: Endre B6 til E9. Les av F6 til F9, rangeringen i G, og duellen i rad 15 til 20.
A36: 2 · Hvem får montørtimene i mars? | B36: Produktvalg | C36: Endre kapasiteten i B5. Les av planen i rad 12 til 16, fella i rad 21 til 25 og forskjellen i C31, C32 og C34.
A37: 3 · Grossisten kan ikke levere | B37: Materiell knapp | C37: Endre materiellrammen i C5. Les av planen i rad 13 til 17, sammenlikningen i rad 22 til 26 og ubrukte timer i C33.
A38: 4 · Rammeavtalen, lærlingen og de tapte kundene | B38: Produktvalg | C38: Les av C39 og C40 — alternativkostnaden regnet på to måter.
A39: 5 · Eksamensnær: to rammeavtaler om de samme timene | B39: Scenario | C39: Les av rad 10 til 18. Sett rabatten i B25 og les av B27 og B28. Sett volumsvikten i B33 og les av B34, B36 og B37.
A41: Kontrollradene
A42: Hvert regneark har en kontrollblokk. Står det OK, henger tallene sammen. Står det AVVIK, farges cellen rød, og teksten sier hva som ikke går opp.
A43: Ett unntak: arket «Din bedrift» står på AVVIK til du har fylt inn dine egne tall.
A44: Kontroller i arbeidsboka: Rangering B23, Rangering B24, Rangering B25, Produktvalg C43, Produktvalg C44, Produktvalg C45, Materiell knapp C36, Materiell knapp C37, Materiell knapp C38, Scenario B40, Scenario B41, Scenario B42, Din bedrift B18, Din bedrift B20
A46: Slik henger kapitlene sammen
A47: Dekningsbidraget per oppdragstype er det samme dekningsbidraget du deler kostnadene i i kapittel 2. Montørtimene er de samme fakturerte timene timeprisen i kapittel 5 regnes av. Og rangeringen her er grunnen til at en bedrift kan ha full ordrebok og likevel et svakt resultat — det er nettopp det kapittel 8 måler.
...

Sheet Rangering
A1: De fire oppdragstypene
A2: Endre de gule cellene. Rangeringen regner seg selv — også når du snur den på hodet.
A5: Oppdragstype | B5: DB per oppdrag | C5: Montørtimer | D5: Materiell, kr | E5: Etterspørsel i måneden | F5: DB per montørtime | G5: Rang | H5: DB per materiellkrone | I5: Rang | J5: Rang per oppdrag | K5: Hva raden forteller
A6: Boliginstallasjon | B6: 900 | C6: 3 | D6: 4000 | E6: 120 | F6: =B6/C6 -> 300 | G6: =RANK(F6,$F$6:$F$9) -> 3 | H6: =B6/D6 -> 0.225 | I6: =RANK(H6,$H$6:$H$9) -> 1 | J6: =RANK(B6,$B$6:$B$9) -> 4 | K6: Middels overalt — men best per materiellkrone.
A7: Nybygg (prosjekt) | B7: 2100 | C7: 9 | D7: 22000 | E7: 40 | F7: =B7/C7 -> 233.33333 | G7: =RANK(F7,$F$6:$F$9) -> 4 | H7: =B7/D7 -> 0.095454545 | I7: =RANK(H7,$H$6:$H$9) -> 4 | J7: =RANK(B7,$B$6:$B$9) -> 2 | K7: Svakest per time og per materiellkrone. Og det er her ordreboka er full.
A8: Solcelleanlegg | B8: 4400 | C8: 14 | D8: 38000 | E8: 30 | F8: =B8/C8 -> 314.28571 | G8: =RANK(F8,$F$6:$F$9) -> 2 | H8: =B8/D8 -> 0.11578947 | I8: =RANK(H8,$H$6:$H$9) -> 3 | J8: =RANK(B8,$B$6:$B$9) -> 1 | K8: Størst per oppdrag. Det er den de fleste peker på først.
A9: Ladepunkt | B9: 1050 | C9: 2 | D9: 6500 | E9: 150 | F9: =B9/C9 -> 525 | G9: =RANK(F9,$F$6:$F$9) -> 1 | H9: =B9/D9 -> 0.16153846 | I9: =RANK(H9,$H$6:$H$9) -> 2 | J9: =RANK(B9,$B$6:$B$9) -> 3 | K9: Den «lille» jobben. Minst per oppdrag, mest per time.
A11: Etterspurte montørtimer i måneden | C11: =SUMPRODUCT(C6:C9,E6:E9) -> 1440
A12: Etterspurt materiell i måneden | D12: =SUMPRODUCT(D6:D9,E6:E9) -> 3475000
A14: Duellen: én timeblokk, to måter å bruke den på
A15: Timeblokk — så lang som ett solcelleanlegg tar | B15: =C8 -> 14 | K15: Cellen henter timetallet for solcelleanlegget i rad 8.
A16: Ett solcelleanlegg gir | B16: =B8 -> 4400
A17: Ladepunkt som får plass i samme blokk | B17: =INT(B15/C9) -> 7
A18: De gir til sammen | B18: =B17*B9 -> 7350
A19: Differanse | B19: =B18-B16 -> 2950
A20: Så mange ganger så lønnsomt per time | B20: =F9/F8 -> 1.6704545 | K20: Dette er hele kapitlet i én linje.
A22: Kontroll
A23: Gir de to rangeringene ulik rekkefølge? | B23: =IF(SUMPRODUCT(--(G6:G9<>J6:J9))>0,"OK — rangering per montørtime og rangering per oppdrag gir ulik rekkefølge. Det er derfor måltallet betyr noe","AVVIK: de to rangeringene er like — da har oppgaven ingen spenning") -> OK — rangering per montørtime og rangering per oppdrag gir ulik rekkefølge. Det er derfor måltallet betyr noe
A24: Er alle dekningsbidrag positive? | B24: =IF(MIN(B6:B9)>0,"OK — alle fire oppdragstypene gir positivt dekningsbidrag","AVVIK: en oppdragstype med negativt dekningsbidrag skal ikke rangeres, den skal droppes") -> OK — alle fire oppdragstypene gir positivt dekningsbidrag
A25: Er kapasiteten faktisk knapp? | B25: =IF(C11>Produktvalg!B5,"OK — etterspørselen krever flere montørtimer enn dere har. Da er timene den knappe faktoren","AVVIK: det er timer nok til alle forespørslene — da finnes det ikke noe prioriteringsproblem") -> OK — etterspørselen krever flere montørtimer enn dere har. Da er timene den knappe faktoren
A27: Prøv dette: sett dekningsbidraget for nybygg i B7 opp til det gir samme beløp per montørtime som ladepunktet. Se hva som skjer med rangeringen — og med planen i arket Produktvalg.
A28: Kilde: Bok 1 kap. 7.1 og 7.2. Oppdragstypene og tallene er Nordlys Elektro AS' egne.

Sheet Produktvalg
A1: Hvem får montørtimene?
A2: Planen fylles ovenfra og ned i rangeringen, med etterspørselen som tak.
A4: 1 · Kapasiteten
A5: Timer | B5: 1200 | C5: montørtimer i måneden | I5: En tolvtedel av de fakturerte timene i året. Dette er den knappe faktoren.
A6: Krav | B6: =Rangering!C11 -> 1440 | C6: etterspurte montørtimer
A7: Gap | B7: =B6-B5 -> 240 | C7: underdekning i timer | I7: Uten underdekning er det ikke noe å prioritere.
A9: 2 · Riktig plan — rangert per dekningsbidrag per montørtime
B10: Fyll ovenfra og ned, men aldri flere enn det finnes forespørsler av.
A11: Rang | B11: Oppdragstype | C11: Etterspørsel | D11: Timer per oppdrag | E11: Antall som tas | F11: Timer brukt | G11: Dekningsbidrag | H11: Avvist | I11: Kommentar | J11: DB/time hvis helt dekket
A12: 1 | B12: =INDEX(Rangering!$A$6:$A$9,MATCH($A12,Rangering!$G$6:$G$9,0)) -> Ladepunkt | C12: =INDEX(Rangering!$E$6:$E$9,MATCH($A12,Rangering!$G$6:$G$9,0)) -> 150 | D12: =INDEX(Rangering!$C$6:$C$9,MATCH($A12,Rangering!$G$6:$G$9,0)) -> 2 | E12: =MIN(C12,INT(($B$5-SUM($F$11:F11))/D12)) -> 150 | F12: =E12*D12 -> 300 | G12: =E12*INDEX(Rangering!$B$6:$B$9,MATCH($A12,Rangering!$G$6:$G$9,0)) -> 157500 | H12: =C12-E12 -> 0 | J12: =IF(AND(E12>0,H12=0),INDEX(Rangering!$F$6:$F$9,MATCH(B12,Rangering!$A$6:$A$9,0)),"") -> 525
A13: 2 | B13: =INDEX(Rangering!$A$6:$A$9,MATCH($A13,Rangering!$G$6:$G$9,0)) -> Solcelleanlegg | C13: =INDEX(Rangering!$E$6:$E$9,MATCH($A13,Rangering!$G$6:$G$9,0)) -> 30 | D13: =INDEX(Rangering!$C$6:$C$9,MATCH($A13,Rangering!$G$6:$G$9,0)) -> 14 | E13: =MIN(C13,INT(($B$5-SUM($F$11:F12))/D13)) -> 30 | F13: =E13*D13 -> 420 | G13: =E13*INDEX(Rangering!$B$6:$B$9,MATCH($A13,Rangering!$G$6:$G$9,0)) -> 132000 | H13: =C13-E13 -> 0 | J13: =IF(AND(E13>0,H13=0),INDEX(Rangering!$F$6:$F$9,MATCH(B13,Rangering!$A$6:$A$9,0)),"") -> 314.28571
A14: 3 | B14: =INDEX(Rangering!$A$6:$A$9,MATCH($A14,Rangering!$G$6:$G$9,0)) -> Boliginstallasjon | C14: =INDEX(Rangering!$E$6:$E$9,MATCH($A14,Rangering!$G$6:$G$9,0)) -> 120 | D14: =INDEX(Rangering!$C$6:$C$9,MATCH($A14,Rangering!$G$6:$G$9,0)) -> 3 | E14: =MIN(C14,INT(($B$5-SUM($F$11:F13))/D14)) -> 120 | F14: =E14*D14 -> 360 | G14: =E14*INDEX(Rangering!$B$6:$B$9,MATCH($A14,Rangering!$G$6:$G$9,0)) -> 108000 | H14: =C14-E14 -> 0 | J14: =IF(AND(E14>0,H14=0),INDEX(Rangering!$F$6:$F$9,MATCH(B14,Rangering!$A$6:$A$9,0)),"") -> 300
A15: 4 | B15: =INDEX(Rangering!$A$6:$A$9,MATCH($A15,Rangering!$G$6:$G$9,0)) -> Nybygg (prosjekt) | C15: =INDEX(Rangering!$E$6:$E$9,MATCH($A15,Rangering!$G$6:$G$9,0)) -> 40 | D15: =INDEX(Rangering!$C$6:$C$9,MATCH($A15,Rangering!$G$6:$G$9,0)) -> 9 | E15: =MIN(C15,INT(($B$5-SUM($F$11:F14))/D15)) -> 13 | F15: =E15*D15 -> 117 | G15: =E15*INDEX(Rangering!$B$6:$B$9,MATCH($A15,Rangering!$G$6:$G$9,0)) -> 27300 | H15: =C15-E15 -> 27 | J15: =IF(AND(E15>0,H15=0),INDEX(Rangering!$F$6:$F$9,MATCH(B15,Rangering!$A$6:$A$9,0)),"")
B16: = Sum | F16: =SUM(F12:F15) -> 1197 | G16: =SUM(G12:G15) -> 424800 | H16: =SUM(H12:H15) -> 27
B17: Ubrukte montørtimer | F17: =$B$5-F16 -> 3
A18: 3 · Fella — rangert per dekningsbidrag per oppdrag
B19: Den store jobben først. Det er slik de fleste ordrebøker fylles.
A20: Rang | B20: Oppdragstype | C20: Etterspørsel | D20: Timer per oppdrag | E20: Antall som tas | F20: Timer brukt | G20: Dekningsbidrag | H20: Avvist | I20: Kommentar
A21: 1 | B21: =INDEX(Rangering!$A$6:$A$9,MATCH($A21,Rangering!$J$6:$J$9,0)) -> Solcelleanlegg | C21: =INDEX(Rangering!$E$6:$E$9,MATCH($A21,Rangering!$J$6:$J$9,0)) -> 30 | D21: =INDEX(Rangering!$C$6:$C$9,MATCH($A21,Rangering!$J$6:$J$9,0)) -> 14 | E21: =MIN(C21,INT(($B$5-SUM($F$20:F20))/D21)) -> 30 | F21: =E21*D21 -> 420 | G21: =E21*INDEX(Rangering!$B$6:$B$9,MATCH($A21,Rangering!$J$6:$J$9,0)) -> 132000 | H21: =C21-E21 -> 0
A22: 2 | B22: =INDEX(Rangering!$A$6:$A$9,MATCH($A22,Rangering!$J$6:$J$9,0)) -> Nybygg (prosjekt) | C22: =INDEX(Rangering!$E$6:$E$9,MATCH($A22,Rangering!$J$6:$J$9,0)) -> 40 | D22: =INDEX(Rangering!$C$6:$C$9,MATCH($A22,Rangering!$J$6:$J$9,0)) -> 9 | E22: =MIN(C22,INT(($B$5-SUM($F$20:F21))/D22)) -> 40 | F22: =E22*D22 -> 360 | G22: =E22*INDEX(Rangering!$B$6:$B$9,MATCH($A22,Rangering!$J$6:$J$9,0)) -> 84000 | H22: =C22-E22 -> 0
A23: 3 | B23: =INDEX(Rangering!$A$6:$A$9,MATCH($A23,Rangering!$J$6:$J$9,0)) -> Ladepunkt | C23: =INDEX(Rangering!$E$6:$E$9,MATCH($A23,Rangering!$J$6:$J$9,0)) -> 150 | D23: =INDEX(Rangering!$C$6:$C$9,MATCH($A23,Rangering!$J$6:$J$9,0)) -> 2 | E23: =MIN(C23,INT(($B$5-SUM($F$20:F22))/D23)) -> 150 | F23: =E23*D23 -> 300 | G23: =E23*INDEX(Rangering!$B$6:$B$9,MATCH($A23,Rangering!$J$6:$J$9,0)) -> 157500 | H23: =C23-E23 -> 0
A24: 4 | B24: =INDEX(Rangering!$A$6:$A$9,MATCH($A24,Rangering!$J$6:$J$9,0)) -> Boliginstallasjon | C24: =INDEX(Rangering!$E$6:$E$9,MATCH($A24,Rangering!$J$6:$J$9,0)) -> 120 | D24: =INDEX(Rangering!$C$6:$C$9,MATCH($A24,Rangering!$J$6:$J$9,0)) -> 3 | E24: =MIN(C24,INT(($B$5-SUM($F$20:F23))/D24)) -> 40 | F24: =E24*D24 -> 120 | G24: =E24*INDEX(Rangering!$B$6:$B$9,MATCH($A24,Rangering!$J$6:$J$9,0)) -> 36000 | H24: =C24-E24 -> 80
B25: = Sum | F25: =SUM(F21:F24) -> 1200 | G25: =SUM(G21:G24) -> 409500 | H25: =SUM(H21:H24) -> 80
B26: Ubrukte montørtimer | F26: =$B$5-F25 -> 0
A28: 4 · Hva feil rangering koster
B29: Riktig plan, dekningsbidrag i måneden | C29: =G16 -> 424800
B30: Fella, dekningsbidrag i måneden | C30: =G25 -> 409500
B31: = Forskjell i måneden | C31: =C29-C30 -> 15300
B32: = Forskjell i året | C32: =C31*12 -> 183600
B33: Driftsresultat 2026 | C33: 1344000
B34: Forskjellen målt mot driftsresultatet | C34: =C32/C33 -> 0.13660714 | I34: Samme montører, samme timer, samme kunder. Bare en annen rekkefølge.
A36: 5 · Hva som faktisk gir fra seg timene
B37: Svakeste oppdragstype som er HELT dekket | C37: =INDEX($B$12:$B$15,MATCH(MIN($J$12:$J$15),$J$12:$J$15,0)) -> Boliginstallasjon | I37: Rangeringen sier rekkefølgen. Etterspørselen sier hvem som har timer å gi fra seg: de som allerede er delvis avvist, venter selv på tur.
B38: Dekningsbidrag per time for den | C38: =INDEX(Rangering!$F$6:$F$9,MATCH(C37,Rangering!$A$6:$A$9,0)) -> 300
B39: Ett nybyggoppdrag ekstra koster, mot toppen av rangeringen | C39: =INDEX(Rangering!$C$6:$C$9,MATCH("Nybygg (prosjekt)",Rangering!$A$6:$A$9,0))*MAX(Rangering!$F$6:$F$9)-INDEX(Rangering!$B$6:$B$9,MATCH("Nybygg (prosjekt)",Rangering!$A$6:$A$9,0)) -> 2625
B40: Ett nybyggoppdrag ekstra koster, mot den som faktisk gir fra seg timene | C40: =INDEX(Rangering!$C$6:$C$9,MATCH("Nybygg (prosjekt)",Rangering!$A$6:$A$9,0))*C38-INDEX(Rangering!$B$6:$B$9,MATCH("Nybygg (prosjekt)",Rangering!$A$6:$A$9,0)) -> 600 | I40: Dette er tallet du skal ta med i en forhandling — ikke det over.
A42: Kontroll
B43: Holder planen seg innenfor kapasiteten? | C43: =IF(AND(F16<=$B$5,F25<=$B$5),"OK — begge planene holder seg innenfor de montørtimene dere har","AVVIK: en av planene bruker flere timer enn kapasiteten") -> OK — begge planene holder seg innenfor de montørtimene dere har
B44: Er den riktige planen faktisk best? | C44: =IF(G16>=G25,"OK — rangering per montørtime gir minst like mye dekningsbidrag som rangering per oppdrag","AVVIK: da er noe galt med rangeringen") -> OK — rangering per montørtime gir minst like mye dekningsbidrag som rangering per oppdrag
B45: Tar planen aldri flere enn det finnes forespørsler av? | C45: =IF(MIN(H12:H15,H21:H24)>=0,"OK — ingen oppdragstype er tatt flere ganger enn den er etterspurt","AVVIK: planen tar flere oppdrag enn kundene har bedt om") -> OK — ingen oppdragstype er tatt flere ganger enn den er etterspurt
...

Sheet Materiell knapp
A1: Når det er materiellet som mangler
A2: Samme måned, samme montører — men grossisten kan ikke levere mer.
A4: 1 · De to takene
B5: Materiellramme i måneden | C5: 2140000 | I5: Varelageret ved månedsstart pluss det Polarlys Elektro Grossist AS kan levere.
B6: Montørtimer i måneden | C6: =Produktvalg!B5 -> 1200
B7: Etterspurt materiell | C7: =Rangering!D12 -> 3475000
B8: Underdekning i materiell | C8: =C7-C5 -> 1335000
A10: 2 · Riktig plan — rangert per dekningsbidrag per materiellkrone
B11: Nå er det kronene hos grossisten som er knappe, ikke timene.
A12: Rang | B12: Oppdragstype | C12: Etterspørsel | D12: Materiell per oppdrag | E12: Antall som tas | F12: Materiell brukt | G12: Dekningsbidrag | H12: Timer brukt | I12: Kommentar
A13: 1 | B13: =INDEX(Rangering!$A$6:$A$9,MATCH($A13,Rangering!$I$6:$I$9,0)) -> Boliginstallasjon | C13: =INDEX(Rangering!$E$6:$E$9,MATCH($A13,Rangering!$I$6:$I$9,0)) -> 120 | D13: =INDEX(Rangering!$D$6:$D$9,MATCH($A13,Rangering!$I$6:$I$9,0)) -> 4000 | E13: =MIN(C13,INT(($C$5-SUM($F$12:F12))/D13),INT(($C$6-SUM($H$12:H12))/INDEX(Rangering!$C$6:$C$9,MATCH($A13,Rangering!$I$6:$I$9,0)))) -> 120 | F13: =E13*D13 -> 480000 | G13: =E13*INDEX(Rangering!$B$6:$B$9,MATCH($A13,Rangering!$I$6:$I$9,0)) -> 108000 | H13: =E13*INDEX(Rangering!$C$6:$C$9,MATCH($A13,Rangering!$I$6:$I$9,0)) -> 360
A14: 2 | B14: =INDEX(Rangering!$A$6:$A$9,MATCH($A14,Rangering!$I$6:$I$9,0)) -> Ladepunkt | C14: =INDEX(Rangering!$E$6:$E$9,MATCH($A14,Rangering!$I$6:$I$9,0)) -> 150 | D14: =INDEX(Rangering!$D$6:$D$9,MATCH($A14,Rangering!$I$6:$I$9,0)) -> 6500 | E14: =MIN(C14,INT(($C$5-SUM($F$12:F13))/D14),INT(($C$6-SUM($H$12:H13))/INDEX(Rangering!$C$6:$C$9,MATCH($A14,Rangering!$I$6:$I$9,0)))) -> 150 | F14: =E14*D14 -> 975000 | G14: =E14*INDEX(Rangering!$B$6:$B$9,MATCH($A14,Rangering!$I$6:$I$9,0)) -> 157500 | H14: =E14*INDEX(Rangering!$C$6:$C$9,MATCH($A14,Rangering!$I$6:$I$9,0)) -> 300
A15: 3 | B15: =INDEX(Rangering!$A$6:$A$9,MATCH($A15,Rangering!$I$6:$I$9,0)) -> Solcelleanlegg | C15: =INDEX(Rangering!$E$6:$E$9,MATCH($A15,Rangering!$I$6:$I$9,0)) -> 30 | D15: =INDEX(Rangering!$D$6:$D$9,MATCH($A15,Rangering!$I$6:$I$9,0)) -> 38000 | E15: =MIN(C15,INT(($C$5-SUM($F$12:F14))/D15),INT(($C$6-SUM($H$12:H14))/INDEX(Rangering!$C$6:$C$9,MATCH($A15,Rangering!$I$6:$I$9,0)))) -> 18 | F15: =E15*D15 -> 684000 | G15: =E15*INDEX(Rangering!$B$6:$B$9,MATCH($A15,Rangering!$I$6:$I$9,0)) -> 79200 | H15: =E15*INDEX(Rangering!$C$6:$C$9,MATCH($A15,Rangering!$I$6:$I$9,0)) -> 252
A16: 4 | B16: =INDEX(Rangering!$A$6:$A$9,MATCH($A16,Rangering!$I$6:$I$9,0)) -> Nybygg (prosjekt) | C16: =INDEX(Rangering!$E$6:$E$9,MATCH($A16,Rangering!$I$6:$I$9,0)) -> 40 | D16: =INDEX(Rangering!$D$6:$D$9,MATCH($A16,Rangering!$I$6:$I$9,0)) -> 22000 | E16: =MIN(C16,INT(($C$5-SUM($F$12:F15))/D16),INT(($C$6-SUM($H$12:H15))/INDEX(Rangering!$C$6:$C$9,MATCH($A16,Rangering!$I$6:$I$9,0)))) -> 0 | F16: =E16*D16 -> 0 | G16: =E16*INDEX(Rangering!$B$6:$B$9,MATCH($A16,Rangering!$I$6:$I$9,0)) -> 0 | H16: =E16*INDEX(Rangering!$C$6:$C$9,MATCH($A16,Rangering!$I$6:$I$9,0)) -> 0
B17: = Sum | F17: =SUM(F13:F16) -> 2139000 | G17: =SUM(G13:G16) -> 344700 | H17: =SUM(H13:H16) -> 912
B18: Ubrukte montørtimer | H18: =$C$6-H17 -> 288
A19: 3 · Samme måned, men rangert per montørtime
B20: Riktig metode, feil måltall. Det er den vanligste feilen når flaskehalsen flytter seg.
A21: Rang | B21: Oppdragstype | C21: Etterspørsel | D21: Materiell per oppdrag | E21: Antall som tas | F21: Materiell brukt | G21: Dekningsbidrag | H21: Timer brukt | I21: Kommentar
A22: 1 | B22: =INDEX(Rangering!$A$6:$A$9,MATCH($A22,Rangering!$G$6:$G$9,0)) -> Ladepunkt | C22: =INDEX(Rangering!$E$6:$E$9,MATCH($A22,Rangering!$G$6:$G$9,0)) -> 150 | D22: =INDEX(Rangering!$D$6:$D$9,MATCH($A22,Rangering!$G$6:$G$9,0)) -> 6500 | E22: =MIN(C22,INT(($C$5-SUM($F$21:F21))/D22),INT(($C$6-SUM($H$21:H21))/INDEX(Rangering!$C$6:$C$9,MATCH($A22,Rangering!$G$6:$G$9,0)))) -> 150 | F22: =E22*D22 -> 975000 | G22: =E22*INDEX(Rangering!$B$6:$B$9,MATCH($A22,Rangering!$G$6:$G$9,0)) -> 157500 | H22: =E22*INDEX(Rangering!$C$6:$C$9,MATCH($A22,Rangering!$G$6:$G$9,0)) -> 300
A23: 2 | B23: =INDEX(Rangering!$A$6:$A$9,MATCH($A23,Rangering!$G$6:$G$9,0)) -> Solcelleanlegg | C23: =INDEX(Rangering!$E$6:$E$9,MATCH($A23,Rangering!$G$6:$G$9,0)) -> 30 | D23: =INDEX(Rangering!$D$6:$D$9,MATCH($A23,Rangering!$G$6:$G$9,0)) -> 38000 | E23: =MIN(C23,INT(($C$5-SUM($F$21:F22))/D23),INT(($C$6-SUM($H$21:H22))/INDEX(Rangering!$C$6:$C$9,MATCH($A23,Rangering!$G$6:$G$9,0)))) -> 30 | F23: =E23*D23 -> 1140000 | G23: =E23*INDEX(Rangering!$B$6:$B$9,MATCH($A23,Rangering!$G$6:$G$9,0)) -> 132000 | H23: =E23*INDEX(Rangering!$C$6:$C$9,MATCH($A23,Rangering!$G$6:$G$9,0)) -> 420
A24: 3 | B24: =INDEX(Rangering!$A$6:$A$9,MATCH($A24,Rangering!$G$6:$G$9,0)) -> Boliginstallasjon | C24: =INDEX(Rangering!$E$6:$E$9,MATCH($A24,Rangering!$G$6:$G$9,0)) -> 120 | D24: =INDEX(Rangering!$D$6:$D$9,MATCH($A24,Rangering!$G$6:$G$9,0)) -> 4000 | E24: =MIN(C24,INT(($C$5-SUM($F$21:F23))/D24),INT(($C$6-SUM($H$21:H23))/INDEX(Rangering!$C$6:$C$9,MATCH($A24,Rangering!$G$6:$G$9,0)))) -> 6 | F24: =E24*D24 -> 24000 | G24: =E24*INDEX(Rangering!$B$6:$B$9,MATCH($A24,Rangering!$G$6:$G$9,0)) -> 5400 | H24: =E24*INDEX(Rangering!$C$6:$C$9,MATCH($A24,Rangering!$G$6:$G$9,0)) -> 18
A25: 4 | B25: =INDEX(Rangering!$A$6:$A$9,MATCH($A25,Rangering!$G$6:$G$9,0)) -> Nybygg (prosjekt) | C25: =INDEX(Rangering!$E$6:$E$9,MATCH($A25,Rangering!$G$6:$G$9,0)) -> 40 | D25: =INDEX(Rangering!$D$6:$D$9,MATCH($A25,Rangering!$G$6:$G$9,0)) -> 22000 | E25: =MIN(C25,INT(($C$5-SUM($F$21:F24))/D25),INT(($C$6-SUM($H$21:H24))/INDEX(Rangering!$C$6:$C$9,MATCH($A25,Rangering!$G$6:$G$9,0)))) -> 0 | F25: =E25*D25 -> 0 | G25: =E25*INDEX(Rangering!$B$6:$B$9,MATCH($A25,Rangering!$G$6:$G$9,0)) -> 0 | H25: =E25*INDEX(Rangering!$C$6:$C$9,MATCH($A25,Rangering!$G$6:$G$9,0)) -> 0
B26: = Sum | F26: =SUM(F22:F25) -> 2139000 | G26: =SUM(G22:G25) -> 294900 | H26: =SUM(H22:H25) -> 738
B27: Ubrukte montørtimer | H27: =$C$6-H26 -> 462
A29: 4 · Hva feil måltall koster
B30: Rangert per materiellkrone | C30: =G17 -> 344700
B31: Rangert per montørtime | C31: =G26 -> 294900
B32: = Forskjell i måneden | C32: =C30-C31 -> 49800
B33: Montørtimer som står ubrukt i den riktige planen | C33: =H18 -> 288 | I33: Ubrukte timer er ikke et tegn på at planen er feil. Det er materiellet som er knapt nå, og da er det materiellkronene som skal utnyttes.
A35: Kontroll
B36: Holder planen seg innenfor materiellrammen? | C36: =IF(AND(F17<=$C$5+1,F26<=$C$5+1),"OK — begge planene holder seg innenfor det grossisten kan levere","AVVIK: en av planene kjøper mer materiell enn rammen tillater") -> OK — begge planene holder seg innenfor det grossisten kan levere
B37: Gir riktig måltall mest dekningsbidrag? | C37: =IF(G17>=G26,"OK — når materiellet er knapt, er det dekningsbidrag per materiellkrone som skal styre","AVVIK: sjekk rangeringen i kolonne I i arket Rangering") -> OK — når materiellet er knapt, er det dekningsbidrag per materiellkrone som skal styre
B38: Står det montørtimer ubrukt? | C38: =IF(H18>0,"OK — det står montørtimer ubrukt, og det skal det: flaskehalsen er materiellet, ikke timene","AVVIK: begge ressursene er brukt opp — da er det to knappe faktorer, og metoden i kapittel 7 rekker ikke til") -> OK — det står montørtimer ubrukt, og det skal det: flaskehalsen er materiellet, ikke timene
A40: Kilde: Bok 1 kap. 7.3 om flere knappe faktorer og om produkter som bidrar til salget av andre.

Sheet Scenario
A1: To rammeavtaler om de samme timene
A2: Oppgave 5 i øvingsheftet. Begge kan ikke tas. Regn først, drøft etterpå.
A4: 1 · De to tilbudene
A5: Montørtimer avtalen legger beslag på, i året | B5: 3600 | E5: Begge avtalene ber om like mange timer. Det er derfor de kan sammenliknes rett fram.
A6: Fakturerte montørtimer i året | B6: 14400
A7: Andel av kapasiteten | B7: =B5/B6 -> 0.25
B9: Avtale A · Kystfiber Entreprenør AS | C9: Avtale B · Kraftpunkt Ladedrift AS | E9: Hva raden betyr
A10: Oppdragstype | B10: =INDEX(Rangering!$A$6:$A$9,MATCH("Nybygg (prosjekt)",Rangering!$A$6:$A$9,0)) -> Nybygg (prosjekt) | C10: =INDEX(Rangering!$A$6:$A$9,MATCH("Ladepunkt",Rangering!$A$6:$A$9,0)) -> Ladepunkt
A11: Montørtimer per oppdrag | B11: =INDEX(Rangering!$C$6:$C$9,MATCH(B10,Rangering!$A$6:$A$9,0)) -> 9 | C11: =INDEX(Rangering!$C$6:$C$9,MATCH(C10,Rangering!$A$6:$A$9,0)) -> 2
A12: Dekningsbidrag per oppdrag | B12: =INDEX(Rangering!$B$6:$B$9,MATCH(B10,Rangering!$A$6:$A$9,0)) -> 2100 | C12: =INDEX(Rangering!$B$6:$B$9,MATCH(C10,Rangering!$A$6:$A$9,0)) -> 1050
A13: Antall oppdrag timene rekker til | B13: =INT($B$5/B11) -> 400 | C13: =INT($B$5/C11) -> 1800
A14: Dekningsbidrag per montørtime | B14: =B12/B11 -> 233.33333 | C14: =C12/C11 -> 525
A15: = Dekningsbidrag i året | B15: =B13*B12 -> 840000 | C15: =C13*C12 -> 1890000
A16: Forskjell | C16: =C15-B15 -> 1050000 | E16: Dette er prisen på å velge feil, ett år.
A17: Driftsresultat 2026 | B17: =Produktvalg!C33 -> 1344000
A18: Forskjellen målt mot driftsresultatet | C18: =C16/B17 -> 0.78125
A20: 2 · Hvor mye tåler prisen?
A21: Prisen Nordlys tar for ett ladepunkt, uten mva. | B21: 8830 | E21: Nordlys' egen pris, den samme som i kapittel 2.
A22: Variabel enhetskostnad — materiell og montørlønn | B22: 7780
A23: Dekningsbidrag per ladepunkt | B23: =B21-B22 -> 1050 | E23: Skal stemme med C12 over. Kontrollen under sier fra hvis den ikke gjør det.
A24: Dekningsbidrag per time hvis kunden får rabatt
A25: Rabatt kunden krever, i kroner | B25: 0 | E25: Endre denne og se når ladepunktet slutter å være det beste valget.
A26: Dekningsbidrag etter rabatt | B26: =B23-B25 -> 1050
A27: Dekningsbidrag per montørtime etter rabatt | B27: =B26/C11 -> 525
A28: = Rabatt før nybyggavtalen blir best | B28: =C12-B14*C11 -> 583.33333 | C28: =B28/B21 -> 0.066062665 | E28: Så lite skal det til. Kolonne C viser rabatten som andel av prisen.
A29: Rabatt før dekningsbidraget er null | B29: =B23 -> 1050 | C29: =B29/B21 -> 0.1189128
A30: Dom | E30: =IF(B27>B14,"Ladepunktet er fortsatt best per montørtime",IF(B26<=0,"Dekningsbidraget er borte — si nei","Nybyggavtalen er nå best per montørtime")) -> Ladepunktet er fortsatt best per montørtime
A32: 3 · Hvor mye tåler volumet?
A33: Andel av avtalt volum som uteblir | B33: 0.4 | E33: Den nye kunden er ikke prøvd før. Hva om han ikke leverer?
A34: Dekningsbidrag hvis de ledige timene står ubrukt | B34: =C15*(1-B33) -> 1134000
A35: Ledige montørtimer | B35: =$B$5*B33 -> 1440
A36: Dekningsbidrag hvis de ledige timene selges som nybygg | B36: =B34+B35*B14 -> 1470000
A37: = Svikt før nybyggavtalen blir best | B37: =1-B15/C15 -> 0.55555556 | E37: Gjelder om timene står helt ubrukt. Kan de selges, tåler avtalen mer.
A39: Kontroll
A40: Stemmer dekningsbidraget med pris minus kostnad? | B40: =IF(ABS(B23-C12)<1,"OK — pris minus variabel enhetskostnad gir samme dekningsbidrag som oppdragstypen i arket Rangering","AVVIK: prisen eller enhetskostnaden i B21 og B22 stemmer ikke med dekningsbidraget i arket Rangering") -> OK — pris minus variabel enhetskostnad gir samme dekningsbidrag som oppdragstypen i arket Rangering
A41: Er de to avtalene sammenliknbare? | B41: =IF(AND(B13*B11<=B5,C13*C11<=B5),"OK — begge avtalene holder seg innenfor de timene som er satt av","AVVIK: en av avtalene krever flere timer enn B5") -> OK — begge avtalene holder seg innenfor de timene som er satt av
A42: Tåler ladeavtalen den volumsvikten scenariet beskriver? | B42: =IF(B34>B15,"OK — selv med denne svikten, og selv om de ledige timene står helt ubrukt, gir ladeavtalen mest","AVVIK: med denne svikten er nybyggavtalen best — da er volumrisikoen det avgjørende, ikke prisen") -> OK — selv med denne svikten, og selv om de ledige timene står helt ubrukt, gir ladeavtalen mest
A44: Legg merke til forskjellen på de to risikoene: volumet må svikte med over halvparten før valget snur, mens en rabatt på under sju prosent av prisen gjør det. Det er prisen dere skal forhandle om, ikke volumgarantien.
A45: Kilde: Bok 1 kap. 7.2 og 7.3. Prisen på ladepunktet er Nordlys' egen, den samme som i kapittel 2 om priselastisitet. Bransjetall: NHO Elektro, Lønnsomhetsrapport 2025, gjengitt i Elektro 24-7 19.08.2026 (hentet 10.09.2026). De 809 er bedriftene i datagrunnlaget, ikke bransjen. NHO Elektro oppgir ikke svarprosent.

Sheet Din bedrift
A1: Din egen bedrift
A2: Samme oppsett, ingen tall. Legg inn dine egne oppdragstyper.
A5: Oppdragstype | B5: DB per oppdrag | C5: Timer | D5: Materiell, kr | E5: Etterspørsel | F5: DB per time | G5: Rang | H5: DB per materiellkrone | I5: Rang | J5: Merknad
B6: 0 | C6: 0 | D6: 0 | E6: 0 | F6: =IF(C6=0,"",B6/C6) | G6: =IF(C6=0,"",RANK(F6,$F$6:$F$10)) | H6: =IF(D6=0,"",B6/D6) | I6: =IF(D6=0,"",RANK(H6,$H$6:$H$10))
B7: 0 | C7: 0 | D7: 0 | E7: 0 | F7: =IF(C7=0,"",B7/C7) | G7: =IF(C7=0,"",RANK(F7,$F$6:$F$10)) | H7: =IF(D7=0,"",B7/D7) | I7: =IF(D7=0,"",RANK(H7,$H$6:$H$10))
B8: 0 | C8: 0 | D8: 0 | E8: 0 | F8: =IF(C8=0,"",B8/C8) | G8: =IF(C8=0,"",RANK(F8,$F$6:$F$10)) | H8: =IF(D8=0,"",B8/D8) | I8: =IF(D8=0,"",RANK(H8,$H$6:$H$10))
B9: 0 | C9: 0 | D9: 0 | E9: 0 | F9: =IF(C9=0,"",B9/C9) | G9: =IF(C9=0,"",RANK(F9,$F$6:$F$10)) | H9: =IF(D9=0,"",B9/D9) | I9: =IF(D9=0,"",RANK(H9,$H$6:$H$10))
B10: 0 | C10: 0 | D10: 0 | E10: 0 | F10: =IF(C10=0,"",B10/C10) | G10: =IF(C10=0,"",RANK(F10,$F$6:$F$10)) | H10: =IF(D10=0,"",B10/D10) | I10: =IF(D10=0,"",RANK(H10,$H$6:$H$10))
A12: Kapasitet i perioden, timer | B12: 0
A13: Etterspurte timer | B13: =SUMPRODUCT(C6:C10,E6:E10) -> 0
A14: Underdekning | B14: =B13-B12 -> 0
A15: Er timene den knappe faktoren? | J15: =IF(B12=0,"Fyll inn kapasiteten i B12",IF(B14>0,"Ja — det er flere forespørsler enn timer. Følg rangeringen i kolonne G","Nei — det er timer nok til alle. Ta alt som gir positivt dekningsbidrag")) -> Fyll inn kapasiteten i B12
A17: Kontroll
A18: Er arket fylt ut? | B18: =IF(SUM(B6:B10)=0,"AVVIK: fyll inn dekningsbidrag og timer for dine egne oppdragstyper","OK — arket rangerer dine egne oppdragstyper") -> AVVIK: fyll inn dekningsbidrag og timer for dine egne oppdragstyper
A19: Dette arket starter tomt, så kontrollen står på AVVIK til du har fylt inn tallene.
A20: Er alle dekningsbidrag positive? | B20: =IF(SUM(B6:B10)=0,"OK — ingen tall lagt inn ennå",IF(MIN(B6:B10)>=0,"OK — alle oppdragstyper gir positivt dekningsbidrag","AVVIK: en oppdragstype med negativt dekningsbidrag skal droppes, ikke rangeres")) -> OK — ingen tall lagt inn ennå
A22: Ta arket med på jobb. Det eneste du trenger å vite, er hva hver oppdragstype gir i dekningsbidrag og hvor mye den bruker av det du har minst av.
