Workbook

Sheet Veiledning
A1: Kapitalbehov og finansiering
A2: LØM Økonomistyring kap. 6 · arbeidsregneark · Fagskolen Oslo, Avdeling Elkraft
A3: Emne: Teknisk kommunikasjon og ledelse for 1ET-klassene · LØM for 2ET, 2EK, 3EK og 4EK
A4: Fargekode
A5: Gul celle med blå skrift | B5: Inndata — dette er tallene du endrer.
A6: Grå eller lyseblå celle, svart skrift | B6: Formel — regner seg selv. Ikke skriv over den.
A7: Mørkeblå rad med hvit skrift | B7: Kolonneoverskrift.
A9: Ark i arbeidsboka
A10: Kapitalbehov | B10: Kalkulatoren. Investeringer, salg, lagringstid og kredittid inn — kapitalbehovet ut. Kapitalbehovet står i B31, og de andre arkene henter det derfra.
A11: Kredittid | B11: Hva kapitalbehovet blir ved ulik betalingsfrist til kundene. Kapitlets viktigste tabell.
A12: Finansiering | B12: Kapitalbehovet sett fra den andre siden: egenkapital, langsiktig gjeld, kortsiktig gjeld og åpningsbalansen som må balansere.
A13: Scenario | B13: Tre spørsmål: hva lengre kredittid koster, hvordan gründerne kommer over bankens krav, og hvorfor kontoen er tom når ordreboka er full.
A14: Din bedrift | B14: Samme oppsett, tomt. Legg inn tallene for din egen bedrift.
A16: Tallene som ligger inne er oppstarten av Nordlys Elektro AS i 2019, den samme bedriften du møter i kapittel 1, 3 og 9.
A17: Kundefordringer og leverandørgjeld regnes INKLUDERT mva., fordi det er beløpene som faktisk står ubetalt.
A18: Varelageret regnes UTEN mva., fordi inngående merverdiavgift får bedriften igjen.
A19: Året settes til 360 dager, tolv måneder à tretti — det er lærebokas konvensjon.
A21: Tallene som ligger inne er et eksempel fra en elektrobedrift. Bytt dem ut med dine egne — alle formler følger med.
A22: Arbeidsregneark til LØM · Fagskolen Oslo, Avdeling Elkraft. Regnearket er øvingsstøtte, ikke et regnskapssystem.
A24: De to knappene
A25: Kapitalbehov!B23 | B25: Kredittid til kundene | C25: Den dyreste dagen i bedriften. Endre den og se hele arbeidsboka flytte seg.
A26: Finansiering!B20 | B26: Egenkapitalen eierne har | C26: Endrer egenkapitalandelen i B21 og dommen i E24.
A28: Hvilken oppgave bruker hvilket ark
A29: Oppgave i øvingsheftet | B29: Ark | C29: Celler du endrer og leser av
A30: A1 · Anbudskunden vil ha 40 dager | B30: Scenario | C30: Scenario A: endre C8 og les av C9, C10, C11 og C12.
A31: A2 · Klasseoppgave: dere mangler 162 500 kroner | B31: Scenario | C31: Scenario B: endre D24, og egenkapitalen i Finansiering!B20. Les av rad 28, 30 og 33.
A32: 1 · Kapitalbehovet ved oppstart | B32: Kapitalbehov | C32: Endre B5, B6, B10, B13, B16, B21, B23 og B25. Les av B14, B22, B24, B26, B31 og B32.
A33: 2 · Finansieringsplan og åpningsbalanse | B33: Finansiering | C33: Endre B5, B6 og B7. Les av B11, B13, B15, B16 og B17. Åpningsbalansen står i rad 28 til 33.
A34: 3 · Hva kredittiden og leverandørkreditten koster | B34: Kredittid | C34: Les hele tabellen. Lagringstida endrer du i Kapitalbehov!B21, leverandørkreditten i Finansiering!B7.
A35: 4 · Kjøpe eller lease servicebilen? | B35: Scenario | C35: Scenario B: sett Kapitalbehov!B6 til null for leasing, og prøv deg fram med lagringstida i D24. Taket for kapitalbehovet står i Finansiering!B23.
A36: 5 · Eksamensnær: full ordrebok, tom konto | B36: Scenario | C36: Scenario C: endre B69 og les av B56, B59, B66, B71, B72, B73 og B79.
A38: Kontrollradene
A39: Hvert regneark har en kontrollblokk. Står det OK, henger tallene sammen. Står det AVVIK, farges cellen rød, og teksten sier hva som ikke går opp.
A40: To unntak: kontrollen i Scenario B84 skal vise AVVIK med tallene som ligger inne — der er avviket selve svaret. Og arket «Din bedrift» står på AVVIK til du har fylt inn dine egne tall.
A41: Kontroller i arbeidsboka: Kapitalbehov B35, Kapitalbehov B36, Kapitalbehov B37, Kredittid C27, Kredittid C28, Kredittid C29, Finansiering B36, Finansiering B37, Finansiering B38, Finansiering B39, Scenario B16, Scenario B36, Scenario B38, Scenario B82, Scenario B83, Scenario B84, Din bedrift B39, Din bedrift B41
A43: Slik henger kapitlene sammen
A44: Kapitalbehovet i 2019 blir til balansen du leser i kapittel 3. Kredittiden du setter her, er den samme kredittiden som avgjør om likviditetsbudsjettet i kapittel 9 går i pluss. Og timeprisen fra kapittel 5 avgjør hvor fort pengene kommer inn igjen.
A46: Kilder
A47: Hjertnes, J. og Skorpen, K.: Økonomistyring for LØM-emnet (ISBN 978-82-450-5544-3), kapittel 6 «Kapitalbehov og finansiering», avsnitt 6.1 til 6.3, 6.5 og 6.7. Merverdiavgiftssatser: merverdiavgiftsloven kapittel 5 (Lovdata).
A48: Bransjetall: NHO Elektro, Lønnsomhetsrapport 2025, gjengitt i Elektro 24-7 19.08.2026 (hentet 10.09.2026). De 809 er bedriftene i datagrunnlaget, ikke bransjen. NHO Elektro oppgir ikke svarprosent.
...

Sheet Kapitalbehov
A1: Hvor mye penger må du ha før du åpner?
A2: Endre de gule cellene. Alt annet regner seg selv.
A4: 1 · Investeringene — det du kjøper og eier
A5: Verktøy, utstyr og inventar | B5: 850000 | D5: Engangsutlegget. Dette er tallet gründeren husker, fordi det står på en faktura.
A6: Biler og maskiner | B6: 480000 | D6: Servicebilen. Leases den i stedet for å kjøpes, settes beløpet til null.
A7: = Sum anleggsmidler | B7: =B5+B6
A9: 2 · Forutsetningene for driften
A10: Budsjettert salg første år, inkl. mva. | B10: 9000000 | D10: Står det «inkl. mva.» i oppgaveteksten, må mva. ut før bruttofortjenesten regnes.
A11: Merverdiavgiftssats | B11: 0.25
A12: Salgsinntekt uten mva. | B12: =B10/(1+B11)
A13: Budsjettert bruttofortjeneste | B13: 0.45 | D13: Det som blir igjen av salget etter varekostnaden.
A14: = Varekostnad for året | B14: =B12*(1-B13) | D14: Uten mva. Varelageret regnes av dette tallet.
A15: Varekjøp inkl. mva. | B15: =B14*(1+B11) | D15: Med mva. Leverandørgjelda regnes av dette tallet — det er det du faktisk skylder.
A16: Andel av salget som skjer på kreditt | B16: 0.25
A17: Kredittsalg inkl. mva. | B17: =B10*B16 | D17: Kundefordringene regnes av dette. Kunden skylder deg beløpet med mva.
A18: Dager i året | B18: 360 | D18: Lærebokas bankår: tolv måneder à tretti dager.
A20: 3 · Kapitalbindingen i driften
A21: Lagringstid, dager | B21: 20 | D21: Hvor lenge materiellet i snitt ligger på lager før det er montert.
A22: Varelager | B22: =B14*B21/B18
A23: Kredittid til kundene, dager | B23: 20 | D23: Betalingsfristen du gir. Dette er et rentefritt lån til kunden.
A24: Kundefordringer | B24: =B17*B23/B18
A25: Likviditetsreserve | B25: 200000 | D25: Pengene som skal ligge der når en stor kunde betaler for seint.
A26: = Driftskapitalbehov | B26: =B22+B24+B25 | D26: Penger som ikke kjøper noe som helst. De skal bare være der.
A28: 4 · Samlet kapitalbehov
A29: Investeringskapitalbehov (anleggsmidler) | B29: =B7
A30: Driftskapitalbehov | B30: =B26
A31: = KAPITALBEHOV | B31: =B29+B30 | D31: Dette er tallet arkene Kredittid, Finansiering og Scenario henter.
A32: Driftens andel av kapitalbehovet | B32: =B30/B31 | D32: Det er denne andelen nystartede bedrifter undervurderer.
A34: Kontroll
A35: Summerer postene seg til kapitalbehovet? | B35: =IF(ABS(B7+B22+B24+B25-B31)<1,"OK — anleggsmidler, varelager, kundefordringer og reserve summerer seg til kapitalbehovet","AVVIK: postene summerer seg ikke til kapitalbehovet")
A36: Er merverdiavgiften behandlet riktig? | B36: =IF(ABS(B12*(1+B11)-B10)<1,"OK — salgsinntekten uten mva. ganget opp med satsen gir salget inkl. mva.","AVVIK: mva.-omregningen stemmer ikke")
A37: Er forutsetningene mulige? | B37: =IF(AND(B13>0,B13<1,B16>=0,B16<=1,B21>=0,B23>=0,B18>0),"OK — bruttofortjeneste og kredittandel ligger mellom null og hundre prosent, og dagene er ikke negative","AVVIK: en av forutsetningene er umulig — sjekk prosentene og dagene")
A39: Hva én dag koster
A40: Én dag lengre kredittid til kundene binder | B40: =B17/B18 | D40: Kredittsalget delt på dagene i året.
A41: Én dag lengre lagringstid binder | B41: =B14/B18 | D41: Varekostnaden delt på dagene i året.
A43: Prøv dette: sett kredittiden i B23 til 40 dager og se hva som skjer med B31. Det er oppgave A1 i øvingsheftet.
A44: Kilde: Bok 1 kap. 6.1 med underavsnitt. Tallene er oppstarten av Nordlys Elektro AS i 2019.

Sheet Kredittid
A1: Hva kredittiden gjør med kapitalbehovet
A2: Samme bedrift, samme salg, samme lager — bare en annen betalingsfrist.
A4: Hentes fra arket Kapitalbehov
A5: Kredittsalg inkl. mva. | B5: =Kapitalbehov!B17
A6: Dager i året | B6: =Kapitalbehov!B18
A7: Kapitalbehov uten kundefordringer | B7: =Kapitalbehov!B31-Kapitalbehov!B24 | F7: Anleggsmidler, varelager og likviditetsreserve. Endrer seg ikke med kredittiden.
A8: Kredittiden du bruker i dag | B8: =Kapitalbehov!B23
A9: Egenkapitalkrav fra banken | B9: =Finansiering!B5
A11: Kredittid, dager | B11: Kundefordringer | C11: Kapitalbehov | D11: Endring fra i dag | E11: Egenkapitalkrav | F11: Hva raden betyr
A12: 0 | B12: =$B$5*A12/$B$6 | C12: =$B$7+B12 | D12: =C12-($B$7+$B$5*$B$8/$B$6) | E12: =C12*$B$9 | F12: Alt kontant. Ingen kapital bundet hos kundene — og ingen næringskunder.
A13: 10 | B13: =$B$5*A13/$B$6 | C13: =$B$7+B13 | D13: =C13-($B$7+$B$5*$B$8/$B$6) | E13: =C13*$B$9 | F13: Kort frist. Vanlig for småjobber som faktureres på stedet.
A14: 20 | B14: =$B$5*A14/$B$6 | C14: =$B$7+B14 | D14: =C14-($B$7+$B$5*$B$8/$B$6) | E14: =C14*$B$9 | F14: Vanlig avtalt betalingsfrist i bransjen.
A15: =$B$8 | B15: =$B$5*A15/$B$6 | C15: =$B$7+B15 | D15: =C15-($B$7+$B$5*$B$8/$B$6) | E15: =C15*$B$9 | F15: Nordlys i 2019.
A16: 30 | B16: =$B$5*A16/$B$6 | C16: =$B$7+B16 | D16: =C16-($B$7+$B$5*$B$8/$B$6) | E16: =C16*$B$9 | F16: En måned. Vanlig krav fra større byggherrer.
A17: 40 | B17: =$B$5*A17/$B$6 | C17: =$B$7+B17 | D17: =C17-($B$7+$B$5*$B$8/$B$6) | E17: =C17*$B$9 | F17: Anbudskunden i økta. Kundefordringene dobler seg fra tjue dager.
A18: 60 | B18: =$B$5*A18/$B$6 | C18: =$B$7+B18 | D18: =C18-($B$7+$B$5*$B$8/$B$6) | E18: =C18*$B$9 | F18: To måneder. Her begynner kredittiden å kreve egen finansiering.
A19: 90 | B19: =$B$5*A19/$B$6 | C19: =$B$7+B19 | D19: =C19-($B$7+$B$5*$B$8/$B$6) | E19: =C19*$B$9 | F19: Tre måneder. Bedriften er blitt kundens bank.
A21: Les tabellen slik
A22: Linja er rett. Kapitalbehovet vokser proporsjonalt med kredittiden, fordi kundefordringene er kredittsalget ganget med en brøkdel av året.
A23: Kredittid er ikke en høflighet. Det er et rentefritt lån du gir kunden, og som du selv må låne penger for å kunne gi.
A24: Og legg merke til siste kolonne: egenkapitalkravet stiger sammen med kapitalbehovet. Lengre kredittid koster eierne penger, ikke bare banken.
A26: Kontroll
A27: Stemmer raden «Nordlys i 2019» med kalkulatoren? | C27: =IF(ABS(C15-Kapitalbehov!B31)<1,"OK — raden gir samme kapitalbehov som arket Kapitalbehov","AVVIK: raden stemmer ikke med kalkulatoren")
A28: Stiger kapitalbehovet med kredittiden? | C28: =IF(AND(C12<C13,C15<C16,C17<C18),"OK — lengre kredittid binder mer kapital, hele tabellen igjennom","AVVIK: tabellen skal stige nedover")
A29: Binder null dagers kredittid null kroner? | C29: =IF(B12=0,"OK — uten kreditt er ingen kapital bundet hos kundene","AVVIK: null dagers kredittid skal gi null i kundefordringer")
A31: Kilde: Bok 1 kap. 6.1.3 om kundefordringer. Tallene er Nordlys Elektro AS' egne.

Sheet Finansiering
A1: Hvem skal skaffe pengene?
A2: Kapitalbehovet sett fra den andre siden: egenkapital, langsiktig og kortsiktig gjeld.
A4: 1 · Kravene banken stiller
A5: Egenkapitalandel, krav | B5: 0.3 | E5: Bankens krav til hvor stor del av kapitalbehovet eierne selv må stille med.
A6: Andel av varelageret som må finansieres langsiktig | B6: 0.5 | E6: Gyllen finansieringsregel: anleggsmidlene i sin helhet, pluss den delen av varelageret som aldri tømmes.
A7: Kredittid fra leverandøren, dager | B7: 15 | E7: Betalingsfristen grossisten gir deg. Dette er gratis finansiering — så lenge du ikke går glipp av en kontantrabatt.
A9: 2 · Finansieringsplanen
A10: Kapitalbehov (fra arket Kapitalbehov) | B10: =Kapitalbehov!B31
A11: Egenkapital | B11: =B10*B5
A12: Krav til langsiktig kapital | B12: =Kapitalbehov!B7+Kapitalbehov!B22*B6 | E12: Anleggsmidler pluss den varige delen av varelageret.
A13: = Langsiktig gjeld, minimum | B13: =B12-B11 | E13: Kravet bestemmer den langsiktige gjelda. Den er ikke «resten etter egenkapitalen».
A14: Samlet lånebehov | B14: =B10-B11
A15: = Kortsiktig gjeld, maksimum | B15: =B14-B13 | E15: Det som blir til overs. DETTE er resten.
A16: herav leverandørgjeld | B16: =Kapitalbehov!B15*B7/Kapitalbehov!B18
A17: herav annen kortsiktig gjeld | B17: =B15-B16 | E17: Kassekreditt og skyldige offentlige avgifter.
A19: 3 · Egenkapitalen dere faktisk har
A20: Egenkapital eierne har | B20: 400000 | E20: Det Kari og Tom har på bok. Endre til deres egne tall.
A21: Egenkapitalandel det gir | B21: =B20/B10
A22: Mangler mot bankens krav | B22: =B11-B20
A23: Høyeste kapitalbehov egenkapitalen bærer | B23: =B20/B5 | E23: Under dette kapitalbehovet er kravet innfridd. Det er dette tallet klasseoppgaven skal ned til.
A24: Dom | E24: =IF(B21>=B5,"Kravet er innfridd","Kravet er ikke innfridd — kapitalbehovet må ned eller egenkapitalen opp")
A26: 4 · Åpningsbalansen 1. januar
A27: Eiendeler | B27: Kroner | C27: Egenkapital og gjeld | D27: Kroner
A28: Verktøy, utstyr og inventar | B28: =Kapitalbehov!B5 | C28: Egenkapital | D28: =B11
A29: Biler og maskiner | B29: =Kapitalbehov!B6 | C29: Langsiktig gjeld | D29: =B13
A30: Varelager | B30: =Kapitalbehov!B22 | C30: Leverandørgjeld | D30: =B16
A31: Kundefordringer | B31: =Kapitalbehov!B24 | C31: Annen kortsiktig gjeld | D31: =B17
A32: Kontanter og bankinnskudd | B32: =Kapitalbehov!B25
A33: = SUM EIENDELER | B33: =SUM(B28:B32) | C33: = SUM EGENKAPITAL OG GJELD | D33: =SUM(D28:D32) | E33: Begge sider er det samme kapitalbehovet, sett fra hver sin kant.
A35: Kontroll
A36: Balanserer åpningsbalansen? | B36: =IF(ABS(B33-D33)<1,"OK — eiendeler er lik egenkapital og gjeld","AVVIK: åpningsbalansen balanserer ikke")
A37: Summerer finansieringsplanen seg til kapitalbehovet? | B37: =IF(ABS(B11+B13+B15-B10)<1,"OK — egenkapital, langsiktig og kortsiktig gjeld dekker kapitalbehovet","AVVIK: finansieringsplanen summerer seg ikke til kapitalbehovet")
A38: Er den gylne finansieringsregelen innfridd? | B38: =IF(B11+B13>=B12-1,"OK — langsiktig kapital dekker anleggsmidlene og den varige delen av lageret","AVVIK: anleggsmidlene er delvis finansiert med kortsiktig gjeld — det er slik bedrifter går tomme for penger")
A39: Er det plass til annen kortsiktig gjeld? | B39: =IF(B17>=0,"OK — leverandørkreditten får plass innenfor den kortsiktige gjelda","AVVIK: leverandørkreditten alene overstiger det kortsiktige lånebehovet — da må mer finansieres langsiktig")
A41: Prøv dette: sett egenkapitalen i B20 og se på B21 og B24. Det er oppgave A2.
A42: Kilde: Bok 1 kap. 6.2 om finansieringsplanen og 6.3 om åpningsbalansen.

Sheet Scenario
A1: Tre scenarioer
A2: Endre de gule cellene og se hva som skjer. Alle tall hentes fra de andre arkene.
A4: Scenario A · anbudskunden krever lengre kredittid
A5: Samme omsetning, samme kredittandel, samme lager. Bare betalingsfristen er en annen.
B7: Nordlys i dag | C7: Scenario A | E7: Hva raden betyr
A8: Kredittid, dager | B8: =Kapitalbehov!B23 | C8: 40 | E8: Den gule cellen er scenarioet. Endre den fritt.
A9: Kundefordringer | B9: =Kapitalbehov!$B$17*B8/Kapitalbehov!$B$18 | C9: =Kapitalbehov!$B$17*C8/Kapitalbehov!$B$18 | E9: Kredittsalg inkl. mva. ganget med kredittiden delt på året.
A10: = Kapitalbehov | B10: =Kapitalbehov!$B$31-Kapitalbehov!$B$24+B9 | C10: =Kapitalbehov!$B$31-Kapitalbehov!$B$24+C9
A11: Egenkapitalkrav | B11: =B10*Finansiering!$B$5 | C11: =C10*Finansiering!$B$5
A12: Mer av eiernes egne penger | C12: =C11-B11 | E12: Dette er prisen på å vinne den avtalen — før første faktura er sendt.
A13: Én dag lengre kredittid binder | B13: =Kapitalbehov!B40
A15: Kontroll
A16: Binder lengre kredittid mer kapital? | B16: =IF(AND(C8>B8,C10>B10),"OK — lengre kredittid binder mer kapital og krever mer egenkapital","AVVIK: sett en lengre kredittid i C8 enn den i B8")
A19: Scenario B · klasseoppgaven: dere har ikke nok egenkapital
A20: Kari og Tom har det de har. Kapitalbehovet må ned til dem, ikke omvendt.
B22: Som planlagt | C22: Bilen leases | D22: + kortere lagringstid | E22: Hva raden betyr
A23: Anleggsmidler | B23: =Kapitalbehov!$B$7 | C23: =Kapitalbehov!$B$5 | D23: =Kapitalbehov!$B$5 | E23: Leasing tar servicebilen ut av anleggsmidlene.
A24: Lagringstid, dager | B24: =Kapitalbehov!$B$21 | C24: =Kapitalbehov!$B$21 | D24: 14 | E24: Den gule cellen: hvor kort må lageret ligge?
A25: Varelager | B25: =Kapitalbehov!$B$14*B24/Kapitalbehov!$B$18 | C25: =Kapitalbehov!$B$14*C24/Kapitalbehov!$B$18 | D25: =Kapitalbehov!$B$14*D24/Kapitalbehov!$B$18
A26: Kundefordringer | B26: =Kapitalbehov!$B$24 | C26: =Kapitalbehov!$B$24 | D26: =Kapitalbehov!$B$24
A27: Likviditetsreserve | B27: =Kapitalbehov!$B$25 | C27: =Kapitalbehov!$B$25 | D27: =Kapitalbehov!$B$25
A28: = Kapitalbehov | B28: =B23+B25+B26+B27 | C28: =C23+C25+C26+C27 | D28: =D23+D25+D26+D27
A29: Egenkapital eierne har | B29: =Finansiering!$B$20 | C29: =Finansiering!$B$20 | D29: =Finansiering!$B$20
A30: = Egenkapitalandel | B30: =B29/B28 | C30: =C29/C28 | D30: =D29/D28
A31: Bankens krav | B31: =Finansiering!$B$5 | C31: =Finansiering!$B$5 | D31: =Finansiering!$B$5
A32: Mangler mot kravet | B32: =B28*B31-B29 | C32: =C28*C31-C29 | D32: =D28*D31-D29 | E32: Negativt tall betyr at kravet er innfridd med god margin.
A33: Dom | B33: =IF(B30>=B31,"Over kravet","Under kravet") | C33: =IF(C30>=C31,"Over kravet","Under kravet") | D33: =IF(D30>=D31,"Over kravet","Under kravet")
A35: Kontroll
A36: Løser leasing alene problemet? | B36: =IF(C30<C31,"OK — leasing løfter egenkapitalandelen, men ikke helt opp til kravet. Én knapp alene holder ikke","AVVIK: leasing alene skal ikke være nok — da mister klasseoppgaven poenget")
A37: Her SKAL det stå OK selv om kravet ikke er innfridd i kolonne C. Det er hele poenget i klasseoppgaven: det trengs to grep, ikke ett.
A38: Kommer leasing pluss kortere lagringstid over kravet? | B38: =IF(D30>=D31,"OK — de to grepene sammen løfter dere over bankens krav","AVVIK: sett lagringstida i D24 lavere — dere er fortsatt under kravet")
A41: Scenario C · full ordrebok, tom konto (2026)
A42: Oppgave 5 i øvingsheftet. Sju år etter oppstarten. Regn først, drøft etterpå.
A44: Slik står Nordlys i dag
A45: Salgsinntekt inkl. mva. | B45: 28000000
A46: Varekostnad for året | B46: 8390000
A47: Kundefordringer | B47: 4200000
A48: Varelager | B48: 1400000
A49: Leverandørgjeld | B49: 2100000
A50: Bankinnskudd | B50: 1000000
...

Sheet Din bedrift
A1: Din egen bedrift
A2: Samme regnestykke, ingen tall. Fyll inn de gule cellene.
A4: 1 · Investeringene
A5: Verktøy, utstyr og inventar | B5: 0 | D5: Alt du kjøper og eier.
A6: Biler og maskiner | B6: 0 | D6: Sett null hvis du leaser.
A7: = Sum anleggsmidler | B7: =B5+B6
A9: 2 · Forutsetningene
A10: Budsjettert salg første år, inkl. mva. | B10: 0
A11: Merverdiavgiftssats | B11: 0.25
A12: Salgsinntekt uten mva. | B12: =B10/(1+B11)
A13: Budsjettert bruttofortjeneste | B13: 0
A14: = Varekostnad | B14: =B12*(1-B13)
A15: Varekjøp inkl. mva. | B15: =B14*(1+B11)
A16: Andel kredittsalg | B16: 0
A17: Kredittsalg inkl. mva. | B17: =B10*B16
A18: Dager i året | B18: 360
A20: 3 · Kapitalbindingen
A21: Lagringstid, dager | B21: 0
A22: Varelager | B22: =B14*B21/B18
A23: Kredittid til kundene, dager | B23: 0
A24: Kundefordringer | B24: =B17*B23/B18
A25: Likviditetsreserve | B25: 0
A26: = Driftskapitalbehov | B26: =B22+B24+B25
A28: 4 · Kapitalbehov og finansiering
A29: = KAPITALBEHOV | B29: =B7+B26
A30: Egenkapitalandel, krav | B30: 0.3
A31: Egenkapital | B31: =B29*B30
A32: Krav til langsiktig kapital | B32: =B7+B22*0.5
A33: Langsiktig gjeld, minimum | B33: =B32-B31
A34: Kortsiktig gjeld, maksimum | B34: =B29-B31-B33
A35: Egenkapital du faktisk har | B35: 0
A36: Egenkapitalandel det gir | B36: =IF(B29=0,"",B35/B29)
A38: Kontroll
A39: Er tallene fylt inn? | B39: =IF(B10=0,"AVVIK: fyll inn budsjettert salg i B10 før du leser av noe annet",IF(B29<=0,"AVVIK: kapitalbehovet er null — fyll inn investeringene og forutsetningene","OK — arket regner på dine egne tall"))
A40: Dette arket starter tomt, så kontrollen står på AVVIK helt til du har fylt inn tallene.
A41: Summerer finansieringen seg til kapitalbehovet? | B41: =IF(ABS(B31+B33+B34-B29)<1,"OK — finansieringen dekker kapitalbehovet","AVVIK: finansieringsplanen summerer seg ikke til kapitalbehovet")
A43: Ta arket med på jobb. Kapitalbehovet er den samme regningen enten bedriften er ett år eller tjue år gammel.
