Workbook

Sheet Veiledning
A1: Nøkkeltall — regnskapsanalyse
A2: LØM Økonomistyring kap. 4 · arbeidsregneark · Fagskolen Oslo, Avdeling Elkraft
A3: Emne: Teknisk kommunikasjon og ledelse for 1ET-klassene · LØM for 2ET, 2EK, 3EK og 4EK
A4: Fargekode
A5: Gul celle med blå skrift | B5: Inndata — dette er tallene du endrer.
A6: Grå eller lyseblå celle, svart skrift | B6: Formel — regner seg selv. Ikke skriv over den.
A7: Mørkeblå rad med hvit skrift | B7: Kolonneoverskrift.
A9: Ark i arbeidsboka
A10: Fra kapittel 3 | B10: Broen: de ni tallene kapittel 4 henter fra resultatet og balansen i kapittel 3, og hva som faktisk er nytt her.
A11: Nordlys | B11: Resultat og balanse for Nordlys Elektro AS 2026. Gule celler er postene i regnskapet. Her ligger den ene cellen du styrer alt fra: B5.
A12: Nøkkeltall | B12: De sju nøkkeltallene regnet av Nordlys-arket, med bransjetall og normtall ved siden av. Under dem de fem effektivitetstallene, Du Pont-modellen og de to vanligste regnefeilene.
A13: Din bedrift | B13: Samme oppstilling, tom for deg. Legg inn tallene fra din egen arbeidsplass, så følger alle sju nøkkeltallene med.
A14: Les og tolk | B14: To bedrifter side ved side. Her regner du ingenting — du skal vurdere.
A15: Scenario | B15: Tre spørsmål: hva et utbytte gjør med nøkkeltallene, hva som skjer når renta stiger, og hvilken av to bedrifter til salgs du ville kjøpt.
A17: De sju nøkkeltallene du skal kunne: driftsmargin, totalkapitalrentabilitet,
A18: egenkapitalrentabilitet, likviditetsgrad 1 og 2, egenkapitalandel og gjeldsgrad.
A19: Egenkapitalrentabiliteten regnes av ordinært resultat før skatt, ikke av årsresultatet.
A20: Rentabilitet regnes av GJENNOMSNITTLIG kapital, og krever derfor fjorårets balanse.
A21: Effektivitetstallene sier hvor LENGE pengene står bundet: kredittid kunder og
A22: leverandører, lagringstid, varelagerets og kapitalens omløpshastighet.
A23: Du Pont: totalkapitalrentabilitet = resultatgrad × kapitalens omløpshastighet.
A25: Tallene som ligger inne er et eksempel fra en elektrobedrift. Bytt dem ut med dine egne — alle formler følger med.
A26: Arbeidsregneark til LØM · Fagskolen Oslo, Avdeling Elkraft. Regnearket er øvingsstøtte, ikke et regnskapssystem.
A28: Den ene knappen
A29: Nordlys!B5 | B29: Salgsinntekt 2026 | C29: Endrer du denne cellen, følger alle sju nøkkeltallene og alle tre scenarioene med.
A31: Koblingen til kapittel 3
A32: LOM_Ovingsark_Okonomistyring_kap03_Resultat_og_balanse_NY.xlsx | B32: Regnearket til kapittel 3 | C32: Nøkkeltallene her er ikke nye opplysninger. De er det samme resultatet og den samme balansen, satt opp mot hverandre. Arket «Fra kapittel 3» viser hvilke ni tall som kommer derfra, og hva som faktisk er nytt.
A34: Hvilken oppgave bruker hvilket ark
A35: Oppgave i øvingsheftet | B35: Ark | C35: Celler du endrer og leser av
A36: A1 · Banken har ti minutter | B36: Nøkkeltall | C36: Les av kolonne C, D og E i radene 6 til 12.
A37: A2 · Eierne får tre ganger så mye | B37: Nøkkeltall, Scenario | C37: Les av C7, C8, C15, C16 og C17. Scenario B lar deg sette renta opp i B35.
A38: A3 · Klasseoppgave: kredittutvalget velger | B38: Les og tolk | C38: Søker B ligger som gule celler i C10 til C15. Kolonne E viser hvem som er høyest, og opptellingen står under tabellen.
A39: 1 · De fire lønnsomhetstallene | B39: Nordlys, Nøkkeltall | C39: Endre B5 til B18 i «Nordlys». Les av C6 i «Nøkkeltall», og avansen i C19.
A40: 2 · Kapitalavkastningen | B40: Nordlys, Nøkkeltall | C40: Se hvordan gjennomsnittstallene kommer fram i «Nordlys» radene 45 til 51. Les av C7, C8 og C15 i «Nøkkeltall», og de to regnefeilene i C47 og C48. Du Pont-blokka i radene 38 til 44 viser hvorfor TKR er som den er.
A41: 3 · Betalingsevne og soliditet | B41: Nordlys, Nøkkeltall | C41: Endre balansen i «Nordlys» B22 til B39. Les av C9, C10, C11, C12 og C18 i «Nøkkeltall». Deloppgave e) prøver du ved å flytte beløp fra B36 til B35. Effektivitetstallene i radene 27 til 35 viser hvor lenge pengene står bundet.
A42: 4 · Medeieren vil ha utbytte | B42: Scenario | C42: Scenario A: legg utbyttet i B7 og les av kolonne B og C i radene 10 til 19.
A43: 5 · Eksamensnær: hvilken ville du kjøpt? | B43: Scenario | C43: Scenario C: endre B53 til B60 og C53 til C60. Les av radene 63 til 77 — særlig B74 og C74, og B75, C75 og B77.
A45: Kontrollradene
A46: Hvert regneark har en kontrollblokk. Står det OK, henger tallene sammen. Står det AVVIK, farges cellen rød, og teksten sier hva som ikke går opp.
A47: Fem unntak: kontrollen på egenkapitalandelen i arket «Nøkkeltall», den første i «Les og tolk», de to første i scenario A og den første i scenario C skal vise AVVIK med tallene som ligger inne. Der er avviket selve svaret — Nordlys ligger under bransjen, søker B ser mest lønnsom ut, et utbytte gjør bedriften svakere samtidig som ett nøkkeltall ser bedre ut, og de to bedriftene til salgs koster praktisk talt det samme.
...

Sheet Nordlys
A1: Nordlys Elektro AS — resultat og balanse 2026
A2: Gule celler er postene fra regnskapet. Alt annet regner seg selv.
A4: 1 · Resultatregnskap 2026
A5: SALGSINNTEKT — den ene knappen | B5: 22400000 | D5: Dette er cellen du endrer. Alle sju nøkkeltallene og alle tre scenarioene henter herfra.
A6: Varekostnad materiell | B6: 7990000
A7: Varekostnad innleide montører | B7: 400000
A8: Sum varekostnad | B8: =B6+B7 | D8: Materiell og innleid hjelp.
A9: = Bruttofortjeneste | B9: =B5-B8 | D9: Det som er igjen før dine egne folk og alle regningene.
A10: Lønnskostnad | B10: 10660000
A11: Avskrivninger | B11: 620000
A12: Andre driftskostnader | B12: 1386000
A13: Sum driftskostnader | B13: =B8+B10+B11+B12
A14: = Driftsresultat | B14: =B5-B13 | D14: Telleren i driftsmarginen.
A15: Renteinntekter | B15: 56000
A16: Rentekostnader | B16: 210000 | D16: Legges tilbake i totalkapitalrentabiliteten — det er långivernes del.
A17: = Ordinært resultat før skatt | B17: =B14+B15-B16 | D17: Dette tallet brukes i både TKR og EKR.
A18: Skattekostnad | B18: 262000
A19: = Årsresultat | B19: =B17-B18 | D19: Brukes IKKE i egenkapitalrentabiliteten.
A21: 2 · Balanse pr. 31.12.2026 — eiendeler
A22: Maskiner og verktøy | B22: 1200000
A23: Biler | B23: 2400000
A24: Sum anleggsmidler | B24: =B22+B23
A25: Varelager | B25: 1400000 | D25: Det minst likvide omløpsmiddelet — trekkes ut i likviditetsgrad 2.
A26: Kundefordringer | B26: 4200000 | D26: Penger som er fakturert, men ikke kommet inn.
A27: Bankinnskudd | B27: 1000000
A28: = Sum omløpsmidler | B28: =B25+B26+B27
A29: = Sum eiendeler (totalkapital) | B29: =B24+B28
A31: 3 · Balanse pr. 31.12.2026 — egenkapital og gjeld
A32: Aksjekapital | B32: 300000
A33: Annen egenkapital | B33: 2610000
A34: = Sum egenkapital | B34: =B32+B33
A35: Banklån (langsiktig gjeld) | B35: 2800000
A36: Leverandørgjeld | B36: 2100000
A37: Skyldige offentlige avgifter | B37: 1200000 | D37: Forskuddstrekk, arbeidsgiveravgift og merverdiavgift. Faste forfallsdatoer.
A38: Skyldige feriepenger | B38: 890000
A39: Kassekreditt | B39: 300000
A40: = Sum kortsiktig gjeld | B40: =B36+B37+B38+B39
A41: Sum gjeld | B41: =B35+B40
A42: = Sum egenkapital og gjeld | B42: =B34+B41
A43: Balanserer den? | B43: =IF(B42=B29,"OK — de to sidene er like store","AVVIK: balansen går ikke opp")
...

Sheet Nøkkeltall
A1: De sju nøkkeltallene for Nordlys Elektro AS
A2: Alle tall er formler mot arket «Nordlys». Endrer du en post der, endrer nøkkeltallet seg her.
A4: 1 · De sju
A5: Nøkkeltall | B5: Slik regnes det | C5: Verdi | D5: Bransje eller norm | E5: Vurdering | F5: Hva det måler
A6: Driftsmargin | B6: Driftsresultat / salgsinntekt | C6: =Nordlys!B14/Nordlys!B5 | D6: 0.075 | E6: =IF(C6>=D6,"Over normen","Under normen") | F6: Hvor mye av hver fakturerte krone som blir igjen etter at hele driften er betalt.
A7: Totalkapitalrentabilitet | B7: (Ord. resultat før skatt + rentekostnader) / gj.sn. totalkapital | C7: =(Nordlys!B17+Nordlys!B16)/Nordlys!B49 | D7: 0.146 | E7: =IF(C7>=D7,"Over normen","Under normen") | F7: Avkastningen på hele kapitalen, uansett hvem som har skutt den inn.
A8: Egenkapitalrentabilitet | B8: Ordinært resultat før skatt / gj.sn. egenkapital | C8: =Nordlys!B17/Nordlys!B50 | D8: 0.2 | E8: =IF(C8>=D8,"Over normen","Under normen") | F8: Avkastningen på eiernes egne penger.
A9: Likviditetsgrad 1 | B9: Omløpsmidler / kortsiktig gjeld | C9: =Nordlys!B28/Nordlys!B40 | D9: 2 | E9: =IF(C9>=D9,"Over normen","Under normen") | F9: Om omløpsmidlene dekker gjelden som forfaller i år.
A10: Likviditetsgrad 2 | B10: (Omløpsmidler − varelager) / kortsiktig gjeld | C10: =(Nordlys!B28-Nordlys!B25)/Nordlys!B40 | D10: 1 | E10: =IF(C10>=D10,"Over normen","Under normen") | F10: Samme spørsmål, men uten det minst likvide omløpsmiddelet.
A11: Egenkapitalandel | B11: Egenkapital / totalkapital | C11: =Nordlys!B34/Nordlys!B29 | D11: 0.362 | E11: =IF(C11>=D11,"Over normen","Under normen") | F11: Hvor mye bedriften tåler å tape før det er långivernes penger som forsvinner.
A12: Gjeldsgrad | B12: Sum gjeld / egenkapital | C12: =Nordlys!B41/Nordlys!B34 | D12: 5 | E12: =IF(C12<=D12,"Innenfor","Over grensen") | F12: Hvor mange kroner bedriften skylder per krone eierne har inne.
A14: 2 · Sammenhengen som er kapitlets poeng
A15: Gjennomsnittlig lånerente | C15: =Nordlys!B16/Nordlys!B51 | F15: Rentekostnader delt på gjennomsnittlig gjeld.
A16: Margin: TKR minus lånerente, i prosentpoeng | C16: =(C7-C15)*100 | F16: Så mye kan lønnsomheten falle før gjelden begynner å spise egenkapitalen.
A17: EKR delt på TKR | C17: =C8/C7 | F17: Hvor mange ganger mer eierne får enn kapitalen som helhet.
A18: Arbeidskapital | C18: =Nordlys!B28-Nordlys!B40 | F18: Omløpsmidler minus kortsiktig gjeld, i kroner. Må være positiv.
A19: Avanse (bruttofortjeneste / varekostnad) | C19: =Nordlys!B9/Nordlys!B8 | F19: Samme kroner som bruttofortjenesten, men delt på varekostnaden i stedet for på salget.
A21: 3 · Effektivitet — hvor lenge står pengene bundet?
A22: Merverdiavgiftssats | B22: 0.25 | F22: Kredittidene regnes av fakturabeløpet, og det er med mva. Salgsinntekten i resultatet er uten.
A23: Salgsinntekt inkl. mva. | C23: =Nordlys!B5*(1+B22)
A24: Varekjøp inkl. mva. | C24: =Nordlys!B8*(1+B22) | F24: Vareforbruket er lik varekjøpet så lenge lageret er like stort ved inngangen og utgangen av året.
A26: Nøkkeltall | B26: Slik regnes det | C26: Verdi | F26: Hva det måler
A27: Kredittid kunder | B27: Kundefordringer × 365 / salgsinntekt inkl. mva. | C27: =Nordlys!B26*365/C23 | F27: Hvor mange dager det i snitt går fra du sender fakturaen til pengene er på konto.
A28: Kredittid leverandører | B28: Leverandørgjeld × 365 / varekjøp inkl. mva. | C28: =Nordlys!B36*365/C24 | F28: Hvor mange dager du i snitt bruker på å betale grossisten. Dette er gratis finansiering så lenge du holder fristen.
A29: Varelagerets omløpshastighet | B29: Varekostnad / varelager | C29: =Nordlys!B8/Nordlys!B25 | F29: Hvor mange ganger i året hele lageret selges ut og fylles opp igjen.
A30: Gjennomsnittlig lagringstid | B30: 365 / varelagerets omløpshastighet | C30: =365/C29 | F30: Hvor lenge en kveilrull i snitt står på hylla før den er montert og fakturert.
A31: Kapitalens omløpshastighet | B31: Salgsinntekt / gj.sn. totalkapital | C31: =Nordlys!B5/Nordlys!B49 | F31: Hvor mange kroner i omsetning hver krone i bedriften drar inn i løpet av et år.
A33: Avtalt kredittid på fakturaen, i dager | B33: 20 | F33: Den samme fristen budsjettet i kapittel 9 regner med.
A34: Så mange dager BRUKER kundene ut over avtalen | C34: =C27-B33 | F34: Dager Nordlys låner ut penger gratis.
A35: Ti dager kortere kredittid frigjør | C35: =C23*10/365 | F35: Uten én krone i økt omsetning. Fakturer samme dag jobben er ferdig, og purr.
A37: 4 · Du Pont — de to veiene til samme lønnsomhet
A38: Resultatgrad | C38: =(Nordlys!B17+Nordlys!B16)/Nordlys!B5 | F38: Hvor mye som blir igjen av hver krone du fakturerer.
A39: Kapitalens omløpshastighet | C39: =C31 | F39: Hvor mange kroner i omsetning hver krone i bedriften drar inn på et år.
A40: = Resultatgrad × omløpshastighet | C40: =C38*C39 | F40: Dette ER totalkapitalrentabiliteten. Du Pont er ingen ny formel — den viser de to knappene du kan skru på.
A42: To bedrifter, samme lønnsomhet, helt ulik drift
A43: Marginbedriften — få og store jobber, høyt påslag, mye kapital bundet | C43: =C38*2*(C39/2) | F43: Dobbel margin, halv omløpshastighet.
A44: Volumbedriften — mange små serviceoppdrag, lavt påslag, lite bundet kapital | C44: =(C38/2)*C39*2 | F44: Halv margin, dobbel omløpshastighet. Begge ender på det samme.
A46: 5 · De to vanligste regnefeilene
A47: TKR uten rentekostnadene i telleren | C47: =Nordlys!B17/Nordlys!B49 | F47: For lavt. Rentene er långivernes del av avkastningen og skal legges tilbake.
A48: EKR med årsresultatet i telleren | C48: =Nordlys!B19/Nordlys!B50 | F48: For lavt. Skattekostnaden sier lite om hvor godt bedriften drives.
...

Sheet Fra kapittel 3
A1: Nøkkeltallene er ikke nye tall
A2: Alt i dette regnearket er hentet fra det samme resultatet og den samme balansen som i kapittel 3.
A4: 1 · De ni tallene kapittel 4 henter fra kapittel 3
A5: Post | B5: Kroner | C5: Hva den brukes til her
A6: Salgsinntekt | B6: =Nordlys!B5 | C6: Nevneren i driftsmargin og resultatgrad.
A7: Driftsresultat | B7: =Nordlys!B14 | C7: Telleren i driftsmarginen.
A8: Ordinært resultat før skattekostnad | B8: =Nordlys!B17 | C8: Telleren i egenkapitalrentabiliteten, og en del av telleren i totalkapitalrentabiliteten.
A9: Rentekostnader | B9: =Nordlys!B16 | C9: Legges tilbake i totalkapitalrentabiliteten — det er långivernes del av avkastningen.
A10: Sum eiendeler (totalkapital) | B10: =Nordlys!B29 | C10: Nevneren i egenkapitalandelen.
A11: Sum egenkapital | B11: =Nordlys!B34 | C11: Telleren i egenkapitalandelen, nevneren i egenkapitalrentabiliteten.
A12: Sum omløpsmidler | B12: =Nordlys!B28 | C12: Telleren i likviditetsgrad 1.
A13: Varelager | B13: =Nordlys!B25 | C13: Trekkes ut av telleren i likviditetsgrad 2.
A14: Sum kortsiktig gjeld | B14: =Nordlys!B40 | C14: Nevneren i begge likviditetsgradene.
A16: 2 · Hva som er nytt i kapittel 4
A17: Inngående totalkapital 01.01.2026 | B17: =Nordlys!B46 | C17: Fjorårets balanse. Uten den kan ingen rentabilitet regnes.
A18: Bransjetall og normtall | C18: Kolonne D i arket «Nøkkeltall». Et nøkkeltall uten et sammenlikningsgrunnlag er bare et tall.
A19: Selve divisjonen | C19: Det er alt. Nøkkeltallene er de samme kronene, satt opp mot hverandre, slik at de kan sammenliknes med i fjor og med andre bedrifter.
A21: 3 · De fire som kan regnes av balansen alene
A22: Egenkapitalandel | B22: =Nøkkeltall!C11 | C22: Regnes også i arket «Til kapittel 4» i regnearket til kapittel 3 — samme formel, samme svar.
A23: Gjeldsgrad | B23: =Nøkkeltall!C12
A24: Likviditetsgrad 1 | B24: =Nøkkeltall!C9
A25: Likviditetsgrad 2 | B25: =Nøkkeltall!C10
A27: 4 · De tre som også trenger resultatregnskapet
A28: Driftsmargin | B28: =Nøkkeltall!C6 | C28: Trenger driftsresultatet.
A29: Totalkapitalrentabilitet | B29: =Nøkkeltall!C7 | C29: Trenger resultat før skatt, rentekostnadene og fjorårets balanse.
A30: Egenkapitalrentabilitet | B30: =Nøkkeltall!C8 | C30: Trenger resultat før skatt og fjorårets balanse.
A32: Kontroll
A33: Er de ni tallene formler mot arket «Nordlys»? | B33: =IF(AND(B6=Nordlys!B5,B10=Nordlys!B29,B11=Nordlys!B34,B14=Nordlys!B40),"OK — alle er formler. Endrer du en post i arket Nordlys, endrer nøkkeltallet seg overalt","AVVIK: en av koblingene er brutt")
A34: Går balansetallene opp? | B34: =IF(ABS(B10-Nordlys!B24-B12)<1,"OK — sum eiendeler er anleggsmidler pluss omløpsmidler","AVVIK: balansetallene henger ikke sammen")
A36: Poenget: en regnskapsanalyse tilfører ingen opplysninger. Den gjør de opplysningene du allerede har, sammenliknbare — med i fjor, med bransjen og med normtall. Derfor er det ingen vei utenom kapittel 3.
A37: Regnearket til kapittel 3: LOM_Ovingsark_Okonomistyring_kap03_Resultat_og_balanse_NY.xlsx. Der finner du de samme postene, og arket «Til kapittel 4» viser den samme broen fra den andre siden.

Sheet Din bedrift
A1: Din egen bedrift — samme oppstilling
A2: Skriv tallene fra din egen arbeidsplass over de gule cellene. Formlene følger med.
A4: Bedrift | B4: Skriv inn navnet her | D4: Regnskapsår | E4: 2026
A6: 1 · Resultatregnskap
A7: Salgsinntekt | B7: 22400000
A8: Sum varekostnad | B8: 8390000
A9: Lønnskostnad | B9: 10660000
A10: Avskrivninger | B10: 620000
A11: Andre driftskostnader | B11: 1386000
A12: Renteinntekter | B12: 56000
A13: Rentekostnader | B13: 210000
A14: Skattekostnad | B14: 262000
A15: = Driftsresultat | B15: =B7-B8-B9-B10-B11
A16: = Ordinært resultat før skatt | B16: =B15+B12-B13
A17: = Årsresultat | B17: =B16-B14
A19: 2 · Balanse
A20: Sum anleggsmidler | B20: 3600000
A21: Varelager | B21: 1400000
A22: Kundefordringer | B22: 4200000
A23: Bankinnskudd og kontanter | B23: 1000000
A24: Sum egenkapital | B24: 2910000
A25: Langsiktig gjeld | B25: 2800000
A26: Sum kortsiktig gjeld | B26: 4490000
A27: Totalkapital ved årets begynnelse | B27: 9400000
A28: = Sum omløpsmidler | B28: =B21+B22+B23
A29: = Sum eiendeler (totalkapital) | B29: =B20+B28
A30: = Sum gjeld | B30: =B25+B26
A31: = Sum egenkapital og gjeld | B31: =B24+B30
A32: Differanse | B32: =B29-B31 | F32: Skal være 0. Er den ikke det, har du glemt en post.
A33: Gjennomsnittlig totalkapital | B33: =(B27+B29)/2
A34: Egenkapital ved årets begynnelse | B34: =B24-B17
A35: Gjennomsnittlig egenkapital | B35: =(B34+B24)/2
A36: Gjennomsnittlig gjeld | B36: =((B27-B34)+B30)/2
A38: 3 · Dine sju nøkkeltall
A39: Nøkkeltall | B39: Din verdi | C39: Bransje eller norm | D39: Vurdering
A40: Driftsmargin | B40: =IF($B$7=0,"",B15/B7) | C40: 0.075 | D40: =IF(B40="","",IF(B40>=C40,"Over normen","Under normen"))
A41: Totalkapitalrentabilitet | B41: =IF(B33=0,"",(B16+B13)/B33) | C41: 0.146 | D41: =IF(B41="","",IF(B41>=C41,"Over normen","Under normen"))
A42: Egenkapitalrentabilitet | B42: =IF(B35=0,"",B16/B35) | C42: 0.2 | D42: =IF(B42="","",IF(B42>=C42,"Over normen","Under normen"))
A43: Likviditetsgrad 1 | B43: =IF(B26=0,"",B28/B26) | C43: 2 | D43: =IF(B43="","",IF(B43>=C43,"Over normen","Under normen"))
A44: Likviditetsgrad 2 | B44: =IF(B26=0,"",(B28-B21)/B26) | C44: 1 | D44: =IF(B44="","",IF(B44>=C44,"Over normen","Under normen"))
...

Sheet Les og tolk
A1: To søkere, én kassekreditt
A2: Her regner du ingenting. Nøkkeltallene er ferdig utregnet — du skal vurdere.
A4: Situasjonen
A5: To elektrobedrifter søker banken om utvidet kassekreditt før en stor rammeavtale. Bare én kan få ja.
A6: Bedrift A er Nordlys Elektro AS. Tallene hentes fra arket «Nøkkeltall».
A7: Bedrift B er Kystfiber Entreprenør AS. Tallene ligger i de gule cellene og kan endres.
A9: Nøkkeltall | B9: A: Nordlys Elektro AS | C9: B: Kystfiber Entreprenør AS | D9: Bransje eller norm | E9: Hvem har det høyeste tallet?
A10: Driftsmargin | B10: =Nøkkeltall!C6 | C10: 0.095 | D10: =Nøkkeltall!D6 | E10: =IF(C10>B10,"B","A")
A11: Totalkapitalrentabilitet | B11: =Nøkkeltall!C7 | C11: 0.19 | D11: =Nøkkeltall!D7 | E11: =IF(C11>B11,"B","A")
A12: Egenkapitalrentabilitet | B12: =Nøkkeltall!C8 | C12: 0.95 | D12: =Nøkkeltall!D8 | E12: =IF(C12>B12,"B","A")
A13: Likviditetsgrad 1 | B13: =Nøkkeltall!C9 | C13: 0.92 | D13: =Nøkkeltall!D9 | E13: =IF(C13>B13,"B","A")
A14: Likviditetsgrad 2 | B14: =Nøkkeltall!C10 | C14: 0.61 | D14: =Nøkkeltall!D10 | E14: =IF(C14>B14,"B","A")
A15: Egenkapitalandel | B15: =Nøkkeltall!C11 | C15: 0.12 | D15: =Nøkkeltall!D11 | E15: =IF(C15>B15,"B","A")
A16: Gjeldsgrad | B16: =Nøkkeltall!C12 | C16: =(1-C15)/C15 | D16: =Nøkkeltall!D12 | E16: =IF(C16>B16,"B","A")
E17: Her er høyest dårligst.
A19: Tell opp
A20: Antall nøkkeltall der B har det høyeste tallet | C20: =COUNTIF(E10:E16,"B")
A21: Av dem: antall der høyest faktisk er best | C21: =C20-IF(E16="B",1,0) | E21: Gjeldsgraden trekkes fra — der er høyest det dårligste.
A23: Kontroll
A24: Ser søker B mest lønnsom ut? | B24: =IF(AND(E10="B",E11="B",E12="B"),"AVVIK: søker B er best på alle tre lønnsomhetstallene. Nettopp derfor er dette en felle — banken hefter for soliditeten, ikke for lønnsomheten","OK — søker B er ikke best på alle lønnsomhetstallene")
A25: Her SKAL det stå AVVIK med tallene som ligger inne. Det er hele poenget i oppgave A3.
A26: Klarer søker B den kortsiktige gjelden? | B26: =IF(C13>=1,"OK — omløpsmidlene dekker den kortsiktige gjelden","AVVIK: likviditetsgrad 1 er under 100 prosent — omløpsmidlene dekker ikke engang gjelden som forfaller i år")
A27: Stemmer søker Bs gjeldsgrad med egenkapitalandelen? | B27: =IF(ABS(C16-(1-C15)/C15)<0.001,"OK — de to henger sammen","AVVIK: gjeldsgraden er regnet av noe annet enn egenkapitalandelen")
A29: Spørsmålene du skal svare på
A30: 1. Hvilken av de to vil banken låne ut til? Gi tre argumenter.
A31: 2. Minst ett av argumentene skal bruke et normtall fra læreboka.
A32: 3. B har nesten dobbelt så høy egenkapitalrentabilitet som A. Forklar hvorfor det ikke gjør B til den tryggeste låntakeren.
A33: 4. Hvilke tre tiltak ville du krevd av den som får nei?
A34: 5. Hva mangler du i denne tabellen for å være helt trygg på vurderingen din?
A36: Skriv vurderingen din her:
A42: Hint til spørsmål 3: se på nevneren i egenkapitalrentabiliteten. Jo mindre eierne har inne, jo større blir prosenten av det samme resultatet.
A43: Hint til spørsmål 5: nøkkeltallene sier ingenting om når kundene betaler, eller om ordrereserven for neste år.
A44: Kilde: metode og normtall fra Økonomistyring for LØM-emnet, kap. 4.2. Tallene for bedrift B er konstruert for øvingen; bedriftsnavnet er hentet fra casemiljøet rundt Nordlys Elektro AS.

Sheet Scenario
A1: Tre scenarioer
A2: Endre de gule cellene og se hva som skjer. Alle tall hentes fra de andre arkene.
A4: Scenario A · medeieren vil ha utbytte
A5: Oppgave 4 i øvingsheftet. Utbyttet tar penger ut av både egenkapitalen og bankkontoen.
A7: Utbytte som foreslås | B7: 600000 | E7: Endre denne og se hvor mye som skal til før tallene bryter normene.
A9: Nøkkeltall | B9: Før utbytte | C9: Etter utbytte | D9: Norm | E9: Hva som skjer
A10: Egenkapital | B10: =Nordlys!B34 | C10: =B10-$B$7
A11: Totalkapital | B11: =Nordlys!B29 | C11: =B11-$B$7
A12: Bankinnskudd | B12: =Nordlys!B27 | C12: =B12-$B$7 | E12: Utbyttet betales herfra. Blir tallet negativt, må bedriften trekke på kassekreditten.
A13: Omløpsmidler | B13: =Nordlys!B28 | C13: =B13-$B$7
A14: Egenkapitalandel | B14: =B10/B11 | C14: =C10/C11 | D14: =Nøkkeltall!D11 | E14: Faller. Bedriften blir mindre solid.
A15: Gjeldsgrad | B15: =(B11-B10)/B10 | C15: =(C11-C10)/C10 | D15: =Nøkkeltall!D12 | E15: Stiger. Samme sak som over, snudd på hodet.
A16: Likviditetsgrad 1 | B16: =B13/Nordlys!B40 | C16: =C13/Nordlys!B40 | D16: =Nøkkeltall!D9
A17: Likviditetsgrad 2 | B17: =(B13-Nordlys!B25)/Nordlys!B40 | C17: =(C13-Nordlys!B25)/Nordlys!B40 | D17: =Nøkkeltall!D10 | E17: Faller. Betalingsevnen blir svakere.
A18: Egenkapitalrentabilitet | B18: =Nordlys!B17/((Nordlys!B47+B10)/2) | C18: =Nordlys!B17/((Nordlys!B47+C10)/2) | D18: =Nøkkeltall!D8 | E18: STIGER — og det er hele poenget. Nevneren blir mindre.
A19: Utbyttet målt mot bankinnskuddet | B19: =$B$7/B12
A21: Kontroll
A22: Blir bedriften mindre solid av utbyttet? | B22: =IF(C14<B14,"AVVIK: egenkapitalandelen faller og gjeldsgraden stiger. Bedriften blir svakere på alt som betyr noe for banken","OK — utbyttet svekker ikke soliditeten")
A23: Her SKAL det stå AVVIK med tallene som ligger inne.
A24: Ser egenkapitalrentabiliteten bedre ut etterpå? | B24: =IF(C18>B18,"AVVIK: egenkapitalrentabiliteten STIGER av utbyttet, samtidig som alt annet blir svakere. Et høyt tall kan være et faresignal","OK — egenkapitalrentabiliteten stiger ikke")
A25: Også dette SKAL vise AVVIK. Det er kapitlets viktigste advarsel, satt i tall.
A26: Er det penger på konto til utbyttet? | B26: =IF(C12>=0,"OK — bankinnskuddet dekker utbyttet, men se hva som blir igjen til lønn og merverdiavgift","AVVIK: bankinnskuddet dekker ikke utbyttet — pengene må hentes fra kassekreditten")
A29: Scenario B · hva om renta stiger?
A30: Gjeldsgraden virker begge veier. Her ser du hvor grensen går.
A32: Gjennomsnittlig gjeld | B32: =Nordlys!B51
A33: Rentekostnader i dag | B33: =Nordlys!B16
A34: Gjennomsnittlig lånerente i dag | B34: =B33/B32
A35: Ny lånerente | B35: 0.06 | E35: Endre denne. Hvor høyt må den før eierne taper på gjelden?
A36: = Nye rentekostnader | B36: =B32*B35
A37: = Nytt ordinært resultat før skatt | B37: =Nordlys!B14+Nordlys!B15-B36
A38: Totalkapitalrentabilitet | B38: =(B37+B36)/Nordlys!B49 | E38: Uendret — TKR påvirkes ikke av renta. Rentene legges jo tilbake.
A39: Egenkapitalrentabilitet | B39: =B37/Nordlys!B50 | E39: Faller når renta stiger. Her ligger hele risikoen ved gjeldsgraden.
A40: Margin: TKR minus ny lånerente, i prosentpoeng | B40: =(B38-B35)*100
A41: Renta som gir null igjen til eierne | B41: =(Nordlys!B14+Nordlys!B15)/B32 | E41: Ved denne renta spiser rentekostnadene hele driftsresultatet.
A43: Kontroll
A44: Er totalkapitalrentabiliteten fortsatt høyere enn lånerenta? | B44: =IF(B38>B35,"OK — den lånte kapitalen tjener fortsatt mer enn den koster","AVVIK: lånerenta har passert totalkapitalrentabiliteten. Nå spiser gjelden egenkapitalen i stedet for å løfte den")
A45: Er totalkapitalrentabiliteten uavhengig av renta? | B45: =IF(ABS(B38-Nøkkeltall!C7)<0.0001,"OK — totalkapitalrentabiliteten er den samme uansett hva renta er. Det er nettopp derfor rentene legges tilbake i telleren","AVVIK: sjekk formlene — TKR skal ikke endre seg av renta alene")
A48: Scenario C · to bedrifter til salgs
A49: Oppgave 5 i øvingsheftet. Begge omsetter for det samme som Nordlys. Her regner du deg fra nøkkeltallene tilbake til kroner.
B51: Fjellheim Elektro AS | C51: Sørvest Installasjon AS | D51: Bransje | E51: Hva raden betyr
...
