Workbook

Sheet Enkelt
A1: Hvorfor får eierne 47,9 prosent? Den enkle versjonen
A2: Fyll inn de fire gule cellene. Svaret står i den grønne. Alt annet regner seg selv. Vil du gå dypere, ligger alle sju nøkkeltallene i arkene bak.
A4: Det du vet
A5: Hva ble resultatet før skatt? | B5: 1167500 | C5: Ordinært resultat før skatt. Ikke årsresultatet, for skatten sier lite om driften.
A6: Hvor mye betalte bedriften i renter? | B6: 232500 | C6: Rentekostnadene i resultatregnskapet. Det er bankens del.
A7: Hvor mye penger sto i bedriften i snitt gjennom året? | B7: 9791325 | C7: Gjennomsnittlig totalkapital: alt bedriften eier, i snitt av 1. januar og 31. desember.
A8: Hvor mye av det var eiernes egne penger, i snitt? | B8: 2437325 | C8: Gjennomsnittlig egenkapital. Resten er gjeld.
A10: Regnestykket
A11: Det hele kapitalen tjente | B11: =B5+B6 -> 1400000 | C11: Resultat før skatt pluss rentene. Rentene legges tilbake fordi de er bankens del.
A12: Totalkapitalrentabilitet | B12: =B11/B7 -> 0.14298371 | C12: Hva alle pengene i bedriften tjener. Bransjen ligger på 14,6 prosent.
A13: Gjeld i snitt gjennom året | B13: =B7-B8 -> 7354000 | C13: Det som ikke er eiernes, er lånt.
A14: Gjennomsnittlig gjeldsrente | B14: =B6/B13 -> 0.031615447 | C14: Rentene delt på all gjeld, også den rentefrie. Banken tar 7,5 % på lånene.
A16: EGENKAPITALRENTABILITET | B16: =B5/B8 -> 0.47900875 | C16: Hva eierne får igjen på sine egne penger.
A17: Hele kapitalen minus gjeldsrenta, i prosentpoeng | B17: =(B12-B14)*100 -> 11.136827 | C17: Så mye mer tjener de lånte pengene enn de koster. Blir tallet negativt, spises egenkapitalen.
A19: Hva svaret betyr
A20: ="Eierne får "&TEXT(B16,"0.0 %")&" på pengene sine, mens hele kapitalen tjener "&TEXT(B12,"0.0 %")&". Forskjellen kommer av at lånet koster "&TEXT(B14,"0.0 %")&" og egenkapitalen er liten." -> Eierne får 47.9 % på pengene sine, mens hele kapitalen tjener 14.3 %. Forskjellen kommer av at lånet koster 3.2 % og egenkapitalen er liten.
A22: Prøv selv
A23: 1. Dobbel rente: sett B6 til 420 000 og B5 til 980 000. Hva skjer med egenkapitalrentabiliteten?
A24: 2. Eierne skyter inn mer: sett B8 til 4 000 000. Blir tallet til eierne høyere eller lavere? Hvorfor?
A25: 3. Hva må stå i B5 for at B17 skal bli null eller negativt? Hva betyr det for eierne?
A27: Tallene er Nordlys Elektro AS sine for 2026 (sammendraget og arket «Nordlys»). Kilde: Økonomistyring for LØM-emnet, kap. 4.2.1 og 4.2.4. Nordlys Elektro AS er en konstruert casebedrift.

Sheet Veiledning
A1: Nøkkeltall — regnskapsanalyse
A2: LØM Økonomistyring kap. 4 · arbeidsregneark · Fagskolen Oslo, Avdeling Elkraft
A3: Emne: Teknisk kommunikasjon og ledelse for 1ET-klassene · LØM for 2ET, 2EK, 3EK og 4EK
A4: Fargekode
A5: Gul celle med blå skrift | B5: Inndata — dette er tallene du endrer.
A6: Grå eller lyseblå celle, svart skrift | B6: Formel — regner seg selv. Ikke skriv over den.
A7: Mørkeblå rad med hvit skrift | B7: Kolonneoverskrift.
A9: Ark i arbeidsboka
A10: Enkelt | B10: Start her. Fire gule celler, ett svar. Hvorfor eierne får 47,9 prosent når hele kapitalen tjener 14,3.
A11: Fra kapittel 3 | B11: Broen: de ni tallene kapittel 4 henter fra resultatet og balansen i kapittel 3, og hva som faktisk er nytt her.
A12: Nordlys | B12: Resultat og balanse for Nordlys Elektro AS 2026. Gule celler er postene i regnskapet. Her ligger den ene cellen du styrer alt fra: B5.
A13: Nøkkeltall | B13: De sju nøkkeltallene regnet av Nordlys-arket, med bransjetall og normtall ved siden av. Under dem de fem effektivitetstallene, resultatgraden og de to vanligste regnefeilene.
A14: Din bedrift | B14: Samme oppstilling, tom for deg. Legg inn tallene fra din egen arbeidsplass, så følger alle sju nøkkeltallene med.
A15: Les og tolk | B15: To bedrifter side ved side. Her regner du ingenting — du skal vurdere.
A16: Scenario | B16: Tre spørsmål: hva et utbytte gjør med nøkkeltallene, hva som skjer når renta stiger, og hvilken av to bedrifter til salgs du ville kjøpt.
A18: De sju nøkkeltallene du skal kunne: driftsmargin, totalkapitalrentabilitet,
A19: egenkapitalrentabilitet, likviditetsgrad 1 og 2, egenkapitalandel og gjeldsgrad.
A20: Egenkapitalrentabiliteten regnes av ordinært resultat før skatt, ikke av årsresultatet.
A21: Rentabilitet regnes av GJENNOMSNITTLIG kapital, og krever derfor fjorårets balanse.
A22: Effektivitetstallene sier hvor LENGE pengene står bundet: kredittid kunder og
A23: leverandører, lagringstid, varelagerets og kapitalens omløpshastighet.
A24: Kredittidene og lagringstiden regnes med 360 dager i året, slik boka gjør.
A26: Tallene som ligger inne er et eksempel fra en elektrobedrift. Bytt dem ut med dine egne — alle formler følger med.
A27: Arbeidsregneark til LØM · Fagskolen Oslo, Avdeling Elkraft. Regnearket er øvingsstøtte, ikke et regnskapssystem.
A29: Den ene knappen
A30: Nordlys!B5 | B30: Salgsinntekt 2026 | C30: Endrer du denne cellen, følger alle sju nøkkeltallene og alle tre scenarioene med.
A32: Koblingen til kapittel 3
A33: OK03_Bedriftens_regnskap_Regneark_Resultat_og_balanse.xlsx | B33: Regnearket til kapittel 3 | C33: Nøkkeltallene her er ikke nye opplysninger. De er det samme resultatet og den samme balansen, satt opp mot hverandre. Arket «Fra kapittel 3» viser hvilke ni tall som kommer derfra, og hva som faktisk er nytt.
A35: Hvilken oppgave bruker hvilket ark
A36: Oppgave i øvingsheftet | B36: Ark | C36: Celler du endrer og leser av
A37: A1 · Banken har ti minutter | B37: Nøkkeltall | C37: Les av kolonne C, D og E i radene 6 til 12.
A38: A2 · Eierne får tre ganger så mye | B38: Nøkkeltall, Scenario | C38: Les av C7, C8, C15, C16 og C17. Scenario B lar deg sette renta opp i B35.
A39: A3 · Klasseoppgave: kredittutvalget velger | B39: Les og tolk | C39: Søker B ligger som gule celler i C10 til C15. Kolonne E viser hvem som er høyest, og opptellingen står under tabellen.
A40: 1 · De fire lønnsomhetstallene | B40: Nordlys, Nøkkeltall | C40: Endre B5 til B18 i «Nordlys». Les av C6 i «Nøkkeltall», og avansen i C19.
A41: 2 · Kapitalavkastningen | B41: Nordlys, Nøkkeltall | C41: Se hvordan gjennomsnittstallene kommer fram i «Nordlys» radene 45 til 51. Les av C7, C8 og C15 i «Nøkkeltall», og de to regnefeilene i C41 og C42.
A42: 3 · Betalingsevne og soliditet | B42: Nordlys, Nøkkeltall | C42: Endre balansen i «Nordlys» B22 til B39. Les av C9, C10, C11, C12 og C18 i «Nøkkeltall». Deloppgave e) prøver du ved å flytte beløp fra B36 til B35. Effektivitetstallene i radene 27 til 35 viser hvor lenge pengene står bundet.
A43: 4 · Medeieren vil ha utbytte | B43: Scenario | C43: Scenario A: legg utbyttet i B7 og les av kolonne B og C i radene 10 til 19.
A44: 5 · Eksamensnær: hvilken ville du kjøpt? | B44: Scenario | C44: Scenario C: endre B53 til B60 og C53 til C60. Les av radene 63 til 77 — særlig B74 og C74, og B75, C75 og B77.
A46: Kontrollradene
A47: Hvert regneark har en kontrollblokk. Står det OK, henger tallene sammen. Står det AVVIK, farges cellen rød, og teksten sier hva som ikke går opp.
...

Sheet Nordlys
A1: Nordlys Elektro AS — resultat og balanse 2026
A2: Gule celler er postene fra regnskapet. Alt annet regner seg selv.
A4: 1 · Resultatregnskap 2026
A5: SALGSINNTEKT — den ene knappen | B5: 22400000 | D5: Dette er cellen du endrer. Alle sju nøkkeltallene og alle tre scenarioene henter herfra.
A6: Varekostnad materiell | B6: 7990000
A7: Varekostnad innleide montører | B7: 400000
A8: Sum varekostnad | B8: =B6+B7 -> 8390000 | D8: Materiell og innleid hjelp.
A9: = Bruttofortjeneste | B9: =B5-B8 -> 14010000 | D9: Det som er igjen før dine egne folk og alle regningene.
A10: Lønnskostnad | B10: 10660000
A11: Avskrivninger | B11: 620000
A12: Andre driftskostnader | B12: 1386000
A13: Sum driftskostnader | B13: =B8+B10+B11+B12 -> 21056000
A14: = Driftsresultat | B14: =B5-B13 -> 1344000 | D14: Telleren i driftsmarginen.
A15: Renteinntekter | B15: 56000
A16: Rentekostnader | B16: 232500 | D16: Legges tilbake i totalkapitalrentabiliteten — det er långivernes del.
A17: = Ordinært resultat før skatt | B17: =B14+B15-B16 -> 1167500 | D17: Dette tallet brukes i både TKR og EKR.
A18: Skattekostnad | B18: 256850
A19: = Årsresultat | B19: =B17-B18 -> 910650 | D19: Brukes IKKE i egenkapitalrentabiliteten.
A21: 2 · Balanse pr. 31.12.2026 — eiendeler
A22: Verktøy og måleinstrumenter | B22: 1200000
A23: Biler | B23: 2400000
A24: Sum anleggsmidler | B24: =B22+B23 -> 3600000
A25: Varelager | B25: 1400000 | D25: Det minst likvide omløpsmiddelet — trekkes ut i likviditetsgrad 2.
A26: Kundefordringer | B26: 4200000 | D26: Penger som er fakturert, men ikke kommet inn.
A27: Bankinnskudd | B27: 982650
A28: = Sum omløpsmidler | B28: =B25+B26+B27 -> 6582650
A29: = Sum eiendeler (totalkapital) | B29: =B24+B28 -> 10182650
A31: 3 · Balanse pr. 31.12.2026 — egenkapital og gjeld
A32: Aksjekapital | B32: 300000
A33: Annen egenkapital | B33: 2592650
A34: = Sum egenkapital | B34: =B32+B33 -> 2892650
A35: Banklån (langsiktig gjeld) | B35: 2800000
A36: Leverandørgjeld | B36: 2100000
A37: Skyldige offentlige avgifter | B37: 1200000 | D37: Forskuddstrekk, arbeidsgiveravgift og merverdiavgift. Faste forfallsdatoer.
A38: Skyldige feriepenger | B38: 890000
A39: Kassekreditt | B39: 300000
A40: = Sum kortsiktig gjeld | B40: =B36+B37+B38+B39 -> 4490000
A41: Sum gjeld | B41: =B35+B40 -> 7290000
A42: = Sum egenkapital og gjeld | B42: =B34+B41 -> 10182650
A43: Balanserer den? | B43: =IF(B42=B29,"OK — de to sidene er like store","AVVIK: balansen går ikke opp") -> OK — de to sidene er like store
...

Sheet Nøkkeltall
A1: De sju nøkkeltallene for Nordlys Elektro AS
A2: Alle tall er formler mot arket «Nordlys». Endrer du en post der, endrer nøkkeltallet seg her.
A4: 1 · De sju
A5: Nøkkeltall | B5: Slik regnes det | C5: Verdi | D5: Bransje eller norm | E5: Vurdering | F5: Hva det måler
A6: Driftsmargin | B6: Driftsresultat / salgsinntekt | C6: =Nordlys!B14/Nordlys!B5 -> 0.06 | D6: 0.075 | E6: =IF(C6>=D6,"Over normen","Under normen") -> Under normen | F6: Hvor mye av hver fakturerte krone som blir igjen etter at hele driften er betalt.
A7: Totalkapitalrentabilitet | B7: (Ord. resultat før skatt + rentekostnader) / gj.sn. totalkapital | C7: =(Nordlys!B17+Nordlys!B16)/Nordlys!B49 -> 0.14298371 | D7: 0.146 | E7: =IF(C7>=D7,"Over normen","Under normen") -> Under normen | F7: Avkastningen på hele kapitalen, uansett hvem som har skutt den inn.
A8: Egenkapitalrentabilitet | B8: Ordinært resultat før skatt / gj.sn. egenkapital | C8: =Nordlys!B17/Nordlys!B50 -> 0.47900875 | D8: 0.2 | E8: =IF(C8>=D8,"Over normen","Under normen") -> Over normen | F8: Avkastningen på eiernes egne penger.
A9: Likviditetsgrad 1 | B9: Omløpsmidler / kortsiktig gjeld | C9: =Nordlys!B28/Nordlys!B40 -> 1.466069 | D9: 2 | E9: =IF(C9>=D9,"Over normen","Under normen") -> Under normen | F9: Om omløpsmidlene dekker gjelden som forfaller i år.
A10: Likviditetsgrad 2 | B10: (Omløpsmidler − varelager) / kortsiktig gjeld | C10: =(Nordlys!B28-Nordlys!B25)/Nordlys!B40 -> 1.154265 | D10: 1 | E10: =IF(C10>=D10,"Over normen","Under normen") -> Over normen | F10: Samme spørsmål, men uten det minst likvide omløpsmiddelet.
A11: Egenkapitalandel | B11: Egenkapital / totalkapital | C11: =Nordlys!B34/Nordlys!B29 -> 0.28407635 | D11: 0.362 | E11: =IF(C11>=D11,"Over normen","Under normen") -> Under normen | F11: Hvor mye bedriften tåler å tape før det er långivernes penger som forsvinner.
A12: Gjeldsgrad | B12: Sum gjeld / egenkapital | C12: =Nordlys!B41/Nordlys!B34 -> 2.5201805 | D12: 5 | E12: =IF(C12<=D12,"Innenfor","Over grensen") -> Innenfor | F12: Hvor mange kroner bedriften skylder per krone eierne har inne.
A14: 2 · Sammenhengen som er kapitlets poeng
A15: Gjennomsnittlig gjeldsrente | C15: =Nordlys!B16/Nordlys!B51 -> 0.031615447 | F15: Rentekostnader delt på gjennomsnittlig gjeld, også den rentefrie. Banken tar 7,5 % på lån og kassekreditt.
A16: Margin: TKR minus gjeldsrente, i prosentpoeng | C16: =(C7-C15)*100 -> 11.136827 | F16: Så mye kan lønnsomheten falle før gjelden begynner å spise egenkapitalen.
A17: EKR delt på TKR | C17: =C8/C7 -> 3.3500931 | F17: Hvor mange ganger mer eierne får enn kapitalen som helhet.
A18: Arbeidskapital | C18: =Nordlys!B28-Nordlys!B40 -> 2092650 | F18: Omløpsmidler minus kortsiktig gjeld, i kroner. Må være positiv.
A19: Avanse (bruttofortjeneste / varekostnad) | C19: =Nordlys!B9/Nordlys!B8 -> 1.6698451 | F19: Samme kroner som bruttofortjenesten, men delt på varekostnaden i stedet for på salget.
A21: 3 · Effektivitet — hvor lenge står pengene bundet?
A22: Merverdiavgiftssats | B22: 0.25 | F22: Kredittidene regnes av fakturabeløpet, og det er med mva. Salgsinntekten i resultatet er uten.
A23: Salgsinntekt inkl. mva. | C23: =Nordlys!B5*(1+B22) -> 28000000
A24: Varekjøp inkl. mva. | C24: =Nordlys!B8*(1+B22) -> 10487500 | F24: Vareforbruket er lik varekjøpet så lenge lageret er like stort ved inngangen og utgangen av året.
A26: Nøkkeltall | B26: Slik regnes det | C26: Verdi | F26: Hva det måler
A27: Kredittid kunder | B27: Kundefordringer × 360 / salgsinntekt inkl. mva. | C27: =Nordlys!B26*360/C23 -> 54 | F27: Hvor mange dager det i snitt går fra du sender fakturaen til pengene er på konto.
A28: Kredittid leverandører | B28: Leverandørgjeld × 360 / varekjøp inkl. mva. | C28: =Nordlys!B36*360/C24 -> 72.085816 | F28: Hvor mange dager du i snitt bruker på å betale grossisten. Dette er gratis finansiering så lenge du holder fristen.
A29: Varelagerets omløpshastighet | B29: Varekostnad / varelager | C29: =Nordlys!B8/Nordlys!B25 -> 5.9928571 | F29: Hvor mange ganger i året hele lageret selges ut og fylles opp igjen.
A30: Gjennomsnittlig lagringstid | B30: 360 / varelagerets omløpshastighet | C30: =360/C29 -> 60.071514 | F30: Hvor lenge en kveilrull i snitt står på hylla før den er montert og fakturert.
A31: Kapitalens omløpshastighet | B31: Salgsinntekt / gj.sn. totalkapital | C31: =Nordlys!B5/Nordlys!B49 -> 2.2877394 | F31: Hvor mange kroner i omsetning hver krone i bedriften drar inn i løpet av et år.
A33: Avtalt kredittid på fakturaen, i dager | B33: 20 | F33: Den samme fristen budsjettet i kapittel 9 regner med.
A34: Så mange dager BRUKER kundene ut over avtalen | C34: =C27-B33 -> 34 | F34: Dager Nordlys låner ut penger gratis.
A35: Ti dager kortere kredittid frigjør | C35: =C23*10/360 -> 777777.78 | F35: Uten én krone i økt omsetning. Fakturer samme dag jobben er ferdig, og purr.
A37: 4 · Resultatgrad
A38: Resultatgrad | B38: (Resultat før skatt + rentekostnader) / salgsinntekt | C38: =(Nordlys!B17+Nordlys!B16)/Nordlys!B5 -> 0.0625 | F38: Hvor mye som blir igjen av hver krone du fakturerer.
A40: 5 · De to vanligste regnefeilene
A41: TKR uten rentekostnadene i telleren | C41: =Nordlys!B17/Nordlys!B49 -> 0.1192382 | F41: For lavt. Rentene er långivernes del av avkastningen og skal legges tilbake.
A42: EKR med årsresultatet i telleren | C42: =Nordlys!B19/Nordlys!B50 -> 0.37362682 | F42: For lavt. Skattekostnaden sier lite om hvor godt bedriften drives.
A44: Kontroll
A45: Er totalkapitalrentabiliteten høyere enn gjeldsrenta? | B45: =IF(C7>C15,"OK — den lånte kapitalen tjener mer enn den koster, og differansen tilfaller eierne","AVVIK: lånene spiser egenkapitalen — da virker gjeldsgraden mot eierne i stedet for for dem") -> OK — den lånte kapitalen tjener mer enn den koster, og differansen tilfaller eierne
A46: Er likviditetsgrad 2 lavere enn grad 1? | B46: =IF(C10<=C9,"OK — grad 2 er alltid lavest, fordi varelageret er trukket ut","AVVIK: varelageret kan ikke være negativt") -> OK — grad 2 er alltid lavest, fordi varelageret er trukket ut
A47: Stemmer gjeldsgraden med egenkapitalandelen? | B47: =IF(ABS(C12-(1-C11)/C11)<0.001,"OK — gjeldsgraden og egenkapitalandelen sier det samme to ganger. Den ene er den andre snudd på hodet","AVVIK: de to henger ikke sammen") -> OK — gjeldsgraden og egenkapitalandelen sier det samme to ganger. Den ene er den andre snudd på hodet
A48: Ligger egenkapitalandelen på bransjenivå? | B48: =IF(C11>=D11,"OK — egenkapitalandelen er på eller over bransjens nivå","AVVIK: egenkapitalandelen ligger under bransjen. Det er det første banken ser") -> AVVIK: egenkapitalandelen ligger under bransjen. Det er det første banken ser
...

Sheet Fra kapittel 3
A1: Nøkkeltallene er ikke nye tall
A2: Alt i dette regnearket er hentet fra det samme resultatet og den samme balansen som i kapittel 3.
A4: 1 · De ni tallene kapittel 4 henter fra kapittel 3
A5: Post | B5: Kroner | C5: Hva den brukes til her
A6: Salgsinntekt | B6: =Nordlys!B5 -> 22400000 | C6: Nevneren i driftsmargin og resultatgrad.
A7: Driftsresultat | B7: =Nordlys!B14 -> 1344000 | C7: Telleren i driftsmarginen.
A8: Ordinært resultat før skattekostnad | B8: =Nordlys!B17 -> 1167500 | C8: Telleren i egenkapitalrentabiliteten, og en del av telleren i totalkapitalrentabiliteten.
A9: Rentekostnader | B9: =Nordlys!B16 -> 232500 | C9: Legges tilbake i totalkapitalrentabiliteten — det er långivernes del av avkastningen.
A10: Sum eiendeler (totalkapital) | B10: =Nordlys!B29 -> 10182650 | C10: Nevneren i egenkapitalandelen.
A11: Sum egenkapital | B11: =Nordlys!B34 -> 2892650 | C11: Telleren i egenkapitalandelen, nevneren i egenkapitalrentabiliteten.
A12: Sum omløpsmidler | B12: =Nordlys!B28 -> 6582650 | C12: Telleren i likviditetsgrad 1.
A13: Varelager | B13: =Nordlys!B25 -> 1400000 | C13: Trekkes ut av telleren i likviditetsgrad 2.
A14: Sum kortsiktig gjeld | B14: =Nordlys!B40 -> 4490000 | C14: Nevneren i begge likviditetsgradene.
A16: 2 · Hva som er nytt i kapittel 4
A17: Inngående totalkapital 01.01.2026 | B17: =Nordlys!B46 -> 9400000 | C17: Fjorårets balanse. Uten den kan ingen rentabilitet regnes.
A18: Bransjetall og normtall | C18: Kolonne D i arket «Nøkkeltall». Et nøkkeltall uten et sammenlikningsgrunnlag er bare et tall.
A19: Selve divisjonen | C19: Det er alt. Nøkkeltallene er de samme kronene, satt opp mot hverandre, slik at de kan sammenliknes med i fjor og med andre bedrifter.
A21: 3 · De fire som kan regnes av balansen alene
A22: Egenkapitalandel | B22: =Nøkkeltall!C11 -> 0.28407635 | C22: Regnes også i arket «Til kapittel 4» i regnearket til kapittel 3 — samme formel, samme svar.
A23: Gjeldsgrad | B23: =Nøkkeltall!C12 -> 2.5201805
A24: Likviditetsgrad 1 | B24: =Nøkkeltall!C9 -> 1.466069
A25: Likviditetsgrad 2 | B25: =Nøkkeltall!C10 -> 1.154265
A27: 4 · De tre som også trenger resultatregnskapet
A28: Driftsmargin | B28: =Nøkkeltall!C6 -> 0.06 | C28: Trenger driftsresultatet.
A29: Totalkapitalrentabilitet | B29: =Nøkkeltall!C7 -> 0.14298371 | C29: Trenger resultat før skatt, rentekostnadene og fjorårets balanse.
A30: Egenkapitalrentabilitet | B30: =Nøkkeltall!C8 -> 0.47900875 | C30: Trenger resultat før skatt og fjorårets balanse.
A32: Kontroll
A33: Er de ni tallene formler mot arket «Nordlys»? | B33: =IF(AND(B6=Nordlys!B5,B10=Nordlys!B29,B11=Nordlys!B34,B14=Nordlys!B40),"OK — alle er formler. Endrer du en post i arket Nordlys, endrer nøkkeltallet seg overalt","AVVIK: en av koblingene er brutt") -> OK — alle er formler. Endrer du en post i arket Nordlys, endrer nøkkeltallet seg overalt
A34: Går balansetallene opp? | B34: =IF(ABS(B10-Nordlys!B24-B12)<1,"OK — sum eiendeler er anleggsmidler pluss omløpsmidler","AVVIK: balansetallene henger ikke sammen") -> OK — sum eiendeler er anleggsmidler pluss omløpsmidler
A36: Poenget: en regnskapsanalyse tilfører ingen opplysninger. Den gjør de opplysningene du allerede har, sammenliknbare — med i fjor, med bransjen og med normtall. Derfor er det ingen vei utenom kapittel 3.
A37: Regnearket til kapittel 3: OK03_Bedriftens_regnskap_Regneark_Resultat_og_balanse.xlsx. Der finner du de samme postene, og arket «Til kapittel 4» viser den samme broen fra den andre siden.

Sheet Din bedrift
A1: Din egen bedrift — samme oppstilling
A2: Skriv tallene fra din egen arbeidsplass over de gule cellene. Formlene følger med.
A4: Bedrift | B4: Skriv inn navnet her | D4: Regnskapsår | E4: 2026
A6: 1 · Resultatregnskap
A7: Salgsinntekt | B7: 22400000
A8: Sum varekostnad | B8: 8390000
A9: Lønnskostnad | B9: 10660000
A10: Avskrivninger | B10: 620000
A11: Andre driftskostnader | B11: 1386000
A12: Renteinntekter | B12: 56000
A13: Rentekostnader | B13: 232500
A14: Skattekostnad | B14: 256850
A15: = Driftsresultat | B15: =B7-B8-B9-B10-B11 -> 1344000
A16: = Ordinært resultat før skatt | B16: =B15+B12-B13 -> 1167500
A17: = Årsresultat | B17: =B16-B14 -> 910650
A19: 2 · Balanse
A20: Sum anleggsmidler | B20: 3600000
A21: Varelager | B21: 1400000
A22: Kundefordringer | B22: 4200000
A23: Bankinnskudd og kontanter | B23: 982650
A24: Sum egenkapital | B24: 2892650
A25: Langsiktig gjeld | B25: 2800000
A26: Sum kortsiktig gjeld | B26: 4490000
A27: Totalkapital ved årets begynnelse | B27: 9400000
A28: = Sum omløpsmidler | B28: =B21+B22+B23 -> 6582650
A29: = Sum eiendeler (totalkapital) | B29: =B20+B28 -> 10182650
A30: = Sum gjeld | B30: =B25+B26 -> 7290000
A31: = Sum egenkapital og gjeld | B31: =B24+B30 -> 10182650
A32: Differanse | B32: =B29-B31 -> 0 | F32: Skal være 0. Er den ikke det, har du glemt en post.
A33: Gjennomsnittlig totalkapital | B33: =(B27+B29)/2 -> 9791325
A34: Egenkapital ved årets begynnelse | B34: =B24-B17 -> 1982000
A35: Gjennomsnittlig egenkapital | B35: =(B34+B24)/2 -> 2437325
A36: Gjennomsnittlig gjeld | B36: =((B27-B34)+B30)/2 -> 7354000
A38: 3 · Dine sju nøkkeltall
A39: Nøkkeltall | B39: Din verdi | C39: Bransje eller norm | D39: Vurdering
A40: Driftsmargin | B40: =IF($B$7=0,"",B15/B7) -> 0.06 | C40: 0.075 | D40: =IF(B40="","",IF(B40>=C40,"Over normen","Under normen")) -> Under normen
A41: Totalkapitalrentabilitet | B41: =IF(B33=0,"",(B16+B13)/B33) -> 0.14298371 | C41: 0.146 | D41: =IF(B41="","",IF(B41>=C41,"Over normen","Under normen")) -> Under normen
A42: Egenkapitalrentabilitet | B42: =IF(B35=0,"",B16/B35) -> 0.47900875 | C42: 0.2 | D42: =IF(B42="","",IF(B42>=C42,"Over normen","Under normen")) -> Over normen
A43: Likviditetsgrad 1 | B43: =IF(B26=0,"",B28/B26) -> 1.466069 | C43: 2 | D43: =IF(B43="","",IF(B43>=C43,"Over normen","Under normen")) -> Under normen
A44: Likviditetsgrad 2 | B44: =IF(B26=0,"",(B28-B21)/B26) -> 1.154265 | C44: 1 | D44: =IF(B44="","",IF(B44>=C44,"Over normen","Under normen")) -> Over normen
...

Sheet Les og tolk
A1: To søkere, én kassekreditt
A2: Her regner du ingenting. Nøkkeltallene er ferdig utregnet — du skal vurdere.
A4: Situasjonen
A5: To elektrobedrifter søker banken om utvidet kassekreditt før en stor rammeavtale. Bare én kan få ja.
A6: Bedrift A er Nordlys Elektro AS. Tallene hentes fra arket «Nøkkeltall».
A7: Bedrift B er Kystfiber Entreprenør AS. Tallene ligger i de gule cellene og kan endres.
A9: Nøkkeltall | B9: A: Nordlys Elektro AS | C9: B: Kystfiber Entreprenør AS | D9: Bransje eller norm | E9: Hvem har det høyeste tallet?
A10: Driftsmargin | B10: =Nøkkeltall!C6 -> 0.06 | C10: 0.095 | D10: =Nøkkeltall!D6 -> 0.075 | E10: =IF(C10>B10,"B","A") -> B
A11: Totalkapitalrentabilitet | B11: =Nøkkeltall!C7 -> 0.14298371 | C11: 0.19 | D11: =Nøkkeltall!D7 -> 0.146 | E11: =IF(C11>B11,"B","A") -> B
A12: Egenkapitalrentabilitet | B12: =Nøkkeltall!C8 -> 0.47900875 | C12: 0.95 | D12: =Nøkkeltall!D8 -> 0.2 | E12: =IF(C12>B12,"B","A") -> B
A13: Likviditetsgrad 1 | B13: =Nøkkeltall!C9 -> 1.466069 | C13: 0.92 | D13: =Nøkkeltall!D9 -> 2 | E13: =IF(C13>B13,"B","A") -> A
A14: Likviditetsgrad 2 | B14: =Nøkkeltall!C10 -> 1.154265 | C14: 0.61 | D14: =Nøkkeltall!D10 -> 1 | E14: =IF(C14>B14,"B","A") -> A
A15: Egenkapitalandel | B15: =Nøkkeltall!C11 -> 0.28407635 | C15: 0.12 | D15: =Nøkkeltall!D11 -> 0.362 | E15: =IF(C15>B15,"B","A") -> A
A16: Gjeldsgrad | B16: =Nøkkeltall!C12 -> 2.5201805 | C16: =(1-C15)/C15 -> 7.3333333 | D16: =Nøkkeltall!D12 -> 5 | E16: =IF(C16>B16,"B","A") -> B
E17: Her er høyest dårligst.
A19: Tell opp
A20: Antall nøkkeltall der B har det høyeste tallet | C20: =COUNTIF(E10:E16,"B") -> 4
A21: Av dem: antall der høyest faktisk er best | C21: =C20-IF(E16="B",1,0) -> 3 | E21: Gjeldsgraden trekkes fra — der er høyest det dårligste.
A23: Kontroll
A24: Ser søker B mest lønnsom ut? | B24: =IF(AND(E10="B",E11="B",E12="B"),"AVVIK: søker B er best på alle tre lønnsomhetstallene. Nettopp derfor er dette en felle — banken hefter for soliditeten, ikke for lønnsomheten","OK — søker B er ikke best på alle lønnsomhetstallene") -> AVVIK: søker B er best på alle tre lønnsomhetstallene. Nettopp derfor er dette en felle — banken hefter for soliditeten, ikke for lønnsomheten
A25: Her SKAL det stå AVVIK med tallene som ligger inne. Det er hele poenget i oppgave A3.
A26: Klarer søker B den kortsiktige gjelden? | B26: =IF(C13>=1,"OK — omløpsmidlene dekker den kortsiktige gjelden","AVVIK: likviditetsgrad 1 er under 100 prosent — omløpsmidlene dekker ikke engang gjelden som forfaller i år") -> AVVIK: likviditetsgrad 1 er under 100 prosent — omløpsmidlene dekker ikke engang gjelden som forfaller i år
A27: Stemmer søker Bs gjeldsgrad med egenkapitalandelen? | B27: =IF(ABS(C16-(1-C15)/C15)<0.001,"OK — de to henger sammen","AVVIK: gjeldsgraden er regnet av noe annet enn egenkapitalandelen") -> OK — de to henger sammen
A29: Spørsmålene du skal svare på
A30: 1. Hvilken av de to vil banken låne ut til? Gi tre argumenter.
A31: 2. Minst ett av argumentene skal bruke et normtall fra læreboka.
A32: 3. B har nesten dobbelt så høy egenkapitalrentabilitet som A. Forklar hvorfor det ikke gjør B til den tryggeste låntakeren.
A33: 4. Hvilke tre tiltak ville du krevd av den som får nei?
A34: 5. Hva mangler du i denne tabellen for å være helt trygg på vurderingen din?
A36: Skriv vurderingen din her:
A42: Hint til spørsmål 3: se på nevneren i egenkapitalrentabiliteten. Jo mindre eierne har inne, jo større blir prosenten av det samme resultatet.
A43: Hint til spørsmål 5: nøkkeltallene sier ingenting om når kundene betaler, eller om ordrereserven for neste år.
A44: Kilde: metode og normtall fra Økonomistyring for LØM-emnet, kap. 4.2. Tallene for bedrift B er konstruert for øvingen; bedriftsnavnet er hentet fra casemiljøet rundt Nordlys Elektro AS.

Sheet Scenario
A1: Tre scenarioer
A2: Endre de gule cellene og se hva som skjer. Alle tall hentes fra de andre arkene.
A4: Scenario A · medeieren vil ha utbytte
A5: Oppgave 4 i øvingsheftet. Utbyttet tar penger ut av både egenkapitalen og bankkontoen.
A7: Utbytte som foreslås | B7: 600000 | E7: Endre denne og se hvor mye som skal til før tallene bryter normene.
A9: Nøkkeltall | B9: Før utbytte | C9: Etter utbytte | D9: Norm | E9: Hva som skjer
A10: Egenkapital | B10: =Nordlys!B34 -> 2892650 | C10: =B10-$B$7 -> 2292650
A11: Totalkapital | B11: =Nordlys!B29 -> 10182650 | C11: =B11-$B$7 -> 9582650
A12: Bankinnskudd | B12: =Nordlys!B27 -> 982650 | C12: =B12-$B$7 -> 382650 | E12: Utbyttet betales herfra. Blir tallet negativt, må bedriften trekke på kassekreditten.
A13: Omløpsmidler | B13: =Nordlys!B28 -> 6582650 | C13: =B13-$B$7 -> 5982650
A14: Egenkapitalandel | B14: =B10/B11 -> 0.28407635 | C14: =C10/C11 -> 0.2392501 | D14: =Nøkkeltall!D11 -> 0.362 | E14: Faller. Bedriften blir mindre solid.
A15: Gjeldsgrad | B15: =(B11-B10)/B10 -> 2.5201805 | C15: =(C11-C10)/C10 -> 3.1797265 | D15: =Nøkkeltall!D12 -> 5 | E15: Stiger. Samme sak som over, snudd på hodet.
A16: Likviditetsgrad 1 | B16: =B13/Nordlys!B40 -> 1.466069 | C16: =C13/Nordlys!B40 -> 1.3324388 | D16: =Nøkkeltall!D9 -> 2
A17: Likviditetsgrad 2 | B17: =(B13-Nordlys!B25)/Nordlys!B40 -> 1.154265 | C17: =(C13-Nordlys!B25)/Nordlys!B40 -> 1.0206347 | D17: =Nøkkeltall!D10 -> 1 | E17: Faller. Betalingsevnen blir svakere.
A18: Egenkapitalrentabilitet | B18: =Nordlys!B17/((Nordlys!B47+B10)/2) -> 0.47900875 | C18: =Nordlys!B17/((Nordlys!B47+C10)/2) -> 0.54624355 | D18: =Nøkkeltall!D8 -> 0.2 | E18: STIGER — og det er hele poenget. Nevneren blir mindre.
A19: Utbyttet målt mot bankinnskuddet | B19: =$B$7/B12 -> 0.6105938
A21: Kontroll
A22: Blir bedriften mindre solid av utbyttet? | B22: =IF(C14<B14,"AVVIK: egenkapitalandelen faller og gjeldsgraden stiger. Bedriften blir svakere på alt som betyr noe for banken","OK — utbyttet svekker ikke soliditeten") -> AVVIK: egenkapitalandelen faller og gjeldsgraden stiger. Bedriften blir svakere på alt som betyr noe for banken
A23: Her SKAL det stå AVVIK med tallene som ligger inne.
A24: Ser egenkapitalrentabiliteten bedre ut etterpå? | B24: =IF(C18>B18,"AVVIK: egenkapitalrentabiliteten STIGER av utbyttet, samtidig som alt annet blir svakere. Et høyt tall kan være et faresignal","OK — egenkapitalrentabiliteten stiger ikke") -> AVVIK: egenkapitalrentabiliteten STIGER av utbyttet, samtidig som alt annet blir svakere. Et høyt tall kan være et faresignal
A25: Også dette SKAL vise AVVIK. Det er kapitlets viktigste advarsel, satt i tall.
A26: Er det penger på konto til utbyttet? | B26: =IF(C12>=0,"OK — bankinnskuddet dekker utbyttet, men se hva som blir igjen til lønn og merverdiavgift","AVVIK: bankinnskuddet dekker ikke utbyttet — pengene må hentes fra kassekreditten") -> OK — bankinnskuddet dekker utbyttet, men se hva som blir igjen til lønn og merverdiavgift
A29: Scenario B · hva om renta stiger?
A30: Gjeldsgraden virker begge veier. Her ser du hvor grensen går.
A32: Gjennomsnittlig gjeld | B32: =Nordlys!B51 -> 7354000
A33: Rentekostnader i dag | B33: =Nordlys!B16 -> 232500
A34: Gjennomsnittlig gjeldsrente i dag | B34: =B33/B32 -> 0.031615447
A35: Ny gjeldsrente, snitt av all gjeld (15 % på lånene, det dobbelte av i dag) | B35: 0.063 | E35: Endre denne. Hvor høyt må den før eierne taper på gjelden?
A36: = Nye rentekostnader | B36: =B32*B35 -> 463302
A37: = Nytt ordinært resultat før skatt | B37: =Nordlys!B14+Nordlys!B15-B36 -> 936698
A38: Totalkapitalrentabilitet | B38: =(B37+B36)/Nordlys!B49 -> 0.14298371 | E38: Uendret — TKR påvirkes ikke av renta. Rentene legges jo tilbake.
A39: Egenkapitalrentabilitet | B39: =B37/Nordlys!B50 -> 0.38431395 | E39: Faller når renta stiger. Her ligger hele risikoen ved gjeldsgraden.
A40: Margin: TKR minus ny gjeldsrente, i prosentpoeng | B40: =(B38-B35)*100 -> 7.9983713
A41: Renta som gir null igjen til eierne | B41: =(Nordlys!B14+Nordlys!B15)/B32 -> 0.19037259 | E41: Ved denne renta spiser rentekostnadene hele driftsresultatet.
A43: Kontroll
A44: Er totalkapitalrentabiliteten fortsatt høyere enn gjeldsrenta? | B44: =IF(B38>B35,"OK — den lånte kapitalen tjener fortsatt mer enn den koster","AVVIK: gjeldsrenta har passert totalkapitalrentabiliteten. Nå spiser gjelden egenkapitalen i stedet for å løfte den") -> OK — den lånte kapitalen tjener fortsatt mer enn den koster
A45: Er totalkapitalrentabiliteten uavhengig av renta? | B45: =IF(ABS(B38-Nøkkeltall!C7)<0.0001,"OK — totalkapitalrentabiliteten er den samme uansett hva renta er. Det er nettopp derfor rentene legges tilbake i telleren","AVVIK: sjekk formlene — TKR skal ikke endre seg av renta alene") -> OK — totalkapitalrentabiliteten er den samme uansett hva renta er. Det er nettopp derfor rentene legges tilbake i telleren
A48: Scenario C · to bedrifter til salgs
A49: Oppgave 5 i øvingsheftet. Begge omsetter for det samme som Nordlys. Her regner du deg fra nøkkeltallene tilbake til kroner.
B51: Fjellheim Elektro AS | C51: Sørvest Installasjon AS | D51: Bransje | E51: Hva raden betyr
...
